Workbook

Sheet 00_はじめに
A1: 🔬 ブレーキパッド EMA｜カーブフィット・窓関数・Excel解析ブック
A2: ハンマリング / PSV-400 / RION SA-01A4 → RFP法によるモード分離（双子モード対応） ｜ ME'scopeVES 準拠の数式つき
A4: ■ このブックの使い方（3行で）
B5: ① | C5: 黄色いセルにだけ数字を入れる。緑のセルが答え。白（灰）のセルは触らない。
B6: ② | C6: シートは左から右へ、番号順に進めば必ず答えにたどり着きます。
B7: ③ | C7: まず「16_検算用サンプルデータ」で練習 → 正解が出たら本番データに差し替え。
A9: ■ セルの色のルール（これだけ覚えれば迷いません）
B10: 色 | C10: 意味 | D10: やること
B11: 黄色（濃い金色の背景） | C11: あなたが入力する場所 | D11: 測定値・推定値をここに打ち込む
B12: 緑（深緑の背景） | C12: 最終的な答え | D12: 読むだけ。書き換えない
B13: 灰色（濃紺の背景） | C13: 途中計算 | D13: 読むだけ。書き換えると壊れます
B14: 赤（暗赤の背景） | C14: 警告・注意 | D14: 出たら必ず本文の指示に従う
A17: ■ 作業の流れ（シート順＝作業順です）
B18: # | C18: シート名 | D18: そこで何をするか | E18: 入力するもの | F18: 出てくるもの
B19: 01 | C19: 01_測定条件の設計 | D19: 窓を使わずに済む測定条件（記録時間・点数）を決める | E19: 予想 fn・予想 η・解析レンジ | F19: 必要記録時間 t、選ぶべき N、Δf
B20: 02 | C20: 02_窓関数の選定 | D20: 窓が要るか要らないかを判定し、要る場合の補正量を出す | E20: 時間波形の終端の様子、指数窓の終端減衰値 | F20: 窓の種類、振幅補正係数、減衰の上乗せ量
B21: 03 | C21: 03_FRFデータ貼付 | D21: 測ったFRFを貼る（ここが全ての出発点） | E21: f [Hz]、Re(H)、Im(H) の3列 | F21: 正規化された Ω・Hn（自動）
B22: 04 | C22: 04_モード数の確認 | D22: 山がいくつあるか数える（＝モード数の決定） | E22: ピーク判定のしきい値 | F22: ピーク位置と本数
B23: 05 | C23: 05_半値幅法_SDOF | D23: 一番簡単な方法で当たりを付ける（初期値づくり） | E23: （自動） | F23: ピーク周波数・η・Q・妥当性の警告
B24: 06 | C24: 06_RFP設計行列 | D24: 連立方程式の材料をつくる（自動） | E24: なし | F24: 240行×8列の係数行列
B25: 07 | C25: 07_RFP係数の解 | D25: 最小二乗法で分子b・分母aを解く（自動） | E25: リッジ係数（通常そのまま） | F25: b0〜b3、a0〜a3
B26: 08 | C26: 08_極の分離_ニュートン法 | D26: 4次方程式を2つに割って双子モードを分離 | E26: 山1・山2の目視周波数、ηの粗推定 | F26: p1,q1,p2,q2（＝2つのモード）
B27: 09 | C27: 09_モーダル諸元 | D27: 固有振動数・減衰を工学単位に変換 | E27: （自動） | F27: fn, fd, ζ, η, Q, 半値幅、指数窓補正後の値
B28: 10 | C28: 10_レジデュー_MEscope | D28: ME'scope手順③に相当。残差＝モード形状の成分を出す | E28: （自動） | F28: レジデュー r、モーダル質量、有効質量
B29: 11 | C29: 11_合成FRFの照合 | D29: 当てはめが成功したかをグラフで目視確認 | E29: （自動） | F29: 合成FRF、相対誤差 [%]、比較グラフ
... B36: 18 | C36: 18_測定記録 | D36: 測定条件を1枚に記録（再現性の担保） | E36: 測定条件 | F36: 解析結果の自動転記
A37: ■ 最短ルート（時間がないとき）
B38: 03 にデータを貼る → 05 で山の周波数を読む → 08 にその2つを打ち込む → 09 で答えを読む → 11 で誤差を確認。以上5手です。
A40: ■ 注意（必ず読んでください）
B41: ・このブックは「2つのモードが重なった帯域（双子モード）」を分離するために作ってあります。1本しか山がない時は 05 の半値幅法だけで十分です。
B42: ・3本以上のモードが重なる帯域には、このブックの RFP（分母4次）は使えません。Python（scipy）へ移行してください。
B43: ・Excelは複素数の固有値分解ができないため、本物の PolyMAX（多参照の多項式固有値問題）そのものは組めません。ここで組んでいるのは、考え方が同じ RFP法（有理多項式法）です。
B44: ・数値は必ず 11_合成FRFの照合 のグラフで「実測と合っているか」を目で確認してください。数字だけを信じないこと。

Sheet 01_測定条件の設計
A1: ① 測定条件の設計｜窓を使わずに済ませるための記録時間を決める
A2: 考え方：叩いた後の揺れが「1コマの中で消えきる」なら窓は不要。消えきらないなら窓が必要になる。
A4: ■ Step1｜叩いた揺れが消えるまでの時間 t を見積もる
B5: 予想される固有振動数 fn [Hz] | C5: 3500 | D5: ← 見たい山のだいたいの周波数。未知なら粗い測定の結果でOK
B6: 予想される損失係数 η（イータ） | C6: 0.008 | D6: ← ブレーキパッド摩擦材なら 0.005〜0.02 が目安（🟡推定・文献値）
B7: 目標の減衰量 [dB] | C7: 60 | D7: ← 60dB＝振幅が1/1000。これだけ小さくなればゼロ扱いしてよい
B8: 必要な最低記録時間 t [秒] | C8: =(C7*LN(10)/20)/(PI()*C5*C6) -> 0.078528814 | D8: 式： t = (dB×ln10/20) ÷ (π・fn・η)
A10: ■ Step2｜アナライザの設定を決める（RION SA-01A4）
B11: 解析周波数レンジ [Hz] | C11: 20000 | D11: ← RIONの［解析周波数］設定値
B12: サンプリング係数 | C12: 2.56 | D12: ← 20kHzレンジ以下＝2.56／40kHzレンジ＝2.4（🟢ハードウェアマニュアル）
B13: サンプリング周波数 fs [Hz] | C13: =C11*C12 -> 51200
B14: 必要な最低点数 | C14: =C13*C8 -> 4020.6753
B15: 選ぶべき解析点数 N（2の累乗） | C15: =MIN(32768,2^ROUNDUP(LOG(MAX(C14,64),2),0)) -> 4096 | D15: ← RIONの選択肢は 64〜32768 点（2^6〜2^15）
B16: 実際の記録時間 T [秒] | C16: =C15/C13 -> 0.08
B17: 周波数分解能 Δf [Hz] | C17: =C13/C15 -> 12.5
B18: 推奨 N（窓なし＋分解能を両方満たす最小値） | C18: =MIN(32768,2^ROUNDUP(LOG(MAX(64,C13*C8,5*C13/MAX(C21,0.0001)),2),0)) -> 8192 | D18: ← この N を RION に設定すれば、窓なし条件と双子分離の分解能を同時に満たせます
A19: ■ Step3｜判定 | B19: そのときの T [秒] / Δf [Hz] | C19: =IFERROR(C18/C13,"") -> 0.16 | D19: =IFERROR(C13/C18,"") -> 6.25 | E19: ← 左がT[秒]、右がΔf[Hz]
B20: 窓は必要？ | C20: =IF(C16>=C8,"不要（窓＝［無し］でOK）","必要（フォース・指数窓へ）") -> 不要（窓＝［無し］でOK） | D20: T ≧ t なら、フレーム内で揺れが消えきっている＝窓は要らない
B21: 分けたい2つのモードの間隔 [Hz] | C21: 40
B22: Δf は間隔の何分の1？ | C22: =IFERROR(C21/C17,"") -> 3.2
B23: 分解能の判定 | C23: =IF(C22>=5,"OK（5倍以上とれている）","要改善（Nを増やすか帯域を狭く）") -> 要改善（Nを増やすか帯域を狭く） | D23: 目安：Δf はモード間隔の1/5以下が望ましい（🟡実務上の目安）
A25: ■ N の候補早見表（今の fs で自動計算）
B26: N（点） | C26: 記録時間 T [秒] | D26: 分解能 Δf [Hz] | E26: 窓なしで足りる？ | F26: 双子分離に足りる？
B27: 64 | C27: =IF($C$13=0,"",64/$C$13) -> 0.00125 | D27: =IF($C$13=0,"",$C$13/64) -> 800 | E27: =IF(C27="","",IF(C27>=$C$8,"○ 足りる","× 足りない")) -> × 足りない | F27: =IF(D27="","",IF($C$21/D27>=5,"○ 足りる","× 足りない")) -> × 足りない
B28: 128 | C28: =IF($C$13=0,"",128/$C$13) -> 0.0025 | D28: =IF($C$13=0,"",$C$13/128) -> 400 | E28: =IF(C28="","",IF(C28>=$C$8,"○ 足りる","× 足りない")) -> × 足りない | F28: =IF(D28="","",IF($C$21/D28>=5,"○ 足りる","× 足りない")) -> × 足りない
B29: 256 | C29: =IF($C$13=0,"",256/$C$13) -> 0.005 | D29: =IF($C$13=0,"",$C$13/256) -> 200 | E29: =IF(C29="","",IF(C29>=$C$8,"○ 足りる","× 足りない")) -> × 足りない | F29: =IF(D29="","",IF($C$21/D29>=5,"○ 足りる","× 足りない")) -> × 足りない
B30: 512 | C30: =IF($C$13=0,"",512/$C$13) -> 0.01 | D30: =IF($C$13=0,"",$C$13/512) -> 100 | E30: =IF(C30="","",IF(C30>=$C$8,"○ 足りる","× 足りない")) -> × 足りない | F30: =IF(D30="","",IF($C$21/D30>=5,"○ 足りる","× 足りない")) -> × 足りない
B31: 1024 | C31: =IF($C$13=0,"",1024/$C$13) -> 0.02 | D31: =IF($C$13=0,"",$C$13/1024) -> 50 | E31: =IF(C31="","",IF(C31>=$C$8,"○ 足りる","× 足りない")) -> × 足りない | F31: =IF(D31="","",IF($C$21/D31>=5,"○ 足りる","× 足りない")) -> × 足りない
B32: 2048 | C32: =IF($C$13=0,"",2048/$C$13) -> 0.04 | D32: =IF($C$13=0,"",$C$13/2048) -> 25 | E32: =IF(C32="","",IF(C32>=$C$8,"○ 足りる","× 足りない")) -> × 足りない | F32: =IF(D32="","",IF($C$21/D32>=5,"○ 足りる","× 足りない")) -> × 足りない
B33: 4096 | C33: =IF($C$13=0,"",4096/$C$13) -> 0.08 | D33: =IF($C$13=0,"",$C$13/4096) -> 12.5 | E33: =IF(C33="","",IF(C33>=$C$8,"○ 足りる","× 足りない")) -> ○ 足りる | F33: =IF(D33="","",IF($C$21/D33>=5,"○ 足りる","× 足りない")) -> × 足りない
B34: 8192 | C34: =IF($C$13=0,"",8192/$C$13) -> 0.16 | D34: =IF($C$13=0,"",$C$13/8192) -> 6.25 | E34: =IF(C34="","",IF(C34>=$C$8,"○ 足りる","× 足りない")) -> ○ 足りる | F34: =IF(D34="","",IF($C$21/D34>=5,"○ 足りる","× 足りない")) -> ○ 足りる
B35: 16384 | C35: =IF($C$13=0,"",16384/$C$13) -> 0.32 | D35: =IF($C$13=0,"",$C$13/16384) -> 3.125 | E35: =IF(C35="","",IF(C35>=$C$8,"○ 足りる","× 足りない")) -> ○ 足りる | F35: =IF(D35="","",IF($C$21/D35>=5,"○ 足りる","× 足りない")) -> ○ 足りる
B36: 32768 | C36: =IF($C$13=0,"",32768/$C$13) -> 0.64 | D36: =IF($C$13=0,"",$C$13/32768) -> 1.5625 | E36: =IF(C36="","",IF(C36>=$C$8,"○ 足りる","× 足りない")) -> ○ 足りる | F36: =IF(D36="","",IF($C$21/D36>=5,"○ 足りる","× 足りない")) -> ○ 足りる
A38: ■ うれしい副産物
B39: 記録時間 T を長くすると、周波数分解能 Δf（＝fs/N）も同時に細かくなります。つまり「窓なしにするため長く録る」＝「双子モードを見分けやすくする」。
B40: この2つは珍しく“両取り”できる関係です。トレードオフではありません。
A42: ■ 出典
B43: 🟢 RION SA-01/SA-01A2/SA-01A4 ハードウェアマニュアル（プロジェクト添付）：FFT解析長 2^N（N=6〜15）／サンプリング周波数 = レンジ×2.56（40kHzレンジは×2.4）

Sheet 02_窓関数の選定
A1: ② 窓関数（まどかんすう）の選定と補正
A2: 窓関数＝1コマの波形の端っこを滑らかにゼロへ落とす“のりしろ”。使うと必ず代償（振幅の目減り・減衰の水増し）が出る。
A4: ■ 判定はたった1つ：フレーム終端で揺れがゼロになっているか
B5: YES → ［無し］（方形窓）。何も足さない＝一番正確。
B6: NO → ［フォース・指数］（基準ch＝ハンマーにフォース窓、応答chに指数窓）。ただし減衰の補正が必須。
B7: 🟢 RIONソフトウェアマニュアル記載：解析モードが「FFT」のとき［フォース・指数］は選択できません（［FFT&1/Nオクターブ］モード時のみ選択可）。FFTモードでは［指数・指数］を使います。
B8: 🟡 推定：フォース窓は「打撃位置を基準に範囲を切る」操作のため、記録済み波形が必要＝オフライン系モード限定、という理屈と整合します（要実機確認）。
A10: ■ 窓関数の性能比較表（Harris 1978 に基づく標準値）
B11: 窓関数 | C11: コヒーレント ゲイン CG | D11: 振幅補正 係数 1/CG | E11: ENBW [bin] | F11: エネルギー 補正係数 | G11: 最大振幅誤差 （スキャロップ損失）[dB] | H11: 最大サイド ローブ [dB] | I11: 主な用途 / 性格
B12: 無し（方形／レクタングラ） | C12: 1 | D12: 1 | E12: 1 | F12: 1 | G12: 3.92 | H12: -13.3 | I12: ハンマリングで揺れが消えきる時。歪みゼロ・最良
B13: ハニング（Hann） | C13: 0.5 | D13: 2 | E13: 1.5 | F13: 1.63299 | G13: 1.42 | H13: -31.5 | I13: 連続ランダム加振の標準。ハンマリングには不向き
B14: ハミング（Hamming） | C14: 0.54 | D14: 1.85185 | E14: 1.36279 | F14: 1.58614 | G14: 1.75 | H14: -42.7 | I14: サイドローブ重視。汎用
B15: フラットトップ | C15: 0.21557 | D15: 4.63886 | E15: 3.77 | F15: 1.96 | G15: 0.01 | H15: -93.6 | I15: 振幅を正確に読む用途（校正・床衝撃音）
B16: ブラックマン・ハリス4項 | C16: 0.35875 | D16: 2.78746 | E16: 2.00442 | F16: 1.96884 | G16: 0.83 | H16: -92 | I16: ダイナミックレンジ最重視
B17: フォース窓（力側） | C17: 1 | D17: 1 | E17: 1 | F17: 1 | G17: － | H17: － | I17: ハンマー信号専用。打撃前後だけ残す＝歪まない
B18: 指数窓（応答側） | C18: － | D18: － | E18: － | F18: － | G18: － | H18: － | I18: 減衰を人工的に足す。必ず下の補正が必要
B20: ※ 用語：CG＝窓の平均値（振幅がどれだけ目減りするか）。ENBW＝等価雑音帯域幅（1本の線が実質何本分に広がるか）。スキャロップ損失＝山の頂点が線と線の間に落ちたときの最大読み損じ。
B21: 🟡 フラットトップの数値は定義がメーカーごとに違います。RIONの実装値は要確認。上表は Harris(1978) の代表的な flat-top 定義に基づく値です。
A23: ■ 指数窓を使ってしまった時の“減衰の水増し”を取り消す計算
B24: フレーム長 T [秒] | C24: =01_測定条件の設計!C16 -> 0.08 | D24: ← 01シートから自動
B25: フレーム終端での減衰値（RION入力値） | C25: 0.01 | D25: 🟢 RIONソフトマニュアル：［指数ウィンド設定］＝「フレームの終端での減衰値を入力します」。0.01＝1%（-40dB）
B26: 指数窓の時定数 τ（タウ）[秒] | C26: =IFERROR(-C24/LN(C25),"") -> 0.017371779 | D26: 式： τ = -T / ln(終端減衰値)
B27: 付加される減衰（減衰係数）σadd [rad/s] | C27: =IFERROR(1/C26,"") -> 57.564627
B28: 対象モードの固有振動数 fn [Hz] | C28: 3500
B29: 損失係数への上乗せ量 Δη | C29: =IFERROR(1/(PI()*C28*C26),"") -> 0.0052352543 | D29: 式： Δη = 1 / (π・fn・τ) ←これを実測ηから引く
B30: 減衰比への上乗せ量 Δζ | C30: =IFERROR(C29/2,"") -> 0.0026176271
B31: 実測した損失係数 η_meas | C31: 0.009
B32: 補正後の真の損失係数 η_true | C32: =IFERROR(C31-C29,"") -> 0.0037647457
B33: 補正の重み | C33: =IFERROR(IF(C29/C31>0.3,"⚠ 補正量が実測値の30%超。窓なし測定に切り替えるべき","OK（補正量は許容範囲）"),"") -> ⚠ 補正量が実測値の30%超。窓なし測定に切り替えるべき
A35: ■ 振幅・エネルギー補正の使い方（ハンマリングでは通常不要ですが念のため）
B36: 選んだ窓（上の表の行番号 1〜7） | C36: 1
B37: → 振幅補正係数 | C37: =INDEX($D$12:$D$18,$C$36) -> 1
B38: → エネルギー補正係数 | C38: =INDEX($F$12:$F$18,$C$36) -> 1
B39: 窓をかけた後のスペクトル振幅 | C39: 1
B40: 補正後の振幅（正弦波など単一周波数） | C40: =C39*C37 -> 1 | D40: 単一周波数成分の高さを読む → 振幅補正係数（1/CG）を掛ける
B41: 補正後の実効値（ランダム信号） | C41: =C39*C38 -> 1 | D41: 広帯域ノイズのパワーを読む → エネルギー補正係数を掛ける
A43: ■ なぜ窓が要るのか（小学生にもわかる説明）
B44: 1. FFTは「切り取った1コマが、そのまま無限にループして繰り返される」と思い込んで計算します。
B45: 2. コマの終わりとコマの始まりで波の高さが違うと、つなぎ目に“段差”ができます。
B46: 3. 段差は、ギザギザした鋭い音（＝本当は無いはずの高い周波数）を生みます。これが漏れ（リーケージ）です。
...

Sheet 03_FRFデータ貼付
A1: ③ FRFデータの貼り付け（ここが出発点）
A2: RION または PSV から書き出した「周波数・実部・虚部」の3列を、下の黄色い範囲に貼るだけ。行数は何点でもOK（最大120点）。
A4: 基準周波数 fref [Hz] | B4: =IF(D4<>"",D4,IF(COUNT(B8:B127)=0,1,(MIN(B8:B127)+MAX(B8:B127))/2)) -> 3500 | C4: 手動指定→ | E4: 空欄なら帯域の中心を自動採用。ふつうは空欄のままでOK。 | G4: データ点数 | H4: =COUNT(B8:B127) -> 21
A5: 基準角周波数 ωref [rad/s] | B5: =2*PI()*B4 -> 21991.149 | E5: 周波数をこの値で割って“1前後の数”にします＝正規化。これをやらないと双子の分離に失敗します。 | G5: 周波数分解能 Δf [Hz] | H5: =IF(H4>1,(MAX(B8:B127)-MIN(B8:B127))/(H4-1),"") -> 10
A6: 振幅基準 Href | B6: =IF(MAX(E8:E127)=0,1,MAX(E8:E127)) -> 0.018393173 | E6: 帯域内 |H| の最大値。振幅も1前後に正規化して、桁の大小による計算誤差を抑えます。 | G6: 解析帯域 [Hz] | H6: =IF(H4>0,TEXT(MIN(B8:B127),"0.0")&" 〜 "&TEXT(MAX(B8:B127),"0.0"),"") -> 3400.0 〜 3600.0
A7: No. | B7: 周波数 f [Hz] ★入力 | C7: 実部 Re(H) ★入力 | D7: 虚部 Im(H) ★入力 | E7: 振幅 |H| | F7: 位相 [deg] | G7: ω [rad/s] | H7: Ω 正規化 角周波数 | I7: Re(Hn) 正規化実部 | J7: Im(Hn) 正規化虚部 | K7: コヒーレンス （任意）
A8: 1 | B8: 3400 | C8: 5.1e-05 | D8: 0.00301 | E8: =IF($B8="","",SQRT($C8^2+$D8^2)) -> 0.003010432 | F8: =IF($B8="","",IFERROR(DEGREES(ATAN2($C8,$D8)),0)) -> 89.029301 | G8: =IF($B8="","",2*PI()*$B8) -> 21362.83 | H8: =IF($B8="","",2*PI()*$B8/$B$5) -> 0.97142857 | I8: =IF($B8="","",$C8/$B$6) -> 0.0027727679 | J8: =IF($B8="","",$D8/$B$6) -> 0.16364767 | L8: ← コヒーレンス（0〜1）は任意入力。0.9未満の点はデータ品質が悪い＝カーブフィットから外す判断材料になります。
A9: 2 | B9: 3410 | C9: 9.3e-05 | D9: 0.003391 | E9: =IF($B9="","",SQRT($C9^2+$D9^2)) -> 0.003392275 | F9: =IF($B9="","",IFERROR(DEGREES(ATAN2($C9,$D9)),0)) -> 88.429026 | G9: =IF($B9="","",2*PI()*$B9) -> 21425.662 | H9: =IF($B9="","",2*PI()*$B9/$B$5) -> 0.97428571 | I9: =IF($B9="","",$C9/$B$6) -> 0.0050562238 | J9: =IF($B9="","",$D9/$B$6) -> 0.18436188
A10: 3 | B10: 3420 | C10: 0.000162 | D10: 0.003876 | E10: =IF($B10="","",SQRT($C10^2+$D10^2)) -> 0.003879384 | F10: =IF($B10="","",IFERROR(DEGREES(ATAN2($C10,$D10)),0)) -> 87.606678 | G10: =IF($B10="","",2*PI()*$B10) -> 21488.494 | H10: =IF($B10="","",2*PI()*$B10/$B$5) -> 0.97714286 | I10: =IF($B10="","",$C10/$B$6) -> 0.0088076156 | J10: =IF($B10="","",$D10/$B$6) -> 0.21073036
A11: 4 | B11: 3430 | C11: 0.00028 | D11: 0.004516 | E11: =IF($B11="","",SQRT($C11^2+$D11^2)) -> 0.0045246719 | F11: =IF($B11="","",IFERROR(DEGREES(ATAN2($C11,$D11)),0)) -> 86.452102 | G11: =IF($B11="","",2*PI()*$B11) -> 21551.326 | H11: =IF($B11="","",2*PI()*$B11/$B$5) -> 0.98 | I11: =IF($B11="","",$C11/$B$6) -> 0.015223039 | J11: =IF($B11="","",$D11/$B$6) -> 0.24552588
A12: 5 | B12: 3440 | C12: 0.000512 | D12: 0.005463 | E12: =IF($B12="","",SQRT($C12^2+$D12^2)) -> 0.0054869402 | F12: =IF($B12="","",IFERROR(DEGREES(ATAN2($C12,$D12)),0)) -> 84.645799 | G12: =IF($B12="","",2*PI()*$B12) -> 21614.157 | H12: =IF($B12="","",2*PI()*$B12/$B$5) -> 0.98285714 | I12: =IF($B12="","",$C12/$B$6) -> 0.027836415 | J12: =IF($B12="","",$D12/$B$6) -> 0.29701237
A13: 6 | B13: 3450 | C13: 0.001016 | D13: 0.006854 | E13: =IF($B13="","",SQRT($C13^2+$D13^2)) -> 0.006928894 | F13: =IF($B13="","",IFERROR(DEGREES(ATAN2($C13,$D13)),0)) -> 81.568184 | G13: =IF($B13="","",2*PI()*$B13) -> 21676.989 | H13: =IF($B13="","",2*PI()*$B13/$B$5) -> 0.98571429 | I13: =IF($B13="","",$C13/$B$6) -> 0.055237885 | J13: =IF($B13="","",$D13/$B$6) -> 0.37263825
A14: 7 | B14: 3460 | C14: 0.002362 | D14: 0.00908 | E14: =IF($B14="","",SQRT($C14^2+$D14^2)) -> 0.0093821876 | F14: =IF($B14="","",IFERROR(DEGREES(ATAN2($C14,$D14)),0)) -> 75.418691 | G14: =IF($B14="","",2*PI()*$B14) -> 21739.821 | H14: =IF($B14="","",2*PI()*$B14/$B$5) -> 0.98857143 | I14: =IF($B14="","",$C14/$B$6) -> 0.12841721 | J14: =IF($B14="","",$D14/$B$6) -> 0.49366142
A15: 8 | B15: 3470 | C15: 0.006939 | D15: 0.012171 | E15: =IF($B15="","",SQRT($C15^2+$D15^2)) -> 0.014010102 | F15: =IF($B15="","",IFERROR(DEGREES(ATAN2($C15,$D15)),0)) -> 60.311424 | G15: =IF($B15="","",2*PI()*$B15) -> 21802.653 | H15: =IF($B15="","",2*PI()*$B15/$B$5) -> 0.99142857 | I15: =IF($B15="","",$C15/$B$6) -> 0.37725953 | J15: =IF($B15="","",$D15/$B$6) -> 0.6617129
A16: 9 | B16: 3480 | C16: 0.016968 | D16: 0.007099 | E16: =IF($B16="","",SQRT($C16^2+$D16^2)) -> 0.018393173 | F16: =IF($B16="","",IFERROR(DEGREES(ATAN2($C16,$D16)),0)) -> 22.703253 | G16: =IF($B16="","",2*PI()*$B16) -> 21865.485 | H16: =IF($B16="","",2*PI()*$B16/$B$5) -> 0.99428571 | I16: =IF($B16="","",$C16/$B$6) -> 0.92251618 | J16: =IF($B16="","",$D16/$B$6) -> 0.38595841
A17: 10 | B17: 3490 | C17: 0.012733 | D17: -0.002205 | E17: =IF($B17="","",SQRT($C17^2+$D17^2)) -> 0.012922512 | F17: =IF($B17="","",IFERROR(DEGREES(ATAN2($C17,$D17)),0)) -> -9.8245937 | G17: =IF($B17="","",2*PI()*$B17) -> 21928.317 | H17: =IF($B17="","",2*PI()*$B17/$B$5) -> 0.99714286 | I17: =IF($B17="","",$C17/$B$6) -> 0.69226771 | J17: =IF($B17="","",$D17/$B$6) -> -0.11988143
A18: 11 | B18: 3500 | C18: 0.009201 | D18: -0.001806 | E18: =IF($B18="","",SQRT($C18^2+$D18^2)) -> 0.0093765685 | F18: =IF($B18="","",IFERROR(DEGREES(ATAN2($C18,$D18)),0)) -> -11.10501 | G18: =IF($B18="","",2*PI()*$B18) -> 21991.149 | H18: =IF($B18="","",2*PI()*$B18/$B$5) -> 1 | I18: =IF($B18="","",$C18/$B$6) -> 0.50023994 | J18: =IF($B18="","",$D18/$B$6) -> -0.098188603
A19: 12 | B19: 3510 | C19: 0.010162 | D19: -0.00152 | E19: =IF($B19="","",SQRT($C19^2+$D19^2)) -> 0.01027505 | F19: =IF($B19="","",IFERROR(DEGREES(ATAN2($C19,$D19)),0)) -> -8.5070532 | G19: =IF($B19="","",2*PI()*$B19) -> 22053.98 | H19: =IF($B19="","",2*PI()*$B19/$B$5) -> 1.0028571 | I19: =IF($B19="","",$C19/$B$6) -> 0.55248759 | J19: =IF($B19="","",$D19/$B$6) -> -0.082639356
A20: 13 | B20: 3520 | C20: 0.011108 | D20: -0.005744 | E20: =IF($B20="","",SQRT($C20^2+$D20^2)) -> 0.012505247 | F20: =IF($B20="","",IFERROR(DEGREES(ATAN2($C20,$D20)),0)) -> -27.343701 | G20: =IF($B20="","",2*PI()*$B20) -> 22116.812 | H20: =IF($B20="","",2*PI()*$B20/$B$5) -> 1.0057143 | I20: =IF($B20="","",$C20/$B$6) -> 0.60391972 | J20: =IF($B20="","",$D20/$B$6) -> -0.31228978
... A28: 21 | B28: 3600 | C28: 0.000393 | D28: -0.002933 | E28: =IF($B28="","",SQRT($C28^2+$D28^2)) -> 0.0029592124 | F28: =IF($B28="","",IFERROR(DEGREES(ATAN2($C28,$D28)),0)) -> -82.368252 | G28: =IF($B28="","",2*PI()*$B28) -> 22619.467 | H28: =IF($B28="","",2*PI()*$B28/$B$5) -> 1.0285714 | I28: =IF($B28="","",$C28/$B$6) -> 0.021366623 | J28: =IF($B28="","",$D28/$B$6) -> -0.15946134
A29: 22 | E29: =IF($B29="","",SQRT($C29^2+$D29^2)) | F29: =IF($B29="","",IFERROR(DEGREES(ATAN2($C29,$D29)),0)) | G29: =IF($B29="","",2*PI()*$B29) | H29: =IF($B29="","",2*PI()*$B29/$B$5) | I29: =IF($B29="","",$C29/$B$6) | J29: =IF($B29="","",$D29/$B$6)
A30: 23 | E30: =IF($B30="","",SQRT($C30^2+$D30^2)) | F30: =IF($B30="","",IFERROR(DEGREES(ATAN2($C30,$D30)),0)) | G30: =IF($B30="","",2*PI()*$B30) | H30: =IF($B30="","",2*PI()*$B30/$B$5) | I30: =IF($B30="","",$C30/$B$6) | J30: =IF($B30="","",$D30/$B$6)
A31: 24 | E31: =IF($B31="","",SQRT($C31^2+$D31^2)) | F31: =IF($B31="","",IFERROR(DEGREES(ATAN2($C31,$D31)),0)) | G31: =IF($B31="","",2*PI()*$B31) | H31: =IF($B31="","",2*PI()*$B31/$B$5) | I31: =IF($B31="","",$C31/$B$6) | J31: =IF($B31="","",$D31/$B$6)
A32: 25 | E32: =IF($B32="","",SQRT($C32^2+$D32^2)) | F32: =IF($B32="","",IFERROR(DEGREES(ATAN2($C32,$D32)),0)) | G32: =IF($B32="","",2*PI()*$B32) | H32: =IF($B32="","",2*PI()*$B32/$B$5) | I32: =IF($B32="","",$C32/$B$6) | J32: =IF($B32="","",$D32/$B$6)
A33: 26 | E33: =IF($B33="","",SQRT($C33^2+$D33^2)) | F33: =IF($B33="","",IFERROR(DEGREES(ATAN2($C33,$D33)),0)) | G33: =IF($B33="","",2*PI()*$B33) | H33: =IF($B33="","",2*PI()*$B33/$B$5) | I33: =IF($B33="","",$C33/$B$6) | J33: =IF($B33="","",$D33/$B$6)
A34: 27 | E34: =IF($B34="","",SQRT($C34^2+$D34^2)) | F34: =IF($B34="","",IFERROR(DEGREES(ATAN2($C34,$D34)),0)) | G34: =IF($B34="","",2*PI()*$B34) | H34: =IF($B34="","",2*PI()*$B34/$B$5) | I34: =IF($B34="","",$C34/$B$6) | J34: =IF($B34="","",$D34/$B$6)
A35: 28 | E35: =IF($B35="","",SQRT($C35^2+$D35^2)) | F35: =IF($B35="","",IFERROR(DEGREES(ATAN2($C35,$D35)),0)) | G35: =IF($B35="","",2*PI()*$B35) | H35: =IF($B35="","",2*PI()*$B35/$B$5) | I35: =IF($B35="","",$C35/$B$6) | J35: =IF($B35="","",$D35/$B$6)
A36: 29 | E36: =IF($B36="","",SQRT($C36^2+$D36^2)) | F36: =IF($B36="","",IFERROR(DEGREES(ATAN2($C36,$D36)),0)) | G36: =IF($B36="","",2*PI()*$B36) | H36: =IF($B36="","",2*PI()*$B36/$B$5) | I36: =IF($B36="","",$C36/$B$6) | J36: =IF($B36="","",$D36/$B$6)
A37: 30 | E37: =IF($B37="","",SQRT($C37^2+$D37^2)) | F37: =IF($B37="","",IFERROR(DEGREES(ATAN2($C37,$D37)),0)) | G37: =IF($B37="","",2*PI()*$B37) | H37: =IF($B37="","",2*PI()*$B37/$B$5) | I37: =IF($B37="","",$C37/$B$6) | J37: =IF($B37="","",$D37/$B$6)
A38: 31 | E38: =IF($B38="","",SQRT($C38^2+$D38^2)) | F38: =IF($B38="","",IFERROR(DEGREES(ATAN2($C38,$D38)),0)) | G38: =IF($B38="","",2*PI()*$B38) | H38: =IF($B38="","",2*PI()*$B38/$B$5) | I38: =IF($B38="","",$C38/$B$6) | J38: =IF($B38="","",$D38/$B$6)
A39: 32 | E39: =IF($B39="","",SQRT($C39^2+$D39^2)) | F39: =IF($B39="","",IFERROR(DEGREES(ATAN2($C39,$D39)),0)) | G39: =IF($B39="","",2*PI()*$B39) | H39: =IF($B39="","",2*PI()*$B39/$B$5) | I39: =IF($B39="","",$C39/$B$6) | J39: =IF($B39="","",$D39/$B$6)
A40: 33 | E40: =IF($B40="","",SQRT($C40^2+$D40^2)) | F40: =IF($B40="","",IFERROR(DEGREES(ATAN2($C40,$D40)),0)) | G40: =IF($B40="","",2*PI()*$B40) | H40: =IF($B40="","",2*PI()*$B40/$B$5) | I40: =IF($B40="","",$C40/$B$6) | J40: =IF($B40="","",$D40/$B$6)
... A127: 120 | E127: =IF($B127="","",SQRT($C127^2+$D127^2)) | F127: =IF($B127="","",IFERROR(DEGREES(ATAN2($C127,$D127)),0)) | G127: =IF($B127="","",2*PI()*$B127) | H127: =IF($B127="","",2*PI()*$B127/$B$5) | I127: =IF($B127="","",$C127/$B$6) | J127: =IF($B127="","",$D127/$B$6)

Sheet 04_モード数の確認
A1: ④ モード数の確認（山はいくつ？）
A2: ME'scope の手順①「Mode Indicator で山を数える」に相当。ここで決めたモード数が、後段の全ての前提になります。
A4: ■ しきい値の設定と判定
B5: ピーク判定のしきい値（|H|最大値に対する割合） | E5: 0.1 | G5: ← 0.10＝最大の10%以上の高さを持つ山だけを数える
B6: → 実際のしきい値 |H| | E6: =E5*MAX(C15:C134) -> 0.0018393173
B7: 検出されたピークの本数 | E7: =COUNTIF(F15:F134,"◀ ピーク") -> 2
B8: 判定 | E8: =IF(E7=0,"山なし。しきい値を下げてください",IF(E7=1,"1本 → 05の半値幅法で十分",IF(E7=2,"2本 → このブックの本命。06以降へ進む","3本以上 → 分母4次のRFPでは足りません。帯域を狭めるかPythonへ"))) -> 2本 → このブックの本命。06以降へ進む | G8: ← 3本以上のときは帯域を狭くして「2本ずつ」に区切るのが実務的な逃げ道です
B9: ピークの周波数一覧 | E9: =IF(E7=0,"－",_xlfn.TEXTJOIN(" / ",TRUE(),G15:G134)) -> 3480.0 Hz / 3520.0 Hz
A11: ■ 単一FRF用モードインジケータ（MIF）
B12: MIF = |Im(H)| ÷ |H| は共振でほぼ1に近づき、共振から外れると小さくなります。振幅の大小に左右されない山の数え方です。
B13: 🔴 本物の CMIF（複素モードインジケータ関数）は「複数参照のFRF行列を各周波数で特異値分解する」もので、Excel単体では組めません。ここは1点加振用の簡易版です。
A14: No. | B14: 周波数 f [Hz] | C14: 振幅 |H| | D14: 位相 [deg] | E14: MIF |Im|/|H| | F14: ピーク判定 | G14: ピーク周波数 | H14: 参考：Re(H) | I14: 参考：Im(H)
A15: =IF(03_FRFデータ貼付!B8="","",03_FRFデータ貼付!A8) -> 1 | B15: =IF(03_FRFデータ貼付!B8="","",03_FRFデータ貼付!B8) -> 3400 | C15: =IF(03_FRFデータ貼付!B8="","",03_FRFデータ貼付!E8) -> 0.003010432 | D15: =IF(03_FRFデータ貼付!B8="","",03_FRFデータ貼付!F8) -> 89.029301 | E15: =IF(OR(03_FRFデータ貼付!B8="",03_FRFデータ貼付!E8=0),"",ABS(03_FRFデータ貼付!D8)/03_FRFデータ貼付!E8) -> 0.99985649 | F15: ="" | G15: ="" | H15: =IF(03_FRFデータ貼付!B8="","",03_FRFデータ貼付!C8) -> 5.1e-05 | I15: =IF(03_FRFデータ貼付!B8="","",03_FRFデータ貼付!D8) -> 0.00301 | K15: 【使い方】
A16: =IF(03_FRFデータ貼付!B9="","",03_FRFデータ貼付!A9) -> 2 | B16: =IF(03_FRFデータ貼付!B9="","",03_FRFデータ貼付!B9) -> 3410 | C16: =IF(03_FRFデータ貼付!B9="","",03_FRFデータ貼付!E9) -> 0.003392275 | D16: =IF(03_FRFデータ貼付!B9="","",03_FRFデータ貼付!F9) -> 88.429026 | E16: =IF(OR(03_FRFデータ貼付!B9="",03_FRFデータ貼付!E9=0),"",ABS(03_FRFデータ貼付!D9)/03_FRFデータ貼付!E9) -> 0.99962413 | F16: =IF(OR(C16="",C15="",C17=""),"",IF(AND(C16>C15,C16>=C17,C16>=$E$6),"◀ ピーク","")) | G16: =IF(F16="◀ ピーク",TEXT(B16,"0.0")&" Hz","") | H16: =IF(03_FRFデータ貼付!B9="","",03_FRFデータ貼付!C9) -> 9.3e-05 | I16: =IF(03_FRFデータ貼付!B9="","",03_FRFデータ貼付!D9) -> 0.003391 | K16: ① まず E5 を 0.10 のままで本数を見る。
A17: =IF(03_FRFデータ貼付!B10="","",03_FRFデータ貼付!A10) -> 3 | B17: =IF(03_FRFデータ貼付!B10="","",03_FRFデータ貼付!B10) -> 3420 | C17: =IF(03_FRFデータ貼付!B10="","",03_FRFデータ貼付!E10) -> 0.003879384 | D17: =IF(03_FRFデータ貼付!B10="","",03_FRFデータ貼付!F10) -> 87.606678 | E17: =IF(OR(03_FRFデータ貼付!B10="",03_FRFデータ貼付!E10=0),"",ABS(03_FRFデータ貼付!D10)/03_FRFデータ貼付!E10) -> 0.9991277 | F17: =IF(OR(C17="",C16="",C18=""),"",IF(AND(C17>C16,C17>=C18,C17>=$E$6),"◀ ピーク","")) | G17: =IF(F17="◀ ピーク",TEXT(B17,"0.0")&" Hz","") | H17: =IF(03_FRFデータ貼付!B10="","",03_FRFデータ貼付!C10) -> 0.000162 | I17: =IF(03_FRFデータ貼付!B10="","",03_FRFデータ貼付!D10) -> 0.003876 | K17: ② ノイズを山と誤検出しているようなら E5 を 0.2〜0.3 に上げる。
A18: =IF(03_FRFデータ貼付!B11="","",03_FRFデータ貼付!A11) -> 4 | B18: =IF(03_FRFデータ貼付!B11="","",03_FRFデータ貼付!B11) -> 3430 | C18: =IF(03_FRFデータ貼付!B11="","",03_FRFデータ貼付!E11) -> 0.0045246719 | D18: =IF(03_FRFデータ貼付!B11="","",03_FRFデータ貼付!F11) -> 86.452102 | E18: =IF(OR(03_FRFデータ貼付!B11="",03_FRFデータ貼付!E11=0),"",ABS(03_FRFデータ貼付!D11)/03_FRFデータ貼付!E11) -> 0.99808341 | F18: =IF(OR(C18="",C17="",C19=""),"",IF(AND(C18>C17,C18>=C19,C18>=$E$6),"◀ ピーク","")) | G18: =IF(F18="◀ ピーク",TEXT(B18,"0.0")&" Hz","") | H18: =IF(03_FRFデータ貼付!B11="","",03_FRFデータ貼付!C11) -> 0.00028 | I18: =IF(03_FRFデータ貼付!B11="","",03_FRFデータ貼付!D11) -> 0.004516 | K18: ③ 小さい方の山を拾えていないなら 0.03〜0.05 に下げる。
A19: =IF(03_FRFデータ貼付!B12="","",03_FRFデータ貼付!A12) -> 5 | B19: =IF(03_FRFデータ貼付!B12="","",03_FRFデータ貼付!B12) -> 3440 | C19: =IF(03_FRFデータ貼付!B12="","",03_FRFデータ貼付!E12) -> 0.0054869402 | D19: =IF(03_FRFデータ貼付!B12="","",03_FRFデータ貼付!F12) -> 84.645799 | E19: =IF(OR(03_FRFデータ貼付!B12="",03_FRFデータ貼付!E12=0),"",ABS(03_FRFデータ貼付!D12)/03_FRFデータ貼付!E12) -> 0.99563687 | F19: =IF(OR(C19="",C18="",C20=""),"",IF(AND(C19>C18,C19>=C20,C19>=$E$6),"◀ ピーク","")) | G19: =IF(F19="◀ ピーク",TEXT(B19,"0.0")&" Hz","") | H19: =IF(03_FRFデータ貼付!B12="","",03_FRFデータ貼付!C12) -> 0.000512 | I19: =IF(03_FRFデータ貼付!B12="","",03_FRFデータ貼付!D12) -> 0.005463 | K19: ④ 本数が確定したら、G列に出た周波数を 08シートの B11・B12 に写す。
A20: =IF(03_FRFデータ貼付!B13="","",03_FRFデータ貼付!A13) -> 6 | B20: =IF(03_FRFデータ貼付!B13="","",03_FRFデータ貼付!B13) -> 3450 | C20: =IF(03_FRFデータ貼付!B13="","",03_FRFデータ貼付!E13) -> 0.006928894 | D20: =IF(03_FRFデータ貼付!B13="","",03_FRFデータ貼付!F13) -> 81.568184 | E20: =IF(OR(03_FRFデータ貼付!B13="",03_FRFデータ貼付!E13=0),"",ABS(03_FRFデータ貼付!D13)/03_FRFデータ貼付!E13) -> 0.98919106 | F20: =IF(OR(C20="",C19="",C21=""),"",IF(AND(C20>C19,C20>=C21,C20>=$E$6),"◀ ピーク","")) | G20: =IF(F20="◀ ピーク",TEXT(B20,"0.0")&" Hz","") | H20: =IF(03_FRFデータ貼付!B13="","",03_FRFデータ貼付!C13) -> 0.001016 | I20: =IF(03_FRFデータ貼付!B13="","",03_FRFデータ貼付!D13) -> 0.006854
A21: =IF(03_FRFデータ貼付!B14="","",03_FRFデータ貼付!A14) -> 7 | B21: =IF(03_FRFデータ貼付!B14="","",03_FRFデータ貼付!B14) -> 3460 | C21: =IF(03_FRFデータ貼付!B14="","",03_FRFデータ貼付!E14) -> 0.0093821876 | D21: =IF(03_FRFデータ貼付!B14="","",03_FRFデータ貼付!F14) -> 75.418691 | E21: =IF(OR(03_FRFデータ貼付!B14="",03_FRFデータ貼付!E14=0),"",ABS(03_FRFデータ貼付!D14)/03_FRFデータ貼付!E14) -> 0.96779135 | F21: =IF(OR(C21="",C20="",C22=""),"",IF(AND(C21>C20,C21>=C22,C21>=$E$6),"◀ ピーク","")) | G21: =IF(F21="◀ ピーク",TEXT(B21,"0.0")&" Hz","") | H21: =IF(03_FRFデータ貼付!B14="","",03_FRFデータ貼付!C14) -> 0.002362 | I21: =IF(03_FRFデータ貼付!B14="","",03_FRFデータ貼付!D14) -> 0.00908 | K21: 【なぜ本数が全ての前提なのか】
A22: =IF(03_FRFデータ貼付!B15="","",03_FRFデータ貼付!A15) -> 8 | B22: =IF(03_FRFデータ貼付!B15="","",03_FRFデータ貼付!B15) -> 3470 | C22: =IF(03_FRFデータ貼付!B15="","",03_FRFデータ貼付!E15) -> 0.014010102 | D22: =IF(03_FRFデータ貼付!B15="","",03_FRFデータ貼付!F15) -> 60.311424 | E22: =IF(OR(03_FRFデータ貼付!B15="",03_FRFデータ貼付!E15=0),"",ABS(03_FRFデータ貼付!D15)/03_FRFデータ貼付!E15) -> 0.86873028 | F22: =IF(OR(C22="",C21="",C23=""),"",IF(AND(C22>C21,C22>=C23,C22>=$E$6),"◀ ピーク","")) | G22: =IF(F22="◀ ピーク",TEXT(B22,"0.0")&" Hz","") | H22: =IF(03_FRFデータ貼付!B15="","",03_FRFデータ貼付!C15) -> 0.006939 | I22: =IF(03_FRFデータ貼付!B15="","",03_FRFデータ貼付!D15) -> 0.012171 | K22: RFP法は『分母を何次にするか』でモードの本数を決め打ちします。
A23: =IF(03_FRFデータ貼付!B16="","",03_FRFデータ貼付!A16) -> 9 | B23: =IF(03_FRFデータ貼付!B16="","",03_FRFデータ貼付!B16) -> 3480 | C23: =IF(03_FRFデータ貼付!B16="","",03_FRFデータ貼付!E16) -> 0.018393173 | D23: =IF(03_FRFデータ貼付!B16="","",03_FRFデータ貼付!F16) -> 22.703253 | E23: =IF(OR(03_FRFデータ貼付!B16="",03_FRFデータ貼付!E16=0),"",ABS(03_FRFデータ貼付!D16)/03_FRFデータ貼付!E16) -> 0.38595841 | F23: =IF(OR(C23="",C22="",C24=""),"",IF(AND(C23>C22,C23>=C24,C23>=$E$6),"◀ ピーク","")) -> ◀ ピーク | G23: =IF(F23="◀ ピーク",TEXT(B23,"0.0")&" Hz","") -> 3480.0 Hz | H23: =IF(03_FRFデータ貼付!B16="","",03_FRFデータ貼付!C16) -> 0.016968 | I23: =IF(03_FRFデータ貼付!B16="","",03_FRFデータ貼付!D16) -> 0.007099 | K23: 本数を間違えると、存在しないモードをでっち上げたり、
A24: =IF(03_FRFデータ貼付!B17="","",03_FRFデータ貼付!A17) -> 10 | B24: =IF(03_FRFデータ貼付!B17="","",03_FRFデータ貼付!B17) -> 3490 | C24: =IF(03_FRFデータ貼付!B17="","",03_FRFデータ貼付!E17) -> 0.012922512 | D24: =IF(03_FRFデータ貼付!B17="","",03_FRFデータ貼付!F17) -> -9.8245937 | E24: =IF(OR(03_FRFデータ貼付!B17="",03_FRFデータ貼付!E17=0),"",ABS(03_FRFデータ貼付!D17)/03_FRFデータ貼付!E17) -> 0.17063246 | F24: =IF(OR(C24="",C23="",C25=""),"",IF(AND(C24>C23,C24>=C25,C24>=$E$6),"◀ ピーク","")) | G24: =IF(F24="◀ ピーク",TEXT(B24,"0.0")&" Hz","") | H24: =IF(03_FRFデータ貼付!B17="","",03_FRFデータ貼付!C17) -> 0.012733 | I24: =IF(03_FRFデータ貼付!B17="","",03_FRFデータ貼付!D17) -> -0.002205 | K24: 実在するモードを1本に融合させたりします。
A25: =IF(03_FRFデータ貼付!B18="","",03_FRFデータ貼付!A18) -> 11 | B25: =IF(03_FRFデータ貼付!B18="","",03_FRFデータ貼付!B18) -> 3500 | C25: =IF(03_FRFデータ貼付!B18="","",03_FRFデータ貼付!E18) -> 0.0093765685 | D25: =IF(03_FRFデータ貼付!B18="","",03_FRFデータ貼付!F18) -> -11.10501 | E25: =IF(OR(03_FRFデータ貼付!B18="",03_FRFデータ貼付!E18=0),"",ABS(03_FRFデータ貼付!D18)/03_FRFデータ貼付!E18) -> 0.19260778 | F25: =IF(OR(C25="",C24="",C26=""),"",IF(AND(C25>C24,C25>=C26,C25>=$E$6),"◀ ピーク","")) | G25: =IF(F25="◀ ピーク",TEXT(B25,"0.0")&" Hz","") | H25: =IF(03_FRFデータ貼付!B18="","",03_FRFデータ貼付!C18) -> 0.009201 | I25: =IF(03_FRFデータ貼付!B18="","",03_FRFデータ貼付!D18) -> -0.001806 | K25: しかも“それらしい数字”は必ず出てしまうので、
A26: =IF(03_FRFデータ貼付!B19="","",03_FRFデータ貼付!A19) -> 12 | B26: =IF(03_FRFデータ貼付!B19="","",03_FRFデータ貼付!B19) -> 3510 | C26: =IF(03_FRFデータ貼付!B19="","",03_FRFデータ貼付!E19) -> 0.01027505 | D26: =IF(03_FRFデータ貼付!B19="","",03_FRFデータ貼付!F19) -> -8.5070532 | E26: =IF(OR(03_FRFデータ貼付!B19="",03_FRFデータ貼付!E19=0),"",ABS(03_FRFデータ貼付!D19)/03_FRFデータ貼付!E19) -> 0.14793116 | F26: =IF(OR(C26="",C25="",C27=""),"",IF(AND(C26>C25,C26>=C27,C26>=$E$6),"◀ ピーク","")) | G26: =IF(F26="◀ ピーク",TEXT(B26,"0.0")&" Hz","") | H26: =IF(03_FRFデータ貼付!B19="","",03_FRFデータ貼付!C19) -> 0.010162 | I26: =IF(03_FRFデータ貼付!B19="","",03_FRFデータ貼付!D19) -> -0.00152 | K26: 11シートの重ね描きで必ず検算してください。
A27: =IF(03_FRFデータ貼付!B20="","",03_FRFデータ貼付!A20) -> 13 | B27: =IF(03_FRFデータ貼付!B20="","",03_FRFデータ貼付!B20) -> 3520 | C27: =IF(03_FRFデータ貼付!B20="","",03_FRFデータ貼付!E20) -> 0.012505247 | D27: =IF(03_FRFデータ貼付!B20="","",03_FRFデータ貼付!F20) -> -27.343701 | E27: =IF(OR(03_FRFデータ貼付!B20="",03_FRFデータ貼付!E20=0),"",ABS(03_FRFデータ貼付!D20)/03_FRFデータ貼付!E20) -> 0.4593272 | F27: =IF(OR(C27="",C26="",C28=""),"",IF(AND(C27>C26,C27>=C28,C27>=$E$6),"◀ ピーク","")) -> ◀ ピーク | G27: =IF(F27="◀ ピーク",TEXT(B27,"0.0")&" Hz","") -> 3520.0 Hz | H27: =IF(03_FRFデータ貼付!B20="","",03_FRFデータ貼付!C20) -> 0.011108 | I27: =IF(03_FRFデータ貼付!B20="","",03_FRFデータ貼付!D20) -> -0.005744
A28: =IF(03_FRFデータ貼付!B21="","",03_FRFデータ貼付!A21) -> 14 | B28: =IF(03_FRFデータ貼付!B21="","",03_FRFデータ貼付!B21) -> 3530 | C28: =IF(03_FRFデータ貼付!B21="","",03_FRFデータ貼付!E21) -> 0.010822017 | D28: =IF(03_FRFデータ貼付!B21="","",03_FRFデータ貼付!F21) -> -53.230695 | E28: =IF(OR(03_FRFデータ貼付!B21="",03_FRFデータ貼付!E21=0),"",ABS(03_FRFデータ貼付!D21)/03_FRFデータ貼付!E21) -> 0.80105218 | F28: =IF(OR(C28="",C27="",C29=""),"",IF(AND(C28>C27,C28>=C29,C28>=$E$6),"◀ ピーク","")) | G28: =IF(F28="◀ ピーク",TEXT(B28,"0.0")&" Hz","") | H28: =IF(03_FRFデータ貼付!B21="","",03_FRFデータ貼付!C21) -> 0.006478 | I28: =IF(03_FRFデータ貼付!B21="","",03_FRFデータ貼付!D21) -> -0.008669
A29: =IF(03_FRFデータ貼付!B22="","",03_FRFデータ貼付!A22) -> 15 | B29: =IF(03_FRFデータ貼付!B22="","",03_FRFデータ貼付!B22) -> 3540 | C29: =IF(03_FRFデータ貼付!B22="","",03_FRFデータ貼付!E22) -> 0.008108501 | D29: =IF(03_FRFデータ貼付!B22="","",03_FRFデータ貼付!F22) -> -67.201307 | E29: =IF(OR(03_FRFデータ貼付!B22="",03_FRFデータ貼付!E22=0),"",ABS(03_FRFデータ貼付!D22)/03_FRFデータ貼付!E22) -> 0.92187199 | F29: =IF(OR(C29="",C28="",C30=""),"",IF(AND(C29>C28,C29>=C30,C29>=$E$6),"◀ ピーク","")) | G29: =IF(F29="◀ ピーク",TEXT(B29,"0.0")&" Hz","") | H29: =IF(03_FRFデータ貼付!B22="","",03_FRFデータ貼付!C22) -> 0.003142 | I29: =IF(03_FRFデータ貼付!B22="","",03_FRFデータ貼付!D22) -> -0.007475
A30: =IF(03_FRFデータ貼付!B23="","",03_FRFデータ貼付!A23) -> 16 | B30: =IF(03_FRFデータ貼付!B23="","",03_FRFデータ貼付!B23) -> 3550 | C30: =IF(03_FRFデータ貼付!B23="","",03_FRFデータ貼付!E23) -> 0.0063062839 | D30: =IF(03_FRFデータ貼付!B23="","",03_FRFデータ貼付!F23) -> -73.803757 | E30: =IF(OR(03_FRFデータ貼付!B23="",03_FRFデータ貼付!E23=0),"",ABS(03_FRFデータ貼付!D23)/03_FRFデータ貼付!E23) -> 0.96031198 | F30: =IF(OR(C30="",C29="",C31=""),"",IF(AND(C30>C29,C30>=C31,C30>=$E$6),"◀ ピーク","")) | G30: =IF(F30="◀ ピーク",TEXT(B30,"0.0")&" Hz","") | H30: =IF(03_FRFデータ貼付!B23="","",03_FRFデータ貼付!C23) -> 0.001759 | I30: =IF(03_FRFデータ貼付!B23="","",03_FRFデータ貼付!D23) -> -0.006056
A31: =IF(03_FRFデータ貼付!B24="","",03_FRFデータ貼付!A24) -> 17 | B31: =IF(03_FRFデータ貼付!B24="","",03_FRFデータ貼付!B24) -> 3560 | C31: =IF(03_FRFデータ貼付!B24="","",03_FRFデータ貼付!E24) -> 0.0051256594 | D31: =IF(03_FRFデータ貼付!B24="","",03_FRFデータ貼付!F24) -> -77.2869 | E31: =IF(OR(03_FRFデータ貼付!B24="",03_FRFデータ貼付!E24=0),"",ABS(03_FRFデータ貼付!D24)/03_FRFデータ貼付!E24) -> 0.97548425 | F31: =IF(OR(C31="",C30="",C32=""),"",IF(AND(C31>C30,C31>=C32,C31>=$E$6),"◀ ピーク","")) | G31: =IF(F31="◀ ピーク",TEXT(B31,"0.0")&" Hz","") | H31: =IF(03_FRFデータ貼付!B24="","",03_FRFデータ貼付!C24) -> 0.001128 | I31: =IF(03_FRFデータ貼付!B24="","",03_FRFデータ貼付!D24) -> -0.005
A32: =IF(03_FRFデータ貼付!B25="","",03_FRFデータ貼付!A25) -> 18 | B32: =IF(03_FRFデータ貼付!B25="","",03_FRFデータ貼付!B25) -> 3570 | C32: =IF(03_FRFデータ貼付!B25="","",03_FRFデータ貼付!E25) -> 0.0043201534 | D32: =IF(03_FRFデータ貼付!B25="","",03_FRFデータ貼付!F25) -> -79.368939 | E32: =IF(OR(03_FRFデータ貼付!B25="",03_FRFデータ貼付!E25=0),"",ABS(03_FRFデータ貼付!D25)/03_FRFデータ貼付!E25) -> 0.98283548 | F32: =IF(OR(C32="",C31="",C33=""),"",IF(AND(C32>C31,C32>=C33,C32>=$E$6),"◀ ピーク","")) | G32: =IF(F32="◀ ピーク",TEXT(B32,"0.0")&" Hz","") | H32: =IF(03_FRFデータ貼付!B25="","",03_FRFデータ貼付!C25) -> 0.000797 | I32: =IF(03_FRFデータ貼付!B25="","",03_FRFデータ貼付!D25) -> -0.004246
A33: =IF(03_FRFデータ貼付!B26="","",03_FRFデータ貼付!A26) -> 19 | B33: =IF(03_FRFデータ貼付!B26="","",03_FRFデータ貼付!B26) -> 3580 | C33: =IF(03_FRFデータ貼付!B26="","",03_FRFデータ貼付!E26) -> 0.0037368099 | D33: =IF(03_FRFデータ貼付!B26="","",03_FRFデータ貼付!F26) -> -80.729251 | E33: =IF(OR(03_FRFデータ貼付!B26="",03_FRFデータ貼付!E26=0),"",ABS(03_FRFデータ貼付!D26)/03_FRFデータ貼付!E26) -> 0.98693809 | F33: =IF(OR(C33="",C32="",C34=""),"",IF(AND(C33>C32,C33>=C34,C33>=$E$6),"◀ ピーク","")) | G33: =IF(F33="◀ ピーク",TEXT(B33,"0.0")&" Hz","") | H33: =IF(03_FRFデータ貼付!B26="","",03_FRFデータ貼付!C26) -> 0.000602 | I33: =IF(03_FRFデータ貼付!B26="","",03_FRFデータ貼付!D26) -> -0.003688
A34: =IF(03_FRFデータ貼付!B27="","",03_FRFデータ貼付!A27) -> 20 | B34: =IF(03_FRFデータ貼付!B27="","",03_FRFデータ貼付!B27) -> 3590 | C34: =IF(03_FRFデータ貼付!B27="","",03_FRFデータ貼付!E27) -> 0.0033017833 | D34: =IF(03_FRFデータ貼付!B27="","",03_FRFデータ貼付!F27) -> -81.676025 | E34: =IF(OR(03_FRFデータ貼付!B27="",03_FRFデータ貼付!E27=0),"",ABS(03_FRFデータ貼付!D27)/03_FRFデータ貼付!E27) -> 0.9894653 | F34: =IF(OR(C34="",C33="",C35=""),"",IF(AND(C34>C33,C34>=C35,C34>=$E$6),"◀ ピーク","")) | G34: =IF(F34="◀ ピーク",TEXT(B34,"0.0")&" Hz","") | H34: =IF(03_FRFデータ貼付!B27="","",03_FRFデータ貼付!C27) -> 0.000478 | I34: =IF(03_FRFデータ貼付!B27="","",03_FRFデータ貼付!D27) -> -0.003267
A35: =IF(03_FRFデータ貼付!B28="","",03_FRFデータ貼付!A28) -> 21 | B35: =IF(03_FRFデータ貼付!B28="","",03_FRFデータ貼付!B28) -> 3600 | C35: =IF(03_FRFデータ貼付!B28="","",03_FRFデータ貼付!E28) -> 0.0029592124 | D35: =IF(03_FRFデータ貼付!B28="","",03_FRFデータ貼付!F28) -> -82.368252 | E35: =IF(OR(03_FRFデータ貼付!B28="",03_FRFデータ貼付!E28=0),"",ABS(03_FRFデータ貼付!D28)/03_FRFデータ貼付!E28) -> 0.9911421 | F35: =IF(OR(C35="",C34="",C36=""),"",IF(AND(C35>C34,C35>=C36,C35>=$E$6),"◀ ピーク","")) | G35: =IF(F35="◀ ピーク",TEXT(B35,"0.0")&" Hz","") | H35: =IF(03_FRFデータ貼付!B28="","",03_FRFデータ貼付!C28) -> 0.000393 | I35: =IF(03_FRFデータ貼付!B28="","",03_FRFデータ貼付!D28) -> -0.002933
A36: =IF(03_FRFデータ貼付!B29="","",03_FRFデータ貼付!A29) | B36: =IF(03_FRFデータ貼付!B29="","",03_FRFデータ貼付!B29) | C36: =IF(03_FRFデータ貼付!B29="","",03_FRFデータ貼付!E29) | D36: =IF(03_FRFデータ貼付!B29="","",03_FRFデータ貼付!F29) | E36: =IF(OR(03_FRFデータ貼付!B29="",03_FRFデータ貼付!E29=0),"",ABS(03_FRFデータ貼付!D29)/03_FRFデータ貼付!E29) | F36: =IF(OR(C36="",C35="",C37=""),"",IF(AND(C36>C35,C36>=C37,C36>=$E$6),"◀ ピーク","")) | G36: =IF(F36="◀ ピーク",TEXT(B36,"0.0")&" Hz","") | H36: =IF(03_FRFデータ貼付!B29="","",03_FRFデータ貼付!C29) | I36: =IF(03_FRFデータ貼付!B29="","",03_FRFデータ貼付!D29)
A37: =IF(03_FRFデータ貼付!B30="","",03_FRFデータ貼付!A30) | B37: =IF(03_FRFデータ貼付!B30="","",03_FRFデータ貼付!B30) | C37: =IF(03_FRFデータ貼付!B30="","",03_FRFデータ貼付!E30) | D37: =IF(03_FRFデータ貼付!B30="","",03_FRFデータ貼付!F30) | E37: =IF(OR(03_FRFデータ貼付!B30="",03_FRFデータ貼付!E30=0),"",ABS(03_FRFデータ貼付!D30)/03_FRFデータ貼付!E30) | F37: =IF(OR(C37="",C36="",C38=""),"",IF(AND(C37>C36,C37>=C38,C37>=$E$6),"◀ ピーク","")) | G37: =IF(F37="◀ ピーク",TEXT(B37,"0.0")&" Hz","") | H37: =IF(03_FRFデータ貼付!B30="","",03_FRFデータ貼付!C30) | I37: =IF(03_FRFデータ貼付!B30="","",03_FRFデータ貼付!D30)
A38: =IF(03_FRFデータ貼付!B31="","",03_FRFデータ貼付!A31) | B38: =IF(03_FRFデータ貼付!B31="","",03_FRFデータ貼付!B31) | C38: =IF(03_FRFデータ貼付!B31="","",03_FRFデータ貼付!E31) | D38: =IF(03_FRFデータ貼付!B31="","",03_FRFデータ貼付!F31) | E38: =IF(OR(03_FRFデータ貼付!B31="",03_FRFデータ貼付!E31=0),"",ABS(03_FRFデータ貼付!D31)/03_FRFデータ貼付!E31) | F38: =IF(OR(C38="",C37="",C39=""),"",IF(AND(C38>C37,C38>=C39,C38>=$E$6),"◀ ピーク","")) | G38: =IF(F38="◀ ピーク",TEXT(B38,"0.0")&" Hz","") | H38: =IF(03_FRFデータ貼付!B31="","",03_FRFデータ貼付!C31) | I38: =IF(03_FRFデータ貼付!B31="","",03_FRFデータ貼付!D31)
... A133: =IF(03_FRFデータ貼付!B126="","",03_FRFデータ貼付!A126) | B133: =IF(03_FRFデータ貼付!B126="","",03_FRFデータ貼付!B126) | C133: =IF(03_FRFデータ貼付!B126="","",03_FRFデータ貼付!E126) | D133: =IF(03_FRFデータ貼付!B126="","",03_FRFデータ貼付!F126) | E133: =IF(OR(03_FRFデータ貼付!B126="",03_FRFデータ貼付!E126=0),"",ABS(03_FRFデータ貼付!D126)/03_FRFデータ貼付!E126) | F133: =IF(OR(C133="",C132="",C134=""),"",IF(AND(C133>C132,C133>=C134,C133>=$E$6),"◀ ピーク","")) | G133: =IF(F133="◀ ピーク",TEXT(B133,"0.0")&" Hz","") | H133: =IF(03_FRFデータ貼付!B126="","",03_FRFデータ貼付!C126) | I133: =IF(03_FRFデータ貼付!B126="","",03_FRFデータ貼付!D126)
A134: =IF(03_FRFデータ貼付!B127="","",03_FRFデータ貼付!A127) | B134: =IF(03_FRFデータ貼付!B127="","",03_FRFデータ貼付!B127) | C134: =IF(03_FRFデータ貼付!B127="","",03_FRFデータ貼付!E127) | D134: =IF(03_FRFデータ貼付!B127="","",03_FRFデータ貼付!F127) | E134: =IF(OR(03_FRFデータ貼付!B127="",03_FRFデータ貼付!E127=0),"",ABS(03_FRFデータ貼付!D127)/03_FRFデータ貼付!E127) | F134: ="" | G134: ="" | H134: =IF(03_FRFデータ貼付!B127="","",03_FRFデータ貼付!C127) | I134: =IF(03_FRFデータ貼付!B127="","",03_FRFデータ貼付!D127)

Sheet 05_半値幅法_SDOF
A1: ⑤ 半値幅法（はんちはばほう）｜一番簡単な方法で“当たり”を付ける
A2: 定規で山の幅を測るだけの方法。08シートのニュートン法に渡す初期値づくりとして使います。山が1本なら、これが最終答えでも構いません。
A4: ■ 自動計算（貼ったデータから最大ピークを1本だけ拾います）
B5: ピークの振幅 |H|max | E5: =MAX(03_FRFデータ貼付!E8:E127) -> 0.018393173
B6: ピーク周波数 fpeak [Hz] | E6: =INDEX(03_FRFデータ貼付!B8:B127,MATCH(E5,03_FRFデータ貼付!E8:E127,0)) -> 3480
B7: 半値レベル（-3dB）= |H|max ÷ √2 | E7: =E5/SQRT(2) -> 0.013005938
B8: 下側交点 f1 [Hz] | E8: =IF(COUNT(F28:F147)=0,"検出できず",MAX(F28:F147)) -> 3467.8302
B9: 上側交点 f2 [Hz] | E9: =IF(COUNT(G28:G147)=0,"検出できず",SMALL(G28:G147,1)) -> 3489.8475
B10: 半値幅 Δf3dB [Hz] | E10: =IFERROR(E9-E8,"") -> 22.017303
B11: 損失係数 η = Δf3dB ÷ fpeak | E11: =IFERROR(E10/E6,"") -> 0.0063268111
B12: 減衰比 ζ = η ÷ 2 | E12: =IFERROR(E11/2,"") -> 0.0031634056
B13: Q値 = 1 ÷ η | E13: =IFERROR(1/E11,"") -> 158.05751
B14: 減衰係数 σ [Hz]（＝半値幅の半分） | E14: =IFERROR(E10/2,"") -> 11.008651
B15: 減衰係数 σ [rad/s] | E15: =IFERROR(2*PI()*E14,"") -> 69.169397
A17: ■ 妥当性チェック（ここが一番大事）
B18: 検出されたピーク本数 | E18: =04_モード数の確認!E7 -> 2
B19: 半値幅法は使ってよい？ | E19: =IF(E18>1,"⚠ NG：山が2本以上あります。半値幅法の答えは信用しないでください（2つの山の合成を1本と誤読するため）。06以降のRFP法へ進んでください。","OK：孤立した1本の山なので半値幅法で妥当です。") -> ⚠ NG：山が2本以上あります。半値幅法の答えは信用しないでください（2つの山の合成を1本と誤読するため）。06以降のRFP法へ進んでください。
B20: 半値幅と Δf の比 | E20: =IFERROR(E10/03_FRFデータ貼付!H5,"") -> 2.2017303
B21: 分解能の判定 | E21: =IFERROR(IF(E20>=8,"OK（山の中に8点以上ある）","⚠ 点が粗すぎ。半値幅の中に最低8点は欲しい（Nを増やす／ズーム測定）"),"") -> ⚠ 点が粗すぎ。半値幅の中に最低8点は欲しい（Nを増やす／ズーム測定）
A23: ■ 08シートへ渡す初期値（ここをそのまま写してください）
B24: 山①のおよその周波数 [Hz] | E24: =IFERROR(IF(E18>=2,"04シートでピーク行を目視して読み取る",E6),"") -> 04シートでピーク行を目視して読み取る | I24: 2本ある時は 04シートの「◀ ピーク」が付いた行の周波数を2つ読み取り、08シートに手入力してください。
B25: 粗い η の推定値 | E25: =IFERROR(E11,"") -> 0.0063268111
A27: No. | B27: 周波数 f [Hz] | C27: 振幅 |H| | D27: 半値レベル比 |H|/半値 | E27: 上り/下り | F27: 下側交点 f1 （内挿） | G27: 上側交点 f2 （内挿） | H27: 備考
A28: =IF(03_FRFデータ貼付!B8="","",03_FRFデータ貼付!A8) -> 1 | B28: =IF(03_FRFデータ貼付!B8="","",03_FRFデータ貼付!B8) -> 3400 | C28: =IF(03_FRFデータ貼付!B8="","",03_FRFデータ貼付!E8) -> 0.003010432 | D28: =IF(OR(C28="",$E$7=0),"",C28/$E$7) -> 0.23146598 | E28: =IF(C28="","",IF(B28<$E$6,"上り","下り")) -> 上り | F28: =IF(OR(C28="",C29=""),"",IF(AND(B29<=$E$6,C28<$E$7,C29>=$E$7),B28+(B29-B28)*($E$7-C28)/(C29-C28),"")) | G28: =IF(OR(C28="",C29=""),"",IF(AND(B28>=$E$6,C28>=$E$7,C29<$E$7),B28+(B29-B28)*($E$7-C28)/(C29-C28),"")) | H28: =IF(F28<>"","← 下側の半値点",IF(G28<>"","← 上側の半値点",""))
A29: =IF(03_FRFデータ貼付!B9="","",03_FRFデータ貼付!A9) -> 2 | B29: =IF(03_FRFデータ貼付!B9="","",03_FRFデータ貼付!B9) -> 3410 | C29: =IF(03_FRFデータ貼付!B9="","",03_FRFデータ貼付!E9) -> 0.003392275 | D29: =IF(OR(C29="",$E$7=0),"",C29/$E$7) -> 0.26082511 | E29: =IF(C29="","",IF(B29<$E$6,"上り","下り")) -> 上り | F29: =IF(OR(C29="",C30=""),"",IF(AND(B30<=$E$6,C29<$E$7,C30>=$E$7),B29+(B30-B29)*($E$7-C29)/(C30-C29),"")) | G29: =IF(OR(C29="",C30=""),"",IF(AND(B29>=$E$6,C29>=$E$7,C30<$E$7),B29+(B30-B29)*($E$7-C29)/(C30-C29),"")) | H29: =IF(F29<>"","← 下側の半値点",IF(G29<>"","← 上側の半値点",""))
A30: =IF(03_FRFデータ貼付!B10="","",03_FRFデータ貼付!A10) -> 3 | B30: =IF(03_FRFデータ貼付!B10="","",03_FRFデータ貼付!B10) -> 3420 | C30: =IF(03_FRFデータ貼付!B10="","",03_FRFデータ貼付!E10) -> 0.003879384 | D30: =IF(OR(C30="",$E$7=0),"",C30/$E$7) -> 0.29827792 | E30: =IF(C30="","",IF(B30<$E$6,"上り","下り")) -> 上り | F30: =IF(OR(C30="",C31=""),"",IF(AND(B31<=$E$6,C30<$E$7,C31>=$E$7),B30+(B31-B30)*($E$7-C30)/(C31-C30),"")) | G30: =IF(OR(C30="",C31=""),"",IF(AND(B30>=$E$6,C30>=$E$7,C31<$E$7),B30+(B31-B30)*($E$7-C30)/(C31-C30),"")) | H30: =IF(F30<>"","← 下側の半値点",IF(G30<>"","← 上側の半値点",""))
A31: =IF(03_FRFデータ貼付!B11="","",03_FRFデータ貼付!A11) -> 4 | B31: =IF(03_FRFデータ貼付!B11="","",03_FRFデータ貼付!B11) -> 3430 | C31: =IF(03_FRFデータ貼付!B11="","",03_FRFデータ貼付!E11) -> 0.0045246719 | D31: =IF(OR(C31="",$E$7=0),"",C31/$E$7) -> 0.34789279 | E31: =IF(C31="","",IF(B31<$E$6,"上り","下り")) -> 上り | F31: =IF(OR(C31="",C32=""),"",IF(AND(B32<=$E$6,C31<$E$7,C32>=$E$7),B31+(B32-B31)*($E$7-C31)/(C32-C31),"")) | G31: =IF(OR(C31="",C32=""),"",IF(AND(B31>=$E$6,C31>=$E$7,C32<$E$7),B31+(B32-B31)*($E$7-C31)/(C32-C31),"")) | H31: =IF(F31<>"","← 下側の半値点",IF(G31<>"","← 上側の半値点",""))
A32: =IF(03_FRFデータ貼付!B12="","",03_FRFデータ貼付!A12) -> 5 | B32: =IF(03_FRFデータ貼付!B12="","",03_FRFデータ貼付!B12) -> 3440 | C32: =IF(03_FRFデータ貼付!B12="","",03_FRFデータ貼付!E12) -> 0.0054869402 | D32: =IF(OR(C32="",$E$7=0),"",C32/$E$7) -> 0.42187964 | E32: =IF(C32="","",IF(B32<$E$6,"上り","下り")) -> 上り | F32: =IF(OR(C32="",C33=""),"",IF(AND(B33<=$E$6,C32<$E$7,C33>=$E$7),B32+(B33-B32)*($E$7-C32)/(C33-C32),"")) | G32: =IF(OR(C32="",C33=""),"",IF(AND(B32>=$E$6,C32>=$E$7,C33<$E$7),B32+(B33-B32)*($E$7-C32)/(C33-C32),"")) | H32: =IF(F32<>"","← 下側の半値点",IF(G32<>"","← 上側の半値点",""))
A33: =IF(03_FRFデータ貼付!B13="","",03_FRFデータ貼付!A13) -> 6 | B33: =IF(03_FRFデータ貼付!B13="","",03_FRFデータ貼付!B13) -> 3450 | C33: =IF(03_FRFデータ貼付!B13="","",03_FRFデータ貼付!E13) -> 0.006928894 | D33: =IF(OR(C33="",$E$7=0),"",C33/$E$7) -> 0.53274852 | E33: =IF(C33="","",IF(B33<$E$6,"上り","下り")) -> 上り | F33: =IF(OR(C33="",C34=""),"",IF(AND(B34<=$E$6,C33<$E$7,C34>=$E$7),B33+(B34-B33)*($E$7-C33)/(C34-C33),"")) | G33: =IF(OR(C33="",C34=""),"",IF(AND(B33>=$E$6,C33>=$E$7,C34<$E$7),B33+(B34-B33)*($E$7-C33)/(C34-C33),"")) | H33: =IF(F33<>"","← 下側の半値点",IF(G33<>"","← 上側の半値点",""))
A34: =IF(03_FRFデータ貼付!B14="","",03_FRFデータ貼付!A14) -> 7 | B34: =IF(03_FRFデータ貼付!B14="","",03_FRFデータ貼付!B14) -> 3460 | C34: =IF(03_FRFデータ貼付!B14="","",03_FRFデータ貼付!E14) -> 0.0093821876 | D34: =IF(OR(C34="",$E$7=0),"",C34/$E$7) -> 0.72137726 | E34: =IF(C34="","",IF(B34<$E$6,"上り","下り")) -> 上り | F34: =IF(OR(C34="",C35=""),"",IF(AND(B35<=$E$6,C34<$E$7,C35>=$E$7),B34+(B35-B34)*($E$7-C34)/(C35-C34),"")) -> 3467.8302 | G34: =IF(OR(C34="",C35=""),"",IF(AND(B34>=$E$6,C34>=$E$7,C35<$E$7),B34+(B35-B34)*($E$7-C34)/(C35-C34),"")) | H34: =IF(F34<>"","← 下側の半値点",IF(G34<>"","← 上側の半値点","")) -> ← 下側の半値点
A35: =IF(03_FRFデータ貼付!B15="","",03_FRFデータ貼付!A15) -> 8 | B35: =IF(03_FRFデータ貼付!B15="","",03_FRFデータ貼付!B15) -> 3470 | C35: =IF(03_FRFデータ貼付!B15="","",03_FRFデータ貼付!E15) -> 0.014010102 | D35: =IF(OR(C35="",$E$7=0),"",C35/$E$7) -> 1.0772082 | E35: =IF(C35="","",IF(B35<$E$6,"上り","下り")) -> 上り | F35: =IF(OR(C35="",C36=""),"",IF(AND(B36<=$E$6,C35<$E$7,C36>=$E$7),B35+(B36-B35)*($E$7-C35)/(C36-C35),"")) | G35: =IF(OR(C35="",C36=""),"",IF(AND(B35>=$E$6,C35>=$E$7,C36<$E$7),B35+(B36-B35)*($E$7-C35)/(C36-C35),"")) | H35: =IF(F35<>"","← 下側の半値点",IF(G35<>"","← 上側の半値点",""))
A36: =IF(03_FRFデータ貼付!B16="","",03_FRFデータ貼付!A16) -> 9 | B36: =IF(03_FRFデータ貼付!B16="","",03_FRFデータ貼付!B16) -> 3480 | C36: =IF(03_FRFデータ貼付!B16="","",03_FRFデータ貼付!E16) -> 0.018393173 | D36: =IF(OR(C36="",$E$7=0),"",C36/$E$7) -> 1.4142136 | E36: =IF(C36="","",IF(B36<$E$6,"上り","下り")) -> 下り | F36: =IF(OR(C36="",C37=""),"",IF(AND(B37<=$E$6,C36<$E$7,C37>=$E$7),B36+(B37-B36)*($E$7-C36)/(C37-C36),"")) | G36: =IF(OR(C36="",C37=""),"",IF(AND(B36>=$E$6,C36>=$E$7,C37<$E$7),B36+(B37-B36)*($E$7-C36)/(C37-C36),"")) -> 3489.8475 | H36: =IF(F36<>"","← 下側の半値点",IF(G36<>"","← 上側の半値点","")) -> ← 上側の半値点
A37: =IF(03_FRFデータ貼付!B17="","",03_FRFデータ貼付!A17) -> 10 | B37: =IF(03_FRFデータ貼付!B17="","",03_FRFデータ貼付!B17) -> 3490 | C37: =IF(03_FRFデータ貼付!B17="","",03_FRFデータ貼付!E17) -> 0.012922512 | D37: =IF(OR(C37="",$E$7=0),"",C37/$E$7) -> 0.99358557 | E37: =IF(C37="","",IF(B37<$E$6,"上り","下り")) -> 下り | F37: =IF(OR(C37="",C38=""),"",IF(AND(B38<=$E$6,C37<$E$7,C38>=$E$7),B37+(B38-B37)*($E$7-C37)/(C38-C37),"")) | G37: =IF(OR(C37="",C38=""),"",IF(AND(B37>=$E$6,C37>=$E$7,C38<$E$7),B37+(B38-B37)*($E$7-C37)/(C38-C37),"")) | H37: =IF(F37<>"","← 下側の半値点",IF(G37<>"","← 上側の半値点",""))
A38: =IF(03_FRFデータ貼付!B18="","",03_FRFデータ貼付!A18) -> 11 | B38: =IF(03_FRFデータ貼付!B18="","",03_FRFデータ貼付!B18) -> 3500 | C38: =IF(03_FRFデータ貼付!B18="","",03_FRFデータ貼付!E18) -> 0.0093765685 | D38: =IF(OR(C38="",$E$7=0),"",C38/$E$7) -> 0.72094522 | E38: =IF(C38="","",IF(B38<$E$6,"上り","下り")) -> 下り | F38: =IF(OR(C38="",C39=""),"",IF(AND(B39<=$E$6,C38<$E$7,C39>=$E$7),B38+(B39-B38)*($E$7-C38)/(C39-C38),"")) | G38: =IF(OR(C38="",C39=""),"",IF(AND(B38>=$E$6,C38>=$E$7,C39<$E$7),B38+(B39-B38)*($E$7-C38)/(C39-C38),"")) | H38: =IF(F38<>"","← 下側の半値点",IF(G38<>"","← 上側の半値点",""))
A39: =IF(03_FRFデータ貼付!B19="","",03_FRFデータ貼付!A19) -> 12 | B39: =IF(03_FRFデータ貼付!B19="","",03_FRFデータ貼付!B19) -> 3510 | C39: =IF(03_FRFデータ貼付!B19="","",03_FRFデータ貼付!E19) -> 0.01027505 | D39: =IF(OR(C39="",$E$7=0),"",C39/$E$7) -> 0.79002759 | E39: =IF(C39="","",IF(B39<$E$6,"上り","下り")) -> 下り | F39: =IF(OR(C39="",C40=""),"",IF(AND(B40<=$E$6,C39<$E$7,C40>=$E$7),B39+(B40-B39)*($E$7-C39)/(C40-C39),"")) | G39: =IF(OR(C39="",C40=""),"",IF(AND(B39>=$E$6,C39>=$E$7,C40<$E$7),B39+(B40-B39)*($E$7-C39)/(C40-C39),"")) | H39: =IF(F39<>"","← 下側の半値点",IF(G39<>"","← 上側の半値点",""))
... A146: =IF(03_FRFデータ貼付!B126="","",03_FRFデータ貼付!A126) | B146: =IF(03_FRFデータ貼付!B126="","",03_FRFデータ貼付!B126) | C146: =IF(03_FRFデータ貼付!B126="","",03_FRFデータ貼付!E126) | D146: =IF(OR(C146="",$E$7=0),"",C146/$E$7) | E146: =IF(C146="","",IF(B146<$E$6,"上り","下り")) | F146: =IF(OR(C146="",C147=""),"",IF(AND(B147<=$E$6,C146<$E$7,C147>=$E$7),B146+(B147-B146)*($E$7-C146)/(C147-C146),"")) | G146: =IF(OR(C146="",C147=""),"",IF(AND(B146>=$E$6,C146>=$E$7,C147<$E$7),B146+(B147-B146)*($E$7-C146)/(C147-C146),"")) | H146: =IF(F146<>"","← 下側の半値点",IF(G146<>"","← 上側の半値点",""))
A147: =IF(03_FRFデータ貼付!B127="","",03_FRFデータ貼付!A127) | B147: =IF(03_FRFデータ貼付!B127="","",03_FRFデータ貼付!B127) | C147: =IF(03_FRFデータ貼付!B127="","",03_FRFデータ貼付!E127) | D147: =IF(OR(C147="",$E$7=0),"",C147/$E$7) | E147: =IF(C147="","",IF(B147<$E$6,"上り","下り")) | F147: ="" | G147: ="" | H147: =IF(F147<>"","← 下側の半値点",IF(G147<>"","← 上側の半値点",""))

Sheet 06_RFP設計行列
A1: ⑥ RFP（有理多項式）法の設計行列｜自動生成・入力不要
A2: FRFを『分子の多項式 ÷ 分母の多項式』に当てはめる連立方程式の“材料”です。1点につき実部・虚部の2本の式ができます。
A4: ■ 当てはめるモデル式
B5: H(Ω) = [ b0 + b1(jΩ) + b2(jΩ)² + b3(jΩ)³ ] ÷ [ a0 + a1(jΩ) + a2(jΩ)² + a3(jΩ)³ + (jΩ)⁴ ]
B6: 分母を4次にするのが肝。4次方程式の根は4つ＝複素共役ペアが2組＝モードが2つ。だから“双子モード”を数式ごと分離できます。
B7: 両辺に分母を掛けると、未知数 b0〜b3, a0〜a3 について完全に1次（線形）の式になります。だから最小二乗法で一発で解けます。
B8: 空白行（データ未入力の行）は係数も右辺も全部0にしてあるので、何点貼っても範囲を書き換える必要はありません。
A10: 種別 | B10: 点番号 | C10: 有効 | D10: Ω 正規化角周波数 | E10: Re(Hn) | F10: Im(Hn) | G10: b0の係数 | H10: b1の係数 | I10: b2の係数 | J10: b3の係数 | K10: a0の係数 | L10: a1の係数 | M10: a2の係数 | N10: a3の係数 | O10: 右辺 RHS
A11: ="実部" -> 実部 | B11: =IF(03_FRFデータ貼付!B8="","",03_FRFデータ貼付!A8) -> 1 | C11: =IF(AND(03_FRFデータ貼付!B8<>"",03_FRFデータ貼付!C8<>"",03_FRFデータ貼付!D8<>""),1,0) -> 1 | D11: =IF($C11=0,0,03_FRFデータ貼付!H8) -> 0.97142857 | E11: =IF($C11=0,0,03_FRFデータ貼付!I8) -> 0.0027727679 | F11: =IF($C11=0,0,03_FRFデータ貼付!J8) -> 0.16364767 | G11: =$C11*1 -> 1 | H11: =0 -> 0 | I11: =-$C11*$D11^2 -> -0.94367347 | J11: =0 -> 0 | K11: =-$C11*$E11 -> -0.0027727679 | L11: =$C11*$D11*$F11 -> 0.15897202 | M11: =$C11*$D11^2*$E11 -> 0.0026165875 | N11: =-$C11*$D11^3*$F11 -> -0.15001768 | O11: =$C11*$D11^4*$E11 -> 0.0024692042 | Q11: 【実部の式】b0 −b2Ω² −a0·Re −(−a1Ω·Im) + a2Ω²Re − a3Ω³Im = Ω⁴·Re
A12: ="実部" -> 実部 | B12: =IF(03_FRFデータ貼付!B9="","",03_FRFデータ貼付!A9) -> 2 | C12: =IF(AND(03_FRFデータ貼付!B9<>"",03_FRFデータ貼付!C9<>"",03_FRFデータ貼付!D9<>""),1,0) -> 1 | D12: =IF($C12=0,0,03_FRFデータ貼付!H9) -> 0.97428571 | E12: =IF($C12=0,0,03_FRFデータ貼付!I9) -> 0.0050562238 | F12: =IF($C12=0,0,03_FRFデータ貼付!J9) -> 0.18436188 | G12: =$C12*1 -> 1 | H12: =0 -> 0 | I12: =-$C12*$D12^2 -> -0.94923265 | J12: =0 -> 0 | K12: =-$C12*$E12 -> -0.0050562238 | L12: =$C12*$D12*$F12 -> 0.17962115 | M12: =$C12*$D12^2*$E12 -> 0.0047995327 | N12: =-$C12*$D12^3*$F12 -> -0.17050226 | O12: =$C12*$D12^4*$E12 -> 0.0045558732 | Q12: 【虚部の式】b1Ω −b3Ω³ −a0·Im −a1Ω·Re + a2Ω²Im + a3Ω³Re = Ω⁴·Im
A13: ="実部" -> 実部 | B13: =IF(03_FRFデータ貼付!B10="","",03_FRFデータ貼付!A10) -> 3 | C13: =IF(AND(03_FRFデータ貼付!B10<>"",03_FRFデータ貼付!C10<>"",03_FRFデータ貼付!D10<>""),1,0) -> 1 | D13: =IF($C13=0,0,03_FRFデータ貼付!H10) -> 0.97714286 | E13: =IF($C13=0,0,03_FRFデータ貼付!I10) -> 0.0088076156 | F13: =IF($C13=0,0,03_FRFデータ貼付!J10) -> 0.21073036 | G13: =$C13*1 -> 1 | H13: =0 -> 0 | I13: =-$C13*$D13^2 -> -0.95480816 | J13: =0 -> 0 | K13: =-$C13*$E13 -> -0.0088076156 | L13: =$C13*$D13*$F13 -> 0.20591366 | M13: =$C13*$D13^2*$E13 -> 0.0084095833 | N13: =-$C13*$D13^3*$F13 -> -0.19660805 | O13: =$C13*$D13^4*$E13 -> 0.0080295387
A14: ="実部" -> 実部 | B14: =IF(03_FRFデータ貼付!B11="","",03_FRFデータ貼付!A11) -> 4 | C14: =IF(AND(03_FRFデータ貼付!B11<>"",03_FRFデータ貼付!C11<>"",03_FRFデータ貼付!D11<>""),1,0) -> 1 | D14: =IF($C14=0,0,03_FRFデータ貼付!H11) -> 0.98 | E14: =IF($C14=0,0,03_FRFデータ貼付!I11) -> 0.015223039 | F14: =IF($C14=0,0,03_FRFデータ貼付!J11) -> 0.24552588 | G14: =$C14*1 -> 1 | H14: =0 -> 0 | I14: =-$C14*$D14^2 -> -0.9604 | J14: =0 -> 0 | K14: =-$C14*$E14 -> -0.015223039 | L14: =$C14*$D14*$F14 -> 0.24061536 | M14: =$C14*$D14^2*$E14 -> 0.014620207 | N14: =-$C14*$D14^3*$F14 -> -0.23108699 | O14: =$C14*$D14^4*$E14 -> 0.014041247 | Q14: ※ Ω＝2πf/ωref（正規化角周波数）、Hn＝H/Href（正規化FRF）。
A15: ="実部" -> 実部 | B15: =IF(03_FRFデータ貼付!B12="","",03_FRFデータ貼付!A12) -> 5 | C15: =IF(AND(03_FRFデータ貼付!B12<>"",03_FRFデータ貼付!C12<>"",03_FRFデータ貼付!D12<>""),1,0) -> 1 | D15: =IF($C15=0,0,03_FRFデータ貼付!H12) -> 0.98285714 | E15: =IF($C15=0,0,03_FRFデータ貼付!I12) -> 0.027836415 | F15: =IF($C15=0,0,03_FRFデータ貼付!J12) -> 0.29701237 | G15: =$C15*1 -> 1 | H15: =0 -> 0 | I15: =-$C15*$D15^2 -> -0.96600816 | J15: =0 -> 0 | K15: =-$C15*$E15 -> -0.027836415 | L15: =$C15*$D15*$F15 -> 0.29192073 | M15: =$C15*$D15^2*$E15 -> 0.026890204 | N15: =-$C15*$D15^3*$F15 -> -0.28199781 | O15: =$C15*$D15^4*$E15 -> 0.025976156 | Q15: ※ 周波数と振幅の両方を1前後に正規化することで、行列の条件数が約1.6×10⁹ → 5.8×10⁵ に改善します（Pythonで検証済み🟢）。
A16: ="実部" -> 実部 | B16: =IF(03_FRFデータ貼付!B13="","",03_FRFデータ貼付!A13) -> 6 | C16: =IF(AND(03_FRFデータ貼付!B13<>"",03_FRFデータ貼付!C13<>"",03_FRFデータ貼付!D13<>""),1,0) -> 1 | D16: =IF($C16=0,0,03_FRFデータ貼付!H13) -> 0.98571429 | E16: =IF($C16=0,0,03_FRFデータ貼付!I13) -> 0.055237885 | F16: =IF($C16=0,0,03_FRFデータ貼付!J13) -> 0.37263825 | G16: =$C16*1 -> 1 | H16: =0 -> 0 | I16: =-$C16*$D16^2 -> -0.97163265 | J16: =0 -> 0 | K16: =-$C16*$E16 -> -0.055237885 | L16: =$C16*$D16*$F16 -> 0.36731485 | M16: =$C16*$D16^2*$E16 -> 0.053670933 | N16: =-$C16*$D16^3*$F16 -> -0.3568951 | O16: =$C16*$D16^4*$E16 -> 0.052148431
A17: ="実部" -> 実部 | B17: =IF(03_FRFデータ貼付!B14="","",03_FRFデータ貼付!A14) -> 7 | C17: =IF(AND(03_FRFデータ貼付!B14<>"",03_FRFデータ貼付!C14<>"",03_FRFデータ貼付!D14<>""),1,0) -> 1 | D17: =IF($C17=0,0,03_FRFデータ貼付!H14) -> 0.98857143 | E17: =IF($C17=0,0,03_FRFデータ貼付!I14) -> 0.12841721 | F17: =IF($C17=0,0,03_FRFデータ貼付!J14) -> 0.49366142 | G17: =$C17*1 -> 1 | H17: =0 -> 0 | I17: =-$C17*$D17^2 -> -0.97727347 | J17: =0 -> 0 | K17: =-$C17*$E17 -> -0.12841721 | L17: =$C17*$D17*$F17 -> 0.48801957 | M17: =$C17*$D17^2*$E17 -> 0.12549873 | N17: =-$C17*$D17^3*$F17 -> -0.47692858 | O17: =$C17*$D17^4*$E17 -> 0.12264658
A18: ="実部" -> 実部 | B18: =IF(03_FRFデータ貼付!B15="","",03_FRFデータ貼付!A15) -> 8 | C18: =IF(AND(03_FRFデータ貼付!B15<>"",03_FRFデータ貼付!C15<>"",03_FRFデータ貼付!D15<>""),1,0) -> 1 | D18: =IF($C18=0,0,03_FRFデータ貼付!H15) -> 0.99142857 | E18: =IF($C18=0,0,03_FRFデータ貼付!I15) -> 0.37725953 | F18: =IF($C18=0,0,03_FRFデータ貼付!J15) -> 0.6617129 | G18: =$C18*1 -> 1 | H18: =0 -> 0 | I18: =-$C18*$D18^2 -> -0.98293061 | J18: =0 -> 0 | K18: =-$C18*$E18 -> -0.37725953 | L18: =$C18*$D18*$F18 -> 0.65604107 | M18: =$C18*$D18^2*$E18 -> 0.37081994 | N18: =-$C18*$D18^3*$F18 -> -0.64484285 | O18: =$C18*$D18^4*$E18 -> 0.36449028
A19: ="実部" -> 実部 | B19: =IF(03_FRFデータ貼付!B16="","",03_FRFデータ貼付!A16) -> 9 | C19: =IF(AND(03_FRFデータ貼付!B16<>"",03_FRFデータ貼付!C16<>"",03_FRFデータ貼付!D16<>""),1,0) -> 1 | D19: =IF($C19=0,0,03_FRFデータ貼付!H16) -> 0.99428571 | E19: =IF($C19=0,0,03_FRFデータ貼付!I16) -> 0.92251618 | F19: =IF($C19=0,0,03_FRFデータ貼付!J16) -> 0.38595841 | G19: =$C19*1 -> 1 | H19: =0 -> 0 | I19: =-$C19*$D19^2 -> -0.98860408 | J19: =0 -> 0 | K19: =-$C19*$E19 -> -0.92251618 | L19: =$C19*$D19*$F19 -> 0.38375294 | M19: =$C19*$D19^2*$E19 -> 0.91200326 | N19: =-$C19*$D19^3*$F19 -> -0.37937972 | O19: =$C19*$D19^4*$E19 -> 0.90161015
A20: ="実部" -> 実部 | B20: =IF(03_FRFデータ貼付!B17="","",03_FRFデータ貼付!A17) -> 10 | C20: =IF(AND(03_FRFデータ貼付!B17<>"",03_FRFデータ貼付!C17<>"",03_FRFデータ貼付!D17<>""),1,0) -> 1 | D20: =IF($C20=0,0,03_FRFデータ貼付!H17) -> 0.99714286 | E20: =IF($C20=0,0,03_FRFデータ貼付!I17) -> 0.69226771 | F20: =IF($C20=0,0,03_FRFデータ貼付!J17) -> -0.11988143 | G20: =$C20*1 -> 1 | H20: =0 -> 0 | I20: =-$C20*$D20^2 -> -0.99429388 | J20: =0 -> 0 | K20: =-$C20*$E20 -> -0.69226771 | L20: =$C20*$D20*$F20 -> -0.11953892 | M20: =$C20*$D20^2*$E20 -> 0.68831755 | N20: =-$C20*$D20^3*$F20 -> 0.11885681 | O20: =$C20*$D20^4*$E20 -> 0.68438992
A21: ="実部" -> 実部 | B21: =IF(03_FRFデータ貼付!B18="","",03_FRFデータ貼付!A18) -> 11 | C21: =IF(AND(03_FRFデータ貼付!B18<>"",03_FRFデータ貼付!C18<>"",03_FRFデータ貼付!D18<>""),1,0) -> 1 | D21: =IF($C21=0,0,03_FRFデータ貼付!H18) -> 1 | E21: =IF($C21=0,0,03_FRFデータ貼付!I18) -> 0.50023994 | F21: =IF($C21=0,0,03_FRFデータ貼付!J18) -> -0.098188603 | G21: =$C21*1 -> 1 | H21: =0 -> 0 | I21: =-$C21*$D21^2 -> -1 | J21: =0 -> 0 | K21: =-$C21*$E21 -> -0.50023994 | L21: =$C21*$D21*$F21 -> -0.098188603 | M21: =$C21*$D21^2*$E21 -> 0.50023994 | N21: =-$C21*$D21^3*$F21 -> 0.098188603 | O21: =$C21*$D21^4*$E21 -> 0.50023994
A22: ="実部" -> 実部 | B22: =IF(03_FRFデータ貼付!B19="","",03_FRFデータ貼付!A19) -> 12 | C22: =IF(AND(03_FRFデータ貼付!B19<>"",03_FRFデータ貼付!C19<>"",03_FRFデータ貼付!D19<>""),1,0) -> 1 | D22: =IF($C22=0,0,03_FRFデータ貼付!H19) -> 1.0028571 | E22: =IF($C22=0,0,03_FRFデータ貼付!I19) -> 0.55248759 | F22: =IF($C22=0,0,03_FRFデータ貼付!J19) -> -0.082639356 | G22: =$C22*1 -> 1 | H22: =0 -> 0 | I22: =-$C22*$D22^2 -> -1.0057224 | J22: =0 -> 0 | K22: =-$C22*$E22 -> -0.55248759 | L22: =$C22*$D22*$F22 -> -0.082875469 | M22: =$C22*$D22^2*$E22 -> 0.55564917 | N22: =-$C22*$D22^3*$F22 -> 0.083349719 | O22: =$C22*$D22^4*$E22 -> 0.55882885
A23: ="実部" -> 実部 | B23: =IF(03_FRFデータ貼付!B20="","",03_FRFデータ貼付!A20) -> 13 | C23: =IF(AND(03_FRFデータ貼付!B20<>"",03_FRFデータ貼付!C20<>"",03_FRFデータ貼付!D20<>""),1,0) -> 1 | D23: =IF($C23=0,0,03_FRFデータ貼付!H20) -> 1.0057143 | E23: =IF($C23=0,0,03_FRFデータ貼付!I20) -> 0.60391972 | F23: =IF($C23=0,0,03_FRFデータ貼付!J20) -> -0.31228978 | G23: =$C23*1 -> 1 | H23: =0 -> 0 | I23: =-$C23*$D23^2 -> -1.0114612 | J23: =0 -> 0 | K23: =-$C23*$E23 -> -0.60391972 | L23: =$C23*$D23*$F23 -> -0.31407429 | M23: =$C23*$D23^2*$E23 -> 0.61084137 | N23: =-$C23*$D23^3*$F23 -> 0.31767397 | O23: =$C23*$D23^4*$E23 -> 0.61784236
A24: ="実部" -> 実部 | B24: =IF(03_FRFデータ貼付!B21="","",03_FRFデータ貼付!A21) -> 14 | C24: =IF(AND(03_FRFデータ貼付!B21<>"",03_FRFデータ貼付!C21<>"",03_FRFデータ貼付!D21<>""),1,0) -> 1 | D24: =IF($C24=0,0,03_FRFデータ貼付!H21) -> 1.0085714 | E24: =IF($C24=0,0,03_FRFデータ貼付!I21) -> 0.35219589 | F24: =IF($C24=0,0,03_FRFデータ貼付!J21) -> -0.47131617 | G24: =$C24*1 -> 1 | H24: =0 -> 0 | I24: =-$C24*$D24^2 -> -1.0172163 | J24: =0 -> 0 | K24: =-$C24*$E24 -> -0.35219589 | L24: =$C24*$D24*$F24 -> -0.47535602 | M24: =$C24*$D24^2*$E24 -> 0.35825941 | N24: =-$C24*$D24^3*$F24 -> 0.48353991 | O24: =$C24*$D24^4*$E24 -> 0.36442732
A25: ="実部" -> 実部 | B25: =IF(03_FRFデータ貼付!B22="","",03_FRFデータ貼付!A22) -> 15 | C25: =IF(AND(03_FRFデータ貼付!B22<>"",03_FRFデータ貼付!C22<>"",03_FRFデータ貼付!D22<>""),1,0) -> 1 | D25: =IF($C25=0,0,03_FRFデータ貼付!H22) -> 1.0114286 | E25: =IF($C25=0,0,03_FRFデータ貼付!I22) -> 0.17082425 | F25: =IF($C25=0,0,03_FRFデータ貼付!J22) -> -0.40640078 | G25: =$C25*1 -> 1 | H25: =0 -> 0 | I25: =-$C25*$D25^2 -> -1.0229878 | J25: =0 -> 0 | K25: =-$C25*$E25 -> -0.17082425 | L25: =$C25*$D25*$F25 -> -0.41104536 | M25: =$C25*$D25^2*$E25 -> 0.17475111 | N25: =-$C25*$D25^3*$F25 -> 0.42049437 | O25: =$C25*$D25^4*$E25 -> 0.17876825
A26: ="実部" -> 実部 | B26: =IF(03_FRFデータ貼付!B23="","",03_FRFデータ貼付!A23) -> 16 | C26: =IF(AND(03_FRFデータ貼付!B23<>"",03_FRFデータ貼付!C23<>"",03_FRFデータ貼付!D23<>""),1,0) -> 1 | D26: =IF($C26=0,0,03_FRFデータ貼付!H23) -> 1.0142857 | E26: =IF($C26=0,0,03_FRFデータ貼付!I23) -> 0.095633307 | F26: =IF($C26=0,0,03_FRFデータ貼付!J23) -> -0.32925259 | G26: =$C26*1 -> 1 | H26: =0 -> 0 | I26: =-$C26*$D26^2 -> -1.0287755 | J26: =0 -> 0 | K26: =-$C26*$E26 -> -0.095633307 | L26: =$C26*$D26*$F26 -> -0.3339562 | M26: =$C26*$D26^2*$E26 -> 0.098385205 | N26: =-$C26*$D26^3*$F26 -> 0.34356596 | O26: =$C26*$D26^4*$E26 -> 0.10121629
A27: ="実部" -> 実部 | B27: =IF(03_FRFデータ貼付!B24="","",03_FRFデータ貼付!A24) -> 17 | C27: =IF(AND(03_FRFデータ貼付!B24<>"",03_FRFデータ貼付!C24<>"",03_FRFデータ貼付!D24<>""),1,0) -> 1 | D27: =IF($C27=0,0,03_FRFデータ貼付!H24) -> 1.0171429 | E27: =IF($C27=0,0,03_FRFデータ貼付!I24) -> 0.061327101 | F27: =IF($C27=0,0,03_FRFデータ貼付!J24) -> -0.27183999 | G27: =$C27*1 -> 1 | H27: =0 -> 0 | I27: =-$C27*$D27^2 -> -1.0345796 | J27: =0 -> 0 | K27: =-$C27*$E27 -> -0.061327101 | L27: =$C27*$D27*$F27 -> -0.2765001 | M27: =$C27*$D27^2*$E27 -> 0.063447767 | N27: =-$C27*$D27^3*$F27 -> 0.28606136 | O27: =$C27*$D27^4*$E27 -> 0.065641765
... A130: ="実部" -> 実部 | B130: =IF(03_FRFデータ貼付!B127="","",03_FRFデータ貼付!A127) | C130: =IF(AND(03_FRFデータ貼付!B127<>"",03_FRFデータ貼付!C127<>"",03_FRFデータ貼付!D127<>""),1,0) -> 0 | D130: =IF($C130=0,0,03_FRFデータ貼付!H127) -> 0 | E130: =IF($C130=0,0,03_FRFデータ貼付!I127) -> 0 | F130: =IF($C130=0,0,03_FRFデータ貼付!J127) -> 0 | G130: =$C130*1 -> 0 | H130: =0 -> 0 | I130: =-$C130*$D130^2 -> 0 | J130: =0 -> 0 | K130: =-$C130*$E130 -> 0 | L130: =$C130*$D130*$F130 -> 0 | M130: =$C130*$D130^2*$E130 -> 0 | N130: =-$C130*$D130^3*$F130 -> 0 | O130: =$C130*$D130^4*$E130 -> 0
A131: ="虚部" -> 虚部 | B131: =IF(03_FRFデータ貼付!B8="","",03_FRFデータ貼付!A8) -> 1 | C131: =IF(AND(03_FRFデータ貼付!B8<>"",03_FRFデータ貼付!C8<>"",03_FRFデータ貼付!D8<>""),1,0) -> 1 | D131: =IF($C131=0,0,03_FRFデータ貼付!H8) -> 0.97142857 | E131: =IF($C131=0,0,03_FRFデータ貼付!I8) -> 0.0027727679 | F131: =IF($C131=0,0,03_FRFデータ貼付!J8) -> 0.16364767 | G131: =0 -> 0 | H131: =$C131*$D131 -> 0.97142857 | I131: =0 -> 0 | J131: =-$C131*$D131^3 -> -0.91671137 | K131: =-$C131*$F131 -> -0.16364767 | L131: =-$C131*$D131*$E131 -> -0.0026935459 | M131: =$C131*$D131^2*$F131 -> 0.15442997 | N131: =$C131*$D131^3*$E131 -> 0.0025418278 | O131: =$C131*$D131^4*$F131 -> 0.14573146
A132: ="虚部" -> 虚部 | B132: =IF(03_FRFデータ貼付!B9="","",03_FRFデータ貼付!A9) -> 2 | C132: =IF(AND(03_FRFデータ貼付!B9<>"",03_FRFデータ貼付!C9<>"",03_FRFデータ貼付!D9<>""),1,0) -> 1 | D132: =IF($C132=0,0,03_FRFデータ貼付!H9) -> 0.97428571 | E132: =IF($C132=0,0,03_FRFデータ貼付!I9) -> 0.0050562238 | F132: =IF($C132=0,0,03_FRFデータ貼付!J9) -> 0.18436188 | G132: =0 -> 0 | H132: =$C132*$D132 -> 0.97428571 | I132: =0 -> 0 | J132: =-$C132*$D132^3 -> -0.92482381 | K132: =-$C132*$F132 -> -0.18436188 | L132: =-$C132*$D132*$E132 -> -0.0049262066 | M132: =$C132*$D132^2*$F132 -> 0.17500232 | N132: =$C132*$D132^3*$E132 -> 0.0046761161 | O132: =$C132*$D132^4*$F132 -> 0.16611791
A133: ="虚部" -> 虚部 | B133: =IF(03_FRFデータ貼付!B10="","",03_FRFデータ貼付!A10) -> 3 | C133: =IF(AND(03_FRFデータ貼付!B10<>"",03_FRFデータ貼付!C10<>"",03_FRFデータ貼付!D10<>""),1,0) -> 1 | D133: =IF($C133=0,0,03_FRFデータ貼付!H10) -> 0.97714286 | E133: =IF($C133=0,0,03_FRFデータ貼付!I10) -> 0.0088076156 | F133: =IF($C133=0,0,03_FRFデータ貼付!J10) -> 0.21073036 | G133: =0 -> 0 | H133: =$C133*$D133 -> 0.97714286 | I133: =0 -> 0 | J133: =-$C133*$D133^3 -> -0.93298398 | K133: =-$C133*$F133 -> -0.21073036 | L133: =-$C133*$D133*$E133 -> -0.0086062987 | M133: =$C133*$D133^2*$F133 -> 0.20120707 | N133: =$C133*$D133^3*$E133 -> 0.0082173642 | O133: =$C133*$D133^4*$F133 -> 0.19211415
A134: ="虚部" -> 虚部 | B134: =IF(03_FRFデータ貼付!B11="","",03_FRFデータ貼付!A11) -> 4 | C134: =IF(AND(03_FRFデータ貼付!B11<>"",03_FRFデータ貼付!C11<>"",03_FRFデータ貼付!D11<>""),1,0) -> 1 | D134: =IF($C134=0,0,03_FRFデータ貼付!H11) -> 0.98 | E134: =IF($C134=0,0,03_FRFデータ貼付!I11) -> 0.015223039 | F134: =IF($C134=0,0,03_FRFデータ貼付!J11) -> 0.24552588 | G134: =0 -> 0 | H134: =$C134*$D134 -> 0.98 | I134: =0 -> 0 | J134: =-$C134*$D134^3 -> -0.941192 | K134: =-$C134*$F134 -> -0.24552588 | L134: =-$C134*$D134*$E134 -> -0.014918578 | M134: =$C134*$D134^2*$F134 -> 0.23580305 | N134: =$C134*$D134^3*$E134 -> 0.014327803 | O134: =$C134*$D134^4*$F134 -> 0.22646525
A135: ="虚部" -> 虚部 | B135: =IF(03_FRFデータ貼付!B12="","",03_FRFデータ貼付!A12) -> 5 | C135: =IF(AND(03_FRFデータ貼付!B12<>"",03_FRFデータ貼付!C12<>"",03_FRFデータ貼付!D12<>""),1,0) -> 1 | D135: =IF($C135=0,0,03_FRFデータ貼付!H12) -> 0.98285714 | E135: =IF($C135=0,0,03_FRFデータ貼付!I12) -> 0.027836415 | F135: =IF($C135=0,0,03_FRFデータ貼付!J12) -> 0.29701237 | G135: =0 -> 0 | H135: =$C135*$D135 -> 0.98285714 | I135: =0 -> 0 | J135: =-$C135*$D135^3 -> -0.94944802 | K135: =-$C135*$F135 -> -0.29701237 | L135: =-$C135*$D135*$E135 -> -0.027359219 | M135: =$C135*$D135^2*$F135 -> 0.28691637 | N135: =$C135*$D135^3*$E135 -> 0.026429229 | O135: =$C135*$D135^4*$F135 -> 0.27716356
