Workbook

Sheet 使い方
A1: ブレーキパッド 金属部（摩擦材抜き）固有振動数予測ブック
A2: 裏板＋シムだけの状態（摩擦材を貼る前）で、ハンマリング試験・PSV-400スキャン試験に向けた予測ピークを出す専用ブック | Ver 1.0
A4: ■ このブックを作った理由（前提の確認）
A5: ご依頼「ハンマリングとトップラー試験に向けて、金属部分だけ・摩擦材抜きで計算したい」に対応。『トップラー試験』は文脈上『PSV-400（レーザードップラー振動計）でのスキャン試験』と解釈しました。違う意味であれば教えてください。 🟡 解釈
A6: 摩擦材を貼った完成パッドの予測は、ナリッジの「ブレーキパッド固有振動数予測.xlsx」を使ってください。このブックは裏板単体・裏板+シムなど、金属だけの状態専用です。
A8: ■ このブックで何ができるか
A9: ① 順算（じゅんざん） | B9: 材質と寸法を入れる → 金属部だけの固有振動数を予測 | C9: シート：形状 → 断面 → 固有振動数
A10: ② スペクトル | B10: 予測した山（ピーク）を並べて、FFT画面そっくりのグラフを作る | C10: シート：スペクトル
A11: ③ 実測比較 | B11: ハンマリング試験・PSV-400スキャンで測った周波数を入力 → ズレ%判定＋裏板Eの逆算 | C11: シート：実測比較
A13: ■ 摩擦材込みブックとの違い（3つだけ覚えればOK）
A14: ① 断面シートの層数 | B14: シム・裏板・接着(任意)の3層のみ。摩擦材の行はそもそもありません | C14: 🟢
A15: ② 鳴きリスク・逆算(摩擦材)シートは無し | B15: 鳴き判定にはローター(ディスク)側の情報が必要で、金属部単体では評価できないため | C15: 🟡
A16: ③ 予測周波数がかなり高く出る | B16: 摩擦材の重さが無いぶん軽く、剛性も高いため。スペクトルの周波数範囲を広め(既定0〜40kHz)にしています | C16: 🟢
A18: ■ 触（さわ）るセルの色分け
A19: アンバー（茶色）のセル | B19: あなたが入力するところ。ここだけ触ればOK | C19: 入力
A20: グリーンのセル | B20: 自動計算の結果。触ると壊（こわ）れます | C20: 出力
A21: グレーのセル | B21: 計算の途中（とちゅう）。見なくてよい | C21: 中間
A23: ■ 使う順番（この順で必ず動きます）
A24: STEP 1 | B24: 「材料DB」で使う材料（裏板の鋼種・シムの有無）を確認
A25: STEP 2 | B25: 「形状」に 金属スケルトンの外形の頂点座標（X,Y）を入力 | C25: 通常はパッド全体と同じ形でOK（プリセットが最初から入っています）
A26: STEP 3 | B26: 「断面」で シム(使う場合のみ1にする)・裏板 の材料と厚さを入力 | C26: 裏板の厚さ・材料名は必ず現物の刻印/図面で確認
A27: STEP 4 | B27: 「固有振動数」を見る → 予測ピーク一覧が出る
A28: STEP 5 | B28: 「スペクトル」でグラフ確認。A〜E列をコピーすれば他ソフトに貼れる
A29: STEP 6 | B29: ハンマリング試験・PSV-400スキャンを実施 | C29: 面外曲げ1次(表の1番上)を最初に狙うと見つけやすい
A30: STEP 7 | B30: 実測できたら「実測比較」に周波数を入力 → ズレ%と裏板Eの逆算値を確認
A32: ■ 信頼度マーク
A33: 🟢 検証済み | B33: 教科書・規格に載っている確立した式。そのまま信じてよい
A34: 🟡 推定 | B34: 妥当（だとう）だが近似。実測で校正（こうせい）してから使う
A35: 🔴 要確認 | B35: 値のばらつきが大きい。必ず自分で測る
A37: ■ 重要な前提（ここを外すと全部ずれます）
A38: 自由−自由（free-free） | B38: ピアノ線で吊（つ）った状態＝どこも固定していない状態を仮定 | C38: 🟢
A39: はり（梁）近似 | B39: パッドを「円周方向に長い1本の棒」とみなす。曲率は無視 | C39: 🟡
A40: 裏板・シムの厚さ／材質 | B40: 図面値ではなく、必ずノギス・マイクロメータで現物実測してから入力する | C40: 🔴
A41: 質量チェックが命綱 | B41: 断面シートの「質量[g]」を電子天秤の実測値と必ず突き合わせる。ズレていれば厚さor材質入力が間違っている | C41: 🟢
A42: この予測は CEA ではない | B42: あくまで金属部単体の目安。摩擦材を貼った後の鳴き判定は複素固有値解析(CEA)で行う | C42: 🟡
A44: ■ よくあるミス
A45: ・断面シートで使わない層の「使用1/0」を1のままにしてしまう → 意図しない層が計算に混入する
A46: ・形状シートの頂点を外周に沿った順番で入れていない（飛び飛びの順） → 面積・重心が壊れる（入力チェックがNGになるので分かる）
A47: ・裏板の厚さをプレス後の実測値ではなく図面公称値のまま使う → 数%〜10%のズレの主因になりやすい
A48: ・スペクトルの周波数範囲が予測ピークより低いまま → グラフに何も山が出ない（開始・Δfを調整する）

Sheet 材料DB
A1: 材料データベース（金属・シムのみ／摩擦材は含みません）
A2: E=ヤング率（かたさ）／ρ=密度（重さ）／ν=ポアソン比／η=損失係数（振動の減りやすさ）
A4: 材料名 | B4: E [GPa] | C4: ρ [kg/m³] | D4: ν | E4: η(目安) | F4: 分類 | G4: 信頼度 | H4: 出典・備考
A5: 鋼 SPCC(裏板) | B5: 205 | C5: 7850 | D5: 0.3 | E5: 0.0002 | F5: 金属 | G5: 🟢 | H5: JIS一般値 / 鋼のEは190-210GPa
A6: 鋼 SS400 | B6: 205 | C6: 7850 | D6: 0.3 | E6: 0.0002 | F6: 金属 | G6: 🟢 | H6: JIS一般値
A7: 鋼 S45C | B7: 205 | C7: 7850 | D7: 0.3 | E7: 0.0002 | F7: 金属 | G7: 🟢 | H7: JIS一般値
A8: ステンレス SUS304 | B8: 193 | C8: 7930 | D8: 0.3 | E8: 0.0005 | F8: 金属 | G8: 🟢 | H8: JIS一般値
A9: ばね鋼 SUP9 | B9: 206 | C9: 7850 | D9: 0.3 | E9: 0.0002 | F9: 金属 | G9: 🟢 | H9: JIS一般値
A10: ねずみ鋳鉄 FC250 | B10: 105 | C10: 7200 | D10: 0.26 | E10: 0.0015 | F10: 金属 | G10: 🟡 | H10: 90-120GPaの幅あり。黒鉛量で変化
A11: アルミ A5052 | B11: 70 | C11: 2680 | D11: 0.33 | E11: 0.0001 | F11: 金属 | G11: 🟢 | H11: JIS一般値
A12: アルミ A6061-T6 | B12: 69 | C12: 2700 | D12: 0.33 | E12: 0.0001 | F12: 金属 | G12: 🟢 | H12: JIS一般値
A13: チタン Ti-6Al-4V | B13: 114 | C13: 4430 | D13: 0.34 | E13: 0.0002 | F13: 金属 | G13: 🟢 | H13: ASTM Grade5
A14: 銅 C1100 | B14: 117 | C14: 8940 | D14: 0.34 | E14: 0.002 | F14: 金属 | G14: 🟢 | H14: JIS一般値
A15: 黄銅 C2600 | B15: 103 | C15: 8530 | D15: 0.35 | E15: 0.001 | F15: 金属 | G15: 🟢 | H15: JIS一般値
A16: シム鋼板 SPCC | B16: 205 | C16: 7850 | D16: 0.3 | E16: 0.0002 | F16: シム | G16: 🟢 | H16: JIS一般値
... A21: (未使用) | B21: 0 | C21: 1 | D21: 0 | E21: 0 | F21: - | G21: - | H21: 空欄行。使わない層に指定する
A23: ※ 行を追加するときは 45行目までに書けば全シートが自動で拾います（数式の参照範囲は $A$5:$A$45）。
A24: ※ このブックは摩擦材を含みません。摩擦材込みの計算は「ナリッジのブレーキパッド固有振動数予測.xlsx」を使ってください。

Sheet 形状
A1: ① 形状入力（金属スケルトンの外形を多角形で入力）
A2: X=円周方向（長手）、Y=半径方向。単位はすべて mm。頂点は最大16点。反時計回り・時計回りどちらでもOK。通常はパッド全体の外形と同じ形を入力すればOK（裏板は摩擦材とほぼ同じ外形のため）。裏板に耳・タブ等があり形が違う場合はその輪郭を入力してください。
E3: 頂点数 N | F3: =COUNT($B$6:$B$21) -> 14
E4: 向き s (+1=反時計/-1=時計) | F4: =IF(SUM($I$6:$I$21)>=0,1,-1) -> 1
A5: No | B5: X [mm] | C5: Y [mm] | D5: 使用 | E5: 次X | F5: 次Y | G5: 前X | H5: 前Y | I5: 外積項 | J5: 辺長 | K5: Ixx項 | L5: Iyy項 | M5: Ixy項 | N5: Cx項 | O5: Cy項 | P5: 内積 | Q5: 外積 | R5: 内角 [°] | S5: 外角 [°] | T5: 出隅/入隅 | V5: ■ プリセット（コピーして B6:C21 に貼る）
A6: 1 | B6: -37.42 | C6: -25.95 | D6: =IF(ROW()-5<=$F$3,1,0) -> 1 | E6: =IF($D6=0,0,INDEX($B$6:$B$21,IF(ROW()-5=$F$3,1,ROW()-5+1))) -> -25.36 | F6: =IF($D6=0,0,INDEX($C$6:$C$21,IF(ROW()-5=$F$3,1,ROW()-5+1))) -> -21.56 | G6: =IF($D6=0,0,INDEX($B$6:$B$21,IF(ROW()-5=1,$F$3,ROW()-5-1))) -> -57.76 | H6: =IF($D6=0,0,INDEX($C$6:$C$21,IF(ROW()-5=1,$F$3,ROW()-5-1))) -> 19.72 | I6: =IF($D6=0,0,B6*F6-E6*C6) -> 148.6832 | J6: =IF($D6=0,0,SQRT((E6-B6)^2+(F6-C6)^2)) -> 12.834161 | K6: =IF($D6=0,0,(C6^2+C6*F6+F6^2)*I6) -> 252422.16 | L6: =IF($D6=0,0,(B6^2+B6*E6+E6^2)*I6) -> 444913.24 | M6: =IF($D6=0,0,(B6*F6+2*B6*C6+2*E6*F6+E6*C6)*I6) -> 669147.02 | N6: =IF($D6=0,0,(B6+E6)*I6) -> -9334.3313 | O6: =IF($D6=0,0,(C6+F6)*I6) -> -7063.9388 | P6: =IF($D6=0,0,(G6-B6)*(E6-B6)+(H6-C6)*(F6-C6)) -> -44.8091 | Q6: =IF($D6=0,0,(G6-B6)*(F6-C6)-(H6-C6)*(E6-B6)) -> -640.0728 | R6: =IF($D6=0,"",IFERROR(MOD(DEGREES(ATAN2(P6,-$F$4*Q6)),360),"")) -> 94.00453 | S6: =IF($D6=0,"",180-R6) -> 85.99547 | T6: =IF($D6=0,"",IF(R6>180,"入隅(凹)","出隅(凸)")) -> 出隅(凸)
A7: 2 | B7: -25.36 | C7: -21.56 | D7: =IF(ROW()-5<=$F$3,1,0) -> 1 | E7: =IF($D7=0,0,INDEX($B$6:$B$21,IF(ROW()-5=$F$3,1,ROW()-5+1))) -> -12.8 | F7: =IF($D7=0,0,INDEX($C$6:$C$21,IF(ROW()-5=$F$3,1,ROW()-5+1))) -> -18.9 | G7: =IF($D7=0,0,INDEX($B$6:$B$21,IF(ROW()-5=1,$F$3,ROW()-5-1))) -> -37.42 | H7: =IF($D7=0,0,INDEX($C$6:$C$21,IF(ROW()-5=1,$F$3,ROW()-5-1))) -> -25.95 | I7: =IF($D7=0,0,B7*F7-E7*C7) -> 203.336 | J7: =IF($D7=0,0,SQRT((E7-B7)^2+(F7-C7)^2)) -> 12.838582 | K7: =IF($D7=0,0,(C7^2+C7*F7+F7^2)*I7) -> 250007.22 | L7: =IF($D7=0,0,(B7^2+B7*E7+E7^2)*I7) -> 230090.46 | M7: =IF($D7=0,0,(B7*F7+2*B7*C7+2*E7*F7+E7*C7)*I7) -> 474308.71 | N7: =IF($D7=0,0,(B7+E7)*I7) -> -7759.3018 | O7: =IF($D7=0,0,(C7+F7)*I7) -> -8226.9746 | P7: =IF($D7=0,0,(G7-B7)*(E7-B7)+(H7-C7)*(F7-C7)) -> -163.151 | Q7: =IF($D7=0,0,(G7-B7)*(F7-C7)-(H7-C7)*(E7-B7)) -> 23.0588 | R7: =IF($D7=0,"",IFERROR(MOD(DEGREES(ATAN2(P7,-$F$4*Q7)),360),"")) -> 188.04457 | S7: =IF($D7=0,"",180-R7) -> -8.0445656 | T7: =IF($D7=0,"",IF(R7>180,"入隅(凹)","出隅(凸)")) -> 入隅(凹)
A8: 3 | B8: -12.8 | C8: -18.9 | D8: =IF(ROW()-5<=$F$3,1,0) -> 1 | E8: =IF($D8=0,0,INDEX($B$6:$B$21,IF(ROW()-5=$F$3,1,ROW()-5+1))) -> 0 | F8: =IF($D8=0,0,INDEX($C$6:$C$21,IF(ROW()-5=$F$3,1,ROW()-5+1))) -> -18 | G8: =IF($D8=0,0,INDEX($B$6:$B$21,IF(ROW()-5=1,$F$3,ROW()-5-1))) -> -25.36 | H8: =IF($D8=0,0,INDEX($C$6:$C$21,IF(ROW()-5=1,$F$3,ROW()-5-1))) -> -21.56 | I8: =IF($D8=0,0,B8*F8-E8*C8) -> 230.4 | J8: =IF($D8=0,0,SQRT((E8-B8)^2+(F8-C8)^2)) -> 12.831602 | K8: =IF($D8=0,0,(C8^2+C8*F8+F8^2)*I8) -> 235332.86 | L8: =IF($D8=0,0,(B8^2+B8*E8+E8^2)*I8) -> 37748.736 | M8: =IF($D8=0,0,(B8*F8+2*B8*C8+2*E8*F8+E8*C8)*I8) -> 164560.9 | N8: =IF($D8=0,0,(B8+E8)*I8) -> -2949.12 | O8: =IF($D8=0,0,(C8+F8)*I8) -> -8501.76 | P8: =IF($D8=0,0,(G8-B8)*(E8-B8)+(H8-C8)*(F8-C8)) -> -163.162 | Q8: =IF($D8=0,0,(G8-B8)*(F8-C8)-(H8-C8)*(E8-B8)) -> 22.744 | R8: =IF($D8=0,"",IFERROR(MOD(DEGREES(ATAN2(P8,-$F$4*Q8)),360),"")) -> 187.93562 | S8: =IF($D8=0,"",180-R8) -> -7.9356214 | T8: =IF($D8=0,"",IF(R8>180,"入隅(凹)","出隅(凸)")) -> 入隅(凹)
A9: 4 | B9: 0 | C9: -18 | D9: =IF(ROW()-5<=$F$3,1,0) -> 1 | E9: =IF($D9=0,0,INDEX($B$6:$B$21,IF(ROW()-5=$F$3,1,ROW()-5+1))) -> 12.8 | F9: =IF($D9=0,0,INDEX($C$6:$C$21,IF(ROW()-5=$F$3,1,ROW()-5+1))) -> -18.9 | G9: =IF($D9=0,0,INDEX($B$6:$B$21,IF(ROW()-5=1,$F$3,ROW()-5-1))) -> -12.8 | H9: =IF($D9=0,0,INDEX($C$6:$C$21,IF(ROW()-5=1,$F$3,ROW()-5-1))) -> -18.9 | I9: =IF($D9=0,0,B9*F9-E9*C9) -> 230.4 | J9: =IF($D9=0,0,SQRT((E9-B9)^2+(F9-C9)^2)) -> 12.831602 | K9: =IF($D9=0,0,(C9^2+C9*F9+F9^2)*I9) -> 235332.86 | L9: =IF($D9=0,0,(B9^2+B9*E9+E9^2)*I9) -> 37748.736 | M9: =IF($D9=0,0,(B9*F9+2*B9*C9+2*E9*F9+E9*C9)*I9) -> -164560.9 | N9: =IF($D9=0,0,(B9+E9)*I9) -> 2949.12 | O9: =IF($D9=0,0,(C9+F9)*I9) -> -8501.76 | P9: =IF($D9=0,0,(G9-B9)*(E9-B9)+(H9-C9)*(F9-C9)) -> -163.03 | Q9: =IF($D9=0,0,(G9-B9)*(F9-C9)-(H9-C9)*(E9-B9)) -> 23.04 | R9: =IF($D9=0,"",IFERROR(MOD(DEGREES(ATAN2(P9,-$F$4*Q9)),360),"")) -> 188.04398 | S9: =IF($D9=0,"",180-R9) -> -8.0439804 | T9: =IF($D9=0,"",IF(R9>180,"入隅(凹)","出隅(凸)")) -> 入隅(凹)
A10: 5 | B10: 12.8 | C10: -18.9 | D10: =IF(ROW()-5<=$F$3,1,0) -> 1 | E10: =IF($D10=0,0,INDEX($B$6:$B$21,IF(ROW()-5=$F$3,1,ROW()-5+1))) -> 25.36 | F10: =IF($D10=0,0,INDEX($C$6:$C$21,IF(ROW()-5=$F$3,1,ROW()-5+1))) -> -21.56 | G10: =IF($D10=0,0,INDEX($B$6:$B$21,IF(ROW()-5=1,$F$3,ROW()-5-1))) -> 0 | H10: =IF($D10=0,0,INDEX($C$6:$C$21,IF(ROW()-5=1,$F$3,ROW()-5-1))) -> -18 | I10: =IF($D10=0,0,B10*F10-E10*C10) -> 203.336 | J10: =IF($D10=0,0,SQRT((E10-B10)^2+(F10-C10)^2)) -> 12.838582 | K10: =IF($D10=0,0,(C10^2+C10*F10+F10^2)*I10) -> 250007.22 | L10: =IF($D10=0,0,(B10^2+B10*E10+E10^2)*I10) -> 230090.46 | M10: =IF($D10=0,0,(B10*F10+2*B10*C10+2*E10*F10+E10*C10)*I10) -> -474308.71 | N10: =IF($D10=0,0,(B10+E10)*I10) -> 7759.3018 | O10: =IF($D10=0,0,(C10+F10)*I10) -> -8226.9746 | P10: =IF($D10=0,0,(G10-B10)*(E10-B10)+(H10-C10)*(F10-C10)) -> -163.162 | Q10: =IF($D10=0,0,(G10-B10)*(F10-C10)-(H10-C10)*(E10-B10)) -> 22.744 | R10: =IF($D10=0,"",IFERROR(MOD(DEGREES(ATAN2(P10,-$F$4*Q10)),360),"")) -> 187.93562 | S10: =IF($D10=0,"",180-R10) -> -7.9356214 | T10: =IF($D10=0,"",IF(R10>180,"入隅(凹)","出隅(凸)")) -> 入隅(凹)
A11: 6 | B11: 25.36 | C11: -21.56 | D11: =IF(ROW()-5<=$F$3,1,0) -> 1 | E11: =IF($D11=0,0,INDEX($B$6:$B$21,IF(ROW()-5=$F$3,1,ROW()-5+1))) -> 37.42 | F11: =IF($D11=0,0,INDEX($C$6:$C$21,IF(ROW()-5=$F$3,1,ROW()-5+1))) -> -25.95 | G11: =IF($D11=0,0,INDEX($B$6:$B$21,IF(ROW()-5=1,$F$3,ROW()-5-1))) -> 12.8 | H11: =IF($D11=0,0,INDEX($C$6:$C$21,IF(ROW()-5=1,$F$3,ROW()-5-1))) -> -18.9 | I11: =IF($D11=0,0,B11*F11-E11*C11) -> 148.6832 | J11: =IF($D11=0,0,SQRT((E11-B11)^2+(F11-C11)^2)) -> 12.834161 | K11: =IF($D11=0,0,(C11^2+C11*F11+F11^2)*I11) -> 252422.16 | L11: =IF($D11=0,0,(B11^2+B11*E11+E11^2)*I11) -> 444913.24 | M11: =IF($D11=0,0,(B11*F11+2*B11*C11+2*E11*F11+E11*C11)*I11) -> -669147.02 | N11: =IF($D11=0,0,(B11+E11)*I11) -> 9334.3313 | O11: =IF($D11=0,0,(C11+F11)*I11) -> -7063.9388 | P11: =IF($D11=0,0,(G11-B11)*(E11-B11)+(H11-C11)*(F11-C11)) -> -163.151 | Q11: =IF($D11=0,0,(G11-B11)*(F11-C11)-(H11-C11)*(E11-B11)) -> 23.0588 | R11: =IF($D11=0,"",IFERROR(MOD(DEGREES(ATAN2(P11,-$F$4*Q11)),360),"")) -> 188.04457 | S11: =IF($D11=0,"",180-R11) -> -8.0445656 | T11: =IF($D11=0,"",IF(R11>180,"入隅(凹)","出隅(凸)")) -> 入隅(凹)
A12: 7 | B12: 37.42 | C12: -25.95 | D12: =IF(ROW()-5<=$F$3,1,0) -> 1 | E12: =IF($D12=0,0,INDEX($B$6:$B$21,IF(ROW()-5=$F$3,1,ROW()-5+1))) -> 57.76 | F12: =IF($D12=0,0,INDEX($C$6:$C$21,IF(ROW()-5=$F$3,1,ROW()-5+1))) -> 19.72 | G12: =IF($D12=0,0,INDEX($B$6:$B$21,IF(ROW()-5=1,$F$3,ROW()-5-1))) -> 25.36 | H12: =IF($D12=0,0,INDEX($C$6:$C$21,IF(ROW()-5=1,$F$3,ROW()-5-1))) -> -21.56 | I12: =IF($D12=0,0,B12*F12-E12*C12) -> 2236.7944 | J12: =IF($D12=0,0,SQRT((E12-B12)^2+(F12-C12)^2)) -> 49.994645 | K12: =IF($D12=0,0,(C12^2+C12*F12+F12^2)*I12) -> 1231460.2 | L12: =IF($D12=0,0,(B12^2+B12*E12+E12^2)*I12) -> 15429079 | M12: =IF($D12=0,0,(B12*F12+2*B12*C12+2*E12*F12+E12*C12)*I12) -> -950622.41 | N12: =IF($D12=0,0,(B12+E12)*I12) -> 212898.09 | O12: =IF($D12=0,0,(C12+F12)*I12) -> -13935.229 | P12: =IF($D12=0,0,(G12-B12)*(E12-B12)+(H12-C12)*(F12-C12)) -> -44.8091 | Q12: =IF($D12=0,0,(G12-B12)*(F12-C12)-(H12-C12)*(E12-B12)) -> -640.0728 | R12: =IF($D12=0,"",IFERROR(MOD(DEGREES(ATAN2(P12,-$F$4*Q12)),360),"")) -> 94.00453 | S12: =IF($D12=0,"",180-R12) -> 85.99547 | T12: =IF($D12=0,"",IF(R12>180,"入隅(凹)","出隅(凸)")) -> 出隅(凸)
A13: 8 | B13: 57.76 | C13: 19.72 | D13: =IF(ROW()-5<=$F$3,1,0) -> 1 | E13: =IF($D13=0,0,INDEX($B$6:$B$21,IF(ROW()-5=$F$3,1,ROW()-5+1))) -> 39.14 | F13: =IF($D13=0,0,INDEX($C$6:$C$21,IF(ROW()-5=$F$3,1,ROW()-5+1))) -> 26.5 | G13: =IF($D13=0,0,INDEX($B$6:$B$21,IF(ROW()-5=1,$F$3,ROW()-5-1))) -> 37.42 | H13: =IF($D13=0,0,INDEX($C$6:$C$21,IF(ROW()-5=1,$F$3,ROW()-5-1))) -> -25.95 | I13: =IF($D13=0,0,B13*F13-E13*C13) -> 758.7992 | J13: =IF($D13=0,0,SQRT((E13-B13)^2+(F13-C13)^2)) -> 19.815973 | K13: =IF($D13=0,0,(C13^2+C13*F13+F13^2)*I13) -> 1224480.6 | L13: =IF($D13=0,0,(B13^2+B13*E13+E13^2)*I13) -> 5409391.2 | M13: =IF($D13=0,0,(B13*F13+2*B13*C13+2*E13*F13+E13*C13)*I13) -> 5049774.7 | N13: =IF($D13=0,0,(B13+E13)*I13) -> 73527.642 | O13: =IF($D13=0,0,(C13+F13)*I13) -> 35071.699 | P13: =IF($D13=0,0,(G13-B13)*(E13-B13)+(H13-C13)*(F13-C13)) -> 69.0882 | Q13: =IF($D13=0,0,(G13-B13)*(F13-C13)-(H13-C13)*(E13-B13)) -> -988.2806 | R13: =IF($D13=0,"",IFERROR(MOD(DEGREES(ATAN2(P13,-$F$4*Q13)),360),"")) -> 86.001103 | S13: =IF($D13=0,"",180-R13) -> 93.998897 | T13: =IF($D13=0,"",IF(R13>180,"入隅(凹)","出隅(凸)")) -> 出隅(凸)
A14: 9 | B14: 39.14 | C14: 26.5 | D14: =IF(ROW()-5<=$F$3,1,0) -> 1 | E14: =IF($D14=0,0,INDEX($B$6:$B$21,IF(ROW()-5=$F$3,1,ROW()-5+1))) -> 19.76 | F14: =IF($D14=0,0,INDEX($C$6:$C$21,IF(ROW()-5=$F$3,1,ROW()-5+1))) -> 30.62 | G14: =IF($D14=0,0,INDEX($B$6:$B$21,IF(ROW()-5=1,$F$3,ROW()-5-1))) -> 57.76 | H14: =IF($D14=0,0,INDEX($C$6:$C$21,IF(ROW()-5=1,$F$3,ROW()-5-1))) -> 19.72 | I14: =IF($D14=0,0,B14*F14-E14*C14) -> 674.8268 | J14: =IF($D14=0,0,SQRT((E14-B14)^2+(F14-C14)^2)) -> 19.813097 | K14: =IF($D14=0,0,(C14^2+C14*F14+F14^2)*I14) -> 1654178.9 | L14: =IF($D14=0,0,(B14^2+B14*E14+E14^2)*I14) -> 1819200.5 | M14: =IF($D14=0,0,(B14*F14+2*B14*C14+2*E14*F14+E14*C14)*I14) -> 3378607.6 | N14: =IF($D14=0,0,(B14+E14)*I14) -> 39747.299 | O14: =IF($D14=0,0,(C14+F14)*I14) -> 38546.107 | P14: =IF($D14=0,0,(G14-B14)*(E14-B14)+(H14-C14)*(F14-C14)) -> -388.7892 | Q14: =IF($D14=0,0,(G14-B14)*(F14-C14)-(H14-C14)*(E14-B14)) -> -54.682 | R14: =IF($D14=0,"",IFERROR(MOD(DEGREES(ATAN2(P14,-$F$4*Q14)),360),"")) -> 171.99404 | S14: =IF($D14=0,"",180-R14) -> 8.0059599 | T14: =IF($D14=0,"",IF(R14>180,"入隅(凹)","出隅(凸)")) -> 出隅(凸)
A15: 10 | B15: 19.76 | C15: 30.62 | D15: =IF(ROW()-5<=$F$3,1,0) -> 1 | E15: =IF($D15=0,0,INDEX($B$6:$B$21,IF(ROW()-5=$F$3,1,ROW()-5+1))) -> 0 | F15: =IF($D15=0,0,INDEX($C$6:$C$21,IF(ROW()-5=$F$3,1,ROW()-5+1))) -> 32 | G15: =IF($D15=0,0,INDEX($B$6:$B$21,IF(ROW()-5=1,$F$3,ROW()-5-1))) -> 39.14 | H15: =IF($D15=0,0,INDEX($C$6:$C$21,IF(ROW()-5=1,$F$3,ROW()-5-1))) -> 26.5 | I15: =IF($D15=0,0,B15*F15-E15*C15) -> 632.32 | J15: =IF($D15=0,0,SQRT((E15-B15)^2+(F15-C15)^2)) -> 19.80813 | K15: =IF($D15=0,0,(C15^2+C15*F15+F15^2)*I15) -> 1859921.5 | L15: =IF($D15=0,0,(B15^2+B15*E15+E15^2)*I15) -> 246894.15 | M15: =IF($D15=0,0,(B15*F15+2*B15*C15+2*E15*F15+E15*C15)*I15) -> 1165000.5 | N15: =IF($D15=0,0,(B15+E15)*I15) -> 12494.643 | O15: =IF($D15=0,0,(C15+F15)*I15) -> 39595.878 | P15: =IF($D15=0,0,(G15-B15)*(E15-B15)+(H15-C15)*(F15-C15)) -> -388.6344 | Q15: =IF($D15=0,0,(G15-B15)*(F15-C15)-(H15-C15)*(E15-B15)) -> -54.6668 | R15: =IF($D15=0,"",IFERROR(MOD(DEGREES(ATAN2(P15,-$F$4*Q15)),360),"")) -> 171.99309 | S15: =IF($D15=0,"",180-R15) -> 8.00691 | T15: =IF($D15=0,"",IF(R15>180,"入隅(凹)","出隅(凸)")) -> 出隅(凸)
A16: 11 | B16: 0 | C16: 32 | D16: =IF(ROW()-5<=$F$3,1,0) -> 1 | E16: =IF($D16=0,0,INDEX($B$6:$B$21,IF(ROW()-5=$F$3,1,ROW()-5+1))) -> -19.76 | F16: =IF($D16=0,0,INDEX($C$6:$C$21,IF(ROW()-5=$F$3,1,ROW()-5+1))) -> 30.62 | G16: =IF($D16=0,0,INDEX($B$6:$B$21,IF(ROW()-5=1,$F$3,ROW()-5-1))) -> 19.76 | H16: =IF($D16=0,0,INDEX($C$6:$C$21,IF(ROW()-5=1,$F$3,ROW()-5-1))) -> 30.62 | I16: =IF($D16=0,0,B16*F16-E16*C16) -> 632.32 | J16: =IF($D16=0,0,SQRT((E16-B16)^2+(F16-C16)^2)) -> 19.80813 | K16: =IF($D16=0,0,(C16^2+C16*F16+F16^2)*I16) -> 1859921.5 | L16: =IF($D16=0,0,(B16^2+B16*E16+E16^2)*I16) -> 246894.15 | M16: =IF($D16=0,0,(B16*F16+2*B16*C16+2*E16*F16+E16*C16)*I16) -> -1165000.5 | N16: =IF($D16=0,0,(B16+E16)*I16) -> -12494.643 | O16: =IF($D16=0,0,(C16+F16)*I16) -> 39595.878 | P16: =IF($D16=0,0,(G16-B16)*(E16-B16)+(H16-C16)*(F16-C16)) -> -388.5532 | Q16: =IF($D16=0,0,(G16-B16)*(F16-C16)-(H16-C16)*(E16-B16)) -> -54.5376 | R16: =IF($D16=0,"",IFERROR(MOD(DEGREES(ATAN2(P16,-$F$4*Q16)),360),"")) -> 172.01012 | S16: =IF($D16=0,"",180-R16) -> 7.9898788 | T16: =IF($D16=0,"",IF(R16>180,"入隅(凹)","出隅(凸)")) -> 出隅(凸)
A17: 12 | B17: -19.76 | C17: 30.62 | D17: =IF(ROW()-5<=$F$3,1,0) -> 1 | E17: =IF($D17=0,0,INDEX($B$6:$B$21,IF(ROW()-5=$F$3,1,ROW()-5+1))) -> -39.14 | F17: =IF($D17=0,0,INDEX($C$6:$C$21,IF(ROW()-5=$F$3,1,ROW()-5+1))) -> 26.5 | G17: =IF($D17=0,0,INDEX($B$6:$B$21,IF(ROW()-5=1,$F$3,ROW()-5-1))) -> 0 | H17: =IF($D17=0,0,INDEX($C$6:$C$21,IF(ROW()-5=1,$F$3,ROW()-5-1))) -> 32 | I17: =IF($D17=0,0,B17*F17-E17*C17) -> 674.8268 | J17: =IF($D17=0,0,SQRT((E17-B17)^2+(F17-C17)^2)) -> 19.813097 | K17: =IF($D17=0,0,(C17^2+C17*F17+F17^2)*I17) -> 1654178.9 | L17: =IF($D17=0,0,(B17^2+B17*E17+E17^2)*I17) -> 1819200.5 | M17: =IF($D17=0,0,(B17*F17+2*B17*C17+2*E17*F17+E17*C17)*I17) -> -3378607.6 | N17: =IF($D17=0,0,(B17+E17)*I17) -> -39747.299 | O17: =IF($D17=0,0,(C17+F17)*I17) -> 38546.107 | P17: =IF($D17=0,0,(G17-B17)*(E17-B17)+(H17-C17)*(F17-C17)) -> -388.6344 | Q17: =IF($D17=0,0,(G17-B17)*(F17-C17)-(H17-C17)*(E17-B17)) -> -54.6668 | R17: =IF($D17=0,"",IFERROR(MOD(DEGREES(ATAN2(P17,-$F$4*Q17)),360),"")) -> 171.99309 | S17: =IF($D17=0,"",180-R17) -> 8.00691 | T17: =IF($D17=0,"",IF(R17>180,"入隅(凹)","出隅(凸)")) -> 出隅(凸)
... A19: 14 | B19: -57.76 | C19: 19.72 | D19: =IF(ROW()-5<=$F$3,1,0) -> 1 | E19: =IF($D19=0,0,INDEX($B$6:$B$21,IF(ROW()-5=$F$3,1,ROW()-5+1))) -> -37.42 | F19: =IF($D19=0,0,INDEX($C$6:$C$21,IF(ROW()-5=$F$3,1,ROW()-5+1))) -> -25.95 | G19: =IF($D19=0,0,INDEX($B$6:$B$21,IF(ROW()-5=1,$F$3,ROW()-5-1))) -> -39.14 | H19: =IF($D19=0,0,INDEX($C$6:$C$21,IF(ROW()-5=1,$F$3,ROW()-5-1))) -> 26.5 | I19: =IF($D19=0,0,B19*F19-E19*C19) -> 2236.7944 | J19: =IF($D19=0,0,SQRT((E19-B19)^2+(F19-C19)^2)) -> 49.994645 | K19: =IF($D19=0,0,(C19^2+C19*F19+F19^2)*I19) -> 1231460.2 | L19: =IF($D19=0,0,(B19^2+B19*E19+E19^2)*I19) -> 15429079 | M19: =IF($D19=0,0,(B19*F19+2*B19*C19+2*E19*F19+E19*C19)*I19) -> 950622.41 | N19: =IF($D19=0,0,(B19+E19)*I19) -> -212898.09 | O19: =IF($D19=0,0,(C19+F19)*I19) -> -13935.229 | P19: =IF($D19=0,0,(G19-B19)*(E19-B19)+(H19-C19)*(F19-C19)) -> 69.0882 | Q19: =IF($D19=0,0,(G19-B19)*(F19-C19)-(H19-C19)*(E19-B19)) -> -988.2806 | R19: =IF($D19=0,"",IFERROR(MOD(DEGREES(ATAN2(P19,-$F$4*Q19)),360),"")) -> 86.001103 | S19: =IF($D19=0,"",180-R19) -> 93.998897 | T19: =IF($D19=0,"",IF(R19>180,"入隅(凹)","出隅(凸)")) -> 出隅(凸)
A20: 15 | D20: =IF(ROW()-5<=$F$3,1,0) -> 0 | E20: =IF($D20=0,0,INDEX($B$6:$B$21,IF(ROW()-5=$F$3,1,ROW()-5+1))) -> 0 | F20: =IF($D20=0,0,INDEX($C$6:$C$21,IF(ROW()-5=$F$3,1,ROW()-5+1))) -> 0 | G20: =IF($D20=0,0,INDEX($B$6:$B$21,IF(ROW()-5=1,$F$3,ROW()-5-1))) -> 0 | H20: =IF($D20=0,0,INDEX($C$6:$C$21,IF(ROW()-5=1,$F$3,ROW()-5-1))) -> 0 | I20: =IF($D20=0,0,B20*F20-E20*C20) -> 0 | J20: =IF($D20=0,0,SQRT((E20-B20)^2+(F20-C20)^2)) -> 0 | K20: =IF($D20=0,0,(C20^2+C20*F20+F20^2)*I20) -> 0 | L20: =IF($D20=0,0,(B20^2+B20*E20+E20^2)*I20) -> 0 | M20: =IF($D20=0,0,(B20*F20+2*B20*C20+2*E20*F20+E20*C20)*I20) -> 0 | N20: =IF($D20=0,0,(B20+E20)*I20) -> 0 | O20: =IF($D20=0,0,(C20+F20)*I20) -> 0 | P20: =IF($D20=0,0,(G20-B20)*(E20-B20)+(H20-C20)*(F20-C20)) -> 0 | Q20: =IF($D20=0,0,(G20-B20)*(F20-C20)-(H20-C20)*(E20-B20)) -> 0 | R20: =IF($D20=0,"",IFERROR(MOD(DEGREES(ATAN2(P20,-$F$4*Q20)),360),"")) | S20: =IF($D20=0,"",180-R20) | T20: =IF($D20=0,"",IF(R20>180,"入隅(凹)","出隅(凸)"))
A21: 16 | D21: =IF(ROW()-5<=$F$3,1,0) -> 0 | E21: =IF($D21=0,0,INDEX($B$6:$B$21,IF(ROW()-5=$F$3,1,ROW()-5+1))) -> 0 | F21: =IF($D21=0,0,INDEX($C$6:$C$21,IF(ROW()-5=$F$3,1,ROW()-5+1))) -> 0 | G21: =IF($D21=0,0,INDEX($B$6:$B$21,IF(ROW()-5=1,$F$3,ROW()-5-1))) -> 0 | H21: =IF($D21=0,0,INDEX($C$6:$C$21,IF(ROW()-5=1,$F$3,ROW()-5-1))) -> 0 | I21: =IF($D21=0,0,B21*F21-E21*C21) -> 0 | J21: =IF($D21=0,0,SQRT((E21-B21)^2+(F21-C21)^2)) -> 0 | K21: =IF($D21=0,0,(C21^2+C21*F21+F21^2)*I21) -> 0 | L21: =IF($D21=0,0,(B21^2+B21*E21+E21^2)*I21) -> 0 | M21: =IF($D21=0,0,(B21*F21+2*B21*C21+2*E21*F21+E21*C21)*I21) -> 0 | N21: =IF($D21=0,0,(B21+E21)*I21) -> 0 | O21: =IF($D21=0,0,(C21+F21)*I21) -> 0 | P21: =IF($D21=0,0,(G21-B21)*(E21-B21)+(H21-C21)*(F21-C21)) -> 0 | Q21: =IF($D21=0,0,(G21-B21)*(F21-C21)-(H21-C21)*(E21-B21)) -> 0 | R21: =IF($D21=0,"",IFERROR(MOD(DEGREES(ATAN2(P21,-$F$4*Q21)),360),"")) | S21: =IF($D21=0,"",180-R21) | T21: =IF($D21=0,"",IF(R21>180,"入隅(凹)","出隅(凸)"))
A23: ■ 形状の計算結果
A24: 符号付き面積 [mm²] | B24: =0.5*SUM(I6:I21) -> 4885.1596 | C24: 多角形の向き判定に使う（＋なら反時計回り）
A25: 面積 A [mm²] | B25: =ABS(B24) -> 4885.1596 | C25: シューレース公式 A=½|Σ(xᵢyᵢ₊₁−xᵢ₊₁yᵢ)| 🟢
A26: 周長 [mm] | B26: =SUM(J6:J21) -> 295.87238
A27: 重心 Cx [mm] | B27: =IF(B25=0,0,SUM(N6:N21)/(6*B25)) -> 0 | C27: 図心のX座標 🟢
A28: 重心 Cy [mm] | B28: =IF(B25=0,0,SUM(O6:O21)/(6*B25)) -> 5.1506868 | C28: 図心のY座標 🟢
A29: Ixx (重心まわり) [mm⁴] | B29: =$F$4*SUM(K6:K21)/12-$B$25*$B$28^2 -> 988366.04 | C29: X軸まわり断面二次モーメント 🟢
A30: Iyy (重心まわり) [mm⁴] | B30: =$F$4*SUM(L6:L21)/12-$B$25*$B$27^2 -> 3936219.6 | C30: Y軸まわり 🟢
A31: Ixy (重心まわり) [mm⁴] | B31: =$F$4*SUM(M6:M21)/24-$B$25*$B$27*$B$28 -> 0 | C31: 相乗モーメント 🟢
A32: Imin [mm⁴] | B32: =($B$29+$B$30)/2-SQRT((($B$29-$B$30)/2)^2+$B$31^2) -> 988366.04
A33: Imax [mm⁴] | B33: =($B$29+$B$30)/2+SQRT((($B$29-$B$30)/2)^2+$B$31^2) -> 3936219.6
A34: 主軸角 θp [°] | B34: =DEGREES(0.5*ATAN2($B$29-$B$30,-2*$B$31)) -> -90 | C34: tan2θ=−2Ixy/(Ixx−Iyy) 🟢
A35: θpでのI [mm⁴] | B35: =($B$29+$B$30)/2+($B$29-$B$30)/2*COS(2*RADIANS($B$34))-$B$31*SIN(2*RADIANS($B$34)) -> 3936219.6
A36: 長手方向の角度 [°] | B36: =IF(ABS($B$35-$B$32)<ABS($B$35-$B$33),$B$34,$B$34+90) -> 0 | C36: 0°に近いほど X軸＝長手。大きくずれたら座標を回して入れ直す
A37: Xmin [mm] | B37: =MIN($B$6:$B$21) -> -57.76
A38: Xmax [mm] | B38: =MAX($B$6:$B$21) -> 57.76
A39: Ymin [mm] | B39: =MIN($C$6:$C$21) -> -25.95
A40: Ymax [mm] | B40: =MAX($C$6:$C$21) -> 32
A41: X方向の長さ [mm] | B41: =$B$38-$B$37 -> 115.52
A42: Y方向の長さ [mm] | B42: =$B$40-$B$39 -> 57.95
...

Sheet 断面
A1: ② 断面（積層）— シム＋裏板（＋任意で接着/固定層）を1本の「はり」に合成 ※摩擦材は含みません
A2: 変換断面法（transformed section）で 曲げ剛性EI・単位長さ質量ρA・中立軸を求める（摩擦材を含む計算式と同じ手法。層数だけ減らしています） 🟢
A3: 幅 b [m]（＝形状シートの採用w） | D3: =形状!$B$48/1000 -> 0.042288431
A4: 長さ L [m]（＝形状シートの採用L） | D4: =形状!$B$47/1000 -> 0.11552
A5: 投影面積 [m²] | D5: =形状!$B$25/1000000 -> 0.0048851596
A7: 層（下から順） | B7: 使用1/0 | C7: 材料名（材料DBと同じ文字） | D7: 厚さ t [mm] | E7: E [GPa] | F7: ρ [kg/m³] | G7: ν | H7: η | I7: t [m] | J7: 下端y [m] | K7: 中心y [m] | L7: E・A [N] | M7: E・A・y | N7: ρ・A [kg/m] | O7: EI項(面外) | P7: EI項(面内) | Q7: E・A(軸) | R7: η・EI項
A8: 1: シム | B8: 0 | C8: シム鋼板 SPCC | D8: 0.8 | E8: =IFERROR(INDEX(材料DB!$B$5:$B$45,MATCH($C8,材料DB!$A$5:$A$45,0)),0) -> 205 | F8: =IFERROR(INDEX(材料DB!$C$5:$C$45,MATCH($C8,材料DB!$A$5:$A$45,0)),0) -> 7850 | G8: =IFERROR(INDEX(材料DB!$D$5:$D$45,MATCH($C8,材料DB!$A$5:$A$45,0)),0) -> 0.3 | H8: =IFERROR(INDEX(材料DB!$E$5:$E$45,MATCH($C8,材料DB!$A$5:$A$45,0)),0) -> 0.0002 | I8: =IF($B8=1,$D8/1000,0) -> 0 | J8: =0 -> 0 | K8: =J8+I8/2 -> 0 | L8: =E8*1000000000*$D$3*I8 -> 0 | M8: =L8*K8 -> 0 | N8: =F8*$D$3*I8 -> 0 | O8: =E8*1000000000*$D$3*(I8^3/12+I8*(K8-$D$14)^2) -> 0 | P8: =E8*1000000000*(I8*$D$3^3/12) -> 0 | Q8: =L8 -> 0 | R8: =H8*O8 -> 0
A9: 2: 裏板 | B9: 1 | C9: 鋼 SPCC(裏板) | D9: 5 | E9: =IFERROR(INDEX(材料DB!$B$5:$B$45,MATCH($C9,材料DB!$A$5:$A$45,0)),0) -> 205 | F9: =IFERROR(INDEX(材料DB!$C$5:$C$45,MATCH($C9,材料DB!$A$5:$A$45,0)),0) -> 7850 | G9: =IFERROR(INDEX(材料DB!$D$5:$D$45,MATCH($C9,材料DB!$A$5:$A$45,0)),0) -> 0.3 | H9: =IFERROR(INDEX(材料DB!$E$5:$E$45,MATCH($C9,材料DB!$A$5:$A$45,0)),0) -> 0.0002 | I9: =IF($B9=1,$D9/1000,0) -> 0.005 | J9: =J8+I8 -> 0 | K9: =J9+I9/2 -> 0.0025 | L9: =E9*1000000000*$D$3*I9 -> 43345642 | M9: =L9*K9 -> 108364.11 | N9: =F9*$D$3*I9 -> 1.6598209 | O9: =E9*1000000000*$D$3*(I9^3/12+I9*(K9-$D$14)^2) -> 90.303421 | P9: =E9*1000000000*(I9*$D$3^3/12) -> 6459.6256 | Q9: =L9 -> 43345642 | R9: =H9*O9 -> 0.018060684
A10: 3: 接着/固定(任意) | B10: 0 | C10: 接着層(汎用/シム固定用) | D10: 0.2 | E10: =IFERROR(INDEX(材料DB!$B$5:$B$45,MATCH($C10,材料DB!$A$5:$A$45,0)),0) -> 3 | F10: =IFERROR(INDEX(材料DB!$C$5:$C$45,MATCH($C10,材料DB!$A$5:$A$45,0)),0) -> 1300 | G10: =IFERROR(INDEX(材料DB!$D$5:$D$45,MATCH($C10,材料DB!$A$5:$A$45,0)),0) -> 0.35 | H10: =IFERROR(INDEX(材料DB!$E$5:$E$45,MATCH($C10,材料DB!$A$5:$A$45,0)),0) -> 0.08 | I10: =IF($B10=1,$D10/1000,0) -> 0 | J10: =J9+I9 -> 0.005 | K10: =J10+I10/2 -> 0.005 | L10: =E10*1000000000*$D$3*I10 -> 0 | M10: =L10*K10 -> 0 | N10: =F10*$D$3*I10 -> 0 | O10: =E10*1000000000*$D$3*(I10^3/12+I10*(K10-$D$14)^2) -> 0 | P10: =E10*1000000000*(I10*$D$3^3/12) -> 0 | Q10: =L10 -> 0 | R10: =H10*O10 -> 0
A12: ■ 合成結果
A13: ΣE・A [N] | D13: =SUM(L8:L10) -> 43345642 | E13: 各層の 弾性率×断面積 の合計
A14: 中立軸 ȳ [m] | D14: =IF($D$13=0,0,SUM(M8:M10)/$D$13) -> 0.0025 | E14: 曲げても伸び縮みしない高さ。下端からの距離 🟢
A15: EI 面外曲げ [N・m²] | D15: =SUM(O8:O10) -> 90.303421 | E15: 厚み方向にたわむ剛性。金属スケルトンの主モードはこれ 🟢
A16: EI 面内曲げ [N・m²] | D16: =SUM(P8:P10) -> 6459.6256 | E16: 面内（半径方向）にたわむ剛性。高周波側 🟢
A17: EA 軸 [N] | D17: =SUM(Q8:Q10) -> 43345642 | E17: 伸び縮みの剛性 🟢
A18: ρA 単位長さ質量 [kg/m] | D18: =SUM(N8:N10) -> 1.6598209 | E18: 1mあたりの重さ 🟢
A19: 総厚 h [m] | D19: =SUM(I8:I10) -> 0.005 | E19: 使用する層の厚さ合計
A20: 等価ヤング率 E_eq(面外) [GPa] | D20: =IF($D$19=0,0,$D$15/($D$3*$D$19^3/12)/1000000000) -> 205 | E20: 1枚板とみなしたときの見かけのE
A21: 等価密度 ρ_eq [kg/m³] | D21: =IF($D$19=0,0,$D$18/($D$3*$D$19)) -> 7850 | E21: 1枚板とみなしたときの見かけのρ
A22: 等価ポアソン比 ν_eq | D22: =IF($D$13=0,0.3,SUMPRODUCT(G8:G10,L8:L10)/$D$13) -> 0.3 | E22: E・Aで重み付け平均
A23: 等価せん断弾性率 G_eq [Pa] | D23: =$D$20*1000000000/(2*(1+$D$22)) -> 7.8846154e+10 | E23: G=E/(2(1+ν)) 🟢
A24: ねじり係数 β | D24: =IF($D$3<=0,0,(1/3)*(1-0.63*($D$19/$D$3)+0.052*($D$19/$D$3)^5)) -> 0.30850425 | E24: 長方形断面のねじり定数 J=β・b・h³ 🟢 Roark近似
A25: GJ ねじり剛性 [N・m²] | D25: =$D$23*$D$24*$D$3*$D$19^3 -> 128.57995 | E25: ねじりにくさ 🟡(積層は近似)
A26: ρIp 単位長さ極慣性 [kg・m] | D26: =$D$18*($D$3^2+$D$19^2)/12 -> 0.00025081436 | E26: ねじりの回りにくさ 🟡
A27: 合成損失係数 η_eq | D27: =IF($D$15=0,0,SUM(R8:R10)/$D$15) -> 0.0002 | E27: EI重み付け平均（RKU法の簡易版）🟡
A28: 質量 [g] | D28: =SUMPRODUCT(F8:F10,I8:I10)*$D$5*1000 -> 191.74251 | E28: 実測して合っていれば厚さ・密度入力は正しい（ハンマリング前に電子天秤で必ず実測）
A30: ■ 中立軸の意味（ここが一番の勘どころ）
A31: 曲げると、上側は縮み・下側は伸びる。その境目で「伸びも縮みもしない面」が中立軸（ちゅうりつじく）です。
A32: このブックはシム(オプション)＋裏板だけなので、シムをONにしていない限り中立軸はほぼ裏板の中心に一致します。
A33: 摩擦材が無い分、剛性(EI)は下がり、質量(ρA)も大きく下がります。全体として固有振動数は摩擦材込みのときよりかなり高く出ます。

Sheet 固有振動数
A1: ③ 固有振動数の予測（自由−自由：ピアノ線で吊った状態／金属スケルトンのみ）
A2: 4系統：①面外曲げ ②ねじり ③面内曲げ ④面内伸縮。せん断変形（Timoshenko）補正つき。単位は Hz。式は摩擦材込みブックと完全に同じです 🟢
A3: 損失係数 η（空欄→断面シートの合成値） | E3: =IF($D$3="",断面!$D$27,$D$3) -> 0.0002 | F3: せん断補正 使う=1 / 使わない=0 | I3: 1 | J3: κ(長方形=5/6) | K3: =5/6 -> 0.83333333
A4: 回転半径 r_out [m] = h/√12 | D4: =断面!$D$19/SQRT(12) -> 0.0014433757 | E4: r_in = w/√12 | F4: =断面!$D$3/SQRT(12) -> 0.012207619 | G4: 1+E/(κG) | H4: =1+2*(1+断面!$D$22)/$K$3 -> 4.12
A5: # | B5: モード種別 | C5: n | D5: 係数 (βL) or n | E5: (βL)² | F5: f Euler [Hz] | G5: せん断補正係数 | H5: f 補正後 [Hz] | I5: ★採用 f [Hz] | J5: 波長 λ [mm] | K5: λ/断面寸法 | L5: 妥当性 | M5: 備考 | O5: f [Hz] | P5: η | Q5: 振幅 A
A6: 1 | B6: 面外曲げ | C6: 1 | D6: 4.730041 | E6: =D6^2 -> 22.373288 | F6: =IFERROR(E6/(2*PI()*断面!$D$4^2)*SQRT(断面!$D$15/断面!$D$18),0) -> 1968.1449 | G6: =IFERROR(1/SQRT(1+E6*($D$4/断面!$D$4)^2*$H$4),1) -> 0.99288156 | H6: =F6*G6 -> 1954.1348 | I6: =IF($I$3=1,H6,F6) -> 1954.1348 | J6: =IFERROR(2*PI()*断面!$D$4/D6*1000,0) -> 153.45186 | K6: =IFERROR(J6/(断面!$D$19*1000),0) -> 30.690371 | L6: =IF(K6>=6,"🟢 良",IF(K6>=3,"🟡 誤差±10%程度","🔴 参考値のみ")) -> 🟢 良 | M6: 板が反（そ）るように曲がる。金属スケルトンで一番低く出るモード群 🟢 | O6: =IF(I6<=0,1000000000,I6) -> 1954.1348 | P6: =$E$3 -> 0.0002 | Q6: 1
A7: 2 | B7: 面外曲げ | C7: 2 | D7: 7.853205 | E7: =D7^2 -> 61.672829 | F7: =IFERROR(E7/(2*PI()*断面!$D$4^2)*SQRT(断面!$D$15/断面!$D$18),0) -> 5425.2671 | G7: =IFERROR(1/SQRT(1+E7*($D$4/断面!$D$4)^2*$H$4),1) -> 0.98073744 | H7: =F7*G7 -> 5320.7625 | I7: =IF($I$3=1,H7,F7) -> 5320.7625 | J7: =IFERROR(2*PI()*断面!$D$4/D7*1000,0) -> 92.425139 | K7: =IFERROR(J7/(断面!$D$19*1000),0) -> 18.485028 | L7: =IF(K7>=6,"🟢 良",IF(K7>=3,"🟡 誤差±10%程度","🔴 参考値のみ")) -> 🟢 良 | M7: 板が反（そ）るように曲がる。金属スケルトンで一番低く出るモード群 🟢 | O7: =IF(I7<=0,1000000000,I7) -> 5320.7625 | P7: =$E$3 -> 0.0002 | Q7: 1
A8: 3 | B8: 面外曲げ | C8: 3 | D8: 10.995608 | E8: =D8^2 -> 120.9034 | F8: =IFERROR(E8/(2*PI()*断面!$D$4^2)*SQRT(断面!$D$15/断面!$D$18),0) -> 10635.692 | G8: =IFERROR(1/SQRT(1+E8*($D$4/断面!$D$4)^2*$H$4),1) -> 0.96324798 | H8: =F8*G8 -> 10244.809 | I8: =IF($I$3=1,H8,F8) -> 10244.809 | J8: =IFERROR(2*PI()*断面!$D$4/D8*1000,0) -> 66.011226 | K8: =IFERROR(J8/(断面!$D$19*1000),0) -> 13.202245 | L8: =IF(K8>=6,"🟢 良",IF(K8>=3,"🟡 誤差±10%程度","🔴 参考値のみ")) -> 🟢 良 | M8: 板が反（そ）るように曲がる。金属スケルトンで一番低く出るモード群 🟢 | O8: =IF(I8<=0,1000000000,I8) -> 10244.809 | P8: =$E$3 -> 0.0002 | Q8: 1
A9: 4 | B9: 面外曲げ | C9: 4 | D9: 14.137165 | E9: =D9^2 -> 199.85943 | F9: =IFERROR(E9/(2*PI()*断面!$D$4^2)*SQRT(断面!$D$15/断面!$D$18),0) -> 17581.337 | G9: =IFERROR(1/SQRT(1+E9*($D$4/断面!$D$4)^2*$H$4),1) -> 0.94132573 | H9: =F9*G9 -> 16549.765 | I9: =IF($I$3=1,H9,F9) -> 16549.765 | J9: =IFERROR(2*PI()*断面!$D$4/D9*1000,0) -> 51.342229 | K9: =IFERROR(J9/(断面!$D$19*1000),0) -> 10.268446 | L9: =IF(K9>=6,"🟢 良",IF(K9>=3,"🟡 誤差±10%程度","🔴 参考値のみ")) -> 🟢 良 | M9: 板が反（そ）るように曲がる。金属スケルトンで一番低く出るモード群 🟢 | O9: =IF(I9<=0,1000000000,I9) -> 16549.765 | P9: =$E$3 -> 0.0002 | Q9: 1
A10: 5 | B10: 面外曲げ | C10: 5 | D10: 17.27876 | E10: =D10^2 -> 298.55555 | F10: =IFERROR(E10/(2*PI()*断面!$D$4^2)*SQRT(断面!$D$15/断面!$D$18),0) -> 26263.488 | G10: =IFERROR(1/SQRT(1+E10*($D$4/断面!$D$4)^2*$H$4),1) -> 0.915918 | H10: =F10*G10 -> 24055.201 | I10: =IF($I$3=1,H10,F10) -> 24055.201 | J10: =IFERROR(2*PI()*断面!$D$4/D10*1000,0) -> 42.007272 | K10: =IFERROR(J10/(断面!$D$19*1000),0) -> 8.4014543 | L10: =IF(K10>=6,"🟢 良",IF(K10>=3,"🟡 誤差±10%程度","🔴 参考値のみ")) -> 🟢 良 | M10: 板が反（そ）るように曲がる。金属スケルトンで一番低く出るモード群 🟢 | O10: =IF(I10<=0,1000000000,I10) -> 24055.201 | P10: =$E$3 -> 0.0002 | Q10: 1
A11: 6 | B11: 面外曲げ | C11: 6 | D11: 20.420352 | E11: =D11^2 -> 416.99078 | F11: =IFERROR(E11/(2*PI()*断面!$D$4^2)*SQRT(断面!$D$15/断面!$D$18),0) -> 36682.059 | G11: =IFERROR(1/SQRT(1+E11*($D$4/断面!$D$4)^2*$H$4),1) -> 0.887984 | H11: =F11*G11 -> 32573.081 | I11: =IF($I$3=1,H11,F11) -> 32573.081 | J11: =IFERROR(2*PI()*断面!$D$4/D11*1000,0) -> 35.544616 | K11: =IFERROR(J11/(断面!$D$19*1000),0) -> 7.1089232 | L11: =IF(K11>=6,"🟢 良",IF(K11>=3,"🟡 誤差±10%程度","🔴 参考値のみ")) -> 🟢 良 | M11: 板が反（そ）るように曲がる。金属スケルトンで一番低く出るモード群 🟢 | O11: =IF(I11<=0,1000000000,I11) -> 32573.081 | P11: =$E$3 -> 0.0002 | Q11: 1
A12: 7 | B12: ねじり | C12: 1 | D12: 1 | E12: =D12^2 -> 1 | F12: =IFERROR(D12/(2*断面!$D$4)*SQRT(断面!$D$25/断面!$D$26),0) -> 3099.012 | G12: 1 | H12: =F12*G12 -> 3099.012 | I12: =IF($I$3=1,H12,F12) -> 3099.012 | J12: =IFERROR(2*断面!$D$4/D12*1000,0) -> 231.04 | K12: =IFERROR(J12/(MAX(断面!$D$3,断面!$D$19)*1000),0) -> 5.4634327 | L12: =IF(K12>=6,"🟢 良",IF(K12>=3,"🟡 誤差±10%程度","🔴 参考値のみ")) -> 🟡 誤差±10%程度 | M12: 板がねじれる。1次ねじりは1次曲げの近くに出やすい 🟡 | O12: =IF(I12<=0,1000000000,I12) -> 3099.012 | P12: =$E$3 -> 0.0002 | Q12: 1
A13: 8 | B13: ねじり | C13: 2 | D13: 2 | E13: =D13^2 -> 4 | F13: =IFERROR(D13/(2*断面!$D$4)*SQRT(断面!$D$25/断面!$D$26),0) -> 6198.0239 | G13: 1 | H13: =F13*G13 -> 6198.0239 | I13: =IF($I$3=1,H13,F13) -> 6198.0239 | J13: =IFERROR(2*断面!$D$4/D13*1000,0) -> 115.52 | K13: =IFERROR(J13/(MAX(断面!$D$3,断面!$D$19)*1000),0) -> 2.7317164 | L13: =IF(K13>=6,"🟢 良",IF(K13>=3,"🟡 誤差±10%程度","🔴 参考値のみ")) -> 🔴 参考値のみ | M13: 板がねじれる。1次ねじりは1次曲げの近くに出やすい 🟡 | O13: =IF(I13<=0,1000000000,I13) -> 6198.0239 | P13: =$E$3 -> 0.0002 | Q13: 1
A14: 9 | B14: ねじり | C14: 3 | D14: 3 | E14: =D14^2 -> 9 | F14: =IFERROR(D14/(2*断面!$D$4)*SQRT(断面!$D$25/断面!$D$26),0) -> 9297.0359 | G14: 1 | H14: =F14*G14 -> 9297.0359 | I14: =IF($I$3=1,H14,F14) -> 9297.0359 | J14: =IFERROR(2*断面!$D$4/D14*1000,0) -> 77.013333 | K14: =IFERROR(J14/(MAX(断面!$D$3,断面!$D$19)*1000),0) -> 1.8211442 | L14: =IF(K14>=6,"🟢 良",IF(K14>=3,"🟡 誤差±10%程度","🔴 参考値のみ")) -> 🔴 参考値のみ | M14: 板がねじれる。1次ねじりは1次曲げの近くに出やすい 🟡 | O14: =IF(I14<=0,1000000000,I14) -> 9297.0359 | P14: =$E$3 -> 0.0002 | Q14: 1
A15: 10 | B15: ねじり | C15: 4 | D15: 4 | E15: =D15^2 -> 16 | F15: =IFERROR(D15/(2*断面!$D$4)*SQRT(断面!$D$25/断面!$D$26),0) -> 12396.048 | G15: 1 | H15: =F15*G15 -> 12396.048 | I15: =IF($I$3=1,H15,F15) -> 12396.048 | J15: =IFERROR(2*断面!$D$4/D15*1000,0) -> 57.76 | K15: =IFERROR(J15/(MAX(断面!$D$3,断面!$D$19)*1000),0) -> 1.3658582 | L15: =IF(K15>=6,"🟢 良",IF(K15>=3,"🟡 誤差±10%程度","🔴 参考値のみ")) -> 🔴 参考値のみ | M15: 板がねじれる。1次ねじりは1次曲げの近くに出やすい 🟡 | O15: =IF(I15<=0,1000000000,I15) -> 12396.048 | P15: =$E$3 -> 0.0002 | Q15: 1
A16: 11 | B16: 面内曲げ | C16: 1 | D16: 4.730041 | E16: =D16^2 -> 22.373288 | F16: =IFERROR(E16/(2*PI()*断面!$D$4^2)*SQRT(断面!$D$16/断面!$D$18),0) -> 16645.952 | G16: =IFERROR(1/SQRT(1+E16*($F$4/断面!$D$4)^2*$H$4),1) -> 0.70197008 | H16: =F16*G16 -> 11684.96 | I16: =IF($I$3=1,H16,F16) -> 11684.96 | J16: =IFERROR(2*PI()*断面!$D$4/D16*1000,0) -> 153.45186 | K16: =IFERROR(J16/(断面!$D$3*1000),0) -> 3.6286958 | L16: =IF(K16>=6,"🟢 良",IF(K16>=3,"🟡 誤差±10%程度","🔴 参考値のみ")) -> 🟡 誤差±10%程度 | M16: 面の中で（半径方向に）波打つ。曲げ剛性が高いぶん高い周波数に出る 🟢 | O16: =IF(I16<=0,1000000000,I16) -> 11684.96 | P16: =$E$3 -> 0.0002 | Q16: 1
A17: 12 | B17: 面内曲げ | C17: 2 | D17: 7.853205 | E17: =D17^2 -> 61.672829 | F17: =IFERROR(E17/(2*PI()*断面!$D$4^2)*SQRT(断面!$D$16/断面!$D$18),0) -> 45885.207 | G17: =IFERROR(1/SQRT(1+E17*($F$4/断面!$D$4)^2*$H$4),1) -> 0.51047536 | H17: =F17*G17 -> 23423.268 | I17: =IF($I$3=1,H17,F17) -> 23423.268 | J17: =IFERROR(2*PI()*断面!$D$4/D17*1000,0) -> 92.425139 | K17: =IFERROR(J17/(断面!$D$3*1000),0) -> 2.1855892 | L17: =IF(K17>=6,"🟢 良",IF(K17>=3,"🟡 誤差±10%程度","🔴 参考値のみ")) -> 🔴 参考値のみ | M17: 面の中で（半径方向に）波打つ。曲げ剛性が高いぶん高い周波数に出る 🟢 | O17: =IF(I17<=0,1000000000,I17) -> 23423.268 | P17: =$E$3 -> 0.0002 | Q17: 1
A18: 13 | B18: 面内曲げ | C18: 3 | D18: 10.995608 | E18: =D18^2 -> 120.9034 | F18: =IFERROR(E18/(2*PI()*断面!$D$4^2)*SQRT(断面!$D$16/断面!$D$18),0) -> 89953.346 | G18: =IFERROR(1/SQRT(1+E18*($F$4/断面!$D$4)^2*$H$4),1) -> 0.39035499 | H18: =F18*G18 -> 35113.737 | I18: =IF($I$3=1,H18,F18) -> 35113.737 | J18: =IFERROR(2*PI()*断面!$D$4/D18*1000,0) -> 66.011226 | K18: =IFERROR(J18/(断面!$D$3*1000),0) -> 1.560976 | L18: =IF(K18>=6,"🟢 良",IF(K18>=3,"🟡 誤差±10%程度","🔴 参考値のみ")) -> 🔴 参考値のみ | M18: 面の中で（半径方向に）波打つ。曲げ剛性が高いぶん高い周波数に出る 🟢 | O18: =IF(I18<=0,1000000000,I18) -> 35113.737 | P18: =$E$3 -> 0.0002 | Q18: 1
A19: 14 | B19: 面内曲げ | C19: 4 | D19: 14.137165 | E19: =D19^2 -> 199.85943 | F19: =IFERROR(E19/(2*PI()*断面!$D$4^2)*SQRT(断面!$D$16/断面!$D$18),0) -> 148697.44 | G19: =IFERROR(1/SQRT(1+E19*($F$4/断面!$D$4)^2*$H$4),1) -> 0.31318317 | H19: =F19*G19 -> 46569.534 | I19: =IF($I$3=1,H19,F19) -> 46569.534 | J19: =IFERROR(2*PI()*断面!$D$4/D19*1000,0) -> 51.342229 | K19: =IFERROR(J19/(断面!$D$3*1000),0) -> 1.2140963 | L19: =IF(K19>=6,"🟢 良",IF(K19>=3,"🟡 誤差±10%程度","🔴 参考値のみ")) -> 🔴 参考値のみ | M19: 面の中で（半径方向に）波打つ。曲げ剛性が高いぶん高い周波数に出る 🟢 | O19: =IF(I19<=0,1000000000,I19) -> 46569.534 | P19: =$E$3 -> 0.0002 | Q19: 1
A20: 15 | B20: 面内伸縮 | C20: 1 | D20: 1 | E20: =D20^2 -> 1 | F20: =IFERROR(D20/(2*断面!$D$4)*SQRT(断面!$D$17/断面!$D$18),0) -> 22118.462 | G20: 1 | H20: =F20*G20 -> 22118.462 | I20: =IF($I$3=1,H20,F20) -> 22118.462 | J20: =IFERROR(2*断面!$D$4/D20*1000,0) -> 231.04 | K20: =IFERROR(J20/(MAX(断面!$D$3,断面!$D$19)*1000),0) -> 5.4634327 | L20: =IF(K20>=6,"🟢 良",IF(K20>=3,"🟡 誤差±10%程度","🔴 参考値のみ")) -> 🟡 誤差±10%程度 | M20: 円周方向に伸び縮み。金属だけだと非常に高い周波数（数十kHz）になりやすい 🟢 | O20: =IF(I20<=0,1000000000,I20) -> 22118.462 | P20: =$E$3 -> 0.0002 | Q20: 1
A21: 16 | B21: 面内伸縮 | C21: 2 | D21: 2 | E21: =D21^2 -> 4 | F21: =IFERROR(D21/(2*断面!$D$4)*SQRT(断面!$D$17/断面!$D$18),0) -> 44236.924 | G21: 1 | H21: =F21*G21 -> 44236.924 | I21: =IF($I$3=1,H21,F21) -> 44236.924 | J21: =IFERROR(2*断面!$D$4/D21*1000,0) -> 115.52 | K21: =IFERROR(J21/(MAX(断面!$D$3,断面!$D$19)*1000),0) -> 2.7317164 | L21: =IF(K21>=6,"🟢 良",IF(K21>=3,"🟡 誤差±10%程度","🔴 参考値のみ")) -> 🔴 参考値のみ | M21: 円周方向に伸び縮み。金属だけだと非常に高い周波数（数十kHz）になりやすい 🟢 | O21: =IF(I21<=0,1000000000,I21) -> 44236.924 | P21: =$E$3 -> 0.0002 | Q21: 1
A22: 17 | B22: 面内伸縮 | C22: 3 | D22: 3 | E22: =D22^2 -> 9 | F22: =IFERROR(D22/(2*断面!$D$4)*SQRT(断面!$D$17/断面!$D$18),0) -> 66355.386 | G22: 1 | H22: =F22*G22 -> 66355.386 | I22: =IF($I$3=1,H22,F22) -> 66355.386 | J22: =IFERROR(2*断面!$D$4/D22*1000,0) -> 77.013333 | K22: =IFERROR(J22/(MAX(断面!$D$3,断面!$D$19)*1000),0) -> 1.8211442 | L22: =IF(K22>=6,"🟢 良",IF(K22>=3,"🟡 誤差±10%程度","🔴 参考値のみ")) -> 🔴 参考値のみ | M22: 円周方向に伸び縮み。金属だけだと非常に高い周波数（数十kHz）になりやすい 🟢 | O22: =IF(I22<=0,1000000000,I22) -> 66355.386 | P22: =$E$3 -> 0.0002 | Q22: 1
A24: ■ 使っている式（🟢＝教科書どおり／🟡＝妥当な近似）／摩擦材込みブックと同じ式です
A25: 面外曲げ・面内曲げ | C25: f = (βL)² /(2π L²) × √(EI / ρA) | G25: 自由−自由はり（Euler-Bernoulli）。βL = 4.7300, 7.8532, 10.9956, 14.1372, 17.2788, 20.4204（cos(βL)cosh(βL)=1 の解） 🟢
A26: 周波数の比 | C26: f₁ : f₂ : f₃ : f₄ = 1 : 2.757 : 5.404 : 8.933 | G26: 実測がこの比から外れたら「曲げモードではない」or「せん断が効いている」 🟢
A27: せん断補正 | C27: f補正 = f / √(1 + (βL)²・(r/L)²・(1 + E/(κG))) | G27: Timoshenkoの一次近似。r=断面回転半径, κ=5/6。金属は薄いほど無視できる 🟡
A28: ねじり | C28: f = n /(2L) × √(GJ / ρIp) | G28: 自由−自由ねじり棒。J=β・b・h³ 🟢/🟡（積層のGJは近似）
A29: 面内伸縮 | C29: f = n /(2L) × √(EA / ρA) | G29: 自由−自由の縦振動。棒の中の音速 c=√(E/ρ) の半波長ずつ 🟢
A30: 波長 | C30: λ = 2πL/(βL)（曲げ）、λ = 2L/n（ねじり・伸縮） | G30: λ/断面寸法 が小さいほど1次元はり近似が苦しい。6以上あれば安心 🟢
A31: 最重要の性質 | C31: f ∝ h / L²（均質1枚板のとき） | G31: 厚さ2倍→周波数2倍。長さ2倍→周波数1/4。設計で一番効くのは L（長さ） 🟢
A33: ■ 摩擦材込みブックとの違い（ここだけ読めばOK）
A34: ・摩擦材が無いので剛性(EI)はやや下がりますが、質量(ρA)は大きく下がります。差し引き、周波数は摩擦材込みより高く出ます（数倍になることも普通）。
A35: ・中立軸が裏板の中心付近に来るため、面外曲げの1次モードが最も低く・最も明瞭に出ます。ハンマリング試験ではまずこのモードを狙ってください。
A36: ・摩擦材が無い分、減衰（η）はとても小さくなります。FFT画面ではピークが鋭く・高く出ます（スペクトルシート参照）。
A37: ・測定した周波数は「実測比較」シートに入力すると、予測とのずれ(%)と、裏板ヤング率Eの逆算値が自動で出ます。

Sheet スペクトル
A1: ④ スペクトル（FFT画面と同じ形のグラフ用データ）
A2: 各モードを1自由度系として複素数で足し合わせ、応答の大きさ |H(f)| を作る（摩擦材込みブックと同じ手法） 🟢
A3: 開始周波数 [Hz] | C3: 0 | D3: 刻み Δf [Hz] | F3: 40 | G3: 点数 | H3: 1001 | I3: dB基準値 | K3: 1 | L3: ※ 金属のみは周波数が高く出やすいので既定を0〜40000Hzにしています。ピークを拡大したいときは 開始・Δf を変更
A5: 周波数 f [Hz] | B5: 実部 Re | C5: 虚部 Im | D5: 応答 |H| | E5: レベル [dB]
A6: =$C$3 -> 0 | B6: =SUMPRODUCT(固有振動数!$Q$6:$Q$22*(1-($A6/固有振動数!$O$6:$O$22)^2)/((1-($A6/固有振動数!$O$6:$O$22)^2)^2+固有振動数!$P$6:$P$22^2)) -> 16.999999 | C6: =-SUMPRODUCT(固有振動数!$Q$6:$Q$22*固有振動数!$P$6:$P$22/((1-($A6/固有振動数!$O$6:$O$22)^2)^2+固有振動数!$P$6:$P$22^2)) -> -0.0033999999 | D6: =SQRT(B6^2+C6^2) -> 17 | E6: =20*LOG10(MAX(D6,0.000000000001)/$K$3) -> 24.608978
A7: =A6+$F$3 -> 40 | B7: =SUMPRODUCT(固有振動数!$Q$6:$Q$22*(1-($A7/固有振動数!$O$6:$O$22)^2)/((1-($A7/固有振動数!$O$6:$O$22)^2)^2+固有振動数!$P$6:$P$22^2)) -> 17.000759 | C7: =-SUMPRODUCT(固有振動数!$Q$6:$Q$22*固有振動数!$P$6:$P$22/((1-($A7/固有振動数!$O$6:$O$22)^2)^2+固有振動数!$P$6:$P$22^2)) -> -0.0034003037 | D7: =SQRT(B7^2+C7^2) -> 17.000759 | E7: =20*LOG10(MAX(D7,0.000000000001)/$K$3) -> 24.609366
A8: =A7+$F$3 -> 80 | B8: =SUMPRODUCT(固有振動数!$Q$6:$Q$22*(1-($A8/固有振動数!$O$6:$O$22)^2)/((1-($A8/固有振動数!$O$6:$O$22)^2)^2+固有振動数!$P$6:$P$22^2)) -> 17.003039 | C8: =-SUMPRODUCT(固有振動数!$Q$6:$Q$22*固有振動数!$P$6:$P$22/((1-($A8/固有振動数!$O$6:$O$22)^2)^2+固有振動数!$P$6:$P$22^2)) -> -0.0034012165 | D8: =SQRT(B8^2+C8^2) -> 17.00304 | E8: =20*LOG10(MAX(D8,0.000000000001)/$K$3) -> 24.610531
A9: =A8+$F$3 -> 120 | B9: =SUMPRODUCT(固有振動数!$Q$6:$Q$22*(1-($A9/固有振動数!$O$6:$O$22)^2)/((1-($A9/固有振動数!$O$6:$O$22)^2)^2+固有振動数!$P$6:$P$22^2)) -> 17.006849 | C9: =-SUMPRODUCT(固有振動数!$Q$6:$Q$22*固有振動数!$P$6:$P$22/((1-($A9/固有振動数!$O$6:$O$22)^2)^2+固有振動数!$P$6:$P$22^2)) -> -0.0034027431 | D9: =SQRT(B9^2+C9^2) -> 17.006849 | E9: =20*LOG10(MAX(D9,0.000000000001)/$K$3) -> 24.612477
A10: =A9+$F$3 -> 160 | B10: =SUMPRODUCT(固有振動数!$Q$6:$Q$22*(1-($A10/固有振動数!$O$6:$O$22)^2)/((1-($A10/固有振動数!$O$6:$O$22)^2)^2+固有振動数!$P$6:$P$22^2)) -> 17.0122 | C10: =-SUMPRODUCT(固有振動数!$Q$6:$Q$22*固有振動数!$P$6:$P$22/((1-($A10/固有振動数!$O$6:$O$22)^2)^2+固有振動数!$P$6:$P$22^2)) -> -0.0034048909 | D10: =SQRT(B10^2+C10^2) -> 17.0122 | E10: =20*LOG10(MAX(D10,0.000000000001)/$K$3) -> 24.61521
A11: =A10+$F$3 -> 200 | B11: =SUMPRODUCT(固有振動数!$Q$6:$Q$22*(1-($A11/固有振動数!$O$6:$O$22)^2)/((1-($A11/固有振動数!$O$6:$O$22)^2)^2+固有振動数!$P$6:$P$22^2)) -> 17.01911 | C11: =-SUMPRODUCT(固有振動数!$Q$6:$Q$22*固有振動数!$P$6:$P$22/((1-($A11/固有振動数!$O$6:$O$22)^2)^2+固有振動数!$P$6:$P$22^2)) -> -0.0034076709 | D11: =SQRT(B11^2+C11^2) -> 17.019111 | E11: =20*LOG10(MAX(D11,0.000000000001)/$K$3) -> 24.618737
A12: =A11+$F$3 -> 240 | B12: =SUMPRODUCT(固有振動数!$Q$6:$Q$22*(1-($A12/固有振動数!$O$6:$O$22)^2)/((1-($A12/固有振動数!$O$6:$O$22)^2)^2+固有振動数!$P$6:$P$22^2)) -> 17.027604 | C12: =-SUMPRODUCT(固有振動数!$Q$6:$Q$22*固有振動数!$P$6:$P$22/((1-($A12/固有振動数!$O$6:$O$22)^2)^2+固有振動数!$P$6:$P$22^2)) -> -0.0034110975 | D12: =SQRT(B12^2+C12^2) -> 17.027604 | E12: =20*LOG10(MAX(D12,0.000000000001)/$K$3) -> 24.623071
A13: =A12+$F$3 -> 280 | B13: =SUMPRODUCT(固有振動数!$Q$6:$Q$22*(1-($A13/固有振動数!$O$6:$O$22)^2)/((1-($A13/固有振動数!$O$6:$O$22)^2)^2+固有振動数!$P$6:$P$22^2)) -> 17.03771 | C13: =-SUMPRODUCT(固有振動数!$Q$6:$Q$22*固有振動数!$P$6:$P$22/((1-($A13/固有振動数!$O$6:$O$22)^2)^2+固有振動数!$P$6:$P$22^2)) -> -0.0034151884 | D13: =SQRT(B13^2+C13^2) -> 17.03771 | E13: =20*LOG10(MAX(D13,0.000000000001)/$K$3) -> 24.628225
A14: =A13+$F$3 -> 320 | B14: =SUMPRODUCT(固有振動数!$Q$6:$Q$22*(1-($A14/固有振動数!$O$6:$O$22)^2)/((1-($A14/固有振動数!$O$6:$O$22)^2)^2+固有振動数!$P$6:$P$22^2)) -> 17.049464 | C14: =-SUMPRODUCT(固有振動数!$Q$6:$Q$22*固有振動数!$P$6:$P$22/((1-($A14/固有振動数!$O$6:$O$22)^2)^2+固有振動数!$P$6:$P$22^2)) -> -0.0034199655 | D14: =SQRT(B14^2+C14^2) -> 17.049464 | E14: =20*LOG10(MAX(D14,0.000000000001)/$K$3) -> 24.634215
A15: =A14+$F$3 -> 360 | B15: =SUMPRODUCT(固有振動数!$Q$6:$Q$22*(1-($A15/固有振動数!$O$6:$O$22)^2)/((1-($A15/固有振動数!$O$6:$O$22)^2)^2+固有振動数!$P$6:$P$22^2)) -> 17.062907 | C15: =-SUMPRODUCT(固有振動数!$Q$6:$Q$22*固有振動数!$P$6:$P$22/((1-($A15/固有振動数!$O$6:$O$22)^2)^2+固有振動数!$P$6:$P$22^2)) -> -0.0034254549 | D15: =SQRT(B15^2+C15^2) -> 17.062907 | E15: =20*LOG10(MAX(D15,0.000000000001)/$K$3) -> 24.641061
A16: =A15+$F$3 -> 400 | B16: =SUMPRODUCT(固有振動数!$Q$6:$Q$22*(1-($A16/固有振動数!$O$6:$O$22)^2)/((1-($A16/固有振動数!$O$6:$O$22)^2)^2+固有振動数!$P$6:$P$22^2)) -> 17.078089 | C16: =-SUMPRODUCT(固有振動数!$Q$6:$Q$22*固有振動数!$P$6:$P$22/((1-($A16/固有振動数!$O$6:$O$22)^2)^2+固有振動数!$P$6:$P$22^2)) -> -0.0034316874 | D16: =SQRT(B16^2+C16^2) -> 17.078089 | E16: =20*LOG10(MAX(D16,0.000000000001)/$K$3) -> 24.648786
A17: =A16+$F$3 -> 440 | B17: =SUMPRODUCT(固有振動数!$Q$6:$Q$22*(1-($A17/固有振動数!$O$6:$O$22)^2)/((1-($A17/固有振動数!$O$6:$O$22)^2)^2+固有振動数!$P$6:$P$22^2)) -> 17.095066 | C17: =-SUMPRODUCT(固有振動数!$Q$6:$Q$22*固有振動数!$P$6:$P$22/((1-($A17/固有振動数!$O$6:$O$22)^2)^2+固有振動数!$P$6:$P$22^2)) -> -0.003438699 | D17: =SQRT(B17^2+C17^2) -> 17.095067 | E17: =20*LOG10(MAX(D17,0.000000000001)/$K$3) -> 24.657416
A18: =A17+$F$3 -> 480 | B18: =SUMPRODUCT(固有振動数!$Q$6:$Q$22*(1-($A18/固有振動数!$O$6:$O$22)^2)/((1-($A18/固有振動数!$O$6:$O$22)^2)^2+固有振動数!$P$6:$P$22^2)) -> 17.113905 | C18: =-SUMPRODUCT(固有振動数!$Q$6:$Q$22*固有振動数!$P$6:$P$22/((1-($A18/固有振動数!$O$6:$O$22)^2)^2+固有振動数!$P$6:$P$22^2)) -> -0.0034465318 | D18: =SQRT(B18^2+C18^2) -> 17.113905 | E18: =20*LOG10(MAX(D18,0.000000000001)/$K$3) -> 24.666982
... A1006: =A1005+$F$3 -> 40000 | B1006: =SUMPRODUCT(固有振動数!$Q$6:$Q$22*(1-($A1006/固有振動数!$O$6:$O$22)^2)/((1-($A1006/固有振動数!$O$6:$O$22)^2)^2+固有振動数!$P$6:$P$22^2)) -> 3.4259657 | C1006: =-SUMPRODUCT(固有振動数!$Q$6:$Q$22*固有振動数!$P$6:$P$22/((1-($A1006/固有振動数!$O$6:$O$22)^2)^2+固有振動数!$P$6:$P$22^2)) -> -0.012618275 | D1006: =SQRT(B1006^2+C1006^2) -> 3.425989 | E1006: =20*LOG10(MAX(D1006,0.000000000001)/$K$3) -> 10.695719
A1008: ■ 使い方
A1009: ・A〜E列をそのままコピーすれば、gnuplot / Python / Origin / Excel の別グラフに貼れます。
A1010: ・CSVで欲しいときは A6:E1006 を選択 → 別シートに値貼り付け → 「CSVで保存」。
A1011: ・縦軸dBは相対値です。絶対値が必要なら実測FRFの1点で K3（基準値）を合わせてください。
A1012: ・山（ピーク）の高さは 1/η に比例します。金属だけだとηが非常に小さいので、山がとても鋭く・高くなります。
A1013: ・⚠ Δf（刻み）が半値幅より粗いと、山が低く・細く描かれます。ηが小さいときは刻みを細かく（例:1Hz）。

Sheet 実測比較
A1: ⑤ 実測比較（ハンマリング試験・PSV-400スキャン試験の結果を記録）
A2: 予測ピークの一覧に、実測した周波数[Hz]をアンバー色のセルへ入力すると、ズレ(%)と判定が自動で出ます 🟢
A4: # | B4: モード種別 | C4: n | D4: 予測 f [Hz] （固有振動数シート） | E4: 実測 f [Hz] （ここに入力） | F4: ズレ [%] | G4: 判定 | H4: メモ（試験方法・実測方法など）
A5: 1 | B5: 面外曲げ | C5: 1 | D5: =固有振動数!$I$6 -> 1954.1348 | F5: =IF(E5="","",(E5-D5)/D5*100) | G5: =IF(E5="","",IF(ABS(F5)<=5,"🟢 良く一致",IF(ABS(F5)<=15,"🟡 まずまず","🔴 要確認(モード誤同定/寸法/E値を疑う)")))
A6: 2 | B6: 面外曲げ | C6: 2 | D6: =固有振動数!$I$7 -> 5320.7625 | F6: =IF(E6="","",(E6-D6)/D6*100) | G6: =IF(E6="","",IF(ABS(F6)<=5,"🟢 良く一致",IF(ABS(F6)<=15,"🟡 まずまず","🔴 要確認(モード誤同定/寸法/E値を疑う)")))
A7: 3 | B7: 面外曲げ | C7: 3 | D7: =固有振動数!$I$8 -> 10244.809 | F7: =IF(E7="","",(E7-D7)/D7*100) | G7: =IF(E7="","",IF(ABS(F7)<=5,"🟢 良く一致",IF(ABS(F7)<=15,"🟡 まずまず","🔴 要確認(モード誤同定/寸法/E値を疑う)")))
A8: 4 | B8: 面外曲げ | C8: 4 | D8: =固有振動数!$I$9 -> 16549.765 | F8: =IF(E8="","",(E8-D8)/D8*100) | G8: =IF(E8="","",IF(ABS(F8)<=5,"🟢 良く一致",IF(ABS(F8)<=15,"🟡 まずまず","🔴 要確認(モード誤同定/寸法/E値を疑う)")))
A9: 5 | B9: 面外曲げ | C9: 5 | D9: =固有振動数!$I$10 -> 24055.201 | F9: =IF(E9="","",(E9-D9)/D9*100) | G9: =IF(E9="","",IF(ABS(F9)<=5,"🟢 良く一致",IF(ABS(F9)<=15,"🟡 まずまず","🔴 要確認(モード誤同定/寸法/E値を疑う)")))
A10: 6 | B10: 面外曲げ | C10: 6 | D10: =固有振動数!$I$11 -> 32573.081 | F10: =IF(E10="","",(E10-D10)/D10*100) | G10: =IF(E10="","",IF(ABS(F10)<=5,"🟢 良く一致",IF(ABS(F10)<=15,"🟡 まずまず","🔴 要確認(モード誤同定/寸法/E値を疑う)")))
A11: 7 | B11: ねじり | C11: 1 | D11: =固有振動数!$I$12 -> 3099.012 | F11: =IF(E11="","",(E11-D11)/D11*100) | G11: =IF(E11="","",IF(ABS(F11)<=5,"🟢 良く一致",IF(ABS(F11)<=15,"🟡 まずまず","🔴 要確認(モード誤同定/寸法/E値を疑う)")))
A12: 8 | B12: ねじり | C12: 2 | D12: =固有振動数!$I$13 -> 6198.0239 | F12: =IF(E12="","",(E12-D12)/D12*100) | G12: =IF(E12="","",IF(ABS(F12)<=5,"🟢 良く一致",IF(ABS(F12)<=15,"🟡 まずまず","🔴 要確認(モード誤同定/寸法/E値を疑う)")))
A13: 9 | B13: ねじり | C13: 3 | D13: =固有振動数!$I$14 -> 9297.0359 | F13: =IF(E13="","",(E13-D13)/D13*100) | G13: =IF(E13="","",IF(ABS(F13)<=5,"🟢 良く一致",IF(ABS(F13)<=15,"🟡 まずまず","🔴 要確認(モード誤同定/寸法/E値を疑う)")))
A14: 10 | B14: ねじり | C14: 4 | D14: =固有振動数!$I$15 -> 12396.048 | F14: =IF(E14="","",(E14-D14)/D14*100) | G14: =IF(E14="","",IF(ABS(F14)<=5,"🟢 良く一致",IF(ABS(F14)<=15,"🟡 まずまず","🔴 要確認(モード誤同定/寸法/E値を疑う)")))
A15: 11 | B15: 面内曲げ | C15: 1 | D15: =固有振動数!$I$16 -> 11684.96 | F15: =IF(E15="","",(E15-D15)/D15*100) | G15: =IF(E15="","",IF(ABS(F15)<=5,"🟢 良く一致",IF(ABS(F15)<=15,"🟡 まずまず","🔴 要確認(モード誤同定/寸法/E値を疑う)")))
A16: 12 | B16: 面内曲げ | C16: 2 | D16: =固有振動数!$I$17 -> 23423.268 | F16: =IF(E16="","",(E16-D16)/D16*100) | G16: =IF(E16="","",IF(ABS(F16)<=5,"🟢 良く一致",IF(ABS(F16)<=15,"🟡 まずまず","🔴 要確認(モード誤同定/寸法/E値を疑う)")))
A17: 13 | B17: 面内曲げ | C17: 3 | D17: =固有振動数!$I$18 -> 35113.737 | F17: =IF(E17="","",(E17-D17)/D17*100) | G17: =IF(E17="","",IF(ABS(F17)<=5,"🟢 良く一致",IF(ABS(F17)<=15,"🟡 まずまず","🔴 要確認(モード誤同定/寸法/E値を疑う)")))
A18: 14 | B18: 面内曲げ | C18: 4 | D18: =固有振動数!$I$19 -> 46569.534 | F18: =IF(E18="","",(E18-D18)/D18*100) | G18: =IF(E18="","",IF(ABS(F18)<=5,"🟢 良く一致",IF(ABS(F18)<=15,"🟡 まずまず","🔴 要確認(モード誤同定/寸法/E値を疑う)")))
A19: 15 | B19: 面内伸縮 | C19: 1 | D19: =固有振動数!$I$20 -> 22118.462 | F19: =IF(E19="","",(E19-D19)/D19*100) | G19: =IF(E19="","",IF(ABS(F19)<=5,"🟢 良く一致",IF(ABS(F19)<=15,"🟡 まずまず","🔴 要確認(モード誤同定/寸法/E値を疑う)")))
A20: 16 | B20: 面内伸縮 | C20: 2 | D20: =固有振動数!$I$21 -> 44236.924 | F20: =IF(E20="","",(E20-D20)/D20*100) | G20: =IF(E20="","",IF(ABS(F20)<=5,"🟢 良く一致",IF(ABS(F20)<=15,"🟡 まずまず","🔴 要確認(モード誤同定/寸法/E値を疑う)")))
A21: 17 | B21: 面内伸縮 | C21: 3 | D21: =固有振動数!$I$22 -> 66355.386 | F21: =IF(E21="","",(E21-D21)/D21*100) | G21: =IF(E21="","",IF(ABS(F21)<=5,"🟢 良く一致",IF(ABS(F21)<=15,"🟡 まずまず","🔴 要確認(モード誤同定/寸法/E値を疑う)")))
A23: ■ 裏板ヤング率Eの逆算（もっとも確実な1次面外曲げモードのピークから）
A24: 考え方：他の寸法・密度が正しければ f は √E に比例します。よって E_実際 = E_今の設定 ×（実測f ÷ 予測f）² で逆算できます。
A25: このせん断補正係数はEに依存しない式になっているため、この比例関係は近似ではなく、幾何形状・密度が正しい前提のもとで成立します 🟢
A27: 対象モード | B27: （固定）上の表の1行目＝面外曲げ1次を参照 | D27: ← 例:「面外曲げ1次」。実測比較表の「モード種別」＋「n」と同じ書き方で
A28: 予測 f [Hz] | B28: =$D$5 -> 1954.1348 | D28: 既定は面外曲げ1次(表の1行目)を参照。別モードで逆算したい場合はD5部分を書き換え
A29: 実測 f [Hz] | B29: =$E$5 -> 0
A30: 現在設定の裏板 E [GPa] | B30: =断面!$E$9 -> 205 | D30: 断面シートの「2: 裏板」の材料DBから引いているE
A31: 逆算した 裏板 E_実際 [GPa] | B31: =IF(OR($B$29="",$B$28=0),"実測値を上の表に入力してください",$B$30*($B$29/$B$28)^2) -> 実測値を上の表に入力してください | D31: 🟢 シム・接着層をOFFのまま(裏板単体)で使うのが最も精度が良い
A33: ■ さらに精密に逆算したいとき（ゴールシーク機能）
A34: 上の逆算は「せん断補正」を含めても数式的に正しい比例式です。ただし n を含む複数モードを同時に合わせたい場合や、
A35: E以外（厚さt・密度ρ）も同時に不確かな場合は、Excelの「ゴールシーク」機能を使うとより柔軟です。
A36: ① データタブ → What-If分析 → ゴールシーク
A37: ② 「数式入力セル」に 固有振動数!I6（=1次面外曲げの予測f）を指定
A38: ③ 「目標値」に実測した周波数[Hz]を入力
A39: ④ 「変化させるセル」に 断面!E9（裏板のE、GPa単位の材料DB参照を外して直接数値を入れておく必要あり）を指定
A40: ⑤ OKを押すと、断面!E9が実測に一致するE値まで自動で調整されます（元の材料DB参照式は上書きされるので、
A41: 試す前に断面シートをコピーしておくと安全です）。
