Workbook

Sheet 使い方
A1: ブレーキパッド 金属部（摩擦材（まさつざい）抜き）固有振動数（こゆうしんどうすう）予測ブック
A2: 裏板（うらいた）＋シムだけの状態 → 固有振動数・スペクトル・鳴（な）きリスク／実測ピーク → 材料定数の逆算（ぎゃくさん） | Ver 2.0（穴入力・図形Ixx・測定計画を追加）
A4: ■ このブックで何ができるか（摩擦材ありブックと同じ7本立て）
A5: ① 順算（じゅんざん） | B5: 金属部の材質と寸法を入れる → 固有振動数（ピークが出る周波数）を予測 | C5: シート：形状 → 断面 → 固有振動数
A6: ② スペクトル | B6: 予測した山（ピーク）を並べて、FFT画面そっくりのグラフを作る | C6: シート：スペクトル（グラフ付き）
A7: ③ 鳴きリスク判定 | B7: その寸法だと鳴（な）きやすいかを点数化。ローターとの一致も見る | C7: シート：鳴きリスク
A8: ④ 逆算（ぎゃくさん） | B8: 実測したピーク周波数 → 裏板の実効ヤング率・形状補正係数を逆に求める | C8: シート：逆算
A9: ⑤ 実測比較 | B9: ハンマリング／PSV-400 で測った値と予測を並べてズレ％判定 | C9: シート：実測比較
A10: ⑥ 測定計画 | B10: FFTの設定（Δf・サンプリング・窓）と吊り方・叩き方を自動計算 | C10: シート：測定計画
A11: ⑦ 式一覧 | B11: 使った式をぜんぶ一覧。コピペしてほかのExcelに貼れる | C11: シート：式一覧
A13: ■ 摩擦材ありブックとの違い（3つだけ覚えればOK）
A14: ① 断面シートの層が3つ | B14: シム／裏板／接着（任意）の3層のみ。摩擦材の行はありません | C14: 🟢
A15: ② 予測周波数がかなり高い | B15: 摩擦材の重さが無いぶん軽いので、同じ形でも周波数は上がります。スペクトルの既定範囲は 0〜40 kHz | C15: 🟢
A16: ③ 鳴きリスクは「参考」 | B16: 実際に鳴くのは摩擦材を貼った完成品。ここでは金属スケルトンの素性を見るのが目的 | C16: 🟡
A18: ■ 触（さわ）るセルの色分け（このブックは全シート共通）
A19: アンバー（茶色）のセル | B19: あなたが入力するところ。ここだけ触ればOK | C19: 入力
A20: グリーンのセル | B20: 自動計算の結果。触ると壊（こわ）れます | C20: 出力
A21: グレーのセル | B21: 計算の途中（とちゅう）。見なくてよい | C21: 中間
A23: ■ 使う順番（この順で必ず動きます）
A24: STEP 0 | B24: 「採寸ガイド」を読む。ノギスで測る場所と、入れる欄が絵で分かるようになっています | C24: ← 初めての人はここから
A25: STEP 1 | B25: 「材料DB」で使う材料（裏板の鋼種・シムの有無）を確認
A26: STEP 2 | B26: 「形状」に 外形の頂点座標（X,Y）を最大24点まで入力（a.jpg のプリセットあり） | C26: V〜Z列のプリセットをコピペでOK
A27: STEP 3 | B27: 「形状」の下のほうにある ■穴の入力 に、2つの穴の 中心X・中心Y・直径 を入力 | C27: ★今回の追加機能
A28: STEP 4 | B28: 「断面」で シム（使うときだけ1）・裏板 の材料と厚さを入力し、質量[g]を電子天秤の実測と突き合わせる
A29: STEP 5 | B29: 「固有振動数」を見る → 予測ピーク一覧が出る
A30: STEP 6 | B30: 「スペクトル」でグラフ確認。A〜E列をコピーすれば他ソフトに貼れる
A31: STEP 7 | B31: 「測定計画」でFFT設定（Δf・fmax・窓）と吊り位置・叩く位置を決める
A32: STEP 8 | B32: 測定 →「実測比較」に周波数を入力 → ズレ％を確認
A33: STEP 9 | B33: 「逆算」で 裏板の実効ヤング率・形状補正係数 を求める → 予測式を自分の現物に合わせ込む
A34: STEP 10 | B34: 「鳴きリスク」でローター（ディスク）の固有振動数を入れて判定
A36: ■ 信頼度マーク
A37: 🟢 検証済み | B37: 教科書・規格に載っている確立した式。そのまま信じてよい
A38: 🟡 推定 | B38: 妥当（だとう）だが近似。実測で校正（こうせい）してから使う
A39: 🔴 要確認 | B39: 値のばらつきが大きい。必ず自分で測る
A41: ■ 重要な前提（ここを外すと全部ずれます）
A42: 自由−自由（free-free） | B42: ピアノ線で吊（つ）った状態＝どこも固定していない状態を仮定 | C42: 🟢
A43: はり（梁）近似 | B43: パッドを「円周方向に長い1本の棒」とみなす。曲率は無視 | C43: 🟡
A44: 穴の扱い | B44: 穴は「面積と断面二次モーメントを減らす」という長さ方向平均の形で入れています。局所的な応力集中までは見ていません | C44: 🟡
A45: 裏板・シムの厚さ／材質 | B45: 図面値ではなく、必ずノギス・マイクロメータで現物実測してから入力する | C45: 🔴
A46: 質量チェックが命綱 | B46: 断面シートの「質量[g]」を電子天秤の実測と必ず突き合わせる。合わなければ入力が間違っている | C46: 🟢
...

Sheet 採寸ガイド
A1: ⓪ 採寸（さいすん）ガイド — 摩擦材抜きのパッドをどう測って、どこに入れるか
A2: ノギス1本でできます。この順にやれば必ず「形状」シートが埋まります。（a.jpg のような形を想定）
A3: ★ カラーの図解は このシートの 112行目あたり にあります（下へスクロール）
A4: ■ 用意するもの
A5: ノギス（デジタル推奨） | B5: 0〜150mm。0.01mm または 0.05mm 読み。穴の内径・板厚・全長すべてこれ1本で足ります | C5: 必須
A6: 方眼紙 or A3コピー用紙 | B6: パッドを置いて輪郭をなぞる。あとで座標を拾うため | C6: 必須
A7: 定規（30cm） | B7: 方眼紙に基準線（X軸・Y軸）を引く | C7: 必須
A8: 電子天秤（0.1g） | B8: 質量チェック用。断面シートの予測質量と突き合わせる命綱 | C8: 強く推奨
A9: マイクロメータ | B9: 板厚をより正確に。無ければノギスで可 | C9: あれば
A10: スマホのカメラ | B10: 真上から撮って輪郭をトレースする裏ワザ用（後述 §6） | C10: あれば
A12: ■ §1 いちばん大事：座標の決め方（ここを間違えると全部ずれます）
A13: パッドを机に置きます。摩擦材が付いていた面（ザラザラした面）を上にして、両端の「耳（みみ）」が左右に来るように置いてください。
A14: この置き方で、左右方向 ＝ X軸（円周方向・長手）、上下方向 ＝ Y軸（半径方向）です。
A15: X軸の＋は右、Y軸の＋は上。単位はぜんぶ mm。小数点第2位（0.01mm）まで書けば充分です。
A16: 原点（0,0）はどこでもかまいません。ブックの中で自動的に重心を計算するので、絶対位置は結果に影響しません。
A17: おすすめの原点：パッドの左下の角。そうすると座標がぜんぶプラスになって間違いにくい。
A18: ※ a.jpg のプリセットは「左右の中央」を X=0、「いちばん下」を Y=0 にしてあります。どちらでも結果は同じです。
A20: ■ §2 外形（そとがたち）の測り方 — 「角（かど）を拾う」だけ
A21: やること：外周をぐるっと一周する順番で、角（かど）の位置を X,Y で書き出す。それだけです。
A22: コツ1：曲線（円弧）のところは、3〜5点くらい打てば充分です。1〜2mm の誤差は周波数に 0.1% も効きません。
A23: コツ2：耳（キャリパに嵌まる出っ張り）と、下側の爪（つめ）は必ず角を拾ってください。ここは形が効きます。
A24: コツ3：必ず「一筆書き」の順番で。反時計回りでも時計回りでもOKですが、飛び飛びはダメ。
... A101: ■ §7 よくある質問
A102: Q. 穴を無視したらどうなる？ | B102: A. 面積と剛性が実際より大きくなり、質量も増えます。今回の形だと質量で約7%、周波数で数%ずれます。入れたほうが良いです。
A103: Q. 面取り（角のC面）まで測る？ | B103: A. 不要です。0.5mm程度の面取りは周波数に0.1%も効きません。
A104: Q. 耳の細かい段差は？ | B104: A. 拾ってください。耳は「腹（はら）」になりやすく、ねじりモードの形に効きます。
A105: Q. 裏板の裏側のリブや刻印は？ | B105: A. このブックは一様厚さの板として扱います。リブがあるなら、厚さを「等価厚さ」として少し厚めに入れて実測で合わせ込むのが現実的です（逆算シートを使う）。
A106: Q. 座標の向きは時計回り？反時計回り？ | B106: A. どちらでも自動判定します（形状シート F3 の「向き s」）。飛び飛びの順番だけがダメです。
A107: Q. 24点で足りない形は？ | B107: A. 曲線部の点を減らして角を優先してください。曲線を1点減らしても誤差はほぼ出ません。
A110: ■ §8 カラー図解（採寸のしかた）
A111: 左：外形の頂点をどう拾うか ／ 右：2つの穴の直径・中心をどう測って、形状シートのどこへ入れるか

Sheet 材料DB
A1: 材料データベース（金属・シムのみ／摩擦材は含みません）
A2: E＝ヤング率（かたさ）／ρ＝密度（重さ）／ν＝ポアソン比（横に膨らむ割合）／η＝損失係数（振動の減りやすさ）
A4: 材料名 | B4: E [GPa] | C4: ρ [kg/m³] | D4: ν | E4: η(目安) | F4: 分類 | G4: 信頼度 | H4: 出典・備考
A5: 鋼 SPCC(裏板) | B5: 205 | C5: 7850 | D5: 0.3 | E5: 0.0002 | F5: 金属 | G5: 🟢 | H5: JIS一般値 / 鋼のEは190-210GPa
A6: 鋼 SS400 | B6: 205 | C6: 7850 | D6: 0.3 | E6: 0.0002 | F6: 金属 | G6: 🟢 | H6: JIS一般値
A7: 鋼 S45C | B7: 205 | C7: 7850 | D7: 0.3 | E7: 0.0002 | F7: 金属 | G7: 🟢 | H7: JIS一般値
A8: ステンレス SUS304 | B8: 193 | C8: 7930 | D8: 0.3 | E8: 0.0005 | F8: 金属 | G8: 🟢 | H8: JIS一般値
A9: ばね鋼 SUP9 | B9: 206 | C9: 7850 | D9: 0.3 | E9: 0.0002 | F9: 金属 | G9: 🟢 | H9: JIS一般値
A10: ねずみ鋳鉄 FC250 | B10: 105 | C10: 7200 | D10: 0.26 | E10: 0.0015 | F10: 金属 | G10: 🟡 | H10: 90-120GPaの幅あり。黒鉛量で変化
A11: アルミ A5052 | B11: 70 | C11: 2680 | D11: 0.33 | E11: 0.0001 | F11: 金属 | G11: 🟢 | H11: JIS一般値
A12: アルミ A6061-T6 | B12: 69 | C12: 2700 | D12: 0.33 | E12: 0.0001 | F12: 金属 | G12: 🟢 | H12: JIS一般値
A13: チタン Ti-6Al-4V | B13: 114 | C13: 4430 | D13: 0.34 | E13: 0.0002 | F13: 金属 | G13: 🟢 | H13: ASTM Grade5
A14: 銅 C1100 | B14: 117 | C14: 8940 | D14: 0.34 | E14: 0.002 | F14: 金属 | G14: 🟢 | H14: JIS一般値
A15: 黄銅 C2600 | B15: 103 | C15: 8530 | D15: 0.35 | E15: 0.001 | F15: 金属 | G15: 🟢 | H15: JIS一般値
A16: シム鋼板 SPCC | B16: 205 | C16: 7850 | D16: 0.3 | E16: 0.0002 | F16: シム | G16: 🟢 | H16: JIS一般値
... A21: (未使用) | B21: 0 | C21: 1 | D21: 0 | E21: 0 | F21: - | G21: - | H21: 空欄行。使わない層に指定する
A23: ※ 行を追加するときは 45行目までに書けば全シートが自動で拾います（数式の参照範囲は $A$5:$A$45）。
A24: ※ このブックは摩擦材を含みません。摩擦材込みの計算は「ブレーキパッド固有振動数予測.xlsx」を使ってください。
A25: ※ 鋼のEは190〜210GPaの幅があります。逆算シートで自分の現物のEを求めて、この表を上書きするのが最終形です。

Sheet 形状
A1: ① 形状入力（金属スケルトン＝裏板の外形を多角形で入力）
A2: X＝円周方向（長手・左右）、Y＝半径方向（上下）。単位はすべて mm。頂点は最大24点。反時計回り・時計回りどちらでもOK。詳しい測り方は「採寸ガイド」シートへ。 | E2: 頂点数 N | F2: =COUNT($B$5:$B$28) -> 22
E3: 向き s (+1=反時計/-1=時計) | F3: =IF(SUM($I$5:$I$28)>=0,1,-1) -> 1 | V3: ■ プリセット：a.jpg をトレースした形（全長100mmに正規化）
A4: No | B4: X [mm] | C4: Y [mm] | D4: 使用 | E4: 次X | F4: 次Y | G4: 前X | H4: 前Y | I4: 外積項 | J4: 辺長 | K4: Ixx項 | L4: Iyy項 | M4: Ixy項 | N4: Cx項 | O4: Cy項 | P4: 内積 | Q4: 外積 | R4: 内角 [°] | S4: 外角 [°] | T4: 出隅/入隅 | V4: あなたが実測した全長 L [mm] → | Y4: 110 | AD4: X閉（描画用） | AE4: Y閉（描画用） | AG4: 穴cX | AH4: 穴cY
A5: 1 | B5: -55 | C5: 16.7 | D5: =IF(ROW()-4<=$F$2,1,0) -> 1 | E5: =IF($D5=0,0,INDEX($B$5:$B$28,IF(ROW()-4=$F$2,1,ROW()-4+1))) -> -41.25 | F5: =IF($D5=0,0,INDEX($C$5:$C$28,IF(ROW()-4=$F$2,1,ROW()-4+1))) -> 16.3 | G5: =IF($D5=0,0,INDEX($B$5:$B$28,IF(ROW()-4=1,$F$2,ROW()-4-1))) -> -54.8 | H5: =IF($D5=0,0,INDEX($C$5:$C$28,IF(ROW()-4=1,$F$2,ROW()-4-1))) -> 26.72 | I5: =IF($D5=0,0,B5*F5-E5*C5) -> -207.625 | J5: =IF($D5=0,0,SQRT((E5-B5)^2+(F5-C5)^2)) -> 13.755817 | K5: =IF($D5=0,0,(C5^2+C5*F5+F5^2)*I5) -> -169586.02 | L5: =IF($D5=0,0,(B5^2+B5*E5+E5^2)*I5) -> -1452401.8 | M5: =IF($D5=0,0,(B5*F5+2*B5*C5+2*E5*F5+E5*C5)*I5) -> 989774.33 | N5: =IF($D5=0,0,(B5+E5)*I5) -> 19983.906 | O5: =IF($D5=0,0,(C5+F5)*I5) -> -6851.625 | P5: =IF($D5=0,0,(G5-B5)*(E5-B5)+(H5-C5)*(F5-C5)) -> -1.258 | Q5: =IF($D5=0,0,(G5-B5)*(F5-C5)-(H5-C5)*(E5-B5)) -> -137.855 | R5: =IF($D5=0,"",IFERROR(MOD(DEGREES(ATAN2(P5,-$F$3*Q5)),360),"")) -> 90.52284 | S5: =IF($D5="","",IF($D5=0,"",180-R5)) -> 89.47716 | T5: =IF($D5=0,"",IF(R5>180,"入隅(凹)","出隅(凸)")) -> 出隅(凸) | V5: 倍率（＝L÷100） | Y5: =$Y$4/100 -> 1.1 | AD5: =INDEX($B$5:$B$28,IF(ROW()-4<=$F$2,ROW()-4,1)) -> -55 | AE5: =INDEX($C$5:$C$28,IF(ROW()-4<=$F$2,ROW()-4,1)) -> 16.7 | AG5: =IF($B55=1,$C55,$C$55) -> -18.93 | AH5: =IF($B55=1,$D55,$D$55) -> 25.32
A6: 2 | B6: -41.25 | C6: 16.3 | D6: =IF(ROW()-4<=$F$2,1,0) -> 1 | E6: =IF($D6=0,0,INDEX($B$5:$B$28,IF(ROW()-4=$F$2,1,ROW()-4+1))) -> -40.27 | F6: =IF($D6=0,0,INDEX($C$5:$C$28,IF(ROW()-4=$F$2,1,ROW()-4+1))) -> 4.72 | G6: =IF($D6=0,0,INDEX($B$5:$B$28,IF(ROW()-4=1,$F$2,ROW()-4-1))) -> -55 | H6: =IF($D6=0,0,INDEX($C$5:$C$28,IF(ROW()-4=1,$F$2,ROW()-4-1))) -> 16.7 | I6: =IF($D6=0,0,B6*F6-E6*C6) -> 461.701 | J6: =IF($D6=0,0,SQRT((E6-B6)^2+(F6-C6)^2)) -> 11.621394 | K6: =IF($D6=0,0,(C6^2+C6*F6+F6^2)*I6) -> 168476.73 | L6: =IF($D6=0,0,(B6^2+B6*E6+E6^2)*I6) -> 2301290 | M6: =IF($D6=0,0,(B6*F6+2*B6*C6+2*E6*F6+E6*C6)*I6) -> -1189341.7 | N6: =IF($D6=0,0,(B6+E6)*I6) -> -37637.866 | O6: =IF($D6=0,0,(C6+F6)*I6) -> 9704.955 | P6: =IF($D6=0,0,(G6-B6)*(E6-B6)+(H6-C6)*(F6-C6)) -> -18.107 | Q6: =IF($D6=0,0,(G6-B6)*(F6-C6)-(H6-C6)*(E6-B6)) -> 158.833 | R6: =IF($D6=0,"",IFERROR(MOD(DEGREES(ATAN2(P6,-$F$3*Q6)),360),"")) -> 263.49634 | S6: =IF($D6="","",IF($D6=0,"",180-R6)) -> -83.496344 | T6: =IF($D6=0,"",IF(R6>180,"入隅(凹)","出隅(凸)")) -> 入隅(凹) | V6: No | W6: X_norm | X6: Y_norm | Y6: → X実寸 | Z6: → Y実寸 | AD6: =INDEX($B$5:$B$28,IF(ROW()-4<=$F$2,ROW()-4,1)) -> -41.25 | AE6: =INDEX($C$5:$C$28,IF(ROW()-4<=$F$2,ROW()-4,1)) -> 16.3 | AG6: =IF($B56=1,$C56,$C$55) -> 14.17 | AH6: =IF($B56=1,$D56,$D$55) -> 28.85
A7: 3 | B7: -40.27 | C7: 4.72 | D7: =IF(ROW()-4<=$F$2,1,0) -> 1 | E7: =IF($D7=0,0,INDEX($B$5:$B$28,IF(ROW()-4=$F$2,1,ROW()-4+1))) -> -38.1 | F7: =IF($D7=0,0,INDEX($C$5:$C$28,IF(ROW()-4=$F$2,1,ROW()-4+1))) -> 0 | G7: =IF($D7=0,0,INDEX($B$5:$B$28,IF(ROW()-4=1,$F$2,ROW()-4-1))) -> -41.25 | H7: =IF($D7=0,0,INDEX($C$5:$C$28,IF(ROW()-4=1,$F$2,ROW()-4-1))) -> 16.3 | I7: =IF($D7=0,0,B7*F7-E7*C7) -> 179.832 | J7: =IF($D7=0,0,SQRT((E7-B7)^2+(F7-C7)^2)) -> 5.1949302 | K7: =IF($D7=0,0,(C7^2+C7*F7+F7^2)*I7) -> 4006.3692 | L7: =IF($D7=0,0,(B7^2+B7*E7+E7^2)*I7) -> 828588.51 | M7: =IF($D7=0,0,(B7*F7+2*B7*C7+2*E7*F7+E7*C7)*I7) -> -100702.47 | N7: =IF($D7=0,0,(B7+E7)*I7) -> -14093.434 | O7: =IF($D7=0,0,(C7+F7)*I7) -> 848.80704 | P7: =IF($D7=0,0,(G7-B7)*(E7-B7)+(H7-C7)*(F7-C7)) -> -56.7842 | Q7: =IF($D7=0,0,(G7-B7)*(F7-C7)-(H7-C7)*(E7-B7)) -> -20.503 | R7: =IF($D7=0,"",IFERROR(MOD(DEGREES(ATAN2(P7,-$F$3*Q7)),360),"")) -> 160.14693 | S7: =IF($D7="","",IF($D7=0,"",180-R7)) -> 19.853067 | T7: =IF($D7=0,"",IF(R7>180,"入隅(凹)","出隅(凸)")) -> 出隅(凸) | V7: 1 | W7: -50 | X7: 15.18 | Y7: =ROUND(W7*$Y$5,2) -> -55 | Z7: =ROUND(X7*$Y$5,2) -> 16.7 | AD7: =INDEX($B$5:$B$28,IF(ROW()-4<=$F$2,ROW()-4,1)) -> -40.27 | AE7: =INDEX($C$5:$C$28,IF(ROW()-4<=$F$2,ROW()-4,1)) -> 4.72 | AG7: =IF($B57=1,$C57,$C$55) -> -18.93 | AH7: =IF($B57=1,$D57,$D$55) -> 25.32
A8: 4 | B8: -38.1 | C8: 0 | D8: =IF(ROW()-4<=$F$2,1,0) -> 1 | E8: =IF($D8=0,0,INDEX($B$5:$B$28,IF(ROW()-4=$F$2,1,ROW()-4+1))) -> -15.32 | F8: =IF($D8=0,0,INDEX($C$5:$C$28,IF(ROW()-4=$F$2,1,ROW()-4+1))) -> 8.84 | G8: =IF($D8=0,0,INDEX($B$5:$B$28,IF(ROW()-4=1,$F$2,ROW()-4-1))) -> -40.27 | H8: =IF($D8=0,0,INDEX($C$5:$C$28,IF(ROW()-4=1,$F$2,ROW()-4-1))) -> 4.72 | I8: =IF($D8=0,0,B8*F8-E8*C8) -> -336.804 | J8: =IF($D8=0,0,SQRT((E8-B8)^2+(F8-C8)^2)) -> 24.435098 | K8: =IF($D8=0,0,(C8^2+C8*F8+F8^2)*I8) -> -26319.751 | L8: =IF($D8=0,0,(B8^2+B8*E8+E8^2)*I8) -> -764546.56 | M8: =IF($D8=0,0,(B8*F8+2*B8*C8+2*E8*F8+E8*C8)*I8) -> 204662.86 | N8: =IF($D8=0,0,(B8+E8)*I8) -> 17992.07 | O8: =IF($D8=0,0,(C8+F8)*I8) -> -2977.3474 | P8: =IF($D8=0,0,(G8-B8)*(E8-B8)+(H8-C8)*(F8-C8)) -> -7.7078 | Q8: =IF($D8=0,0,(G8-B8)*(F8-C8)-(H8-C8)*(E8-B8)) -> -126.7044 | R8: =IF($D8=0,"",IFERROR(MOD(DEGREES(ATAN2(P8,-$F$3*Q8)),360),"")) -> 93.48118 | S8: =IF($D8="","",IF($D8=0,"",180-R8)) -> 86.51882 | T8: =IF($D8=0,"",IF(R8>180,"入隅(凹)","出隅(凸)")) -> 出隅(凸) | V8: 2 | W8: -37.5 | X8: 14.82 | Y8: =ROUND(W8*$Y$5,2) -> -41.25 | Z8: =ROUND(X8*$Y$5,2) -> 16.3 | AD8: =INDEX($B$5:$B$28,IF(ROW()-4<=$F$2,ROW()-4,1)) -> -38.1 | AE8: =INDEX($C$5:$C$28,IF(ROW()-4<=$F$2,ROW()-4,1)) -> 0 | AG8: =IF($B58=1,$C58,$C$55) -> -18.93 | AH8: =IF($B58=1,$D58,$D$55) -> 25.32
A9: 5 | B9: -15.32 | C9: 8.84 | D9: =IF(ROW()-4<=$F$2,1,0) -> 1 | E9: =IF($D9=0,0,INDEX($B$5:$B$28,IF(ROW()-4=$F$2,1,ROW()-4+1))) -> -0.78 | F9: =IF($D9=0,0,INDEX($C$5:$C$28,IF(ROW()-4=$F$2,1,ROW()-4+1))) -> 11.2 | G9: =IF($D9=0,0,INDEX($B$5:$B$28,IF(ROW()-4=1,$F$2,ROW()-4-1))) -> -38.1 | H9: =IF($D9=0,0,INDEX($C$5:$C$28,IF(ROW()-4=1,$F$2,ROW()-4-1))) -> 0 | I9: =IF($D9=0,0,B9*F9-E9*C9) -> -164.6888 | J9: =IF($D9=0,0,SQRT((E9-B9)^2+(F9-C9)^2)) -> 14.730282 | K9: =IF($D9=0,0,(C9^2+C9*F9+F9^2)*I9) -> -49833.777 | L9: =IF($D9=0,0,(B9^2+B9*E9+E9^2)*I9) -> -40721.019 | M9: =IF($D9=0,0,(B9*F9+2*B9*C9+2*E9*F9+E9*C9)*I9) -> 76878.181 | N9: =IF($D9=0,0,(B9+E9)*I9) -> 2651.4897 | O9: =IF($D9=0,0,(C9+F9)*I9) -> -3300.3636 | P9: =IF($D9=0,0,(G9-B9)*(E9-B9)+(H9-C9)*(F9-C9)) -> -352.0836 | Q9: =IF($D9=0,0,(G9-B9)*(F9-C9)-(H9-C9)*(E9-B9)) -> 74.7728 | R9: =IF($D9=0,"",IFERROR(MOD(DEGREES(ATAN2(P9,-$F$3*Q9)),360),"")) -> 191.9899 | S9: =IF($D9="","",IF($D9=0,"",180-R9)) -> -11.989898 | T9: =IF($D9=0,"",IF(R9>180,"入隅(凹)","出隅(凸)")) -> 入隅(凹) | V9: 3 | W9: -36.61 | X9: 4.29 | Y9: =ROUND(W9*$Y$5,2) -> -40.27 | Z9: =ROUND(X9*$Y$5,2) -> 4.72 | AD9: =INDEX($B$5:$B$28,IF(ROW()-4<=$F$2,ROW()-4,1)) -> -15.32 | AE9: =INDEX($C$5:$C$28,IF(ROW()-4<=$F$2,ROW()-4,1)) -> 8.84
A10: 6 | B10: -0.78 | C10: 11.2 | D10: =IF(ROW()-4<=$F$2,1,0) -> 1 | E10: =IF($D10=0,0,INDEX($B$5:$B$28,IF(ROW()-4=$F$2,1,ROW()-4+1))) -> 23.18 | F10: =IF($D10=0,0,INDEX($C$5:$C$28,IF(ROW()-4=$F$2,1,ROW()-4+1))) -> 10.8 | G10: =IF($D10=0,0,INDEX($B$5:$B$28,IF(ROW()-4=1,$F$2,ROW()-4-1))) -> -15.32 | H10: =IF($D10=0,0,INDEX($C$5:$C$28,IF(ROW()-4=1,$F$2,ROW()-4-1))) -> 8.84 | I10: =IF($D10=0,0,B10*F10-E10*C10) -> -268.04 | J10: =IF($D10=0,0,SQRT((E10-B10)^2+(F10-C10)^2)) -> 23.963339 | K10: =IF($D10=0,0,(C10^2+C10*F10+F10^2)*I10) -> -97309.242 | L10: =IF($D10=0,0,(B10^2+B10*E10+E10^2)*I10) -> -139338.02 | M10: =IF($D10=0,0,(B10*F10+2*B10*C10+2*E10*F10+E10*C10)*I10) -> -196850.72 | N10: =IF($D10=0,0,(B10+E10)*I10) -> -6004.096 | O10: =IF($D10=0,0,(C10+F10)*I10) -> -5896.88 | P10: =IF($D10=0,0,(G10-B10)*(E10-B10)+(H10-C10)*(F10-C10)) -> -347.4344 | Q10: =IF($D10=0,0,(G10-B10)*(F10-C10)-(H10-C10)*(E10-B10)) -> 62.3616 | R10: =IF($D10=0,"",IFERROR(MOD(DEGREES(ATAN2(P10,-$F$3*Q10)),360),"")) -> 190.17576 | S10: =IF($D10="","",IF($D10=0,"",180-R10)) -> -10.175763 | T10: =IF($D10=0,"",IF(R10>180,"入隅(凹)","出隅(凸)")) -> 入隅(凹) | V10: 4 | W10: -34.64 | X10: 0 | Y10: =ROUND(W10*$Y$5,2) -> -38.1 | Z10: =ROUND(X10*$Y$5,2) -> 0 | AD10: =INDEX($B$5:$B$28,IF(ROW()-4<=$F$2,ROW()-4,1)) -> -0.78 | AE10: =INDEX($C$5:$C$28,IF(ROW()-4<=$F$2,ROW()-4,1)) -> 11.2
A11: 7 | B11: 23.18 | C11: 10.8 | D11: =IF(ROW()-4<=$F$2,1,0) -> 1 | E11: =IF($D11=0,0,INDEX($B$5:$B$28,IF(ROW()-4=$F$2,1,ROW()-4+1))) -> 41.45 | F11: =IF($D11=0,0,INDEX($C$5:$C$28,IF(ROW()-4=$F$2,1,ROW()-4+1))) -> 4.72 | G11: =IF($D11=0,0,INDEX($B$5:$B$28,IF(ROW()-4=1,$F$2,ROW()-4-1))) -> -0.78 | H11: =IF($D11=0,0,INDEX($C$5:$C$28,IF(ROW()-4=1,$F$2,ROW()-4-1))) -> 11.2 | I11: =IF($D11=0,0,B11*F11-E11*C11) -> -338.2504 | J11: =IF($D11=0,0,SQRT((E11-B11)^2+(F11-C11)^2)) -> 19.255111 | K11: =IF($D11=0,0,(C11^2+C11*F11+F11^2)*I11) -> -64231.857 | L11: =IF($D11=0,0,(B11^2+B11*E11+E11^2)*I11) -> -1087889.7 | M11: =IF($D11=0,0,(B11*F11+2*B11*C11+2*E11*F11+E11*C11)*I11) -> -490140.25 | N11: =IF($D11=0,0,(B11+E11)*I11) -> -21861.123 | O11: =IF($D11=0,0,(C11+F11)*I11) -> -5249.6462 | P11: =IF($D11=0,0,(G11-B11)*(E11-B11)+(H11-C11)*(F11-C11)) -> -440.1812 | Q11: =IF($D11=0,0,(G11-B11)*(F11-C11)-(H11-C11)*(E11-B11)) -> 138.3688 | R11: =IF($D11=0,"",IFERROR(MOD(DEGREES(ATAN2(P11,-$F$3*Q11)),360),"")) -> 197.45028 | S11: =IF($D11="","",IF($D11=0,"",180-R11)) -> -17.450285 | T11: =IF($D11=0,"",IF(R11>180,"入隅(凹)","出隅(凸)")) -> 入隅(凹) | V11: 5 | W11: -13.93 | X11: 8.04 | Y11: =ROUND(W11*$Y$5,2) -> -15.32 | Z11: =ROUND(X11*$Y$5,2) -> 8.84 | AD11: =INDEX($B$5:$B$28,IF(ROW()-4<=$F$2,ROW()-4,1)) -> 23.18 | AE11: =INDEX($C$5:$C$28,IF(ROW()-4<=$F$2,ROW()-4,1)) -> 10.8
A12: 8 | B12: 41.45 | C12: 4.72 | D12: =IF(ROW()-4<=$F$2,1,0) -> 1 | E12: =IF($D12=0,0,INDEX($B$5:$B$28,IF(ROW()-4=$F$2,1,ROW()-4+1))) -> 42.62 | F12: =IF($D12=0,0,INDEX($C$5:$C$28,IF(ROW()-4=$F$2,1,ROW()-4+1))) -> 15.52 | G12: =IF($D12=0,0,INDEX($B$5:$B$28,IF(ROW()-4=1,$F$2,ROW()-4-1))) -> 23.18 | H12: =IF($D12=0,0,INDEX($C$5:$C$28,IF(ROW()-4=1,$F$2,ROW()-4-1))) -> 10.8 | I12: =IF($D12=0,0,B12*F12-E12*C12) -> 442.1376 | J12: =IF($D12=0,0,SQRT((E12-B12)^2+(F12-C12)^2)) -> 10.86319 | K12: =IF($D12=0,0,(C12^2+C12*F12+F12^2)*I12) -> 148736.5 | L12: =IF($D12=0,0,(B12^2+B12*E12+E12^2)*I12) -> 2343844.8 | M12: =IF($D12=0,0,(B12*F12+2*B12*C12+2*E12*F12+E12*C12)*I12) -> 1131290 | N12: =IF($D12=0,0,(B12+E12)*I12) -> 37170.508 | O12: =IF($D12=0,0,(C12+F12)*I12) -> 8948.865 | P12: =IF($D12=0,0,(G12-B12)*(E12-B12)+(H12-C12)*(F12-C12)) -> 44.2881 | Q12: =IF($D12=0,0,(G12-B12)*(F12-C12)-(H12-C12)*(E12-B12)) -> -204.4296 | R12: =IF($D12=0,"",IFERROR(MOD(DEGREES(ATAN2(P12,-$F$3*Q12)),360),"")) -> 77.77621 | S12: =IF($D12="","",IF($D12=0,"",180-R12)) -> 102.22379 | T12: =IF($D12=0,"",IF(R12>180,"入隅(凹)","出隅(凸)")) -> 出隅(凸) | V12: 6 | W12: -0.71 | X12: 10.18 | Y12: =ROUND(W12*$Y$5,2) -> -0.78 | Z12: =ROUND(X12*$Y$5,2) -> 11.2 | AD12: =INDEX($B$5:$B$28,IF(ROW()-4<=$F$2,ROW()-4,1)) -> 41.45 | AE12: =INDEX($C$5:$C$28,IF(ROW()-4<=$F$2,ROW()-4,1)) -> 4.72
A13: 9 | B13: 42.62 | C13: 15.52 | D13: =IF(ROW()-4<=$F$2,1,0) -> 1 | E13: =IF($D13=0,0,INDEX($B$5:$B$28,IF(ROW()-4=$F$2,1,ROW()-4+1))) -> 53.23 | F13: =IF($D13=0,0,INDEX($C$5:$C$28,IF(ROW()-4=$F$2,1,ROW()-4+1))) -> 13.35 | G13: =IF($D13=0,0,INDEX($B$5:$B$28,IF(ROW()-4=1,$F$2,ROW()-4-1))) -> 41.45 | H13: =IF($D13=0,0,INDEX($C$5:$C$28,IF(ROW()-4=1,$F$2,ROW()-4-1))) -> 4.72 | I13: =IF($D13=0,0,B13*F13-E13*C13) -> -257.1526 | J13: =IF($D13=0,0,SQRT((E13-B13)^2+(F13-C13)^2)) -> 10.829635 | K13: =IF($D13=0,0,(C13^2+C13*F13+F13^2)*I13) -> -161050.79 | L13: =IF($D13=0,0,(B13^2+B13*E13+E13^2)*I13) -> -1779125.7 | M13: =IF($D13=0,0,(B13*F13+2*B13*C13+2*E13*F13+E13*C13)*I13) -> -1064424.7 | N13: =IF($D13=0,0,(B13+E13)*I13) -> -24648.077 | O13: =IF($D13=0,0,(C13+F13)*I13) -> -7423.9956 | P13: =IF($D13=0,0,(G13-B13)*(E13-B13)+(H13-C13)*(F13-C13)) -> 11.0223 | Q13: =IF($D13=0,0,(G13-B13)*(F13-C13)-(H13-C13)*(E13-B13)) -> 117.1269 | R13: =IF($D13=0,"",IFERROR(MOD(DEGREES(ATAN2(P13,-$F$3*Q13)),360),"")) -> 275.37602 | S13: =IF($D13="","",IF($D13=0,"",180-R13)) -> -95.376023 | T13: =IF($D13=0,"",IF(R13>180,"入隅(凹)","出隅(凸)")) -> 入隅(凹) | V13: 7 | W13: 21.07 | X13: 9.82 | Y13: =ROUND(W13*$Y$5,2) -> 23.18 | Z13: =ROUND(X13*$Y$5,2) -> 10.8 | AD13: =INDEX($B$5:$B$28,IF(ROW()-4<=$F$2,ROW()-4,1)) -> 42.62 | AE13: =INDEX($C$5:$C$28,IF(ROW()-4<=$F$2,ROW()-4,1)) -> 15.52
A14: 10 | B14: 53.23 | C14: 13.35 | D14: =IF(ROW()-4<=$F$2,1,0) -> 1 | E14: =IF($D14=0,0,INDEX($B$5:$B$28,IF(ROW()-4=$F$2,1,ROW()-4+1))) -> 55 | F14: =IF($D14=0,0,INDEX($C$5:$C$28,IF(ROW()-4=$F$2,1,ROW()-4+1))) -> 15.13 | G14: =IF($D14=0,0,INDEX($B$5:$B$28,IF(ROW()-4=1,$F$2,ROW()-4-1))) -> 42.62 | H14: =IF($D14=0,0,INDEX($C$5:$C$28,IF(ROW()-4=1,$F$2,ROW()-4-1))) -> 15.52 | I14: =IF($D14=0,0,B14*F14-E14*C14) -> 71.1199 | J14: =IF($D14=0,0,SQRT((E14-B14)^2+(F14-C14)^2)) -> 2.510239 | K14: =IF($D14=0,0,(C14^2+C14*F14+F14^2)*I14) -> 43320.902 | L14: =IF($D14=0,0,(B14^2+B14*E14+E14^2)*I14) -> 624865.34 | M14: =IF($D14=0,0,(B14*F14+2*B14*C14+2*E14*F14+E14*C14)*I14) -> 328940.98 | N14: =IF($D14=0,0,(B14+E14)*I14) -> 7697.3068 | O14: =IF($D14=0,0,(C14+F14)*I14) -> 2025.4948 | P14: =IF($D14=0,0,(G14-B14)*(E14-B14)+(H14-C14)*(F14-C14)) -> -14.9171 | Q14: =IF($D14=0,0,(G14-B14)*(F14-C14)-(H14-C14)*(E14-B14)) -> -22.7267 | R14: =IF($D14=0,"",IFERROR(MOD(DEGREES(ATAN2(P14,-$F$3*Q14)),360),"")) -> 123.27965 | S14: =IF($D14="","",IF($D14=0,"",180-R14)) -> 56.720349 | T14: =IF($D14=0,"",IF(R14>180,"入隅(凹)","出隅(凸)")) -> 出隅(凸) | V14: 8 | W14: 37.68 | X14: 4.29 | Y14: =ROUND(W14*$Y$5,2) -> 41.45 | Z14: =ROUND(X14*$Y$5,2) -> 4.72 | AD14: =INDEX($B$5:$B$28,IF(ROW()-4<=$F$2,ROW()-4,1)) -> 53.23 | AE14: =INDEX($C$5:$C$28,IF(ROW()-4<=$F$2,ROW()-4,1)) -> 13.35
A15: 11 | B15: 55 | C15: 15.13 | D15: =IF(ROW()-4<=$F$2,1,0) -> 1 | E15: =IF($D15=0,0,INDEX($B$5:$B$28,IF(ROW()-4=$F$2,1,ROW()-4+1))) -> 53.23 | F15: =IF($D15=0,0,INDEX($C$5:$C$28,IF(ROW()-4=$F$2,1,ROW()-4+1))) -> 30.05 | G15: =IF($D15=0,0,INDEX($B$5:$B$28,IF(ROW()-4=1,$F$2,ROW()-4-1))) -> 53.23 | H15: =IF($D15=0,0,INDEX($C$5:$C$28,IF(ROW()-4=1,$F$2,ROW()-4-1))) -> 13.35 | I15: =IF($D15=0,0,B15*F15-E15*C15) -> 847.3801 | J15: =IF($D15=0,0,SQRT((E15-B15)^2+(F15-C15)^2)) -> 15.024623 | K15: =IF($D15=0,0,(C15^2+C15*F15+F15^2)*I15) -> 1344432.8 | L15: =IF($D15=0,0,(B15^2+B15*E15+E15^2)*I15) -> 7445151.8 | M15: =IF($D15=0,0,(B15*F15+2*B15*C15+2*E15*F15+E15*C15)*I15) -> 6204129.8 | N15: =IF($D15=0,0,(B15+E15)*I15) -> 91711.948 | O15: =IF($D15=0,0,(C15+F15)*I15) -> 38284.633 | P15: =IF($D15=0,0,(G15-B15)*(E15-B15)+(H15-C15)*(F15-C15)) -> -23.4247 | Q15: =IF($D15=0,0,(G15-B15)*(F15-C15)-(H15-C15)*(E15-B15)) -> -29.559 | R15: =IF($D15=0,"",IFERROR(MOD(DEGREES(ATAN2(P15,-$F$3*Q15)),360),"")) -> 128.39586 | S15: =IF($D15="","",IF($D15=0,"",180-R15)) -> 51.604137 | T15: =IF($D15=0,"",IF(R15>180,"入隅(凹)","出隅(凸)")) -> 出隅(凸) | V15: 9 | W15: 38.75 | X15: 14.11 | Y15: =ROUND(W15*$Y$5,2) -> 42.63 | Z15: =ROUND(X15*$Y$5,2) -> 15.52 | AD15: =INDEX($B$5:$B$28,IF(ROW()-4<=$F$2,ROW()-4,1)) -> 55 | AE15: =INDEX($C$5:$C$28,IF(ROW()-4<=$F$2,ROW()-4,1)) -> 15.13
A16: 12 | B16: 53.23 | C16: 30.05 | D16: =IF(ROW()-4<=$F$2,1,0) -> 1 | E16: =IF($D16=0,0,INDEX($B$5:$B$28,IF(ROW()-4=$F$2,1,ROW()-4+1))) -> 41.45 | F16: =IF($D16=0,0,INDEX($C$5:$C$28,IF(ROW()-4=$F$2,1,ROW()-4+1))) -> 30.45 | G16: =IF($D16=0,0,INDEX($B$5:$B$28,IF(ROW()-4=1,$F$2,ROW()-4-1))) -> 55 | H16: =IF($D16=0,0,INDEX($C$5:$C$28,IF(ROW()-4=1,$F$2,ROW()-4-1))) -> 15.13 | I16: =IF($D16=0,0,B16*F16-E16*C16) -> 375.281 | J16: =IF($D16=0,0,SQRT((E16-B16)^2+(F16-C16)^2)) -> 11.786789 | K16: =IF($D16=0,0,(C16^2+C16*F16+F16^2)*I16) -> 1030231.7 | L16: =IF($D16=0,0,(B16^2+B16*E16+E16^2)*I16) -> 2536118.6 | M16: =IF($D16=0,0,(B16*F16+2*B16*C16+2*E16*F16+E16*C16)*I16) -> 3223609 | N16: =IF($D16=0,0,(B16+E16)*I16) -> 35531.605 | O16: =IF($D16=0,0,(C16+F16)*I16) -> 22704.5 | P16: =IF($D16=0,0,(G16-B16)*(E16-B16)+(H16-C16)*(F16-C16)) -> -26.8186 | Q16: =IF($D16=0,0,(G16-B16)*(F16-C16)-(H16-C16)*(E16-B16)) -> -175.0496 | R16: =IF($D16=0,"",IFERROR(MOD(DEGREES(ATAN2(P16,-$F$3*Q16)),360),"")) -> 98.710313 | S16: =IF($D16="","",IF($D16=0,"",180-R16)) -> 81.289687 | T16: =IF($D16=0,"",IF(R16>180,"入隅(凹)","出隅(凸)")) -> 出隅(凸) | V16: 10 | W16: 48.39 | X16: 12.14 | Y16: =ROUND(W16*$Y$5,2) -> 53.23 | Z16: =ROUND(X16*$Y$5,2) -> 13.35 | AD16: =INDEX($B$5:$B$28,IF(ROW()-4<=$F$2,ROW()-4,1)) -> 53.23 | AE16: =INDEX($C$5:$C$28,IF(ROW()-4<=$F$2,ROW()-4,1)) -> 30.05
A17: 13 | B17: 41.45 | C17: 30.45 | D17: =IF(ROW()-4<=$F$2,1,0) -> 1 | E17: =IF($D17=0,0,INDEX($B$5:$B$28,IF(ROW()-4=$F$2,1,ROW()-4+1))) -> 39.48 | F17: =IF($D17=0,0,INDEX($C$5:$C$28,IF(ROW()-4=$F$2,1,ROW()-4+1))) -> 39.48 | G17: =IF($D17=0,0,INDEX($B$5:$B$28,IF(ROW()-4=1,$F$2,ROW()-4-1))) -> 53.23 | H17: =IF($D17=0,0,INDEX($C$5:$C$28,IF(ROW()-4=1,$F$2,ROW()-4-1))) -> 30.05 | I17: =IF($D17=0,0,B17*F17-E17*C17) -> 434.28 | J17: =IF($D17=0,0,SQRT((E17-B17)^2+(F17-C17)^2)) -> 9.2423915 | K17: =IF($D17=0,0,(C17^2+C17*F17+F17^2)*I17) -> 1601641.5 | L17: =IF($D17=0,0,(B17^2+B17*E17+E17^2)*I17) -> 2133712.7 | M17: =IF($D17=0,0,(B17*F17+2*B17*C17+2*E17*F17+E17*C17)*I17) -> 3682806.4 | N17: =IF($D17=0,0,(B17+E17)*I17) -> 35146.28 | O17: =IF($D17=0,0,(C17+F17)*I17) -> 30369.2 | P17: =IF($D17=0,0,(G17-B17)*(E17-B17)+(H17-C17)*(F17-C17)) -> -26.8186 | Q17: =IF($D17=0,0,(G17-B17)*(F17-C17)-(H17-C17)*(E17-B17)) -> 105.5854 | R17: =IF($D17=0,"",IFERROR(MOD(DEGREES(ATAN2(P17,-$F$3*Q17)),360),"")) -> 255.74831 | S17: =IF($D17="","",IF($D17=0,"",180-R17)) -> -75.748305 | T17: =IF($D17=0,"",IF(R17>180,"入隅(凹)","出隅(凸)")) -> 入隅(凹) | V17: 11 | W17: 50 | X17: 13.75 | Y17: =ROUND(W17*$Y$5,2) -> 55 | Z17: =ROUND(X17*$Y$5,2) -> 15.13 | AD17: =INDEX($B$5:$B$28,IF(ROW()-4<=$F$2,ROW()-4,1)) -> 41.45 | AE17: =INDEX($C$5:$C$28,IF(ROW()-4<=$F$2,ROW()-4,1)) -> 30.45
A18: 14 | B18: 39.48 | C18: 39.48 | D18: =IF(ROW()-4<=$F$2,1,0) -> 1 | E18: =IF($D18=0,0,INDEX($B$5:$B$28,IF(ROW()-4=$F$2,1,ROW()-4+1))) -> 23.18 | F18: =IF($D18=0,0,INDEX($C$5:$C$28,IF(ROW()-4=$F$2,1,ROW()-4+1))) -> 51.07 | G18: =IF($D18=0,0,INDEX($B$5:$B$28,IF(ROW()-4=1,$F$2,ROW()-4-1))) -> 41.45 | H18: =IF($D18=0,0,INDEX($C$5:$C$28,IF(ROW()-4=1,$F$2,ROW()-4-1))) -> 30.45 | I18: =IF($D18=0,0,B18*F18-E18*C18) -> 1101.0972 | J18: =IF($D18=0,0,SQRT((E18-B18)^2+(F18-C18)^2)) -> 20.000452 | K18: =IF($D18=0,0,(C18^2+C18*F18+F18^2)*I18) -> 6808148.8 | L18: =IF($D18=0,0,(B18^2+B18*E18+E18^2)*I18) -> 3315545.9 | M18: =IF($D18=0,0,(B18*F18+2*B18*C18+2*E18*F18+E18*C18)*I18) -> 9267204 | N18: =IF($D18=0,0,(B18+E18)*I18) -> 68994.751 | O18: =IF($D18=0,0,(C18+F18)*I18) -> 99704.351 | P18: =IF($D18=0,0,(G18-B18)*(E18-B18)+(H18-C18)*(F18-C18)) -> -136.7687 | Q18: =IF($D18=0,0,(G18-B18)*(F18-C18)-(H18-C18)*(E18-B18)) -> -124.3567 | R18: =IF($D18=0,"",IFERROR(MOD(DEGREES(ATAN2(P18,-$F$3*Q18)),360),"")) -> 137.72138 | S18: =IF($D18="","",IF($D18=0,"",180-R18)) -> 42.278624 | T18: =IF($D18=0,"",IF(R18>180,"入隅(凹)","出隅(凸)")) -> 出隅(凸) | V18: 12 | W18: 48.39 | X18: 27.32 | Y18: =ROUND(W18*$Y$5,2) -> 53.23 | Z18: =ROUND(X18*$Y$5,2) -> 30.05 | AD18: =INDEX($B$5:$B$28,IF(ROW()-4<=$F$2,ROW()-4,1)) -> 39.48 | AE18: =INDEX($C$5:$C$28,IF(ROW()-4<=$F$2,ROW()-4,1)) -> 39.48
A19: 15 | B19: 23.18 | C19: 51.07 | D19: =IF(ROW()-4<=$F$2,1,0) -> 1 | E19: =IF($D19=0,0,INDEX($B$5:$B$28,IF(ROW()-4=$F$2,1,ROW()-4+1))) -> 9.43 | F19: =IF($D19=0,0,INDEX($C$5:$C$28,IF(ROW()-4=$F$2,1,ROW()-4+1))) -> 55 | G19: =IF($D19=0,0,INDEX($B$5:$B$28,IF(ROW()-4=1,$F$2,ROW()-4-1))) -> 39.48 | H19: =IF($D19=0,0,INDEX($C$5:$C$28,IF(ROW()-4=1,$F$2,ROW()-4-1))) -> 39.48 | I19: =IF($D19=0,0,B19*F19-E19*C19) -> 793.3099 | J19: =IF($D19=0,0,SQRT((E19-B19)^2+(F19-C19)^2)) -> 14.300608 | K19: =IF($D19=0,0,(C19^2+C19*F19+F19^2)*I19) -> 6697118.1 | L19: =IF($D19=0,0,(B19^2+B19*E19+E19^2)*I19) -> 670207.8 | M19: =IF($D19=0,0,(B19*F19+2*B19*C19+2*E19*F19+E19*C19)*I19) -> 4094586 | N19: =IF($D19=0,0,(B19+E19)*I19) -> 25869.836 | O19: =IF($D19=0,0,(C19+F19)*I19) -> 84146.381 | P19: =IF($D19=0,0,(G19-B19)*(E19-B19)+(H19-C19)*(F19-C19)) -> -269.6737 | Q19: =IF($D19=0,0,(G19-B19)*(F19-C19)-(H19-C19)*(E19-B19)) -> -95.3035 | R19: =IF($D19=0,"",IFERROR(MOD(DEGREES(ATAN2(P19,-$F$3*Q19)),360),"")) -> 160.53644 | S19: =IF($D19="","",IF($D19=0,"",180-R19)) -> 19.463562 | T19: =IF($D19=0,"",IF(R19>180,"入隅(凹)","出隅(凸)")) -> 出隅(凸) | V19: 13 | W19: 37.68 | X19: 27.68 | Y19: =ROUND(W19*$Y$5,2) -> 41.45 | Z19: =ROUND(X19*$Y$5,2) -> 30.45 | AD19: =INDEX($B$5:$B$28,IF(ROW()-4<=$F$2,ROW()-4,1)) -> 23.18 | AE19: =INDEX($C$5:$C$28,IF(ROW()-4<=$F$2,ROW()-4,1)) -> 51.07
A20: 16 | B20: 9.43 | C20: 55 | D20: =IF(ROW()-4<=$F$2,1,0) -> 1 | E20: =IF($D20=0,0,INDEX($B$5:$B$28,IF(ROW()-4=$F$2,1,ROW()-4+1))) -> -8.65 | F20: =IF($D20=0,0,INDEX($C$5:$C$28,IF(ROW()-4=$F$2,1,ROW()-4+1))) -> 53.63 | G20: =IF($D20=0,0,INDEX($B$5:$B$28,IF(ROW()-4=1,$F$2,ROW()-4-1))) -> 23.18 | H20: =IF($D20=0,0,INDEX($C$5:$C$28,IF(ROW()-4=1,$F$2,ROW()-4-1))) -> 51.07 | I20: =IF($D20=0,0,B20*F20-E20*C20) -> 981.4809 | J20: =IF($D20=0,0,SQRT((E20-B20)^2+(F20-C20)^2)) -> 18.131831 | K20: =IF($D20=0,0,(C20^2+C20*F20+F20^2)*I20) -> 8686917.6 | L20: =IF($D20=0,0,(B20^2+B20*E20+E20^2)*I20) -> 80656.039 | M20: =IF($D20=0,0,(B20*F20+2*B20*C20+2*E20*F20+E20*C20)*I20) -> 136898.82 | N20: =IF($D20=0,0,(B20+E20)*I20) -> 765.5551 | O20: =IF($D20=0,0,(C20+F20)*I20) -> 106618.27 | P20: =IF($D20=0,0,(G20-B20)*(E20-B20)+(H20-C20)*(F20-C20)) -> -243.2159 | Q20: =IF($D20=0,0,(G20-B20)*(F20-C20)-(H20-C20)*(E20-B20)) -> -89.8919 | R20: =IF($D20=0,"",IFERROR(MOD(DEGREES(ATAN2(P20,-$F$3*Q20)),360),"")) -> 159.71583 | S20: =IF($D20="","",IF($D20=0,"",180-R20)) -> 20.284168 | T20: =IF($D20=0,"",IF(R20>180,"入隅(凹)","出隅(凸)")) -> 出隅(凸) | V20: 14 | W20: 35.89 | X20: 35.89 | Y20: =ROUND(W20*$Y$5,2) -> 39.48 | Z20: =ROUND(X20*$Y$5,2) -> 39.48 | AD20: =INDEX($B$5:$B$28,IF(ROW()-4<=$F$2,ROW()-4,1)) -> 9.43 | AE20: =INDEX($C$5:$C$28,IF(ROW()-4<=$F$2,ROW()-4,1)) -> 55
... A26: 22 | B26: -54.8 | C26: 26.72 | D26: =IF(ROW()-4<=$F$2,1,0) -> 1 | E26: =IF($D26=0,0,INDEX($B$5:$B$28,IF(ROW()-4=$F$2,1,ROW()-4+1))) -> -55 | F26: =IF($D26=0,0,INDEX($C$5:$C$28,IF(ROW()-4=$F$2,1,ROW()-4+1))) -> 16.7 | G26: =IF($D26=0,0,INDEX($B$5:$B$28,IF(ROW()-4=1,$F$2,ROW()-4-1))) -> -42.43 | H26: =IF($D26=0,0,INDEX($C$5:$C$28,IF(ROW()-4=1,$F$2,ROW()-4-1))) -> 26.52 | I26: =IF($D26=0,0,B26*F26-E26*C26) -> 554.44 | J26: =IF($D26=0,0,SQRT((E26-B26)^2+(F26-C26)^2)) -> 10.021996 | K26: =IF($D26=0,0,(C26^2+C26*F26+F26^2)*I26) -> 797879.3 | L26: =IF($D26=0,0,(B26^2+B26*E26+E26^2)*I26) -> 5013268.7 | M26: =IF($D26=0,0,(B26*F26+2*B26*C26+2*E26*F26+E26*C26)*I26) -> -3964396.8 | N26: =IF($D26=0,0,(B26+E26)*I26) -> -60877.512 | O26: =IF($D26=0,0,(C26+F26)*I26) -> 24073.785 | P26: =IF($D26=0,0,(G26-B26)*(E26-B26)+(H26-C26)*(F26-C26)) -> -0.47 | Q26: =IF($D26=0,0,(G26-B26)*(F26-C26)-(H26-C26)*(E26-B26)) -> -123.9874 | R26: =IF($D26=0,"",IFERROR(MOD(DEGREES(ATAN2(P26,-$F$3*Q26)),360),"")) -> 90.217191 | S26: =IF($D26="","",IF($D26=0,"",180-R26)) -> 89.782809 | T26: =IF($D26=0,"",IF(R26>180,"入隅(凹)","出隅(凸)")) -> 出隅(凸) | V26: 20 | W26: -38.75 | X26: 30.71 | Y26: =ROUND(W26*$Y$5,2) -> -42.63 | Z26: =ROUND(X26*$Y$5,2) -> 33.78 | AD26: =INDEX($B$5:$B$28,IF(ROW()-4<=$F$2,ROW()-4,1)) -> -54.8 | AE26: =INDEX($C$5:$C$28,IF(ROW()-4<=$F$2,ROW()-4,1)) -> 26.72
A27: 23 | D27: =IF(ROW()-4<=$F$2,1,0) -> 0 | E27: =IF($D27=0,0,INDEX($B$5:$B$28,IF(ROW()-4=$F$2,1,ROW()-4+1))) -> 0 | F27: =IF($D27=0,0,INDEX($C$5:$C$28,IF(ROW()-4=$F$2,1,ROW()-4+1))) -> 0 | G27: =IF($D27=0,0,INDEX($B$5:$B$28,IF(ROW()-4=1,$F$2,ROW()-4-1))) -> 0 | H27: =IF($D27=0,0,INDEX($C$5:$C$28,IF(ROW()-4=1,$F$2,ROW()-4-1))) -> 0 | I27: =IF($D27=0,0,B27*F27-E27*C27) -> 0 | J27: =IF($D27=0,0,SQRT((E27-B27)^2+(F27-C27)^2)) -> 0 | K27: =IF($D27=0,0,(C27^2+C27*F27+F27^2)*I27) -> 0 | L27: =IF($D27=0,0,(B27^2+B27*E27+E27^2)*I27) -> 0 | M27: =IF($D27=0,0,(B27*F27+2*B27*C27+2*E27*F27+E27*C27)*I27) -> 0 | N27: =IF($D27=0,0,(B27+E27)*I27) -> 0 | O27: =IF($D27=0,0,(C27+F27)*I27) -> 0 | P27: =IF($D27=0,0,(G27-B27)*(E27-B27)+(H27-C27)*(F27-C27)) -> 0 | Q27: =IF($D27=0,0,(G27-B27)*(F27-C27)-(H27-C27)*(E27-B27)) -> 0 | R27: =IF($D27=0,"",IFERROR(MOD(DEGREES(ATAN2(P27,-$F$3*Q27)),360),"")) | S27: =IF($D27="","",IF($D27=0,"",180-R27)) | T27: =IF($D27=0,"",IF(R27>180,"入隅(凹)","出隅(凸)")) | V27: 21 | W27: -38.57 | X27: 24.11 | Y27: =ROUND(W27*$Y$5,2) -> -42.43 | Z27: =ROUND(X27*$Y$5,2) -> 26.52 | AD27: =INDEX($B$5:$B$28,IF(ROW()-4<=$F$2,ROW()-4,1)) -> -55 | AE27: =INDEX($C$5:$C$28,IF(ROW()-4<=$F$2,ROW()-4,1)) -> 16.7
A28: 24 | D28: =IF(ROW()-4<=$F$2,1,0) -> 0 | E28: =IF($D28=0,0,INDEX($B$5:$B$28,IF(ROW()-4=$F$2,1,ROW()-4+1))) -> 0 | F28: =IF($D28=0,0,INDEX($C$5:$C$28,IF(ROW()-4=$F$2,1,ROW()-4+1))) -> 0 | G28: =IF($D28=0,0,INDEX($B$5:$B$28,IF(ROW()-4=1,$F$2,ROW()-4-1))) -> 0 | H28: =IF($D28=0,0,INDEX($C$5:$C$28,IF(ROW()-4=1,$F$2,ROW()-4-1))) -> 0 | I28: =IF($D28=0,0,B28*F28-E28*C28) -> 0 | J28: =IF($D28=0,0,SQRT((E28-B28)^2+(F28-C28)^2)) -> 0 | K28: =IF($D28=0,0,(C28^2+C28*F28+F28^2)*I28) -> 0 | L28: =IF($D28=0,0,(B28^2+B28*E28+E28^2)*I28) -> 0 | M28: =IF($D28=0,0,(B28*F28+2*B28*C28+2*E28*F28+E28*C28)*I28) -> 0 | N28: =IF($D28=0,0,(B28+E28)*I28) -> 0 | O28: =IF($D28=0,0,(C28+F28)*I28) -> 0 | P28: =IF($D28=0,0,(G28-B28)*(E28-B28)+(H28-C28)*(F28-C28)) -> 0 | Q28: =IF($D28=0,0,(G28-B28)*(F28-C28)-(H28-C28)*(E28-B28)) -> 0 | R28: =IF($D28=0,"",IFERROR(MOD(DEGREES(ATAN2(P28,-$F$3*Q28)),360),"")) | S28: =IF($D28="","",IF($D28=0,"",180-R28)) | T28: =IF($D28=0,"",IF(R28>180,"入隅(凹)","出隅(凸)")) | V28: 22 | W28: -49.82 | X28: 24.29 | Y28: =ROUND(W28*$Y$5,2) -> -54.8 | Z28: =ROUND(X28*$Y$5,2) -> 26.72 | AD28: =INDEX($B$5:$B$28,IF(ROW()-4<=$F$2,ROW()-4,1)) -> -55 | AE28: =INDEX($C$5:$C$28,IF(ROW()-4<=$F$2,ROW()-4,1)) -> 16.7
AD29: =INDEX($B$5:$B$28,IF(ROW()-4<=$F$2,ROW()-4,1)) -> -55 | AE29: =INDEX($C$5:$C$28,IF(ROW()-4<=$F$2,ROW()-4,1)) -> 16.7
A30: ■ 形状の計算結果（外形のみ／穴を引く前） | V30: ■ 穴のプリセット（同じく全長100mm正規化）
A31: 符号付き面積 [mm²] | B31: =0.5*SUM($I$5:$I$28) -> 3775.89 | C31: 多角形の向き判定に使う（＋なら反時計回り） | V31: No | W31: cX_norm | X31: cY_norm | Y31: d_norm | Z31: → cX | AA31: → cY | AB31: → d
A32: 外形面積 A_gross [mm²] | B32: =ABS($B$31) -> 3775.89 | C32: シューレース公式 A=½|Σ(xᵢyᵢ₊₁−xᵢ₊₁yᵢ)| 🟢 | V32: 1 | W32: -17.21 | X32: 23.02 | Y32: 13.34 | Z32: =ROUND(W32*$Y$5,2) -> -18.93 | AA32: =ROUND(X32*$Y$5,2) -> 25.32 | AB32: =ROUND(Y32*$Y$5,2) -> 14.67
A33: 周長 [mm] | B33: =SUM($J$5:$J$28) -> 296.79407 | C33: 各辺の長さの合計 | V33: 2 | W33: 12.88 | X33: 26.23 | Y33: 10.66 | Z33: =ROUND(W33*$Y$5,2) -> 14.17 | AA33: =ROUND(X33*$Y$5,2) -> 28.85 | AB33: =ROUND(Y33*$Y$5,2) -> 11.73
A34: 重心 Cx_gross [mm] | B34: =IF($B$31=0,0,SUM($N$5:$N$28)/(6*$B$31)) -> -0.12129453 | C34: 図心のX座標 🟢
A35: 重心 Cy_gross [mm] | B35: =IF($B$31=0,0,SUM($O$5:$O$28)/(6*$B$31)) -> 28.298212 | C35: 図心のY座標 🟢 | V35: 使い方：Y4に実測全長を入れる → Y7:Z28 をコピーして B5:C28 に「値貼り付け」
A36: Ixx_gross（重心まわり）[mm⁴] | B36: =$F$3*SUM($K$5:$K$28)/12-$B$32*$B$35^2 -> 571531.3 | C36: X軸（長手軸）まわり。面内曲げに効く 🟢 | V36: 穴も Z32:AB33 をコピーして C55:E56 に貼る（列の順番が 中心X→中心Y→直径 で一致します）
A37: Iyy_gross（重心まわり）[mm⁴] | B37: =$F$3*SUM($L$5:$L$28)/12-$B$32*$B$34^2 -> 2647658.3 | C37: Y軸まわり 🟢 | V37: ※ トレースは当たり付け。全長・全高・穴径だけは必ずノギスで実測して上書きしてください 🔴
A38: Ixy（重心まわり）[mm⁴] | B38: =$F$3*SUM($M$5:$M$28)/24-$B$32*$B$34*$B$35 -> 51866.4 | C38: 相乗モーメント 🟢
A39: Imin [mm⁴] | B39: =($B$36+$B$37)/2-SQRT((($B$36-$B$37)/2)^2+$B$38^2) -> 570236.37 | C39: 主（しゅ）断面二次モーメント 最小 | V39: ▼ 入力した座標をそのまま描いたもの。パッドの形に見えなければ座標の順番か符号が間違っています（※縦横比はグラフの都合で正確ではありません）
A40: Imax [mm⁴] | B40: =($B$36+$B$37)/2+SQRT((($B$36-$B$37)/2)^2+$B$38^2) -> 2648953.3 | C40: 主断面二次モーメント 最大
A41: 主軸角 θp [°] | B41: =DEGREES(0.5*ATAN2($B$36-$B$37,-2*$B$38)) -> -88.56981 | C41: tan2θ=−2Ixy/(Ixx−Iyy) 🟢
A42: θp での I [mm⁴] | B42: =($B$36+$B$37)/2+($B$36-$B$37)/2*COS(2*RADIANS($B$41))-$B$38*SIN(2*RADIANS($B$41)) -> 2648953.3 | C42: 判定用の中間値
A43: 長手方向の角度 [°] | B43: =IF(ABS($B$42-$B$39)<ABS($B$42-$B$40),$B$41,$B$41+90) -> 1.4301902 | C43: 0°に近いほど X軸＝長手。大きくずれたら座標を回して入れ直す
A44: Xmin [mm] | B44: =MIN($B$5:$B$28) -> -55
A45: Xmax [mm] | B45: =MAX($B$5:$B$28) -> 55
...

Sheet 断面
A1: ② 断面（積層）— シム＋裏板（＋任意で接着/固定層）を1本の「はり」に合成 ※摩擦材は含みません
A2: 変換断面法（へんかんだんめんほう／transformed section）で 曲げ剛性EI・単位長さ質量ρA・中立軸（ちゅうりつじく）を求める 🟢
A3: 幅 w [m]（＝形状の採用w：穴を引いた正味） | D3: =形状!$B$72/1000 -> 0.031807274 | E3: 形状シート B72 と連動
A4: 長さ L [m]（＝形状の採用L） | D4: =形状!$B$71/1000 -> 0.11 | E4: 形状シート B71 と連動
A5: 正味 投影面積 [m²]（穴を引いた値） | D5: =形状!$B$62/1000000 -> 0.0034988002 | E5: 質量の計算に使う
A6: 正味 Ixx [m⁴]（穴を引いた値） | D6: =形状!$B$73/1000000000000 -> 5.6674012e-07 | E6: 面内曲げ剛性に使う（形状Ixx版）
A7: 面内EI の計算方式（1＝形状Ixx版・推奨 / 0＝長方形近似） | D7: 1 | E7: 1 にすると、耳・爪・穴まで含めた実形状の断面二次モーメントを使います 🟢
A9: 層（下から順） | B9: 使用1/0 | C9: 材料名（材料DBと同じ文字） | D9: 厚さ t [mm] | E9: E [GPa] | F9: ρ [kg/m³] | G9: ν | H9: η | I9: t [m] | J9: 下端y [m] | K9: 中心y [m] | L9: E·A [N] | M9: E·A·y | N9: ρ·A [kg/m] | O9: EI項(面外) | P9: EI項(面内・長方形) | Q9: EI項(面内・形状Ixx) | R9: E·A(軸) | S9: η·EI項
A10: 1: シム | B10: 0 | C10: シム鋼板 SPCC | D10: 0.8 | E10: =IFERROR(INDEX(材料DB!$B$5:$B$45,MATCH($C10,材料DB!$A$5:$A$45,0)),0) -> 205 | F10: =IFERROR(INDEX(材料DB!$C$5:$C$45,MATCH($C10,材料DB!$A$5:$A$45,0)),0) -> 7850 | G10: =IFERROR(INDEX(材料DB!$D$5:$D$45,MATCH($C10,材料DB!$A$5:$A$45,0)),0) -> 0.3 | H10: =IFERROR(INDEX(材料DB!$E$5:$E$45,MATCH($C10,材料DB!$A$5:$A$45,0)),0) -> 0.0002 | I10: =IF($B10=1,$D10/1000,0) -> 0 | J10: =0 -> 0 | K10: =J10+I10/2 -> 0 | L10: =E10*1000000000*$D$3*I10 -> 0 | M10: =L10*K10 -> 0 | N10: =F10*$D$3*I10 -> 0 | O10: =E10*1000000000*$D$3*(I10^3/12+I10*(K10-$D$16)^2) -> 0 | P10: =E10*1000000000*(I10*$D$3^3/12) -> 0 | Q10: =IF($D$4=0,0,E10*1000000000*I10*$D$6/$D$4) -> 0 | R10: =L10 -> 0 | S10: =H10*O10 -> 0
A11: 2: 裏板 | B11: 1 | C11: 鋼 SPCC(裏板) | D11: 5 | E11: =IFERROR(INDEX(材料DB!$B$5:$B$45,MATCH($C11,材料DB!$A$5:$A$45,0)),0) -> 205 | F11: =IFERROR(INDEX(材料DB!$C$5:$C$45,MATCH($C11,材料DB!$A$5:$A$45,0)),0) -> 7850 | G11: =IFERROR(INDEX(材料DB!$D$5:$D$45,MATCH($C11,材料DB!$A$5:$A$45,0)),0) -> 0.3 | H11: =IFERROR(INDEX(材料DB!$E$5:$E$45,MATCH($C11,材料DB!$A$5:$A$45,0)),0) -> 0.0002 | I11: =IF($B11=1,$D11/1000,0) -> 0.005 | J11: =J10+I10 -> 0 | K11: =J11+I11/2 -> 0.0025 | L11: =E11*1000000000*$D$3*I11 -> 32602456 | M11: =L11*K11 -> 81506.14 | N11: =F11*$D$3*I11 -> 1.2484355 | O11: =E11*1000000000*$D$3*(I11^3/12+I11*(K11-$D$16)^2) -> 67.921783 | P11: =E11*1000000000*(I11*$D$3^3/12) -> 2748.6661 | Q11: =IF($D$4=0,0,E11*1000000000*I11*$D$6/$D$4) -> 5280.9875 | R11: =L11 -> 32602456 | S11: =H11*O11 -> 0.013584357
A12: 3: 接着/固定(任意) | B12: 0 | C12: 接着層(汎用/シム固定用) | D12: 0.2 | E12: =IFERROR(INDEX(材料DB!$B$5:$B$45,MATCH($C12,材料DB!$A$5:$A$45,0)),0) -> 3 | F12: =IFERROR(INDEX(材料DB!$C$5:$C$45,MATCH($C12,材料DB!$A$5:$A$45,0)),0) -> 1300 | G12: =IFERROR(INDEX(材料DB!$D$5:$D$45,MATCH($C12,材料DB!$A$5:$A$45,0)),0) -> 0.35 | H12: =IFERROR(INDEX(材料DB!$E$5:$E$45,MATCH($C12,材料DB!$A$5:$A$45,0)),0) -> 0.08 | I12: =IF($B12=1,$D12/1000,0) -> 0 | J12: =J11+I11 -> 0.005 | K12: =J12+I12/2 -> 0.005 | L12: =E12*1000000000*$D$3*I12 -> 0 | M12: =L12*K12 -> 0 | N12: =F12*$D$3*I12 -> 0 | O12: =E12*1000000000*$D$3*(I12^3/12+I12*(K12-$D$16)^2) -> 0 | P12: =E12*1000000000*(I12*$D$3^3/12) -> 0 | Q12: =IF($D$4=0,0,E12*1000000000*I12*$D$6/$D$4) -> 0 | R12: =L12 -> 0 | S12: =H12*O12 -> 0
A14: ■ 合成結果
A15: ΣE·A [N] | D15: =SUM($L$10:$L$12) -> 32602456 | E15: 各層の 弾性率×断面積 の合計
A16: 中立軸 ȳ [m] | D16: =IF($D$15=0,0,SUM($M$10:$M$12)/$D$15) -> 0.0025 | E16: 曲げても伸び縮みしない高さ。下端からの距離 🟢
A17: EI 面外曲げ [N·m²] | D17: =SUM($O$10:$O$12) -> 67.921783 | E17: 厚み方向にたわむ剛性。主モードはこれ 🟢
A18: EI 面内（長方形近似）[N·m²] | D18: =SUM($P$10:$P$12) -> 2748.6661 | E18: w³/12 で近似したもの（参考）
A19: EI 面内（形状Ixx版）[N·m²] | D19: =SUM($Q$10:$Q$12) -> 5280.9875 | E19: 耳・爪・穴を含む実形状から。こちらが正確 🟢
A20: ★採用 EI 面内 [N·m²] | D20: =IF($D$7=1,$D$19,$D$18) -> 5280.9875 | E20: D7 のスイッチで切替
A21: EA 軸 [N] | D21: =SUM($R$10:$R$12) -> 32602456 | E21: 伸び縮みの剛性 🟢
A22: ρA 単位長さ質量 [kg/m] | D22: =SUM($N$10:$N$12) -> 1.2484355 | E22: 1mあたりの重さ 🟢
A23: 総厚 h [m] | D23: =SUM($I$10:$I$12) -> 0.005 | E23: 使用する層の厚さ合計
A24: 等価ヤング率 E_eq(面外) [GPa] | D24: =IF($D$23=0,0,$D$17/($D$3*$D$23^3/12)/1000000000) -> 205 | E24: 1枚板とみなしたときの見かけのE
A25: 等価密度 ρ_eq [kg/m³] | D25: =IF($D$23=0,0,$D$22/($D$3*$D$23)) -> 7850 | E25: 1枚板とみなしたときの見かけのρ
A26: 等価ポアソン比 ν_eq | D26: =IF($D$15=0,0.3,SUMPRODUCT($G$10:$G$12,$L$10:$L$12)/$D$15) -> 0.3 | E26: E·Aで重み付け平均
A27: 等価せん断弾性率 G_eq [Pa] | D27: =$D$24*1000000000/(2*(1+$D$26)) -> 7.8846154e+10 | E27: G＝E/(2(1+ν)) 🟢
A28: ねじり係数 β | D28: =IF($D$3<=0,0,(1/3)*(1-0.63*($D$23/$D$3)+0.052*($D$23/$D$3)^5)) -> 0.30032368 | E28: 長方形断面のねじり定数 J=β·w·h³ 🟢 Roark近似
A29: GJ ねじり剛性 [N·m²] | D29: =$D$27*$D$28*$D$3*$D$23^3 -> 94.147015 | E29: ねじりにくさ 🟡（積層は近似）
A30: ρIp 単位長さ極慣性 [kg·m] | D30: =$D$22*($D$3^2+$D$23^2)/12 -> 0.0001078547 | E30: ねじりの回りにくさ 🟡
A31: 合成損失係数 η_eq | D31: =IF($D$17=0,0,SUM($S$10:$S$12)/$D$17) -> 0.0002 | E31: EI重み付け平均（RKU法の簡易版）🟡
A32: 予測 質量 [g] | D32: =SUMPRODUCT($F$10:$F$12,$I$10:$I$12)*$D$5*1000 -> 137.32791 | E32: 厚さ・密度・正味面積から計算した値
A33: ★ 実測 質量 [g]（電子天秤） | E33: 0.1g まで測って入力。ここが最強のデバッグ手段です
A34: 質量の差 [%] | D34: =IF(OR($D$33="",$D$33=0),"",($D$33/$D$32-1)*100)
A35: 質量チェック 判定 | D35: =IF(NOT(ISNUMBER($D$34)),"← D33 に実測質量を入力",IF(ABS($D$34)<=3,"🟢 一致（厚さ・材質・形状OK）",IF(ABS($D$34)<=8,"🟡 やや不一致（厚さを再測定）","🔴 不一致：厚さ・材質・座標のどれかが違う"))) -> ← D33 に実測質量を入力
A37: ■ 中立軸の意味（ここが一番の勘どころ）
A38: 曲げると、上側は縮み・下側は伸びます。その境目で「伸びも縮みもしない面」が中立軸（ちゅうりつじく）です。
A39: このブックはシム（任意）＋裏板だけなので、シムをOFFにしていれば中立軸はちょうど裏板の真ん中に来ます。
A40: 摩擦材が無いぶん、剛性EIは下がりますが、質量ρAはもっと大きく下がります。f ∝ √(EI/ρA) なので、
A41: 結果として金属部だけの固有振動数は、摩擦材付きよりかなり高く出ます（体感で1.5〜2倍程度）。
A42: 裏板を 5.0mm → 6.0mm にすると EI は (6/5)³＝1.73倍、質量は1.2倍なので、周波数は約 √(1.73/1.2)＝1.2倍に上がります。
A44: ■ 面内EI の2つの計算方式のちがい（D7で切替）
...

Sheet 固有振動数
A1: ③ 固有振動数の予測（自由−自由：ピアノ線で吊った状態）
A2: 4系統：①面外曲げ ②ねじり ③面内曲げ ④面内伸縮。せん断変形（Timoshenko）補正つき。単位は Hz
A3: 損失係数 η（空欄→断面シートの合成値） | E3: =IF($D$3="",断面!$D$31,$D$3) -> 0.0002 | F3: せん断補正 使う=1 / 使わない=0 | I3: 1 | J3: κ(長方形=5/6) | K3: =5/6 -> 0.83333333 | L3: スペクトル描画用 η の下限 | N3: 0.01
A4: 回転半径 r_out [m] = h/√12 | D4: =断面!$D$23/SQRT(12) -> 0.0014433757 | E4: r_in = w/√12 | F4: =断面!$D$3/SQRT(12) -> 0.0091819692 | G4: 1+E/(κG) | H4: =1+2*(1+断面!$D$26)/$K$3 -> 4.12
A5: # | B5: モード種別 | C5: n | D5: 係数 (βL) or n | E5: (βL)² | F5: f Euler [Hz] | G5: せん断補正係数 | H5: f 補正後 [Hz] | I5: ★採用 f [Hz] | J5: 波長 λ [mm] | K5: λ/断面寸法 | L5: 妥当性 | M5: 備考 | N5: J2521帯域 | O5: f [Hz] | P5: η | Q5: 振幅 A | R5: モード名
A6: 1 | B6: 面外曲げ | C6: 1 | D6: 4.730041 | E6: =D6^2 -> 22.373288 | F6: =IFERROR(E6/(2*PI()*断面!$D$4^2)*SQRT(断面!$D$17/断面!$D$22),0) -> 2170.6313 | G6: =IFERROR(1/SQRT(1+E6*($D$4/断面!$D$4)^2*$H$4),1) -> 0.9921578 | H6: =F6*G6 -> 2153.6087 | I6: =IF($I$3=1,H6,F6) -> 2153.6087 | J6: =IFERROR(2*PI()*断面!$D$4/D6*1000,0) -> 146.11932 | K6: =IFERROR(J6/(断面!$D$23*1000),0) -> 29.223864 | L6: =IF(K6>=6,"🟢 良",IF(K6>=3,"🟡 誤差±10%程度","🔴 参考値のみ")) -> 🟢 良 | M6: 板が反（そ）るように曲がる。鳴きの主役 🟢 | N6: =IF(AND(I6>=1250,I6<=16000),"○ 帯域内","− 帯域外") -> ○ 帯域内 | O6: =IF(I6<=0,1000000000,I6) -> 2153.6087 | P6: =MAX($E$3,$N$3) -> 0.01 | Q6: 1 | R6: =B6&" "&C6&"次" -> 面外曲げ 1次
A7: 2 | B7: 面外曲げ | C7: 2 | D7: 7.853205 | E7: =D7^2 -> 61.672829 | F7: =IFERROR(E7/(2*PI()*断面!$D$4^2)*SQRT(断面!$D$17/断面!$D$22),0) -> 5983.4286 | G7: =IFERROR(1/SQRT(1+E7*($D$4/断面!$D$4)^2*$H$4),1) -> 0.97881821 | H7: =F7*G7 -> 5856.6889 | I7: =IF($I$3=1,H7,F7) -> 5856.6889 | J7: =IFERROR(2*PI()*断面!$D$4/D7*1000,0) -> 88.008703 | K7: =IFERROR(J7/(断面!$D$23*1000),0) -> 17.601741 | L7: =IF(K7>=6,"🟢 良",IF(K7>=3,"🟡 誤差±10%程度","🔴 参考値のみ")) -> 🟢 良 | M7: 板が反（そ）るように曲がる。鳴きの主役 🟢 | N7: =IF(AND(I7>=1250,I7<=16000),"○ 帯域内","− 帯域外") -> ○ 帯域内 | O7: =IF(I7<=0,1000000000,I7) -> 5856.6889 | P7: =MAX($E$3,$N$3) -> 0.01 | Q7: 1 | R7: =B7&" "&C7&"次" -> 面外曲げ 2次
A8: 3 | B8: 面外曲げ | C8: 3 | D8: 10.995608 | E8: =D8^2 -> 120.9034 | F8: =IFERROR(E8/(2*PI()*断面!$D$4^2)*SQRT(断面!$D$17/断面!$D$22),0) -> 11729.912 | G8: =IFERROR(1/SQRT(1+E8*($D$4/断面!$D$4)^2*$H$4),1) -> 0.95969254 | H8: =F8*G8 -> 11257.109 | I8: =IF($I$3=1,H8,F8) -> 11257.109 | J8: =IFERROR(2*PI()*断面!$D$4/D8*1000,0) -> 62.85695 | K8: =IFERROR(J8/(断面!$D$23*1000),0) -> 12.57139 | L8: =IF(K8>=6,"🟢 良",IF(K8>=3,"🟡 誤差±10%程度","🔴 参考値のみ")) -> 🟢 良 | M8: 板が反（そ）るように曲がる。鳴きの主役 🟢 | N8: =IF(AND(I8>=1250,I8<=16000),"○ 帯域内","− 帯域外") -> ○ 帯域内 | O8: =IF(I8<=0,1000000000,I8) -> 11257.109 | P8: =MAX($E$3,$N$3) -> 0.01 | Q8: 1 | R8: =B8&" "&C8&"次" -> 面外曲げ 3次
A9: 4 | B9: 面外曲げ | C9: 4 | D9: 14.137165 | E9: =D9^2 -> 199.85943 | F9: =IFERROR(E9/(2*PI()*断面!$D$4^2)*SQRT(断面!$D$17/断面!$D$22),0) -> 19390.138 | G9: =IFERROR(1/SQRT(1+E9*($D$4/断面!$D$4)^2*$H$4),1) -> 0.93585811 | H9: =F9*G9 -> 18146.418 | I9: =IF($I$3=1,H9,F9) -> 18146.418 | J9: =IFERROR(2*PI()*断面!$D$4/D9*1000,0) -> 48.888896 | K9: =IFERROR(J9/(断面!$D$23*1000),0) -> 9.7777791 | L9: =IF(K9>=6,"🟢 良",IF(K9>=3,"🟡 誤差±10%程度","🔴 参考値のみ")) -> 🟢 良 | M9: 板が反（そ）るように曲がる。鳴きの主役 🟢 | N9: =IF(AND(I9>=1250,I9<=16000),"○ 帯域内","− 帯域外") -> − 帯域外 | O9: =IF(I9<=0,1000000000,I9) -> 18146.418 | P9: =MAX($E$3,$N$3) -> 0.01 | Q9: 1 | R9: =B9&" "&C9&"次" -> 面外曲げ 4次
A10: 5 | B10: 面外曲げ | C10: 5 | D10: 17.27876 | E10: =D10^2 -> 298.55555 | F10: =IFERROR(E10/(2*PI()*断面!$D$4^2)*SQRT(断面!$D$17/断面!$D$22),0) -> 28965.524 | G10: =IFERROR(1/SQRT(1+E10*($D$4/断面!$D$4)^2*$H$4),1) -> 0.908421 | H10: =F10*G10 -> 26312.89 | I10: =IF($I$3=1,H10,F10) -> 26312.89 | J10: =IFERROR(2*PI()*断面!$D$4/D10*1000,0) -> 39.999999 | K10: =IFERROR(J10/(断面!$D$23*1000),0) -> 7.9999998 | L10: =IF(K10>=6,"🟢 良",IF(K10>=3,"🟡 誤差±10%程度","🔴 参考値のみ")) -> 🟢 良 | M10: 板が反（そ）るように曲がる。鳴きの主役 🟢 | N10: =IF(AND(I10>=1250,I10<=16000),"○ 帯域内","− 帯域外") -> − 帯域外 | O10: =IF(I10<=0,1000000000,I10) -> 26312.89 | P10: =MAX($E$3,$N$3) -> 0.01 | Q10: 1 | R10: =B10&" "&C10&"次" -> 面外曲げ 5次
A11: 6 | B11: 面外曲げ | C11: 6 | D11: 20.420352 | E11: =D11^2 -> 416.99078 | F11: =IFERROR(E11/(2*PI()*断面!$D$4^2)*SQRT(断面!$D$17/断面!$D$22),0) -> 40455.977 | G11: =IFERROR(1/SQRT(1+E11*($D$4/断面!$D$4)^2*$H$4),1) -> 0.8784785 | H11: =F11*G11 -> 35539.706 | I11: =IF($I$3=1,H11,F11) -> 35539.706 | J11: =IFERROR(2*PI()*断面!$D$4/D11*1000,0) -> 33.846154 | K11: =IFERROR(J11/(断面!$D$23*1000),0) -> 6.7692309 | L11: =IF(K11>=6,"🟢 良",IF(K11>=3,"🟡 誤差±10%程度","🔴 参考値のみ")) -> 🟢 良 | M11: 板が反（そ）るように曲がる。鳴きの主役 🟢 | N11: =IF(AND(I11>=1250,I11<=16000),"○ 帯域内","− 帯域外") -> − 帯域外 | O11: =IF(I11<=0,1000000000,I11) -> 35539.706 | P11: =MAX($E$3,$N$3) -> 0.01 | Q11: 1 | R11: =B11&" "&C11&"次" -> 面外曲げ 6次
A12: 7 | B12: ねじり | C12: 1 | D12: 1 | E12: =D12^2 -> 1 | F12: =IFERROR(D12/(2*断面!$D$4)*SQRT(断面!$D$29/断面!$D$30),0) -> 4246.7926 | G12: =1 -> 1 | H12: =F12*G12 -> 4246.7926 | I12: =IF($I$3=1,H12,F12) -> 4246.7926 | J12: =IFERROR(2*断面!$D$4/D12*1000,0) -> 220 | K12: =IFERROR(J12/(MAX(断面!$D$3,断面!$D$23)*1000),0) -> 6.9166568 | L12: =IF(K12>=6,"🟢 良",IF(K12>=3,"🟡 誤差±10%程度","🔴 参考値のみ")) -> 🟢 良 | M12: 板がねじれる。1次ねじりは1次曲げの近くに出やすい 🟡 | N12: =IF(AND(I12>=1250,I12<=16000),"○ 帯域内","− 帯域外") -> ○ 帯域内 | O12: =IF(I12<=0,1000000000,I12) -> 4246.7926 | P12: =MAX($E$3,$N$3) -> 0.01 | Q12: 1 | R12: =B12&" "&C12&"次" -> ねじり 1次
A13: 8 | B13: ねじり | C13: 2 | D13: 2 | E13: =D13^2 -> 4 | F13: =IFERROR(D13/(2*断面!$D$4)*SQRT(断面!$D$29/断面!$D$30),0) -> 8493.5852 | G13: =1 -> 1 | H13: =F13*G13 -> 8493.5852 | I13: =IF($I$3=1,H13,F13) -> 8493.5852 | J13: =IFERROR(2*断面!$D$4/D13*1000,0) -> 110 | K13: =IFERROR(J13/(MAX(断面!$D$3,断面!$D$23)*1000),0) -> 3.4583284 | L13: =IF(K13>=6,"🟢 良",IF(K13>=3,"🟡 誤差±10%程度","🔴 参考値のみ")) -> 🟡 誤差±10%程度 | M13: 板がねじれる。1次ねじりは1次曲げの近くに出やすい 🟡 | N13: =IF(AND(I13>=1250,I13<=16000),"○ 帯域内","− 帯域外") -> ○ 帯域内 | O13: =IF(I13<=0,1000000000,I13) -> 8493.5852 | P13: =MAX($E$3,$N$3) -> 0.01 | Q13: 1 | R13: =B13&" "&C13&"次" -> ねじり 2次
A14: 9 | B14: ねじり | C14: 3 | D14: 3 | E14: =D14^2 -> 9 | F14: =IFERROR(D14/(2*断面!$D$4)*SQRT(断面!$D$29/断面!$D$30),0) -> 12740.378 | G14: =1 -> 1 | H14: =F14*G14 -> 12740.378 | I14: =IF($I$3=1,H14,F14) -> 12740.378 | J14: =IFERROR(2*断面!$D$4/D14*1000,0) -> 73.333333 | K14: =IFERROR(J14/(MAX(断面!$D$3,断面!$D$23)*1000),0) -> 2.3055523 | L14: =IF(K14>=6,"🟢 良",IF(K14>=3,"🟡 誤差±10%程度","🔴 参考値のみ")) -> 🔴 参考値のみ | M14: 板がねじれる。1次ねじりは1次曲げの近くに出やすい 🟡 | N14: =IF(AND(I14>=1250,I14<=16000),"○ 帯域内","− 帯域外") -> ○ 帯域内 | O14: =IF(I14<=0,1000000000,I14) -> 12740.378 | P14: =MAX($E$3,$N$3) -> 0.01 | Q14: 1 | R14: =B14&" "&C14&"次" -> ねじり 3次
A15: 10 | B15: ねじり | C15: 4 | D15: 4 | E15: =D15^2 -> 16 | F15: =IFERROR(D15/(2*断面!$D$4)*SQRT(断面!$D$29/断面!$D$30),0) -> 16987.17 | G15: =1 -> 1 | H15: =F15*G15 -> 16987.17 | I15: =IF($I$3=1,H15,F15) -> 16987.17 | J15: =IFERROR(2*断面!$D$4/D15*1000,0) -> 55 | K15: =IFERROR(J15/(MAX(断面!$D$3,断面!$D$23)*1000),0) -> 1.7291642 | L15: =IF(K15>=6,"🟢 良",IF(K15>=3,"🟡 誤差±10%程度","🔴 参考値のみ")) -> 🔴 参考値のみ | M15: 板がねじれる。1次ねじりは1次曲げの近くに出やすい 🟡 | N15: =IF(AND(I15>=1250,I15<=16000),"○ 帯域内","− 帯域外") -> − 帯域外 | O15: =IF(I15<=0,1000000000,I15) -> 16987.17 | P15: =MAX($E$3,$N$3) -> 0.01 | Q15: 1 | R15: =B15&" "&C15&"次" -> ねじり 4次
A16: 11 | B16: 面内曲げ | C16: 1 | D16: 4.730041 | E16: =D16^2 -> 22.373288 | F16: =IFERROR(E16/(2*PI()*断面!$D$4^2)*SQRT(断面!$D$20/断面!$D$22),0) -> 19139.874 | G16: =IFERROR(1/SQRT(1+E16*($F$4/断面!$D$4)^2*$H$4),1) -> 0.78033047 | H16: =F16*G16 -> 14935.427 | I16: =IF($I$3=1,H16,F16) -> 14935.427 | J16: =IFERROR(2*PI()*断面!$D$4/D16*1000,0) -> 146.11932 | K16: =IFERROR(J16/(断面!$D$3*1000),0) -> 4.5938964 | L16: =IF(K16>=6,"🟢 良",IF(K16>=3,"🟡 誤差±10%程度","🔴 参考値のみ")) -> 🟡 誤差±10%程度 | M16: 面の中で（半径方向に）波打つ。5kHz以上で効く 🟢 | N16: =IF(AND(I16>=1250,I16<=16000),"○ 帯域内","− 帯域外") -> ○ 帯域内 | O16: =IF(I16<=0,1000000000,I16) -> 14935.427 | P16: =MAX($E$3,$N$3) -> 0.01 | Q16: 1 | R16: =B16&" "&C16&"次" -> 面内曲げ 1次
A17: 12 | B17: 面内曲げ | C17: 2 | D17: 7.853205 | E17: =D17^2 -> 61.672829 | F17: =IFERROR(E17/(2*PI()*断面!$D$4^2)*SQRT(断面!$D$20/断面!$D$22),0) -> 52759.8 | G17: =IFERROR(1/SQRT(1+E17*($F$4/断面!$D$4)^2*$H$4),1) -> 0.60079575 | H17: =F17*G17 -> 31697.864 | I17: =IF($I$3=1,H17,F17) -> 31697.864 | J17: =IFERROR(2*PI()*断面!$D$4/D17*1000,0) -> 88.008703 | K17: =IFERROR(J17/(断面!$D$3*1000),0) -> 2.7669363 | L17: =IF(K17>=6,"🟢 良",IF(K17>=3,"🟡 誤差±10%程度","🔴 参考値のみ")) -> 🔴 参考値のみ | M17: 面の中で（半径方向に）波打つ。5kHz以上で効く 🟢 | N17: =IF(AND(I17>=1250,I17<=16000),"○ 帯域内","− 帯域外") -> − 帯域外 | O17: =IF(I17<=0,1000000000,I17) -> 31697.864 | P17: =MAX($E$3,$N$3) -> 0.01 | Q17: 1 | R17: =B17&" "&C17&"次" -> 面内曲げ 2次
A18: 13 | B18: 面内曲げ | C18: 3 | D18: 10.995608 | E18: =D18^2 -> 120.9034 | F18: =IFERROR(E18/(2*PI()*断面!$D$4^2)*SQRT(断面!$D$20/断面!$D$22),0) -> 103430.3 | G18: =IFERROR(1/SQRT(1+E18*($F$4/断面!$D$4)^2*$H$4),1) -> 0.47294466 | H18: =F18*G18 -> 48916.806 | I18: =IF($I$3=1,H18,F18) -> 48916.806 | J18: =IFERROR(2*PI()*断面!$D$4/D18*1000,0) -> 62.85695 | K18: =IFERROR(J18/(断面!$D$3*1000),0) -> 1.9761816 | L18: =IF(K18>=6,"🟢 良",IF(K18>=3,"🟡 誤差±10%程度","🔴 参考値のみ")) -> 🔴 参考値のみ | M18: 面の中で（半径方向に）波打つ。5kHz以上で効く 🟢 | N18: =IF(AND(I18>=1250,I18<=16000),"○ 帯域内","− 帯域外") -> − 帯域外 | O18: =IF(I18<=0,1000000000,I18) -> 48916.806 | P18: =MAX($E$3,$N$3) -> 0.01 | Q18: 1 | R18: =B18&" "&C18&"次" -> 面内曲げ 3次
A19: 14 | B19: 面内曲げ | C19: 4 | D19: 14.137165 | E19: =D19^2 -> 199.85943 | F19: =IFERROR(E19/(2*PI()*断面!$D$4^2)*SQRT(断面!$D$20/断面!$D$22),0) -> 170975.52 | G19: =IFERROR(1/SQRT(1+E19*($F$4/断面!$D$4)^2*$H$4),1) -> 0.38526256 | H19: =F19*G19 -> 65870.465 | I19: =IF($I$3=1,H19,F19) -> 65870.465 | J19: =IFERROR(2*PI()*断面!$D$4/D19*1000,0) -> 48.888896 | K19: =IFERROR(J19/(断面!$D$3*1000),0) -> 1.5370351 | L19: =IF(K19>=6,"🟢 良",IF(K19>=3,"🟡 誤差±10%程度","🔴 参考値のみ")) -> 🔴 参考値のみ | M19: 面の中で（半径方向に）波打つ。5kHz以上で効く 🟢 | N19: =IF(AND(I19>=1250,I19<=16000),"○ 帯域内","− 帯域外") -> − 帯域外 | O19: =IF(I19<=0,1000000000,I19) -> 65870.465 | P19: =MAX($E$3,$N$3) -> 0.01 | Q19: 1 | R19: =B19&" "&C19&"次" -> 面内曲げ 4次
A20: 15 | B20: 面内伸縮 | C20: 1 | D20: 1 | E20: =D20^2 -> 1 | F20: =IFERROR(D20/(2*断面!$D$4)*SQRT(断面!$D$21/断面!$D$22),0) -> 23228.407 | G20: =1 -> 1 | H20: =F20*G20 -> 23228.407 | I20: =IF($I$3=1,H20,F20) -> 23228.407 | J20: =IFERROR(2*断面!$D$4/D20*1000,0) -> 220 | K20: =IFERROR(J20/(MAX(断面!$D$3,断面!$D$23)*1000),0) -> 6.9166568 | L20: =IF(K20>=6,"🟢 良",IF(K20>=3,"🟡 誤差±10%程度","🔴 参考値のみ")) -> 🟢 良 | M20: 円周方向に伸び縮み。10kHz超の高音鳴きに関与 🟢 | N20: =IF(AND(I20>=1250,I20<=16000),"○ 帯域内","− 帯域外") -> − 帯域外 | O20: =IF(I20<=0,1000000000,I20) -> 23228.407 | P20: =MAX($E$3,$N$3) -> 0.01 | Q20: 1 | R20: =B20&" "&C20&"次" -> 面内伸縮 1次
A21: 16 | B21: 面内伸縮 | C21: 2 | D21: 2 | E21: =D21^2 -> 4 | F21: =IFERROR(D21/(2*断面!$D$4)*SQRT(断面!$D$21/断面!$D$22),0) -> 46456.813 | G21: =1 -> 1 | H21: =F21*G21 -> 46456.813 | I21: =IF($I$3=1,H21,F21) -> 46456.813 | J21: =IFERROR(2*断面!$D$4/D21*1000,0) -> 110 | K21: =IFERROR(J21/(MAX(断面!$D$3,断面!$D$23)*1000),0) -> 3.4583284 | L21: =IF(K21>=6,"🟢 良",IF(K21>=3,"🟡 誤差±10%程度","🔴 参考値のみ")) -> 🟡 誤差±10%程度 | M21: 円周方向に伸び縮み。10kHz超の高音鳴きに関与 🟢 | N21: =IF(AND(I21>=1250,I21<=16000),"○ 帯域内","− 帯域外") -> − 帯域外 | O21: =IF(I21<=0,1000000000,I21) -> 46456.813 | P21: =MAX($E$3,$N$3) -> 0.01 | Q21: 1 | R21: =B21&" "&C21&"次" -> 面内伸縮 2次
A22: 17 | B22: 面内伸縮 | C22: 3 | D22: 3 | E22: =D22^2 -> 9 | F22: =IFERROR(D22/(2*断面!$D$4)*SQRT(断面!$D$21/断面!$D$22),0) -> 69685.22 | G22: =1 -> 1 | H22: =F22*G22 -> 69685.22 | I22: =IF($I$3=1,H22,F22) -> 69685.22 | J22: =IFERROR(2*断面!$D$4/D22*1000,0) -> 73.333333 | K22: =IFERROR(J22/(MAX(断面!$D$3,断面!$D$23)*1000),0) -> 2.3055523 | L22: =IF(K22>=6,"🟢 良",IF(K22>=3,"🟡 誤差±10%程度","🔴 参考値のみ")) -> 🔴 参考値のみ | M22: 円周方向に伸び縮み。10kHz超の高音鳴きに関与 🟢 | N22: =IF(AND(I22>=1250,I22<=16000),"○ 帯域内","− 帯域外") -> − 帯域外 | O22: =IF(I22<=0,1000000000,I22) -> 69685.22 | P22: =MAX($E$3,$N$3) -> 0.01 | Q22: 1 | R22: =B22&" "&C22&"次" -> 面内伸縮 3次
A24: ■ 使っている式（🟢＝教科書どおり／🟡＝妥当な近似）
A25: 面外曲げ・面内曲げ | C25: f = (βL)² /(2π L²) × √(EI / ρA) | G25: 自由−自由はり（Euler-Bernoulli）。βL = 4.7300, 7.8532, 10.9956, 14.1372, 17.2788, 20.4204（cos(βL)cosh(βL)=1 の解） 🟢
A26: 周波数の比 | C26: f₁ : f₂ : f₃ : f₄ = 1 : 2.757 : 5.404 : 8.933 | G26: 実測がこの比から外れたら「曲げモードではない」or「せん断が効いている」 🟢
A27: せん断補正 | C27: f補正 = f / √(1 + (βL)²·(r/L)²·(1 + E/(κG))) | G27: Timoshenkoの一次近似。r＝断面回転半径, κ＝5/6。高次ほど大きく下がる 🟡
A28: ねじり | C28: f = n /(2L) × √(GJ / ρIp) | G28: 自由−自由ねじり棒。J＝β·w·h³、β＝(1/3)(1−0.630(h/w)+0.052(h/w)⁵) 🟢/🟡
A29: 面内伸縮 | C29: f = n /(2L) × √(EA / ρA) | G29: 自由−自由の縦振動。棒の中の音速 c＝√(E/ρ) の半波長ずつ 🟢
A30: 波長 | C30: λ = 2πL/(βL)（曲げ）、λ = 2L/n（ねじり・伸縮） | G30: λ/断面寸法 が小さいほど1次元はり近似が苦しい。6以上あれば安心 🟢
A31: 最重要の性質 | C31: f ∝ h / L²（均質1枚板のとき） | G31: 厚さ2倍→周波数2倍。長さ2倍→周波数1/4。設計で一番効くのは L（長さ） 🟢
A33: ■ 感度（どこをいじると何Hz動くか）
A34: 長さ L を x 倍 → 面外曲げは 1/x² 倍。L が 5% 伸びるだけで周波数は約 9% 下がる（最も効く）
A35: 板厚 t を x 倍 → EI は x³、質量は x なので周波数はおよそ x 倍
A36: 穴を大きくする → 質量も剛性も減る。中央の穴は剛性側が勝つので周波数は下がる方向 🟡
A37: ヤング率 E を x 倍 → 周波数は √x 倍（鋼なら 190〜210GPa の幅＝周波数±2.6%）
A38: ⚠ せん断補正を OFF にすると高次モードを 20〜50% 高く出します。実測と合わないときはまずここを疑う
A40: ■ 金属部だけを測るときのコツ
A41: ・N3「スペクトル描画用 η の下限」は グラフを見やすくするための表示専用の値です（既定0.01）。実測では吊り・空気・窓の影響で必ずこの程度以上になります。物理的な減衰そのものは D3/E3 のηです。
A42: ・裏板は摩擦材付きより 減衰（げんすい）が桁違いに小さい（η≒0.0002）。ピークが鋭いので、周波数分解能 Δf を細かくしないと山を取り逃します。→「測定計画」シートへ
A43: ・鋭いピーク＝長く鳴り続ける。ハンマリングの指数窓（exponential window）を強くかけると減衰を大きく間違えます。周波数だけなら問題ありません。
...

Sheet スペクトル
A1: ④ スペクトル（FFT画面と同じ形のグラフ用データ）
A2: 各モードを1自由度系として複素数で足し合わせ、応答の大きさ |H(f)| を作る 🟢 ※金属部は減衰が小さいのでピークが鋭く出ます
A3: 開始周波数 [Hz] | C3: 0 | D3: 刻み Δf [Hz] | F3: 20 | G3: 点数 | H3: 2001 | I3: dB基準値 | K3: 1 | L3: ※ 既定は 0〜40000 Hz。ピークを拡大したいときは 開始=8000, Δf=1 のように変える
A5: 周波数 f [Hz] | B5: 実部 Re | C5: 虚部 Im | D5: 応答 |H| | E5: レベル [dB]
A6: =$C$3 -> 0 | B6: =SUMPRODUCT(固有振動数!$Q$6:$Q$22*(1-($A6/固有振動数!$O$6:$O$22)^2)/((1-($A6/固有振動数!$O$6:$O$22)^2)^2+固有振動数!$P$6:$P$22^2)) -> 16.9983 | C6: =-SUMPRODUCT(固有振動数!$Q$6:$Q$22*固有振動数!$P$6:$P$22/((1-($A6/固有振動数!$O$6:$O$22)^2)^2+固有振動数!$P$6:$P$22^2)) -> -0.169983 | D6: =SQRT(B6^2+C6^2) -> 16.99915 | E6: =20*LOG10(MAX(D6,0.000000000001)/$K$3) -> 24.608544
A7: =A6+$F$3 -> 20 | B7: =SUMPRODUCT(固有振動数!$Q$6:$Q$22*(1-($A7/固有振動数!$O$6:$O$22)^2)/((1-($A7/固有振動数!$O$6:$O$22)^2)^2+固有振動数!$P$6:$P$22^2)) -> 16.998438 | C7: =-SUMPRODUCT(固有振動数!$Q$6:$Q$22*固有振動数!$P$6:$P$22/((1-($A7/固有振動数!$O$6:$O$22)^2)^2+固有振動数!$P$6:$P$22^2)) -> -0.16998577 | D7: =SQRT(B7^2+C7^2) -> 16.999288 | E7: =20*LOG10(MAX(D7,0.000000000001)/$K$3) -> 24.608615
A8: =A7+$F$3 -> 40 | B8: =SUMPRODUCT(固有振動数!$Q$6:$Q$22*(1-($A8/固有振動数!$O$6:$O$22)^2)/((1-($A8/固有振動数!$O$6:$O$22)^2)^2+固有振動数!$P$6:$P$22^2)) -> 16.998853 | C8: =-SUMPRODUCT(固有振動数!$Q$6:$Q$22*固有振動数!$P$6:$P$22/((1-($A8/固有振動数!$O$6:$O$22)^2)^2+固有振動数!$P$6:$P$22^2)) -> -0.16999406 | D8: =SQRT(B8^2+C8^2) -> 16.999703 | E8: =20*LOG10(MAX(D8,0.000000000001)/$K$3) -> 24.608827
A9: =A8+$F$3 -> 60 | B9: =SUMPRODUCT(固有振動数!$Q$6:$Q$22*(1-($A9/固有振動数!$O$6:$O$22)^2)/((1-($A9/固有振動数!$O$6:$O$22)^2)^2+固有振動数!$P$6:$P$22^2)) -> 16.999544 | C9: =-SUMPRODUCT(固有振動数!$Q$6:$Q$22*固有振動数!$P$6:$P$22/((1-($A9/固有振動数!$O$6:$O$22)^2)^2+固有振動数!$P$6:$P$22^2)) -> -0.17000789 | D9: =SQRT(B9^2+C9^2) -> 17.000394 | E9: =20*LOG10(MAX(D9,0.000000000001)/$K$3) -> 24.60918
A10: =A9+$F$3 -> 80 | B10: =SUMPRODUCT(固有振動数!$Q$6:$Q$22*(1-($A10/固有振動数!$O$6:$O$22)^2)/((1-($A10/固有振動数!$O$6:$O$22)^2)^2+固有振動数!$P$6:$P$22^2)) -> 17.000513 | C10: =-SUMPRODUCT(固有振動数!$Q$6:$Q$22*固有振動数!$P$6:$P$22/((1-($A10/固有振動数!$O$6:$O$22)^2)^2+固有振動数!$P$6:$P$22^2)) -> -0.17002728 | D10: =SQRT(B10^2+C10^2) -> 17.001363 | E10: =20*LOG10(MAX(D10,0.000000000001)/$K$3) -> 24.609675
A11: =A10+$F$3 -> 100 | B11: =SUMPRODUCT(固有振動数!$Q$6:$Q$22*(1-($A11/固有振動数!$O$6:$O$22)^2)/((1-($A11/固有振動数!$O$6:$O$22)^2)^2+固有振動数!$P$6:$P$22^2)) -> 17.001759 | C11: =-SUMPRODUCT(固有振動数!$Q$6:$Q$22*固有振動数!$P$6:$P$22/((1-($A11/固有振動数!$O$6:$O$22)^2)^2+固有振動数!$P$6:$P$22^2)) -> -0.17005224 | D11: =SQRT(B11^2+C11^2) -> 17.00261 | E11: =20*LOG10(MAX(D11,0.000000000001)/$K$3) -> 24.610312
A12: =A11+$F$3 -> 120 | B12: =SUMPRODUCT(固有振動数!$Q$6:$Q$22*(1-($A12/固有振動数!$O$6:$O$22)^2)/((1-($A12/固有振動数!$O$6:$O$22)^2)^2+固有振動数!$P$6:$P$22^2)) -> 17.003285 | C12: =-SUMPRODUCT(固有振動数!$Q$6:$Q$22*固有振動数!$P$6:$P$22/((1-($A12/固有振動数!$O$6:$O$22)^2)^2+固有振動数!$P$6:$P$22^2)) -> -0.17008281 | D12: =SQRT(B12^2+C12^2) -> 17.004135 | E12: =20*LOG10(MAX(D12,0.000000000001)/$K$3) -> 24.611091
A13: =A12+$F$3 -> 140 | B13: =SUMPRODUCT(固有振動数!$Q$6:$Q$22*(1-($A13/固有振動数!$O$6:$O$22)^2)/((1-($A13/固有振動数!$O$6:$O$22)^2)^2+固有振動数!$P$6:$P$22^2)) -> 17.00509 | C13: =-SUMPRODUCT(固有振動数!$Q$6:$Q$22*固有振動数!$P$6:$P$22/((1-($A13/固有振動数!$O$6:$O$22)^2)^2+固有振動数!$P$6:$P$22^2)) -> -0.170119 | D13: =SQRT(B13^2+C13^2) -> 17.005941 | E13: =20*LOG10(MAX(D13,0.000000000001)/$K$3) -> 24.612013
A14: =A13+$F$3 -> 160 | B14: =SUMPRODUCT(固有振動数!$Q$6:$Q$22*(1-($A14/固有振動数!$O$6:$O$22)^2)/((1-($A14/固有振動数!$O$6:$O$22)^2)^2+固有振動数!$P$6:$P$22^2)) -> 17.007176 | C14: =-SUMPRODUCT(固有振動数!$Q$6:$Q$22*固有振動数!$P$6:$P$22/((1-($A14/固有振動数!$O$6:$O$22)^2)^2+固有振動数!$P$6:$P$22^2)) -> -0.17016087 | D14: =SQRT(B14^2+C14^2) -> 17.008027 | E14: =20*LOG10(MAX(D14,0.000000000001)/$K$3) -> 24.613079
A15: =A14+$F$3 -> 180 | B15: =SUMPRODUCT(固有振動数!$Q$6:$Q$22*(1-($A15/固有振動数!$O$6:$O$22)^2)/((1-($A15/固有振動数!$O$6:$O$22)^2)^2+固有振動数!$P$6:$P$22^2)) -> 17.009545 | C15: =-SUMPRODUCT(固有振動数!$Q$6:$Q$22*固有振動数!$P$6:$P$22/((1-($A15/固有振動数!$O$6:$O$22)^2)^2+固有振動数!$P$6:$P$22^2)) -> -0.17020846 | D15: =SQRT(B15^2+C15^2) -> 17.010397 | E15: =20*LOG10(MAX(D15,0.000000000001)/$K$3) -> 24.614289
A16: =A15+$F$3 -> 200 | B16: =SUMPRODUCT(固有振動数!$Q$6:$Q$22*(1-($A16/固有振動数!$O$6:$O$22)^2)/((1-($A16/固有振動数!$O$6:$O$22)^2)^2+固有振動数!$P$6:$P$22^2)) -> 17.012198 | C16: =-SUMPRODUCT(固有振動数!$Q$6:$Q$22*固有振動数!$P$6:$P$22/((1-($A16/固有振動数!$O$6:$O$22)^2)^2+固有振動数!$P$6:$P$22^2)) -> -0.17026182 | D16: =SQRT(B16^2+C16^2) -> 17.01305 | E16: =20*LOG10(MAX(D16,0.000000000001)/$K$3) -> 24.615644
A17: =A16+$F$3 -> 220 | B17: =SUMPRODUCT(固有振動数!$Q$6:$Q$22*(1-($A17/固有振動数!$O$6:$O$22)^2)/((1-($A17/固有振動数!$O$6:$O$22)^2)^2+固有振動数!$P$6:$P$22^2)) -> 17.015138 | C17: =-SUMPRODUCT(固有振動数!$Q$6:$Q$22*固有振動数!$P$6:$P$22/((1-($A17/固有振動数!$O$6:$O$22)^2)^2+固有振動数!$P$6:$P$22^2)) -> -0.170321 | D17: =SQRT(B17^2+C17^2) -> 17.01599 | E17: =20*LOG10(MAX(D17,0.000000000001)/$K$3) -> 24.617145
A18: =A17+$F$3 -> 240 | B18: =SUMPRODUCT(固有振動数!$Q$6:$Q$22*(1-($A18/固有振動数!$O$6:$O$22)^2)/((1-($A18/固有振動数!$O$6:$O$22)^2)^2+固有振動数!$P$6:$P$22^2)) -> 17.018366 | C18: =-SUMPRODUCT(固有振動数!$Q$6:$Q$22*固有振動数!$P$6:$P$22/((1-($A18/固有振動数!$O$6:$O$22)^2)^2+固有振動数!$P$6:$P$22^2)) -> -0.17038608 | D18: =SQRT(B18^2+C18^2) -> 17.019219 | E18: =20*LOG10(MAX(D18,0.000000000001)/$K$3) -> 24.618792
... A2006: =A2005+$F$3 -> 40000 | B2006: =SUMPRODUCT(固有振動数!$Q$6:$Q$22*(1-($A2006/固有振動数!$O$6:$O$22)^2)/((1-($A2006/固有振動数!$O$6:$O$22)^2)^2+固有振動数!$P$6:$P$22^2)) -> 2.324423 | C2006: =-SUMPRODUCT(固有振動数!$Q$6:$Q$22*固有振動数!$P$6:$P$22/((1-($A2006/固有振動数!$O$6:$O$22)^2)^2+固有振動数!$P$6:$P$22^2)) -> -0.46645465 | D2006: =SQRT(B2006^2+C2006^2) -> 2.370764 | E2006: =20*LOG10(MAX(D2006,0.000000000001)/$K$3) -> 7.4977666
A2009: ■ グラフの読み方
A2010: 山（ピーク）の位置＝固有振動数。ここが実測FFTのピークと一致するかを見ます。
A2011: 山の高さ＝1/η（損失係数の逆数）。金属だけだと本当の η は 0.0002 程度で、理屈上は非常に高く鋭い山になります。
A2012: そのままだと Δf の網目からピークがすり抜けて見えないので、固有振動数シート N3 に「描画用 η の下限（既定0.01）」を置いています。
A2013: 山の高さがモードごとにバラつくのは、Δf が山の幅より粗いためです。物理ではなくサンプリングの都合です。
A2014: 実測では吊り・空気・センサの影響で必ずもっと低く・太くなります。高さは合わなくて当然、位置を見てください。
A2015: 山が見えない → 周波数範囲が合っていません。C3（開始）とF3（Δf）を調整してください。
A2016: ■ 他ソフトへ持っていくとき
A2017: A列〜E列を選択してコピー → メモ帳やCSVにそのまま貼れます（TSV形式）。
A2018: Python / gnuplot / Origin へは A列(f) と E列(dB) の2列だけで充分です。
A2019: RION SA-01A4 の実測スペクトルと重ねると、モードの取りこぼしがひと目で分かります。

Sheet 鳴きリスク
A1: ⑤ 鳴（な）きリスク スクリーニング（金属部の素性チェック）
A2: SAE J2521 の対象帯域 1.25〜16 kHz を基準に、モード密集とディスクとの一致度を点数化 🟡（CEAの代わりにはなりません）
A3: 帯域 下限 [Hz] | C3: 1250 | D3: 帯域 上限 [Hz] | F3: 16000 | G3: 接近とみなす差 [%] | I3: 3
A4: 摩擦材シフト係数 k | C4: 1 | D4: 評価に使う f ＝ 金属部の f × k | G4: ※ 金属部だけで見るなら k=1.00 のまま。摩擦材を貼った完成品を想像したいときだけ 0.5〜0.7 を入れる 🟡
A6: ■ ディスク（ローター）の固有振動数 [Hz]（分かる範囲で入力／空欄可）
A7: D1 | B7: 1800 | C7: ← ここは「例」です。必ず自分のローターの実測値／FEM値に差し替えてください（🔴 要確認）
A8: D2 | B8: 3200
A9: D3 | B9: 5000
A10: D4 | B10: 7100
A11: D5 | B11: 9400
A12: D6
A13: D7
A14: D8
A15: D9
A16: D10
A18: # | B18: モード名 | C18: 金属部 f [Hz] | D18: 評価用 f [Hz] | E18: 帯域内? | F18: 最近接モード差 [%] | G18: 最近接ディスク差 [%] | H18: 個別判定 | I18: 帯域内のみ:モード差 | J18: 帯域内のみ:ディスク差
