Workbook

Sheet 使い方
A1: 近接ピーク(双子モード)分離 RFP法カーブフィット ― 自動計算シート
B5: 1つの山（ピーク）に見えるところが、実は近い周波数の「2つの山が重なったもの」（双子モード・縮退モード）だった場合に、
B6: 1自由度（1個の山専用）のカーブフィットでは正しく分離できません。半値幅法やサークルフィット、これまでの鉄板ワークブック
B7: （1自由度・逆FRF2次多項式フィット）は、山が1つだけ孤立している前提の手法だからです。
B8: このファイルは「有理多項式法（RFP法／Rational Fraction Polynomial method）」という、2つの山を数式ごと同時に
B9: 分離できるカーブフィット法を使い、貼り付けたFRFデータ（周波数・実部・虚部 または 周波数・振幅・位相）から、
B10: 2つのモードそれぞれの固有振動数 fn と損失係数 η を自動計算します。Excelの数式（MMULT・MINVERSE・SQRT・ACOS等の
B11: 標準関数）だけで完結しており、Solver（ソルバー）アドインの手動操作は不要です。データを貼り替えれば自動で再計算されます。
B15: STEP1 「設定」シートの黄色いセルに、基準周波数 fref（帯域の中心くらい）と、入力データの形式を設定する。
B16: STEP2 「データ入力」シートに、双子モードの周波数帯を含むFRFデータ（20〜80点程度）を貼り付ける（4行目から）。
B17: ※ 今は動作確認用のサンプルデータ（既存ガイドで検証済みの数値）が入っています。上書きしてOKです。
B18: STEP3 再計算する（LibreOffice Calc は Ctrl+Shift+F9 で完全再計算。Excelは自動で再計算されます）。
B19: STEP4 「モード分離結果」シートの一番上、緑色の★セルを見る。2つのモードの fn・η が答えです。
... B45: ⑤ この方法はハンマー1点×応答1点（SISO）のデータ専用です。複数加振点のMIMO化は既存ガイド4-8節を参照。

Sheet 設定
A1: 設定 ― 基準周波数・入力データ形式・判定しきい値
A3: 【1】基準周波数と正規化
A4: 基準周波数 fref [Hz] | B4: 3500 | C4: 帯域のだいたい中心の周波数。生の周波数のままでは数値誤差で分離に失敗するため、正規化に使う基準値。
A5: ωref [rad/s] | B5: =2*PI()*B4 -> 21991.149 | C5: ωref = 2π・fref（自動計算）
A7: 【2】入力データの形式
A8: データの種類 | B8: 実部虚部 | C8: 「実部虚部」または「振幅位相」。データ入力シートのB・C列に貼るデータの意味が変わります。
A9: 振幅の単位（振幅位相の時のみ有効） | B9: dB | C9: 「dB」または「リニア」。RION SA-01A4の画面表示単位に合わせてください。
A11: 【3】モード分離（Ferrari法）の判定しきい値
A12: u 最小しきい値（正規化・無次元） | B12: 1e-06 | C12: 2つのモードの損失係数がほぼ同じで数式が不安定になる境界を検出するためのしきい値。通常は変更不要。
A13: 判定の意味 | B13: u（αの2乗）がこの値を下回ると「要確認」。2モードの損失係数が非常に近い、まれな境界条件を意味します。
A15: 【4】このファイルの前提
A16: ・貼り付ける帯域には、山がちょうど2つだけ含まれている必要があります（3つ以上は非対応）。
A17: ・データ入力シートは最大80点まで（実部用80行＋虚部用80行＝160本の連立方程式）。
A18: ・入力データが少ない/帯域が不適切だと、fnは高精度でもηの誤差が大きくなることがあります（RFP法自体の性質）。

Sheet データ入力
A1: データ入力 ― 双子モードを含む周波数帯のFRFデータを貼り付け（4行目から）
A2: 設定シートで「実部虚部」を選んだ場合：B列=実部Re(H)、C列=虚部Im(H)。「振幅位相」を選んだ場合：B列=振幅、C列=位相[度]。
A3: ★ 今は動作確認用のサンプルデータ（既存ガイドで検証済み：モードA≈3480Hz/η≈0.006、モードB≈3520Hz/η≈0.008）が入っています。上書きしてOKです。
A4: 周波数 f [Hz] | B4: 測定値1 (実部 or 振幅) | C4: 測定値2 (虚部 or 位相[度]) | D4: 計算用 Re(H) | E4: 計算用 Im(H) | F4: 正規化角周波数 Ω
A5: 3400 | B5: 5.1e-05 | C5: 0.00301 | D5: =IF($A5="","",IF(設定!$B$8="実部虚部",$B5,IF(設定!$B$9="dB",10^($B5/20),$B5)*COS($C5*PI()/180))) -> 5.1e-05 | E5: =IF($A5="","",IF(設定!$B$8="実部虚部",$C5,IF(設定!$B$9="dB",10^($B5/20),$B5)*SIN($C5*PI()/180))) -> 0.00301 | F5: =IF($A5="","",2*PI()*$A5/設定!$B$5) -> 0.97142857
A6: 3410 | B6: 9.3e-05 | C6: 0.003391 | D6: =IF($A6="","",IF(設定!$B$8="実部虚部",$B6,IF(設定!$B$9="dB",10^($B6/20),$B6)*COS($C6*PI()/180))) -> 9.3e-05 | E6: =IF($A6="","",IF(設定!$B$8="実部虚部",$C6,IF(設定!$B$9="dB",10^($B6/20),$B6)*SIN($C6*PI()/180))) -> 0.003391 | F6: =IF($A6="","",2*PI()*$A6/設定!$B$5) -> 0.97428571
A7: 3420 | B7: 0.000162 | C7: 0.003876 | D7: =IF($A7="","",IF(設定!$B$8="実部虚部",$B7,IF(設定!$B$9="dB",10^($B7/20),$B7)*COS($C7*PI()/180))) -> 0.000162 | E7: =IF($A7="","",IF(設定!$B$8="実部虚部",$C7,IF(設定!$B$9="dB",10^($B7/20),$B7)*SIN($C7*PI()/180))) -> 0.003876 | F7: =IF($A7="","",2*PI()*$A7/設定!$B$5) -> 0.97714286
A8: 3430 | B8: 0.00028 | C8: 0.004516 | D8: =IF($A8="","",IF(設定!$B$8="実部虚部",$B8,IF(設定!$B$9="dB",10^($B8/20),$B8)*COS($C8*PI()/180))) -> 0.00028 | E8: =IF($A8="","",IF(設定!$B$8="実部虚部",$C8,IF(設定!$B$9="dB",10^($B8/20),$B8)*SIN($C8*PI()/180))) -> 0.004516 | F8: =IF($A8="","",2*PI()*$A8/設定!$B$5) -> 0.98
A9: 3440 | B9: 0.000512 | C9: 0.005463 | D9: =IF($A9="","",IF(設定!$B$8="実部虚部",$B9,IF(設定!$B$9="dB",10^($B9/20),$B9)*COS($C9*PI()/180))) -> 0.000512 | E9: =IF($A9="","",IF(設定!$B$8="実部虚部",$C9,IF(設定!$B$9="dB",10^($B9/20),$B9)*SIN($C9*PI()/180))) -> 0.005463 | F9: =IF($A9="","",2*PI()*$A9/設定!$B$5) -> 0.98285714
A10: 3450 | B10: 0.001016 | C10: 0.006854 | D10: =IF($A10="","",IF(設定!$B$8="実部虚部",$B10,IF(設定!$B$9="dB",10^($B10/20),$B10)*COS($C10*PI()/180))) -> 0.001016 | E10: =IF($A10="","",IF(設定!$B$8="実部虚部",$C10,IF(設定!$B$9="dB",10^($B10/20),$B10)*SIN($C10*PI()/180))) -> 0.006854 | F10: =IF($A10="","",2*PI()*$A10/設定!$B$5) -> 0.98571429
A11: 3460 | B11: 0.002362 | C11: 0.00908 | D11: =IF($A11="","",IF(設定!$B$8="実部虚部",$B11,IF(設定!$B$9="dB",10^($B11/20),$B11)*COS($C11*PI()/180))) -> 0.002362 | E11: =IF($A11="","",IF(設定!$B$8="実部虚部",$C11,IF(設定!$B$9="dB",10^($B11/20),$B11)*SIN($C11*PI()/180))) -> 0.00908 | F11: =IF($A11="","",2*PI()*$A11/設定!$B$5) -> 0.98857143
A12: 3470 | B12: 0.006939 | C12: 0.012171 | D12: =IF($A12="","",IF(設定!$B$8="実部虚部",$B12,IF(設定!$B$9="dB",10^($B12/20),$B12)*COS($C12*PI()/180))) -> 0.006939 | E12: =IF($A12="","",IF(設定!$B$8="実部虚部",$C12,IF(設定!$B$9="dB",10^($B12/20),$B12)*SIN($C12*PI()/180))) -> 0.012171 | F12: =IF($A12="","",2*PI()*$A12/設定!$B$5) -> 0.99142857
A13: 3480 | B13: 0.016968 | C13: 0.007099 | D13: =IF($A13="","",IF(設定!$B$8="実部虚部",$B13,IF(設定!$B$9="dB",10^($B13/20),$B13)*COS($C13*PI()/180))) -> 0.016968 | E13: =IF($A13="","",IF(設定!$B$8="実部虚部",$C13,IF(設定!$B$9="dB",10^($B13/20),$B13)*SIN($C13*PI()/180))) -> 0.007099 | F13: =IF($A13="","",2*PI()*$A13/設定!$B$5) -> 0.99428571
A14: 3490 | B14: 0.012733 | C14: -0.002205 | D14: =IF($A14="","",IF(設定!$B$8="実部虚部",$B14,IF(設定!$B$9="dB",10^($B14/20),$B14)*COS($C14*PI()/180))) -> 0.012733 | E14: =IF($A14="","",IF(設定!$B$8="実部虚部",$C14,IF(設定!$B$9="dB",10^($B14/20),$B14)*SIN($C14*PI()/180))) -> -0.002205 | F14: =IF($A14="","",2*PI()*$A14/設定!$B$5) -> 0.99714286
A15: 3500 | B15: 0.009201 | C15: -0.001806 | D15: =IF($A15="","",IF(設定!$B$8="実部虚部",$B15,IF(設定!$B$9="dB",10^($B15/20),$B15)*COS($C15*PI()/180))) -> 0.009201 | E15: =IF($A15="","",IF(設定!$B$8="実部虚部",$C15,IF(設定!$B$9="dB",10^($B15/20),$B15)*SIN($C15*PI()/180))) -> -0.001806 | F15: =IF($A15="","",2*PI()*$A15/設定!$B$5) -> 1
A16: 3510 | B16: 0.010162 | C16: -0.00152 | D16: =IF($A16="","",IF(設定!$B$8="実部虚部",$B16,IF(設定!$B$9="dB",10^($B16/20),$B16)*COS($C16*PI()/180))) -> 0.010162 | E16: =IF($A16="","",IF(設定!$B$8="実部虚部",$C16,IF(設定!$B$9="dB",10^($B16/20),$B16)*SIN($C16*PI()/180))) -> -0.00152 | F16: =IF($A16="","",2*PI()*$A16/設定!$B$5) -> 1.0028571
... A25: 3600 | B25: 0.000393 | C25: -0.002933 | D25: =IF($A25="","",IF(設定!$B$8="実部虚部",$B25,IF(設定!$B$9="dB",10^($B25/20),$B25)*COS($C25*PI()/180))) -> 0.000393 | E25: =IF($A25="","",IF(設定!$B$8="実部虚部",$C25,IF(設定!$B$9="dB",10^($B25/20),$B25)*SIN($C25*PI()/180))) -> -0.002933 | F25: =IF($A25="","",2*PI()*$A25/設定!$B$5) -> 1.0285714
D26: =IF($A26="","",IF(設定!$B$8="実部虚部",$B26,IF(設定!$B$9="dB",10^($B26/20),$B26)*COS($C26*PI()/180))) | E26: =IF($A26="","",IF(設定!$B$8="実部虚部",$C26,IF(設定!$B$9="dB",10^($B26/20),$B26)*SIN($C26*PI()/180))) | F26: =IF($A26="","",2*PI()*$A26/設定!$B$5)
D27: =IF($A27="","",IF(設定!$B$8="実部虚部",$B27,IF(設定!$B$9="dB",10^($B27/20),$B27)*COS($C27*PI()/180))) | E27: =IF($A27="","",IF(設定!$B$8="実部虚部",$C27,IF(設定!$B$9="dB",10^($B27/20),$B27)*SIN($C27*PI()/180))) | F27: =IF($A27="","",2*PI()*$A27/設定!$B$5)
D28: =IF($A28="","",IF(設定!$B$8="実部虚部",$B28,IF(設定!$B$9="dB",10^($B28/20),$B28)*COS($C28*PI()/180))) | E28: =IF($A28="","",IF(設定!$B$8="実部虚部",$C28,IF(設定!$B$9="dB",10^($B28/20),$B28)*SIN($C28*PI()/180))) | F28: =IF($A28="","",2*PI()*$A28/設定!$B$5)
D29: =IF($A29="","",IF(設定!$B$8="実部虚部",$B29,IF(設定!$B$9="dB",10^($B29/20),$B29)*COS($C29*PI()/180))) | E29: =IF($A29="","",IF(設定!$B$8="実部虚部",$C29,IF(設定!$B$9="dB",10^($B29/20),$B29)*SIN($C29*PI()/180))) | F29: =IF($A29="","",2*PI()*$A29/設定!$B$5)
D30: =IF($A30="","",IF(設定!$B$8="実部虚部",$B30,IF(設定!$B$9="dB",10^($B30/20),$B30)*COS($C30*PI()/180))) | E30: =IF($A30="","",IF(設定!$B$8="実部虚部",$C30,IF(設定!$B$9="dB",10^($B30/20),$B30)*SIN($C30*PI()/180))) | F30: =IF($A30="","",2*PI()*$A30/設定!$B$5)
D31: =IF($A31="","",IF(設定!$B$8="実部虚部",$B31,IF(設定!$B$9="dB",10^($B31/20),$B31)*COS($C31*PI()/180))) | E31: =IF($A31="","",IF(設定!$B$8="実部虚部",$C31,IF(設定!$B$9="dB",10^($B31/20),$B31)*SIN($C31*PI()/180))) | F31: =IF($A31="","",2*PI()*$A31/設定!$B$5)
D32: =IF($A32="","",IF(設定!$B$8="実部虚部",$B32,IF(設定!$B$9="dB",10^($B32/20),$B32)*COS($C32*PI()/180))) | E32: =IF($A32="","",IF(設定!$B$8="実部虚部",$C32,IF(設定!$B$9="dB",10^($B32/20),$B32)*SIN($C32*PI()/180))) | F32: =IF($A32="","",2*PI()*$A32/設定!$B$5)
D33: =IF($A33="","",IF(設定!$B$8="実部虚部",$B33,IF(設定!$B$9="dB",10^($B33/20),$B33)*COS($C33*PI()/180))) | E33: =IF($A33="","",IF(設定!$B$8="実部虚部",$C33,IF(設定!$B$9="dB",10^($B33/20),$B33)*SIN($C33*PI()/180))) | F33: =IF($A33="","",2*PI()*$A33/設定!$B$5)
D34: =IF($A34="","",IF(設定!$B$8="実部虚部",$B34,IF(設定!$B$9="dB",10^($B34/20),$B34)*COS($C34*PI()/180))) | E34: =IF($A34="","",IF(設定!$B$8="実部虚部",$C34,IF(設定!$B$9="dB",10^($B34/20),$B34)*SIN($C34*PI()/180))) | F34: =IF($A34="","",2*PI()*$A34/設定!$B$5)
D35: =IF($A35="","",IF(設定!$B$8="実部虚部",$B35,IF(設定!$B$9="dB",10^($B35/20),$B35)*COS($C35*PI()/180))) | E35: =IF($A35="","",IF(設定!$B$8="実部虚部",$C35,IF(設定!$B$9="dB",10^($B35/20),$B35)*SIN($C35*PI()/180))) | F35: =IF($A35="","",2*PI()*$A35/設定!$B$5)
D36: =IF($A36="","",IF(設定!$B$8="実部虚部",$B36,IF(設定!$B$9="dB",10^($B36/20),$B36)*COS($C36*PI()/180))) | E36: =IF($A36="","",IF(設定!$B$8="実部虚部",$C36,IF(設定!$B$9="dB",10^($B36/20),$B36)*SIN($C36*PI()/180))) | F36: =IF($A36="","",2*PI()*$A36/設定!$B$5)
D37: =IF($A37="","",IF(設定!$B$8="実部虚部",$B37,IF(設定!$B$9="dB",10^($B37/20),$B37)*COS($C37*PI()/180))) | E37: =IF($A37="","",IF(設定!$B$8="実部虚部",$C37,IF(設定!$B$9="dB",10^($B37/20),$B37)*SIN($C37*PI()/180))) | F37: =IF($A37="","",2*PI()*$A37/設定!$B$5)
... D84: =IF($A84="","",IF(設定!$B$8="実部虚部",$B84,IF(設定!$B$9="dB",10^($B84/20),$B84)*COS($C84*PI()/180))) | E84: =IF($A84="","",IF(設定!$B$8="実部虚部",$C84,IF(設定!$B$9="dB",10^($B84/20),$B84)*SIN($C84*PI()/180))) | F84: =IF($A84="","",2*PI()*$A84/設定!$B$5)

Sheet RFP計算
A1: RFP計算 ― 有理多項式フィット（線形連立方程式をMMULT・MINVERSEで解く）
A2: H(jΩ)=[b0+b1(jΩ)+b2(jΩ)²+b3(jΩ)³]/[a0+a1(jΩ)+a2(jΩ)²+a3(jΩ)³+(jΩ)⁴] を、実部の式・虚部の式それぞれ点ごとに1行として並べ、最小二乗法で解きます（カーブフィット_窓関数_Excel解析ガイド.html 第4部と同じ考え方）。
M3: ▼ 行列計算（8×8） 係数 [b0,b1,b2,b3,a0,a1,a2,a3] を最小二乗法で求める
A4: 種別 | B4: 周波数f[Hz] | C4: b0 | D4: b1 | E4: b2 | F4: b3 | G4: a0 | H4: a1 | I4: a2 | J4: a3 | K4: RHS | M4: AᵀA (8×8) | V4: Aᵀc | X4: 係数（答え）
A5: 実部 | B5: =データ入力!$A$5 -> 3400 | C5: =IF(データ入力!$A$5="",0,1) -> 1 | D5: 0 | E5: =IF(データ入力!$A$5="",0,-(データ入力!$F$5^2)) -> -0.94367347 | F5: 0 | G5: =IF(データ入力!$A$5="",0,-データ入力!$D$5) -> -5.1e-05 | H5: =IF(データ入力!$A$5="",0,データ入力!$F$5*データ入力!$E$5) -> 0.002924 | I5: =IF(データ入力!$A$5="",0,データ入力!$F$5^2*データ入力!$D$5) -> 4.8127347e-05 | J5: =IF(データ入力!$A$5="",0,-データ入力!$F$5^3*データ入力!$E$5) -> -0.0027593012 | K5: =IF(データ入力!$A$5="",0,データ入力!$F$5^4*データ入力!$D$5) -> 4.54165e-05 | M5: {=MMULT(TRANSPOSE(C5:J164),C5:J164)} -> 21 | N5: 0 | O5: -21.006286 | P5: 0 | Q5: -0.086364 | R5: 0.0013588086 | S5: 0.086420175 | T5: 0.0016227248 | V5: {=MMULT(TRANSPOSE(C5:J164),K5:K164)} -> 0.086498173 | W5: b0 | X5: {=MMULT(M14:T21,V5:V12)} -> -8.8198532e-06
A6: 実部 | B6: =データ入力!$A$6 -> 3410 | C6: =IF(データ入力!$A$6="",0,1) -> 1 | D6: 0 | E6: =IF(データ入力!$A$6="",0,-(データ入力!$F$6^2)) -> -0.94923265 | F6: 0 | G6: =IF(データ入力!$A$6="",0,-データ入力!$D$6) -> -9.3e-05 | H6: =IF(データ入力!$A$6="",0,データ入力!$F$6*データ入力!$E$6) -> 0.0033038029 | I6: =IF(データ入力!$A$6="",0,データ入力!$F$6^2*データ入力!$D$6) -> 8.8278637e-05 | J6: =IF(データ入力!$A$6="",0,-データ入力!$F$6^3*データ入力!$E$6) -> -0.0031360776 | K6: =IF(データ入力!$A$6="",0,データ入力!$F$6^4*データ入力!$D$6) -> 8.3796965e-05 | M6: 0 | N6: 21.006286 | O6: 0 | P6: -21.037718 | Q6: -0.0013588086 | R6: -0.086420175 | S6: -0.0016227248 | T6: 0.086498173 | V6: -0.0046040764 | W6: b1 | X6: 0.00016382418
A7: 実部 | B7: =データ入力!$A$7 -> 3420 | C7: =IF(データ入力!$A$7="",0,1) -> 1 | D7: 0 | E7: =IF(データ入力!$A$7="",0,-(データ入力!$F$7^2)) -> -0.95480816 | F7: 0 | G7: =IF(データ入力!$A$7="",0,-データ入力!$D$7) -> -0.000162 | H7: =IF(データ入力!$A$7="",0,データ入力!$F$7*データ入力!$E$7) -> 0.0037874057 | I7: =IF(データ入力!$A$7="",0,データ入力!$F$7^2*データ入力!$D$7) -> 0.00015467892 | J7: =IF(データ入力!$A$7="",0,-データ入力!$F$7^3*データ入力!$E$7) -> -0.0036162459 | K7: =IF(データ入力!$A$7="",0,データ入力!$F$7^4*データ入力!$D$7) -> 0.0001476887 | M7: -21.006286 | N7: 0 | O7: 21.037718 | P7: 0 | Q7: 0.086420175 | R7: 0.0016227248 | S7: -0.086498173 | T7: -0.0046040764 | V7: -0.086598243 | W7: b2 | X7: -7.1350026e-06
A8: 実部 | B8: =データ入力!$A$8 -> 3430 | C8: =IF(データ入力!$A$8="",0,1) -> 1 | D8: 0 | E8: =IF(データ入力!$A$8="",0,-(データ入力!$F$8^2)) -> -0.9604 | F8: 0 | G8: =IF(データ入力!$A$8="",0,-データ入力!$D$8) -> -0.00028 | H8: =IF(データ入力!$A$8="",0,データ入力!$F$8*データ入力!$E$8) -> 0.00442568 | I8: =IF(データ入力!$A$8="",0,データ入力!$F$8^2*データ入力!$D$8) -> 0.000268912 | J8: =IF(データ入力!$A$8="",0,-データ入力!$F$8^3*データ入力!$E$8) -> -0.0042504231 | K8: =IF(データ入力!$A$8="",0,データ入力!$F$8^4*データ入力!$D$8) -> 0.00025826308 | M8: 0 | N8: -21.037718 | O8: 0 | P8: 21.094336 | Q8: -0.0016227248 | R8: 0.086498173 | S8: 0.0046040764 | T8: -0.086598243 | V8: 0.0075895873 | W8: b3 | X8: 0.00016371244
A9: 実部 | B9: =データ入力!$A$9 -> 3440 | C9: =IF(データ入力!$A$9="",0,1) -> 1 | D9: 0 | E9: =IF(データ入力!$A$9="",0,-(データ入力!$F$9^2)) -> -0.96600816 | F9: 0 | G9: =IF(データ入力!$A$9="",0,-データ入力!$D$9) -> -0.000512 | H9: =IF(データ入力!$A$9="",0,データ入力!$F$9*データ入力!$E$9) -> 0.0053693486 | I9: =IF(データ入力!$A$9="",0,データ入力!$F$9^2*データ入力!$D$9) -> 0.00049459618 | J9: =IF(データ入力!$A$9="",0,-データ入力!$F$9^3*データ入力!$E$9) -> -0.0051868346 | K9: =IF(データ入力!$A$9="",0,データ入力!$F$9^4*データ入力!$D$9) -> 0.00047778395 | M9: -0.086364 | N9: -0.0013588086 | O9: 0.086420175 | P9: -0.0016227248 | Q9: 0.0015748866 | R9: 0 | S9: -0.0015702088 | T9: 0 | V9: -0.0015661548 | W9: a0 | X9: 0.99994035
A10: 実部 | B10: =データ入力!$A$10 -> 3450 | C10: =IF(データ入力!$A$10="",0,1) -> 1 | D10: 0 | E10: =IF(データ入力!$A$10="",0,-(データ入力!$F$10^2)) -> -0.97163265 | F10: 0 | G10: =IF(データ入力!$A$10="",0,-データ入力!$D$10) -> -0.001016 | H10: =IF(データ入力!$A$10="",0,データ入力!$F$10*データ入力!$E$10) -> 0.0067560857 | I10: =IF(データ入力!$A$10="",0,データ入力!$F$10^2*データ入力!$D$10) -> 0.00098717878 | J10: =IF(データ入力!$A$10="",0,-データ入力!$F$10^3*データ入力!$E$10) -> -0.0065644335 | K10: =IF(データ入力!$A$10="",0,データ入力!$F$10^4*データ入力!$D$10) -> 0.00095917513 | M10: 0.0013588086 | N10: -0.086420175 | O10: 0.0016227248 | P10: 0.086498173 | Q10: 0 | R10: 0.0015702088 | S10: 1.6199505e-20 | T10: -0.0015661548 | V10: 2.6840357e-20 | W10: a1 | X10: 0.013984335
A11: 実部 | B11: =データ入力!$A$11 -> 3460 | C11: =IF(データ入力!$A$11="",0,1) -> 1 | D11: 0 | E11: =IF(データ入力!$A$11="",0,-(データ入力!$F$11^2)) -> -0.97727347 | F11: 0 | G11: =IF(データ入力!$A$11="",0,-データ入力!$D$11) -> -0.002362 | H11: =IF(データ入力!$A$11="",0,データ入力!$F$11*データ入力!$E$11) -> 0.0089762286 | I11: =IF(データ入力!$A$11="",0,データ入力!$F$11^2*データ入力!$D$11) -> 0.0023083199 | J11: =IF(データ入力!$A$11="",0,-データ入力!$F$11^3*データ入力!$E$11) -> -0.00877223 | K11: =IF(データ入力!$A$11="",0,データ入力!$F$11^4*データ入力!$D$11) -> 0.0022558598 | M11: 0.086420175 | N11: -0.0016227248 | O11: -0.086498173 | P11: 0.0046040764 | Q11: -0.0015702088 | R11: 1.6199505e-20 | S11: 0.0015661548 | T11: -1.4796607e-20 | V11: 0.0015627235 | W11: a2 | X11: 2.0001189
A12: 実部 | B12: =データ入力!$A$12 -> 3470 | C12: =IF(データ入力!$A$12="",0,1) -> 1 | D12: 0 | E12: =IF(データ入力!$A$12="",0,-(データ入力!$F$12^2)) -> -0.98293061 | F12: 0 | G12: =IF(データ入力!$A$12="",0,-データ入力!$D$12) -> -0.006939 | H12: =IF(データ入力!$A$12="",0,データ入力!$F$12*データ入力!$E$12) -> 0.012066677 | I12: =IF(データ入力!$A$12="",0,データ入力!$F$12^2*データ入力!$D$12) -> 0.0068205555 | J12: =IF(データ入力!$A$12="",0,-データ入力!$F$12^3*データ入力!$E$12) -> -0.011860706 | K12: =IF(データ入力!$A$12="",0,データ入力!$F$12^4*データ入力!$D$12) -> 0.0067041328 | M12: 0.0016227248 | N12: 0.086498173 | O12: -0.0046040764 | P12: -0.086598243 | Q12: 0 | R12: -0.0015661548 | S12: -1.4796607e-20 | T12: 0.0015627235 | V12: 0 | W12: a3 | X12: 0.014007476
A13: 実部 | B13: =データ入力!$A$13 -> 3480 | C13: =IF(データ入力!$A$13="",0,1) -> 1 | D13: 0 | E13: =IF(データ入力!$A$13="",0,-(データ入力!$F$13^2)) -> -0.98860408 | F13: 0 | G13: =IF(データ入力!$A$13="",0,-データ入力!$D$13) -> -0.016968 | H13: =IF(データ入力!$A$13="",0,データ入力!$F$13*データ入力!$E$13) -> 0.0070584343 | I13: =IF(データ入力!$A$13="",0,データ入力!$F$13^2*データ入力!$D$13) -> 0.016774634 | J13: =IF(データ入力!$A$13="",0,-データ入力!$F$13^3*データ入力!$E$13) -> -0.0069779969 | K13: =IF(データ入力!$A$13="",0,データ入力!$F$13^4*データ入力!$D$13) -> 0.016583472 | M13: (AᵀA)⁻¹ (8×8)
A14: 実部 | B14: =データ入力!$A$14 -> 3490 | C14: =IF(データ入力!$A$14="",0,1) -> 1 | D14: 0 | E14: =IF(データ入力!$A$14="",0,-(データ入力!$F$14^2)) -> -0.99429388 | F14: 0 | G14: =IF(データ入力!$A$14="",0,-データ入力!$D$14) -> -0.012733 | H14: =IF(データ入力!$A$14="",0,データ入力!$F$14*データ入力!$E$14) -> -0.0021987 | I14: =IF(データ入力!$A$14="",0,データ入力!$F$14^2*データ入力!$D$14) -> 0.012660344 | J14: =IF(データ入力!$A$14="",0,-データ入力!$F$14^3*データ入力!$E$14) -> 0.0021861539 | K14: =IF(データ入力!$A$14="",0,データ入力!$F$14^4*データ入力!$D$14) -> 0.012588102 | M14: {=MINVERSE(M5:T12)} -> 62.862317 | N14: -2.3713514 | O14: 63.806849 | P14: 0.058014335 | Q14: -9104.8611 | R14: 6303.1291 | S14: -9075.7598 | T14: 6574.1513
A15: 実部 | B15: =データ入力!$A$15 -> 3500 | C15: =IF(データ入力!$A$15="",0,1) -> 1 | D15: 0 | E15: =IF(データ入力!$A$15="",0,-(データ入力!$F$15^2)) -> -1 | F15: 0 | G15: =IF(データ入力!$A$15="",0,-データ入力!$D$15) -> -0.009201 | H15: =IF(データ入力!$A$15="",0,データ入力!$F$15*データ入力!$E$15) -> -0.001806 | I15: =IF(データ入力!$A$15="",0,データ入力!$F$15^2*データ入力!$D$15) -> 0.009201 | J15: =IF(データ入力!$A$15="",0,-データ入力!$F$15^3*データ入力!$E$15) -> 0.001806 | K15: =IF(データ入力!$A$15="",0,データ入力!$F$15^4*データ入力!$D$15) -> 0.009201 | M15: -2.3713514 | N15: 61.533713 | O15: -4.7809507 | P15: 61.736181 | Q15: -3015.4204 | R15: -9416.09 | S15: -3274.1568 | T15: -9433.228
A16: 実部 | B16: =データ入力!$A$16 -> 3510 | C16: =IF(データ入力!$A$16="",0,1) -> 1 | D16: 0 | E16: =IF(データ入力!$A$16="",0,-(データ入力!$F$16^2)) -> -1.0057224 | F16: 0 | G16: =IF(データ入力!$A$16="",0,-データ入力!$D$16) -> -0.010162 | H16: =IF(データ入力!$A$16="",0,データ入力!$F$16*データ入力!$E$16) -> -0.0015243429 | I16: =IF(データ入力!$A$16="",0,データ入力!$F$16^2*データ入力!$D$16) -> 0.010220152 | J16: =IF(データ入力!$A$16="",0,-データ入力!$F$16^3*データ入力!$E$16) -> 0.0015330658 | K16: =IF(データ入力!$A$16="",0,データ入力!$F$16^4*データ入力!$D$16) -> 0.010278636 | M16: 63.806849 | N16: -4.7809507 | O16: 65.502472 | P16: -2.3522297 | Q16: -8668.4716 | R16: 9877.4432 | S16: -8592.1224 | T16: 10160.138
A17: 実部 | B17: =データ入力!$A$17 -> 3520 | C17: =IF(データ入力!$A$17="",0,1) -> 1 | D17: 0 | E17: =IF(データ入力!$A$17="",0,-(データ入力!$F$17^2)) -> -1.0114612 | F17: 0 | G17: =IF(データ入力!$A$17="",0,-データ入力!$D$17) -> -0.011108 | H17: =IF(データ入力!$A$17="",0,データ入力!$F$17*データ入力!$E$17) -> -0.0057768229 | I17: =IF(データ入力!$A$17="",0,データ入力!$F$17^2*データ入力!$D$17) -> 0.011235311 | J17: =IF(データ入力!$A$17="",0,-データ入力!$F$17^3*データ入力!$E$17) -> 0.0058430323 | K17: =IF(データ入力!$A$17="",0,データ入力!$F$17^4*データ入力!$D$17) -> 0.011364082 | M17: 0.058014335 | N17: 61.736181 | O17: -2.3522297 | P17: 62.685777 | Q17: -6577.3061 | R17: -9034.3181 | S17: -6847.759 | T17: -9004.57
A18: 実部 | B18: =データ入力!$A$18 -> 3530 | C18: =IF(データ入力!$A$18="",0,1) -> 1 | D18: 0 | E18: =IF(データ入力!$A$18="",0,-(データ入力!$F$18^2)) -> -1.0172163 | F18: 0 | G18: =IF(データ入力!$A$18="",0,-データ入力!$D$18) -> -0.006478 | H18: =IF(データ入力!$A$18="",0,データ入力!$F$18*データ入力!$E$18) -> -0.0087433057 | I18: =IF(データ入力!$A$18="",0,データ入力!$F$18^2*データ入力!$D$18) -> 0.0065895274 | J18: =IF(データ入力!$A$18="",0,-データ入力!$F$18^3*データ入力!$E$18) -> 0.0088938333 | K18: =IF(データ入力!$A$18="",0,データ入力!$F$18^4*データ入力!$D$18) -> 0.0067029748 | M18: -9104.8611 | N18: -3015.4204 | O18: -8668.4716 | P18: -6577.3061 | Q18: 18938975 | R18: 238248.2 | S18: 19027858 | T18: 25112.02
A19: 実部 | B19: =データ入力!$A$19 -> 3540 | C19: =IF(データ入力!$A$19="",0,1) -> 1 | D19: 0 | E19: =IF(データ入力!$A$19="",0,-(データ入力!$F$19^2)) -> -1.0229878 | F19: 0 | G19: =IF(データ入力!$A$19="",0,-データ入力!$D$19) -> -0.003142 | H19: =IF(データ入力!$A$19="",0,データ入力!$F$19*データ入力!$E$19) -> -0.0075604286 | I19: =IF(データ入力!$A$19="",0,データ入力!$F$19^2*データ入力!$D$19) -> 0.0032142275 | J19: =IF(データ入力!$A$19="",0,-データ入力!$F$19^3*データ入力!$E$19) -> 0.0077342259 | K19: =IF(データ入力!$A$19="",0,データ入力!$F$19^4*データ入力!$D$19) -> 0.0032881154 | M19: 6303.1291 | N19: -9416.09 | O19: 9877.4432 | P19: -9034.3181 | Q19: 238248.2 | R19: 18909547 | S19: 453389.2 | T19: 18994176
A20: 実部 | B20: =データ入力!$A$20 -> 3550 | C20: =IF(データ入力!$A$20="",0,1) -> 1 | D20: 0 | E20: =IF(データ入力!$A$20="",0,-(データ入力!$F$20^2)) -> -1.0287755 | F20: 0 | G20: =IF(データ入力!$A$20="",0,-データ入力!$D$20) -> -0.001759 | H20: =IF(データ入力!$A$20="",0,データ入力!$F$20*データ入力!$E$20) -> -0.0061425143 | I20: =IF(データ入力!$A$20="",0,データ入力!$F$20^2*データ入力!$D$20) -> 0.0018096161 | J20: =IF(データ入力!$A$20="",0,-データ入力!$F$20^3*データ入力!$E$20) -> 0.0063192683 | K20: =IF(データ入力!$A$20="",0,データ入力!$F$20^4*データ入力!$D$20) -> 0.0018616887 | M20: -9075.7598 | N20: -3274.1568 | O20: -8592.1224 | P20: -6847.759 | Q20: 19027858 | R20: 453389.2 | S20: 19120748 | T20: 240254.29
A21: 実部 | B21: =データ入力!$A$21 -> 3560 | C21: =IF(データ入力!$A$21="",0,1) -> 1 | D21: 0 | E21: =IF(データ入力!$A$21="",0,-(データ入力!$F$21^2)) -> -1.0345796 | F21: 0 | G21: =IF(データ入力!$A$21="",0,-データ入力!$D$21) -> -0.001128 | H21: =IF(データ入力!$A$21="",0,データ入力!$F$21*データ入力!$E$21) -> -0.0050857143 | I21: =IF(データ入力!$A$21="",0,データ入力!$F$21^2*データ入力!$D$21) -> 0.0011670058 | J21: =IF(データ入力!$A$21="",0,-データ入力!$F$21^3*データ入力!$E$21) -> 0.0052615762 | K21: =IF(データ入力!$A$21="",0,データ入力!$F$21^4*データ入力!$D$21) -> 0.0012073604 | M21: 6574.1513 | N21: -9433.228 | O21: 10160.138 | P21: -9004.57 | Q21: 25112.02 | R21: 18994176 | S21: 240254.29 | T21: 19082778
A22: 実部 | B22: =データ入力!$A$22 -> 3570 | C22: =IF(データ入力!$A$22="",0,1) -> 1 | D22: 0 | E22: =IF(データ入力!$A$22="",0,-(データ入力!$F$22^2)) -> -1.0404 | F22: 0 | G22: =IF(データ入力!$A$22="",0,-データ入力!$D$22) -> -0.000797 | H22: =IF(データ入力!$A$22="",0,データ入力!$F$22*データ入力!$E$22) -> -0.00433092 | I22: =IF(データ入力!$A$22="",0,データ入力!$F$22^2*データ入力!$D$22) -> 0.0008291988 | J22: =IF(データ入力!$A$22="",0,-データ入力!$F$22^3*データ入力!$E$22) -> 0.0045058892 | K22: =IF(データ入力!$A$22="",0,データ入力!$F$22^4*データ入力!$D$22) -> 0.00086269843
A23: 実部 | B23: =データ入力!$A$23 -> 3580 | C23: =IF(データ入力!$A$23="",0,1) -> 1 | D23: 0 | E23: =IF(データ入力!$A$23="",0,-(データ入力!$F$23^2)) -> -1.0462367 | F23: 0 | G23: =IF(データ入力!$A$23="",0,-データ入力!$D$23) -> -0.000602 | H23: =IF(データ入力!$A$23="",0,データ入力!$F$23*データ入力!$E$23) -> -0.0037722971 | I23: =IF(データ入力!$A$23="",0,データ入力!$F$23^2*データ入力!$D$23) -> 0.00062983451 | J23: =IF(データ入力!$A$23="",0,-データ入力!$F$23^3*データ入力!$E$23) -> 0.0039467158 | K23: =IF(データ入力!$A$23="",0,データ入力!$F$23^4*データ入力!$D$23) -> 0.00065895601
A24: 実部 | B24: =データ入力!$A$24 -> 3590 | C24: =IF(データ入力!$A$24="",0,1) -> 1 | D24: 0 | E24: =IF(データ入力!$A$24="",0,-(データ入力!$F$24^2)) -> -1.0520898 | F24: 0 | G24: =IF(データ入力!$A$24="",0,-データ入力!$D$24) -> -0.000478 | H24: =IF(データ入力!$A$24="",0,データ入力!$F$24*データ入力!$E$24) -> -0.0033510086 | I24: =IF(データ入力!$A$24="",0,データ入力!$F$24^2*データ入力!$D$24) -> 0.00050289892 | J24: =IF(データ入力!$A$24="",0,-データ入力!$F$24^3*データ入力!$E$24) -> 0.0035255619 | K24: =IF(データ入力!$A$24="",0,データ入力!$F$24^4*データ入力!$D$24) -> 0.00052909482
A25: 実部 | B25: =データ入力!$A$25 -> 3600 | C25: =IF(データ入力!$A$25="",0,1) -> 1 | D25: 0 | E25: =IF(データ入力!$A$25="",0,-(データ入力!$F$25^2)) -> -1.0579592 | F25: 0 | G25: =IF(データ入力!$A$25="",0,-データ入力!$D$25) -> -0.000393 | H25: =IF(データ入力!$A$25="",0,データ入力!$F$25*データ入力!$E$25) -> -0.0030168 | I25: =IF(データ入力!$A$25="",0,データ入力!$F$25^2*データ入力!$D$25) -> 0.00041577796 | J25: =IF(データ入力!$A$25="",0,-データ入力!$F$25^3*データ入力!$E$25) -> 0.0031916513 | K25: =IF(データ入力!$A$25="",0,データ入力!$F$25^4*データ入力!$D$25) -> 0.00043987611
A26: 実部 | B26: =データ入力!$A$26 -> 0 | C26: =IF(データ入力!$A$26="",0,1) -> 0 | D26: 0 | E26: =IF(データ入力!$A$26="",0,-(データ入力!$F$26^2)) -> 0 | F26: 0 | G26: =IF(データ入力!$A$26="",0,-データ入力!$D$26) -> 0 | H26: =IF(データ入力!$A$26="",0,データ入力!$F$26*データ入力!$E$26) -> 0 | I26: =IF(データ入力!$A$26="",0,データ入力!$F$26^2*データ入力!$D$26) -> 0 | J26: =IF(データ入力!$A$26="",0,-データ入力!$F$26^3*データ入力!$E$26) -> 0 | K26: =IF(データ入力!$A$26="",0,データ入力!$F$26^4*データ入力!$D$26) -> 0
A27: 実部 | B27: =データ入力!$A$27 -> 0 | C27: =IF(データ入力!$A$27="",0,1) -> 0 | D27: 0 | E27: =IF(データ入力!$A$27="",0,-(データ入力!$F$27^2)) -> 0 | F27: 0 | G27: =IF(データ入力!$A$27="",0,-データ入力!$D$27) -> 0 | H27: =IF(データ入力!$A$27="",0,データ入力!$F$27*データ入力!$E$27) -> 0 | I27: =IF(データ入力!$A$27="",0,データ入力!$F$27^2*データ入力!$D$27) -> 0 | J27: =IF(データ入力!$A$27="",0,-データ入力!$F$27^3*データ入力!$E$27) -> 0 | K27: =IF(データ入力!$A$27="",0,データ入力!$F$27^4*データ入力!$D$27) -> 0
A28: 実部 | B28: =データ入力!$A$28 -> 0 | C28: =IF(データ入力!$A$28="",0,1) -> 0 | D28: 0 | E28: =IF(データ入力!$A$28="",0,-(データ入力!$F$28^2)) -> 0 | F28: 0 | G28: =IF(データ入力!$A$28="",0,-データ入力!$D$28) -> 0 | H28: =IF(データ入力!$A$28="",0,データ入力!$F$28*データ入力!$E$28) -> 0 | I28: =IF(データ入力!$A$28="",0,データ入力!$F$28^2*データ入力!$D$28) -> 0 | J28: =IF(データ入力!$A$28="",0,-データ入力!$F$28^3*データ入力!$E$28) -> 0 | K28: =IF(データ入力!$A$28="",0,データ入力!$F$28^4*データ入力!$D$28) -> 0
A29: 実部 | B29: =データ入力!$A$29 -> 0 | C29: =IF(データ入力!$A$29="",0,1) -> 0 | D29: 0 | E29: =IF(データ入力!$A$29="",0,-(データ入力!$F$29^2)) -> 0 | F29: 0 | G29: =IF(データ入力!$A$29="",0,-データ入力!$D$29) -> 0 | H29: =IF(データ入力!$A$29="",0,データ入力!$F$29*データ入力!$E$29) -> 0 | I29: =IF(データ入力!$A$29="",0,データ入力!$F$29^2*データ入力!$D$29) -> 0 | J29: =IF(データ入力!$A$29="",0,-データ入力!$F$29^3*データ入力!$E$29) -> 0 | K29: =IF(データ入力!$A$29="",0,データ入力!$F$29^4*データ入力!$D$29) -> 0
A30: 実部 | B30: =データ入力!$A$30 -> 0 | C30: =IF(データ入力!$A$30="",0,1) -> 0 | D30: 0 | E30: =IF(データ入力!$A$30="",0,-(データ入力!$F$30^2)) -> 0 | F30: 0 | G30: =IF(データ入力!$A$30="",0,-データ入力!$D$30) -> 0 | H30: =IF(データ入力!$A$30="",0,データ入力!$F$30*データ入力!$E$30) -> 0 | I30: =IF(データ入力!$A$30="",0,データ入力!$F$30^2*データ入力!$D$30) -> 0 | J30: =IF(データ入力!$A$30="",0,-データ入力!$F$30^3*データ入力!$E$30) -> 0 | K30: =IF(データ入力!$A$30="",0,データ入力!$F$30^4*データ入力!$D$30) -> 0
A31: 実部 | B31: =データ入力!$A$31 -> 0 | C31: =IF(データ入力!$A$31="",0,1) -> 0 | D31: 0 | E31: =IF(データ入力!$A$31="",0,-(データ入力!$F$31^2)) -> 0 | F31: 0 | G31: =IF(データ入力!$A$31="",0,-データ入力!$D$31) -> 0 | H31: =IF(データ入力!$A$31="",0,データ入力!$F$31*データ入力!$E$31) -> 0 | I31: =IF(データ入力!$A$31="",0,データ入力!$F$31^2*データ入力!$D$31) -> 0 | J31: =IF(データ入力!$A$31="",0,-データ入力!$F$31^3*データ入力!$E$31) -> 0 | K31: =IF(データ入力!$A$31="",0,データ入力!$F$31^4*データ入力!$D$31) -> 0
A32: 実部 | B32: =データ入力!$A$32 -> 0 | C32: =IF(データ入力!$A$32="",0,1) -> 0 | D32: 0 | E32: =IF(データ入力!$A$32="",0,-(データ入力!$F$32^2)) -> 0 | F32: 0 | G32: =IF(データ入力!$A$32="",0,-データ入力!$D$32) -> 0 | H32: =IF(データ入力!$A$32="",0,データ入力!$F$32*データ入力!$E$32) -> 0 | I32: =IF(データ入力!$A$32="",0,データ入力!$F$32^2*データ入力!$D$32) -> 0 | J32: =IF(データ入力!$A$32="",0,-データ入力!$F$32^3*データ入力!$E$32) -> 0 | K32: =IF(データ入力!$A$32="",0,データ入力!$F$32^4*データ入力!$D$32) -> 0
A33: 実部 | B33: =データ入力!$A$33 -> 0 | C33: =IF(データ入力!$A$33="",0,1) -> 0 | D33: 0 | E33: =IF(データ入力!$A$33="",0,-(データ入力!$F$33^2)) -> 0 | F33: 0 | G33: =IF(データ入力!$A$33="",0,-データ入力!$D$33) -> 0 | H33: =IF(データ入力!$A$33="",0,データ入力!$F$33*データ入力!$E$33) -> 0 | I33: =IF(データ入力!$A$33="",0,データ入力!$F$33^2*データ入力!$D$33) -> 0 | J33: =IF(データ入力!$A$33="",0,-データ入力!$F$33^3*データ入力!$E$33) -> 0 | K33: =IF(データ入力!$A$33="",0,データ入力!$F$33^4*データ入力!$D$33) -> 0
A34: 実部 | B34: =データ入力!$A$34 -> 0 | C34: =IF(データ入力!$A$34="",0,1) -> 0 | D34: 0 | E34: =IF(データ入力!$A$34="",0,-(データ入力!$F$34^2)) -> 0 | F34: 0 | G34: =IF(データ入力!$A$34="",0,-データ入力!$D$34) -> 0 | H34: =IF(データ入力!$A$34="",0,データ入力!$F$34*データ入力!$E$34) -> 0 | I34: =IF(データ入力!$A$34="",0,データ入力!$F$34^2*データ入力!$D$34) -> 0 | J34: =IF(データ入力!$A$34="",0,-データ入力!$F$34^3*データ入力!$E$34) -> 0 | K34: =IF(データ入力!$A$34="",0,データ入力!$F$34^4*データ入力!$D$34) -> 0
A35: 実部 | B35: =データ入力!$A$35 -> 0 | C35: =IF(データ入力!$A$35="",0,1) -> 0 | D35: 0 | E35: =IF(データ入力!$A$35="",0,-(データ入力!$F$35^2)) -> 0 | F35: 0 | G35: =IF(データ入力!$A$35="",0,-データ入力!$D$35) -> 0 | H35: =IF(データ入力!$A$35="",0,データ入力!$F$35*データ入力!$E$35) -> 0 | I35: =IF(データ入力!$A$35="",0,データ入力!$F$35^2*データ入力!$D$35) -> 0 | J35: =IF(データ入力!$A$35="",0,-データ入力!$F$35^3*データ入力!$E$35) -> 0 | K35: =IF(データ入力!$A$35="",0,データ入力!$F$35^4*データ入力!$D$35) -> 0
A36: 実部 | B36: =データ入力!$A$36 -> 0 | C36: =IF(データ入力!$A$36="",0,1) -> 0 | D36: 0 | E36: =IF(データ入力!$A$36="",0,-(データ入力!$F$36^2)) -> 0 | F36: 0 | G36: =IF(データ入力!$A$36="",0,-データ入力!$D$36) -> 0 | H36: =IF(データ入力!$A$36="",0,データ入力!$F$36*データ入力!$E$36) -> 0 | I36: =IF(データ入力!$A$36="",0,データ入力!$F$36^2*データ入力!$D$36) -> 0 | J36: =IF(データ入力!$A$36="",0,-データ入力!$F$36^3*データ入力!$E$36) -> 0 | K36: =IF(データ入力!$A$36="",0,データ入力!$F$36^4*データ入力!$D$36) -> 0
A37: 実部 | B37: =データ入力!$A$37 -> 0 | C37: =IF(データ入力!$A$37="",0,1) -> 0 | D37: 0 | E37: =IF(データ入力!$A$37="",0,-(データ入力!$F$37^2)) -> 0 | F37: 0 | G37: =IF(データ入力!$A$37="",0,-データ入力!$D$37) -> 0 | H37: =IF(データ入力!$A$37="",0,データ入力!$F$37*データ入力!$E$37) -> 0 | I37: =IF(データ入力!$A$37="",0,データ入力!$F$37^2*データ入力!$D$37) -> 0 | J37: =IF(データ入力!$A$37="",0,-データ入力!$F$37^3*データ入力!$E$37) -> 0 | K37: =IF(データ入力!$A$37="",0,データ入力!$F$37^4*データ入力!$D$37) -> 0
A38: 実部 | B38: =データ入力!$A$38 -> 0 | C38: =IF(データ入力!$A$38="",0,1) -> 0 | D38: 0 | E38: =IF(データ入力!$A$38="",0,-(データ入力!$F$38^2)) -> 0 | F38: 0 | G38: =IF(データ入力!$A$38="",0,-データ入力!$D$38) -> 0 | H38: =IF(データ入力!$A$38="",0,データ入力!$F$38*データ入力!$E$38) -> 0 | I38: =IF(データ入力!$A$38="",0,データ入力!$F$38^2*データ入力!$D$38) -> 0 | J38: =IF(データ入力!$A$38="",0,-データ入力!$F$38^3*データ入力!$E$38) -> 0 | K38: =IF(データ入力!$A$38="",0,データ入力!$F$38^4*データ入力!$D$38) -> 0
A39: 実部 | B39: =データ入力!$A$39 -> 0 | C39: =IF(データ入力!$A$39="",0,1) -> 0 | D39: 0 | E39: =IF(データ入力!$A$39="",0,-(データ入力!$F$39^2)) -> 0 | F39: 0 | G39: =IF(データ入力!$A$39="",0,-データ入力!$D$39) -> 0 | H39: =IF(データ入力!$A$39="",0,データ入力!$F$39*データ入力!$E$39) -> 0 | I39: =IF(データ入力!$A$39="",0,データ入力!$F$39^2*データ入力!$D$39) -> 0 | J39: =IF(データ入力!$A$39="",0,-データ入力!$F$39^3*データ入力!$E$39) -> 0 | K39: =IF(データ入力!$A$39="",0,データ入力!$F$39^4*データ入力!$D$39) -> 0
A40: 実部 | B40: =データ入力!$A$40 -> 0 | C40: =IF(データ入力!$A$40="",0,1) -> 0 | D40: 0 | E40: =IF(データ入力!$A$40="",0,-(データ入力!$F$40^2)) -> 0 | F40: 0 | G40: =IF(データ入力!$A$40="",0,-データ入力!$D$40) -> 0 | H40: =IF(データ入力!$A$40="",0,データ入力!$F$40*データ入力!$E$40) -> 0 | I40: =IF(データ入力!$A$40="",0,データ入力!$F$40^2*データ入力!$D$40) -> 0 | J40: =IF(データ入力!$A$40="",0,-データ入力!$F$40^3*データ入力!$E$40) -> 0 | K40: =IF(データ入力!$A$40="",0,データ入力!$F$40^4*データ入力!$D$40) -> 0
...

Sheet モード分離結果
A1: モード分離結果 ― 2つのモードの固有振動数fnと損失係数η（★答えはここ）
B3: モードA（低い方） | C3: モードB（高い方） | D3: 備考
A4: 固有振動数 fn [Hz] | B4: =IF(B67="","",MIN(B65,B66)) -> 3480.0075 | C4: =IF(B67="","",MAX(B65,B66)) -> 3520.0024 | D4: 小さい方をモードAとして表示
A5: 損失係数 η | B5: =IF(B67="","",IF(B65<=B66,C65,C66)) -> 0.00600372 | C5: =IF(B67="","",IF(B65<=B66,C66,C65)) -> 0.0079923745 | D5: fnと対になる損失係数
A6: 判定 | B6: =B67 -> OK：正常に分離できました
A8: 判定が「要確認」の場合は、下の詳細計算欄にある「分解の判定」「uしきい値判定」「最終判定」の行で理由（前提条件・境界条件）を確認してください。「OK」の場合でも、検算シートで既知サンプルとの整合を確認しておくと安心です。
A11: ▼ 詳細計算：4次方程式 s⁴+a3s³+a2s²+a1s+a0 = (s²+p1s+q1)(s²+p2s+q2) に閉形式で分解
A13: a0 (RFP計算より) | B13: =RFP計算!$X$9 -> 0.99994035
A14: a1 | B14: =RFP計算!$X$10 -> 0.013984335
A15: a2 | B15: =RFP計算!$X$11 -> 2.0001189
A16: a3 | B16: =RFP計算!$X$12 -> 0.014007476
A18: p（depress） | B18: =B15-3*B16^2/8 -> 2.0000453 | C18: s=z-a3/4 と置いて3次の項を消した4次式 z⁴+pz²+qz+r の係数
A19: q（depress） | B19: =B14-B15*B16/2+B16^3/8 -> -2.3630911e-05
A20: r（depress） | B20: =B13-B14*B16/4+B15*B16^2/16-3*B16^4/256 -> 0.99991591
A22: レゾルベント3次方程式 u³+Ac2 u²+Ac1 u+Ac0=0 を解いて u=α² を求める
A23: Ac2 = 2p | B23: =2*B18 -> 4.0000907
A24: Ac1 = p²-4r | B24: =B18^2-4*B20 -> 0.0005177051
A25: Ac0 = -q² | B25: =-(B19^2) -> -5.5841995e-10
A26: P（レゾルベント depress） | B26: =B24-B23^2/3 -> -5.3330574
A27: Q（レゾルベント depress） | B27: =2*B23^3/27-B23*B24/3+B25 -> 4.7403729
A28: 分解の判定：レゾルベントのP<0か | B28: =B26<0 -> TRUE | C28: TRUEなら以下の三角関数解法（実根3つ）が使えます。FALSEな場合は既存ガイド4-5節のSolver法に切替えてください。
A29: m = 2√(-P/3) | B29: =2*SQRT(MAX(-B26/3,0.0000000000001)) -> 2.6665977
A30: θ = ACOS( clip(3Q/(Pm)) )/3 | B30: =ACOS(MAX(-1,MIN(1,IF(OR(B26=0,B29=0),0,3*B27/(B26*B29)))))/3 -> 1.0471691
A31: u1(仮) = m・cosθ - Ac2/3 | B31: =B29*COS(B30)-B23/3 -> 1.0698027e-06
A32: u2(仮) = m・cos(θ-2π/3) - Ac2/3 | B32: =B29*COS(B30-2*PI()/3)-B23/3 -> -0.00013049737
A33: u3(仮) = m・cos(θ-4π/3) - Ac2/3 | B33: =B29*COS(B30-4*PI()/3)-B23/3 -> -3.9999612
A35: 桁落ち対策（deflation）：3根のうち絶対値が最大＝計算精度の良いものだけ直接採用し、残り2根は代数的に分離
A36: u_safe（3仮根のうち|値|最大＝安全に計算できているもの） | B36: =IF(ABS(B31)>=ABS(B32),IF(ABS(B31)>=ABS(B33),B31,B33),IF(ABS(B32)>=ABS(B33),B32,B33)) -> -3.9999612
A37: B'（残り2根の和の符号反転：ヴィエタの公式） | B37: =B23+B36 -> 0.00012942756
A38: C'（残り2根の積：ヴィエタの公式） | B38: =IFERROR(-B25/B36,0) -> -1.3960634e-10
A39: 残り2根の判別式 | B39: =MAX(B37^2-4*B38,0) -> 1.7309919e-08
A40: 符号が桁落ちしない側の根（大きい方） | B40: =(-B37-IF(B37>=0,1,-1)*SQRT(B39))/2 -> -0.00013049736
A41: もう一方の根＝C'÷大きい方（割り算なので桁落ちしない） | B41: =IFERROR(B38/B40,(-B37+SQRT(B39))/2) -> 1.069802e-06
A42: u = MAX(全ての候補, 0) ←これを採用 | B42: =MAX(B40,B41,B36,0) -> 1.069802e-06
A43: u しきい値判定 | B43: =B42>=設定!$B$12 -> TRUE
A45: α・β・γ を求め、2つの2次式 s²+p1s+q1=0 と s²+p2s+q2=0 に戻す
A46: α = √u | B46: =IFERROR(SQRT(B42),"") -> 0.0010343123
A47: β | B47: =IF(B46="","",((B18+B42)-B19/B46)/2) -> 1.0114467
A48: γ | B48: =IF(B46="","",((B18+B42)+B19/B46)/2) -> 0.98859971
A49: p1 = a3/2 + α | B49: =IF(B46="","",B16/2+B46) -> 0.0080380506
...

Sheet 検算
A1: 検算 ― このワークブックが正しく計算できているかのセルフチェック
A2: ★重要：この検算は「データ入力シートに、出荷時のままのサンプルデータが入っている」ことが前提です。ご自身の測定データに上書きした後は、この検算シートの「一致判定」は意味を持ちません（上書き後は代わりに、モード分離結果シートの判定欄と、物理的な妥当性で確認してください）。
B4: 期待値 (既存ガイドで検証済み) | C4: 実際の計算結果 | D4: 誤差 | E4: 判定
A5: モードA fn [Hz] | B5: 3480.01 | C5: =モード分離結果!$B$4 -> 3480.0075 | D5: =ABS(C5-B5)/B5 -> 7.1211367e-07 | E5: =IF(D5<0.005,"OK","要確認") -> OK
A6: モードA η | B6: 0.006004 | C6: =モード分離結果!$B$5 -> 0.00600372 | D6: =ABS(C6-B6)/B6 -> 4.6639768e-05 | E6: =IF(D6<0.03,"OK","要確認") -> OK
A7: モードB fn [Hz] | B7: 3520 | C7: =モード分離結果!$C$4 -> 3520.0024 | D7: =ABS(C7-B7)/B7 -> 6.6873122e-07 | E7: =IF(D7<0.005,"OK","要確認") -> OK
A8: モードB η | B8: 0.007992 | C8: =モード分離結果!$C$5 -> 0.0079923745 | D8: =ABS(C8-B8)/B8 -> 4.6855667e-05 | E8: =IF(D8<0.03,"OK","要確認") -> OK
A10: 総合判定 | B10: =IF(COUNTIF(E5:E8,"要確認")=0,"🟢 OK：正しく計算できています","🔴 要確認：計算がズレています。データ入力シートがサンプルのままか確認してください") -> 🟢 OK：正しく計算できています
A12: ・期待値は、既存ガイド（カーブフィット_窓関数_Excel解析ガイド.html）と同じ21点のサンプルデータを、Python(NumPy)で二重計算して得たものです。固有値問題(numpy.roots)による厳密解と、本ワークブックのFerrari閉形式法（数式のみ）の両方が、この値に一致することを確認済みです。
A13: ・fnの許容誤差0.5%、ηの許容誤差3%としているのは、Excel/LibreOfficeとPythonの浮動小数点演算の実装差（丸め誤差）を吸収するためのマージンです。
