Workbook

Sheet 使い方
A1: ブレーキパッド 固有振動数予測ブック
A2: 材質・寸法 → 固有振動数・スペクトル・鳴きリスク／実測ピーク → 材質の逆算 | Ver 1.0
A5: ■ このブックで何ができるか
A6: ① 順算（じゅんざん） | B6: 材質と寸法を入れる → 固有振動数を予測 | C6: シート：形状 → 断面 → 固有振動数
A7: ② スペクトル | B7: 予測した山（ピーク）を並べて、FFT画面そっくりのグラフを作る | C7: シート：スペクトル
A8: ③ 鳴きリスク判定 | B8: その寸法だと鳴きやすいかを点数化 | C8: シート：鳴きリスク
A9: ④ 逆算 | B9: 実測したピーク周波数 → 摩擦材のヤング率を逆に求める | C9: シート：逆算
A11: ■ 触るセルの色分け
A12: アンバー（茶色）のセル | B12: あなたが入力するところ。ここだけ触ればOK | C12: 入力
A13: グリーンのセル | B13: 自動計算の結果。触ると壊れます | C13: 出力
A14: グレーのセル | B14: 計算の途中。見なくてよい | C14: 中間
A16: ■ 使う順番（この順で必ず動きます）
A17: STEP 1 | B17: 「材料DB」で使う材料を確認（無ければ行を追加）
A18: STEP 2 | B18: 「形状」に パッド外形の頂点座標（X,Y）を 12/14/16 点まで入力 | C18: 右のプリセットをコピペでもOK
A19: STEP 3 | B19: 「断面」で 層（シム／裏板／接着／摩擦材）の材料と厚さを入力
A20: STEP 4 | B20: 「固有振動数」を見る → 予測ピーク一覧が出る
A21: STEP 5 | B21: 「スペクトル」でグラフ確認。A〜E列をコピーすれば他ソフトに貼れる
A22: STEP 6 | B22: 「鳴きリスク」でディスク（ローター）の固有振動数を入れて判定
A23: STEP 7 | B23: 実測値があれば「逆算」で摩擦材のヤング率を求める
A25: ■ 信頼度マーク
A26: 🟢 検証済み | B26: 教科書・規格に載っている確立した式。そのまま信じてよい
A27: 🟡 推定 | B27: 妥当だが近似。実測で校正してから使う
A28: 🔴 要確認 | B28: 値のばらつきが大きい。必ず自分で測る
A30: ■ 重要な前提（ここを外すと全部ずれます）
A31: 自由−自由（free-free） | B31: ピアノ線で吊った状態＝どこも固定していない状態を仮定 | C31: 🟢
A32: はり（梁）近似 | B32: パッドを「円周方向に長い1本の棒」とみなす。曲率は無視 | C32: 🟡
A33: 摩擦材のヤング率 | B33: 配合で 0.5〜35 GPa と 70倍以上ばらつく。ここが最大の誤差源 | C33: 🔴
A34: この予測は CEA ではない | B34: 鳴きリスクは「素通し検査」。本番の不安定性判定は複素固有値解析(CEA)で | C34: 🟡

Sheet 材料DB
A1: 材料データベース
A2: E=ヤング率（かたさ）／ρ=密度（重さ）／ν=ポアソン比／η=損失係数（振動の減りやすさ）
A4: 材料名 | B4: E [GPa] | C4: ρ [kg/m³] | D4: ν | E4: η(目安) | F4: 分類 | G4: 信頼度 | H4: 出典・備考
A5: 鋼 SPCC(裏板) | B5: 205 | C5: 7850 | D5: 0.3 | E5: 0.0002 | F5: 金属 | G5: 🟢 | H5: JIS一般値 / 鋼のEは190-210GPa
A6: 鋼 SS400 | B6: 205 | C6: 7850 | D6: 0.3 | E6: 0.0002 | F6: 金属 | G6: 🟢 | H6: JIS一般値
A7: 鋼 S45C | B7: 205 | C7: 7850 | D7: 0.3 | E7: 0.0002 | F7: 金属 | G7: 🟢 | H7: JIS一般値
A8: ステンレス SUS304 | B8: 193 | C8: 7930 | D8: 0.3 | E8: 0.0005 | F8: 金属 | G8: 🟢 | H8: JIS一般値
A9: ばね鋼 SUP9 | B9: 206 | C9: 7850 | D9: 0.3 | E9: 0.0002 | F9: 金属 | G9: 🟢 | H9: JIS一般値
A10: ねずみ鋳鉄 FC250 | B10: 105 | C10: 7200 | D10: 0.26 | E10: 0.0015 | F10: 金属 | G10: 🟡 | H10: 90-120GPaの幅あり。黒鉛量で変化
A11: アルミ A5052 | B11: 70 | C11: 2680 | D11: 0.33 | E11: 0.0001 | F11: 金属 | G11: 🟢 | H11: JIS一般値
A12: アルミ A6061-T6 | B12: 69 | C12: 2700 | D12: 0.33 | E12: 0.0001 | F12: 金属 | G12: 🟢 | H12: JIS一般値
A13: チタン Ti-6Al-4V | B13: 114 | C13: 4430 | D13: 0.34 | E13: 0.0002 | F13: 金属 | G13: 🟢 | H13: ASTM Grade5
A14: 銅 C1100 | B14: 117 | C14: 8940 | D14: 0.34 | E14: 0.002 | F14: 金属 | G14: 🟢 | H14: JIS一般値
A15: 黄銅 C2600 | B15: 103 | C15: 8530 | D15: 0.35 | E15: 0.001 | F15: 金属 | G15: 🟢 | H15: JIS一般値
A16: 摩擦材 NAO(軟) | B16: 0.5 | C16: 2400 | D16: 0.25 | E16: 0.05 | F16: 摩擦材 | G16: 🟡 | H16: 文献値0.5-1.5GPa (Belhocine 2016系)
... A27: (未使用) | B27: 0 | C27: 1 | D27: 0 | E27: 0 | F27: - | G27: - | H27: 空欄行。使わない層に指定する
A29: ※ 行を追加するときは 40行目までに書けば全シートが自動で拾います。
A30: ※ 摩擦材のEは配合で 0.5〜35 GPa（70倍）変わる。予測精度を決める最大要因なので「逆算」シートで自分の材料を同定してください。

Sheet 形状
A1: ① 形状入力（パッド外形を多角形で入力）
A2: X=円周方向（長手）、Y=半径方向。単位はすべて mm。頂点は最大16点。反時計回り・時計回りどちらでもOK | E2: 頂点数 N | F2: =COUNT($B$5:$B$20) -> 14
E3: 向き s (+1=反時計/-1=時計) | F3: =IF(SUM($I$5:$I$20)>=0,1,-1) -> 1
A4: No | B4: X [mm] | C4: Y [mm] | D4: 使用 | E4: 次X | F4: 次Y | G4: 前X | H4: 前Y | I4: 外積項 | J4: 辺長 | K4: Ixx項 | L4: Iyy項 | M4: Ixy項 | N4: Cx項 | O4: Cy項 | P4: 内積 | Q4: 外積 | R4: 内角 [°] | S4: 外角 [°] | T4: 出隅/入隅 | V4: ■ プリセット（コピーして B5:C20 に貼る）
A5: 1 | B5: -37.42 | C5: -25.95 | D5: =IF(ROW()-4<=$F$2,1,0) -> 1 | E5: =IF($D5=0,0,INDEX($B$5:$B$20,IF(ROW()-4=$F$2,1,ROW()-4+1))) -> -25.36 | F5: =IF($D5=0,0,INDEX($C$5:$C$20,IF(ROW()-4=$F$2,1,ROW()-4+1))) -> -21.56 | G5: =IF($D5=0,0,INDEX($B$5:$B$20,IF(ROW()-4=1,$F$2,ROW()-4-1))) -> -57.76 | H5: =IF($D5=0,0,INDEX($C$5:$C$20,IF(ROW()-4=1,$F$2,ROW()-4-1))) -> 19.72 | I5: =IF($D5=0,0,B5*F5-E5*C5) -> 148.6832 | J5: =IF($D5=0,0,SQRT((E5-B5)^2+(F5-C5)^2)) -> 12.834161 | K5: =IF($D5=0,0,(C5^2+C5*F5+F5^2)*I5) -> 252422.16 | L5: =IF($D5=0,0,(B5^2+B5*E5+E5^2)*I5) -> 444913.24 | M5: =IF($D5=0,0,(B5*F5+2*B5*C5+2*E5*F5+E5*C5)*I5) -> 669147.02 | N5: =IF($D5=0,0,(B5+E5)*I5) -> -9334.3313 | O5: =IF($D5=0,0,(C5+F5)*I5) -> -7063.9388 | P5: =IF($D5=0,0,(G5-B5)*(E5-B5)+(H5-C5)*(F5-C5)) -> -44.8091 | Q5: =IF($D5=0,0,(G5-B5)*(F5-C5)-(H5-C5)*(E5-B5)) -> -640.0728 | R5: =IF($D5=0,"",IFERROR(MOD(DEGREES(ATAN2(P5,-$F$3*Q5)),360),"")) -> 94.00453 | S5: =IF($D5=0,"",180-R5) -> 85.99547 | T5: =IF($D5=0,"",IF(R5>180,"入隅(凹)","出隅(凸)")) -> 出隅(凸) | V5: 12点(スリット無) | X5: 14点(スリット無) | Z5: 16点(スリット有→入隅2)
A6: 2 | B6: -25.36 | C6: -21.56 | D6: =IF(ROW()-4<=$F$2,1,0) -> 1 | E6: =IF($D6=0,0,INDEX($B$5:$B$20,IF(ROW()-4=$F$2,1,ROW()-4+1))) -> -12.8 | F6: =IF($D6=0,0,INDEX($C$5:$C$20,IF(ROW()-4=$F$2,1,ROW()-4+1))) -> -18.9 | G6: =IF($D6=0,0,INDEX($B$5:$B$20,IF(ROW()-4=1,$F$2,ROW()-4-1))) -> -37.42 | H6: =IF($D6=0,0,INDEX($C$5:$C$20,IF(ROW()-4=1,$F$2,ROW()-4-1))) -> -25.95 | I6: =IF($D6=0,0,B6*F6-E6*C6) -> 203.336 | J6: =IF($D6=0,0,SQRT((E6-B6)^2+(F6-C6)^2)) -> 12.838582 | K6: =IF($D6=0,0,(C6^2+C6*F6+F6^2)*I6) -> 250007.22 | L6: =IF($D6=0,0,(B6^2+B6*E6+E6^2)*I6) -> 230090.46 | M6: =IF($D6=0,0,(B6*F6+2*B6*C6+2*E6*F6+E6*C6)*I6) -> 474308.71 | N6: =IF($D6=0,0,(B6+E6)*I6) -> -7759.3018 | O6: =IF($D6=0,0,(C6+F6)*I6) -> -8226.9746 | P6: =IF($D6=0,0,(G6-B6)*(E6-B6)+(H6-C6)*(F6-C6)) -> -163.151 | Q6: =IF($D6=0,0,(G6-B6)*(F6-C6)-(H6-C6)*(E6-B6)) -> 23.0588 | R6: =IF($D6=0,"",IFERROR(MOD(DEGREES(ATAN2(P6,-$F$3*Q6)),360),"")) -> 188.04457 | S6: =IF($D6=0,"",180-R6) -> -8.0445656 | T6: =IF($D6=0,"",IF(R6>180,"入隅(凹)","出隅(凸)")) -> 入隅(凹) | V6: X | W6: Y | X6: X | Y6: Y | Z6: X | AA6: Y
A7: 3 | B7: -12.8 | C7: -18.9 | D7: =IF(ROW()-4<=$F$2,1,0) -> 1 | E7: =IF($D7=0,0,INDEX($B$5:$B$20,IF(ROW()-4=$F$2,1,ROW()-4+1))) -> 0 | F7: =IF($D7=0,0,INDEX($C$5:$C$20,IF(ROW()-4=$F$2,1,ROW()-4+1))) -> -18 | G7: =IF($D7=0,0,INDEX($B$5:$B$20,IF(ROW()-4=1,$F$2,ROW()-4-1))) -> -25.36 | H7: =IF($D7=0,0,INDEX($C$5:$C$20,IF(ROW()-4=1,$F$2,ROW()-4-1))) -> -21.56 | I7: =IF($D7=0,0,B7*F7-E7*C7) -> 230.4 | J7: =IF($D7=0,0,SQRT((E7-B7)^2+(F7-C7)^2)) -> 12.831602 | K7: =IF($D7=0,0,(C7^2+C7*F7+F7^2)*I7) -> 235332.86 | L7: =IF($D7=0,0,(B7^2+B7*E7+E7^2)*I7) -> 37748.736 | M7: =IF($D7=0,0,(B7*F7+2*B7*C7+2*E7*F7+E7*C7)*I7) -> 164560.9 | N7: =IF($D7=0,0,(B7+E7)*I7) -> -2949.12 | O7: =IF($D7=0,0,(C7+F7)*I7) -> -8501.76 | P7: =IF($D7=0,0,(G7-B7)*(E7-B7)+(H7-C7)*(F7-C7)) -> -163.162 | Q7: =IF($D7=0,0,(G7-B7)*(F7-C7)-(H7-C7)*(E7-B7)) -> 22.744 | R7: =IF($D7=0,"",IFERROR(MOD(DEGREES(ATAN2(P7,-$F$3*Q7)),360),"")) -> 187.93562 | S7: =IF($D7=0,"",180-R7) -> -7.9356214 | T7: =IF($D7=0,"",IF(R7>180,"入隅(凹)","出隅(凸)")) -> 入隅(凹) | V7: -37.42 | W7: -25.95 | X7: -37.42 | Y7: -25.95 | Z7: -37.42 | AA7: -25.95
A8: 4 | B8: 0 | C8: -18 | D8: =IF(ROW()-4<=$F$2,1,0) -> 1 | E8: =IF($D8=0,0,INDEX($B$5:$B$20,IF(ROW()-4=$F$2,1,ROW()-4+1))) -> 12.8 | F8: =IF($D8=0,0,INDEX($C$5:$C$20,IF(ROW()-4=$F$2,1,ROW()-4+1))) -> -18.9 | G8: =IF($D8=0,0,INDEX($B$5:$B$20,IF(ROW()-4=1,$F$2,ROW()-4-1))) -> -12.8 | H8: =IF($D8=0,0,INDEX($C$5:$C$20,IF(ROW()-4=1,$F$2,ROW()-4-1))) -> -18.9 | I8: =IF($D8=0,0,B8*F8-E8*C8) -> 230.4 | J8: =IF($D8=0,0,SQRT((E8-B8)^2+(F8-C8)^2)) -> 12.831602 | K8: =IF($D8=0,0,(C8^2+C8*F8+F8^2)*I8) -> 235332.86 | L8: =IF($D8=0,0,(B8^2+B8*E8+E8^2)*I8) -> 37748.736 | M8: =IF($D8=0,0,(B8*F8+2*B8*C8+2*E8*F8+E8*C8)*I8) -> -164560.9 | N8: =IF($D8=0,0,(B8+E8)*I8) -> 2949.12 | O8: =IF($D8=0,0,(C8+F8)*I8) -> -8501.76 | P8: =IF($D8=0,0,(G8-B8)*(E8-B8)+(H8-C8)*(F8-C8)) -> -163.03 | Q8: =IF($D8=0,0,(G8-B8)*(F8-C8)-(H8-C8)*(E8-B8)) -> 23.04 | R8: =IF($D8=0,"",IFERROR(MOD(DEGREES(ATAN2(P8,-$F$3*Q8)),360),"")) -> 188.04398 | S8: =IF($D8=0,"",180-R8) -> -8.0439804 | T8: =IF($D8=0,"",IF(R8>180,"入隅(凹)","出隅(凸)")) -> 入隅(凹) | V8: -22.88 | W8: -20.89 | X8: -25.36 | Y8: -21.56 | Z8: -27.12 | AA8: -22.09
A9: 5 | B9: 12.8 | C9: -18.9 | D9: =IF(ROW()-4<=$F$2,1,0) -> 1 | E9: =IF($D9=0,0,INDEX($B$5:$B$20,IF(ROW()-4=$F$2,1,ROW()-4+1))) -> 25.36 | F9: =IF($D9=0,0,INDEX($C$5:$C$20,IF(ROW()-4=$F$2,1,ROW()-4+1))) -> -21.56 | G9: =IF($D9=0,0,INDEX($B$5:$B$20,IF(ROW()-4=1,$F$2,ROW()-4-1))) -> 0 | H9: =IF($D9=0,0,INDEX($C$5:$C$20,IF(ROW()-4=1,$F$2,ROW()-4-1))) -> -18 | I9: =IF($D9=0,0,B9*F9-E9*C9) -> 203.336 | J9: =IF($D9=0,0,SQRT((E9-B9)^2+(F9-C9)^2)) -> 12.838582 | K9: =IF($D9=0,0,(C9^2+C9*F9+F9^2)*I9) -> 250007.22 | L9: =IF($D9=0,0,(B9^2+B9*E9+E9^2)*I9) -> 230090.46 | M9: =IF($D9=0,0,(B9*F9+2*B9*C9+2*E9*F9+E9*C9)*I9) -> -474308.71 | N9: =IF($D9=0,0,(B9+E9)*I9) -> 7759.3018 | O9: =IF($D9=0,0,(C9+F9)*I9) -> -8226.9746 | P9: =IF($D9=0,0,(G9-B9)*(E9-B9)+(H9-C9)*(F9-C9)) -> -163.162 | Q9: =IF($D9=0,0,(G9-B9)*(F9-C9)-(H9-C9)*(E9-B9)) -> 22.744 | R9: =IF($D9=0,"",IFERROR(MOD(DEGREES(ATAN2(P9,-$F$3*Q9)),360),"")) -> 187.93562 | S9: =IF($D9=0,"",180-R9) -> -7.9356214 | T9: =IF($D9=0,"",IF(R9>180,"入隅(凹)","出隅(凸)")) -> 入隅(凹) | V9: -7.7 | W9: -18.32 | X9: -12.8 | Y9: -18.9 | Z9: -16.43 | AA9: -19.48
A10: 6 | B10: 25.36 | C10: -21.56 | D10: =IF(ROW()-4<=$F$2,1,0) -> 1 | E10: =IF($D10=0,0,INDEX($B$5:$B$20,IF(ROW()-4=$F$2,1,ROW()-4+1))) -> 37.42 | F10: =IF($D10=0,0,INDEX($C$5:$C$20,IF(ROW()-4=$F$2,1,ROW()-4+1))) -> -25.95 | G10: =IF($D10=0,0,INDEX($B$5:$B$20,IF(ROW()-4=1,$F$2,ROW()-4-1))) -> 12.8 | H10: =IF($D10=0,0,INDEX($C$5:$C$20,IF(ROW()-4=1,$F$2,ROW()-4-1))) -> -18.9 | I10: =IF($D10=0,0,B10*F10-E10*C10) -> 148.6832 | J10: =IF($D10=0,0,SQRT((E10-B10)^2+(F10-C10)^2)) -> 12.834161 | K10: =IF($D10=0,0,(C10^2+C10*F10+F10^2)*I10) -> 252422.16 | L10: =IF($D10=0,0,(B10^2+B10*E10+E10^2)*I10) -> 444913.24 | M10: =IF($D10=0,0,(B10*F10+2*B10*C10+2*E10*F10+E10*C10)*I10) -> -669147.02 | N10: =IF($D10=0,0,(B10+E10)*I10) -> 9334.3313 | O10: =IF($D10=0,0,(C10+F10)*I10) -> -7063.9388 | P10: =IF($D10=0,0,(G10-B10)*(E10-B10)+(H10-C10)*(F10-C10)) -> -163.151 | Q10: =IF($D10=0,0,(G10-B10)*(F10-C10)-(H10-C10)*(E10-B10)) -> 23.0588 | R10: =IF($D10=0,"",IFERROR(MOD(DEGREES(ATAN2(P10,-$F$3*Q10)),360),"")) -> 188.04457 | S10: =IF($D10=0,"",180-R10) -> -8.0445656 | T10: =IF($D10=0,"",IF(R10>180,"入隅(凹)","出隅(凸)")) -> 入隅(凹) | V10: 7.7 | W10: -18.32 | X10: 0 | Y10: -18 | Z10: -5.5 | AA10: -18.16
A11: 7 | B11: 37.42 | C11: -25.95 | D11: =IF(ROW()-4<=$F$2,1,0) -> 1 | E11: =IF($D11=0,0,INDEX($B$5:$B$20,IF(ROW()-4=$F$2,1,ROW()-4+1))) -> 57.76 | F11: =IF($D11=0,0,INDEX($C$5:$C$20,IF(ROW()-4=$F$2,1,ROW()-4+1))) -> 19.72 | G11: =IF($D11=0,0,INDEX($B$5:$B$20,IF(ROW()-4=1,$F$2,ROW()-4-1))) -> 25.36 | H11: =IF($D11=0,0,INDEX($C$5:$C$20,IF(ROW()-4=1,$F$2,ROW()-4-1))) -> -21.56 | I11: =IF($D11=0,0,B11*F11-E11*C11) -> 2236.7944 | J11: =IF($D11=0,0,SQRT((E11-B11)^2+(F11-C11)^2)) -> 49.994645 | K11: =IF($D11=0,0,(C11^2+C11*F11+F11^2)*I11) -> 1231460.2 | L11: =IF($D11=0,0,(B11^2+B11*E11+E11^2)*I11) -> 15429079 | M11: =IF($D11=0,0,(B11*F11+2*B11*C11+2*E11*F11+E11*C11)*I11) -> -950622.41 | N11: =IF($D11=0,0,(B11+E11)*I11) -> 212898.09 | O11: =IF($D11=0,0,(C11+F11)*I11) -> -13935.229 | P11: =IF($D11=0,0,(G11-B11)*(E11-B11)+(H11-C11)*(F11-C11)) -> -44.8091 | Q11: =IF($D11=0,0,(G11-B11)*(F11-C11)-(H11-C11)*(E11-B11)) -> -640.0728 | R11: =IF($D11=0,"",IFERROR(MOD(DEGREES(ATAN2(P11,-$F$3*Q11)),360),"")) -> 94.00453 | S11: =IF($D11=0,"",180-R11) -> 85.99547 | T11: =IF($D11=0,"",IF(R11>180,"入隅(凹)","出隅(凸)")) -> 出隅(凸) | V11: 22.88 | W11: -20.89 | X11: 12.8 | Y11: -18.9 | Z11: 5.5 | AA11: -18.16
A12: 8 | B12: 57.76 | C12: 19.72 | D12: =IF(ROW()-4<=$F$2,1,0) -> 1 | E12: =IF($D12=0,0,INDEX($B$5:$B$20,IF(ROW()-4=$F$2,1,ROW()-4+1))) -> 39.14 | F12: =IF($D12=0,0,INDEX($C$5:$C$20,IF(ROW()-4=$F$2,1,ROW()-4+1))) -> 26.5 | G12: =IF($D12=0,0,INDEX($B$5:$B$20,IF(ROW()-4=1,$F$2,ROW()-4-1))) -> 37.42 | H12: =IF($D12=0,0,INDEX($C$5:$C$20,IF(ROW()-4=1,$F$2,ROW()-4-1))) -> -25.95 | I12: =IF($D12=0,0,B12*F12-E12*C12) -> 758.7992 | J12: =IF($D12=0,0,SQRT((E12-B12)^2+(F12-C12)^2)) -> 19.815973 | K12: =IF($D12=0,0,(C12^2+C12*F12+F12^2)*I12) -> 1224480.6 | L12: =IF($D12=0,0,(B12^2+B12*E12+E12^2)*I12) -> 5409391.2 | M12: =IF($D12=0,0,(B12*F12+2*B12*C12+2*E12*F12+E12*C12)*I12) -> 5049774.7 | N12: =IF($D12=0,0,(B12+E12)*I12) -> 73527.642 | O12: =IF($D12=0,0,(C12+F12)*I12) -> 35071.699 | P12: =IF($D12=0,0,(G12-B12)*(E12-B12)+(H12-C12)*(F12-C12)) -> 69.0882 | Q12: =IF($D12=0,0,(G12-B12)*(F12-C12)-(H12-C12)*(E12-B12)) -> -988.2806 | R12: =IF($D12=0,"",IFERROR(MOD(DEGREES(ATAN2(P12,-$F$3*Q12)),360),"")) -> 86.001103 | S12: =IF($D12=0,"",180-R12) -> 93.998897 | T12: =IF($D12=0,"",IF(R12>180,"入隅(凹)","出隅(凸)")) -> 出隅(凸) | V12: 37.42 | W12: -25.95 | X12: 25.36 | Y12: -21.56 | Z12: 16.43 | AA12: -19.48
A13: 9 | B13: 39.14 | C13: 26.5 | D13: =IF(ROW()-4<=$F$2,1,0) -> 1 | E13: =IF($D13=0,0,INDEX($B$5:$B$20,IF(ROW()-4=$F$2,1,ROW()-4+1))) -> 19.76 | F13: =IF($D13=0,0,INDEX($C$5:$C$20,IF(ROW()-4=$F$2,1,ROW()-4+1))) -> 30.62 | G13: =IF($D13=0,0,INDEX($B$5:$B$20,IF(ROW()-4=1,$F$2,ROW()-4-1))) -> 57.76 | H13: =IF($D13=0,0,INDEX($C$5:$C$20,IF(ROW()-4=1,$F$2,ROW()-4-1))) -> 19.72 | I13: =IF($D13=0,0,B13*F13-E13*C13) -> 674.8268 | J13: =IF($D13=0,0,SQRT((E13-B13)^2+(F13-C13)^2)) -> 19.813097 | K13: =IF($D13=0,0,(C13^2+C13*F13+F13^2)*I13) -> 1654178.9 | L13: =IF($D13=0,0,(B13^2+B13*E13+E13^2)*I13) -> 1819200.5 | M13: =IF($D13=0,0,(B13*F13+2*B13*C13+2*E13*F13+E13*C13)*I13) -> 3378607.6 | N13: =IF($D13=0,0,(B13+E13)*I13) -> 39747.299 | O13: =IF($D13=0,0,(C13+F13)*I13) -> 38546.107 | P13: =IF($D13=0,0,(G13-B13)*(E13-B13)+(H13-C13)*(F13-C13)) -> -388.7892 | Q13: =IF($D13=0,0,(G13-B13)*(F13-C13)-(H13-C13)*(E13-B13)) -> -54.682 | R13: =IF($D13=0,"",IFERROR(MOD(DEGREES(ATAN2(P13,-$F$3*Q13)),360),"")) -> 171.99404 | S13: =IF($D13=0,"",180-R13) -> 8.0059599 | T13: =IF($D13=0,"",IF(R13>180,"入隅(凹)","出隅(凸)")) -> 出隅(凸) | V13: 57.76 | W13: 19.72 | X13: 37.42 | Y13: -25.95 | Z13: 27.12 | AA13: -22.09
A14: 10 | B14: 19.76 | C14: 30.62 | D14: =IF(ROW()-4<=$F$2,1,0) -> 1 | E14: =IF($D14=0,0,INDEX($B$5:$B$20,IF(ROW()-4=$F$2,1,ROW()-4+1))) -> 0 | F14: =IF($D14=0,0,INDEX($C$5:$C$20,IF(ROW()-4=$F$2,1,ROW()-4+1))) -> 32 | G14: =IF($D14=0,0,INDEX($B$5:$B$20,IF(ROW()-4=1,$F$2,ROW()-4-1))) -> 39.14 | H14: =IF($D14=0,0,INDEX($C$5:$C$20,IF(ROW()-4=1,$F$2,ROW()-4-1))) -> 26.5 | I14: =IF($D14=0,0,B14*F14-E14*C14) -> 632.32 | J14: =IF($D14=0,0,SQRT((E14-B14)^2+(F14-C14)^2)) -> 19.80813 | K14: =IF($D14=0,0,(C14^2+C14*F14+F14^2)*I14) -> 1859921.5 | L14: =IF($D14=0,0,(B14^2+B14*E14+E14^2)*I14) -> 246894.15 | M14: =IF($D14=0,0,(B14*F14+2*B14*C14+2*E14*F14+E14*C14)*I14) -> 1165000.5 | N14: =IF($D14=0,0,(B14+E14)*I14) -> 12494.643 | O14: =IF($D14=0,0,(C14+F14)*I14) -> 39595.878 | P14: =IF($D14=0,0,(G14-B14)*(E14-B14)+(H14-C14)*(F14-C14)) -> -388.6344 | Q14: =IF($D14=0,0,(G14-B14)*(F14-C14)-(H14-C14)*(E14-B14)) -> -54.6668 | R14: =IF($D14=0,"",IFERROR(MOD(DEGREES(ATAN2(P14,-$F$3*Q14)),360),"")) -> 171.99309 | S14: =IF($D14=0,"",180-R14) -> 8.00691 | T14: =IF($D14=0,"",IF(R14>180,"入隅(凹)","出隅(凸)")) -> 出隅(凸) | V14: 35.31 | W14: 27.54 | X14: 57.76 | Y14: 19.72 | Z14: 37.42 | AA14: -25.95
A15: 11 | B15: 0 | C15: 32 | D15: =IF(ROW()-4<=$F$2,1,0) -> 1 | E15: =IF($D15=0,0,INDEX($B$5:$B$20,IF(ROW()-4=$F$2,1,ROW()-4+1))) -> -19.76 | F15: =IF($D15=0,0,INDEX($C$5:$C$20,IF(ROW()-4=$F$2,1,ROW()-4+1))) -> 30.62 | G15: =IF($D15=0,0,INDEX($B$5:$B$20,IF(ROW()-4=1,$F$2,ROW()-4-1))) -> 19.76 | H15: =IF($D15=0,0,INDEX($C$5:$C$20,IF(ROW()-4=1,$F$2,ROW()-4-1))) -> 30.62 | I15: =IF($D15=0,0,B15*F15-E15*C15) -> 632.32 | J15: =IF($D15=0,0,SQRT((E15-B15)^2+(F15-C15)^2)) -> 19.80813 | K15: =IF($D15=0,0,(C15^2+C15*F15+F15^2)*I15) -> 1859921.5 | L15: =IF($D15=0,0,(B15^2+B15*E15+E15^2)*I15) -> 246894.15 | M15: =IF($D15=0,0,(B15*F15+2*B15*C15+2*E15*F15+E15*C15)*I15) -> -1165000.5 | N15: =IF($D15=0,0,(B15+E15)*I15) -> -12494.643 | O15: =IF($D15=0,0,(C15+F15)*I15) -> 39595.878 | P15: =IF($D15=0,0,(G15-B15)*(E15-B15)+(H15-C15)*(F15-C15)) -> -388.5532 | Q15: =IF($D15=0,0,(G15-B15)*(F15-C15)-(H15-C15)*(E15-B15)) -> -54.5376 | R15: =IF($D15=0,"",IFERROR(MOD(DEGREES(ATAN2(P15,-$F$3*Q15)),360),"")) -> 172.01012 | S15: =IF($D15=0,"",180-R15) -> 7.9898788 | T15: =IF($D15=0,"",IF(R15>180,"入隅(凹)","出隅(凸)")) -> 出隅(凸) | V15: 11.88 | W15: 31.5 | X15: 39.14 | Y15: 26.5 | Z15: 57.76 | AA15: 19.72
A16: 12 | B16: -19.76 | C16: 30.62 | D16: =IF(ROW()-4<=$F$2,1,0) -> 1 | E16: =IF($D16=0,0,INDEX($B$5:$B$20,IF(ROW()-4=$F$2,1,ROW()-4+1))) -> -39.14 | F16: =IF($D16=0,0,INDEX($C$5:$C$20,IF(ROW()-4=$F$2,1,ROW()-4+1))) -> 26.5 | G16: =IF($D16=0,0,INDEX($B$5:$B$20,IF(ROW()-4=1,$F$2,ROW()-4-1))) -> 0 | H16: =IF($D16=0,0,INDEX($C$5:$C$20,IF(ROW()-4=1,$F$2,ROW()-4-1))) -> 32 | I16: =IF($D16=0,0,B16*F16-E16*C16) -> 674.8268 | J16: =IF($D16=0,0,SQRT((E16-B16)^2+(F16-C16)^2)) -> 19.813097 | K16: =IF($D16=0,0,(C16^2+C16*F16+F16^2)*I16) -> 1654178.9 | L16: =IF($D16=0,0,(B16^2+B16*E16+E16^2)*I16) -> 1819200.5 | M16: =IF($D16=0,0,(B16*F16+2*B16*C16+2*E16*F16+E16*C16)*I16) -> -3378607.6 | N16: =IF($D16=0,0,(B16+E16)*I16) -> -39747.299 | O16: =IF($D16=0,0,(C16+F16)*I16) -> 38546.107 | P16: =IF($D16=0,0,(G16-B16)*(E16-B16)+(H16-C16)*(F16-C16)) -> -388.6344 | Q16: =IF($D16=0,0,(G16-B16)*(F16-C16)-(H16-C16)*(E16-B16)) -> -54.6668 | R16: =IF($D16=0,"",IFERROR(MOD(DEGREES(ATAN2(P16,-$F$3*Q16)),360),"")) -> 171.99309 | S16: =IF($D16=0,"",180-R16) -> 8.00691 | T16: =IF($D16=0,"",IF(R16>180,"入隅(凹)","出隅(凸)")) -> 出隅(凸) | V16: -11.88 | W16: 31.5 | X16: 19.76 | Y16: 30.62 | Z16: 29.52 | AA16: 28.9
A17: 13 | B17: -39.14 | C17: 26.5 | D17: =IF(ROW()-4<=$F$2,1,0) -> 1 | E17: =IF($D17=0,0,INDEX($B$5:$B$20,IF(ROW()-4=$F$2,1,ROW()-4+1))) -> -57.76 | F17: =IF($D17=0,0,INDEX($C$5:$C$20,IF(ROW()-4=$F$2,1,ROW()-4+1))) -> 19.72 | G17: =IF($D17=0,0,INDEX($B$5:$B$20,IF(ROW()-4=1,$F$2,ROW()-4-1))) -> -19.76 | H17: =IF($D17=0,0,INDEX($C$5:$C$20,IF(ROW()-4=1,$F$2,ROW()-4-1))) -> 30.62 | I17: =IF($D17=0,0,B17*F17-E17*C17) -> 758.7992 | J17: =IF($D17=0,0,SQRT((E17-B17)^2+(F17-C17)^2)) -> 19.815973 | K17: =IF($D17=0,0,(C17^2+C17*F17+F17^2)*I17) -> 1224480.6 | L17: =IF($D17=0,0,(B17^2+B17*E17+E17^2)*I17) -> 5409391.2 | M17: =IF($D17=0,0,(B17*F17+2*B17*C17+2*E17*F17+E17*C17)*I17) -> -5049774.7 | N17: =IF($D17=0,0,(B17+E17)*I17) -> -73527.642 | O17: =IF($D17=0,0,(C17+F17)*I17) -> 35071.699 | P17: =IF($D17=0,0,(G17-B17)*(E17-B17)+(H17-C17)*(F17-C17)) -> -388.7892 | Q17: =IF($D17=0,0,(G17-B17)*(F17-C17)-(H17-C17)*(E17-B17)) -> -54.682 | R17: =IF($D17=0,"",IFERROR(MOD(DEGREES(ATAN2(P17,-$F$3*Q17)),360),"")) -> 171.99404 | S17: =IF($D17=0,"",180-R17) -> 8.0059599 | T17: =IF($D17=0,"",IF(R17>180,"入隅(凹)","出隅(凸)")) -> 出隅(凸) | V17: -35.31 | W17: 27.54 | X17: 0 | Y17: 32 | Z17: 9.91 | AA17: 31.65
A18: 14 | B18: -57.76 | C18: 19.72 | D18: =IF(ROW()-4<=$F$2,1,0) -> 1 | E18: =IF($D18=0,0,INDEX($B$5:$B$20,IF(ROW()-4=$F$2,1,ROW()-4+1))) -> -37.42 | F18: =IF($D18=0,0,INDEX($C$5:$C$20,IF(ROW()-4=$F$2,1,ROW()-4+1))) -> -25.95 | G18: =IF($D18=0,0,INDEX($B$5:$B$20,IF(ROW()-4=1,$F$2,ROW()-4-1))) -> -39.14 | H18: =IF($D18=0,0,INDEX($C$5:$C$20,IF(ROW()-4=1,$F$2,ROW()-4-1))) -> 26.5 | I18: =IF($D18=0,0,B18*F18-E18*C18) -> 2236.7944 | J18: =IF($D18=0,0,SQRT((E18-B18)^2+(F18-C18)^2)) -> 49.994645 | K18: =IF($D18=0,0,(C18^2+C18*F18+F18^2)*I18) -> 1231460.2 | L18: =IF($D18=0,0,(B18^2+B18*E18+E18^2)*I18) -> 15429079 | M18: =IF($D18=0,0,(B18*F18+2*B18*C18+2*E18*F18+E18*C18)*I18) -> 950622.41 | N18: =IF($D18=0,0,(B18+E18)*I18) -> -212898.09 | O18: =IF($D18=0,0,(C18+F18)*I18) -> -13935.229 | P18: =IF($D18=0,0,(G18-B18)*(E18-B18)+(H18-C18)*(F18-C18)) -> 69.0882 | Q18: =IF($D18=0,0,(G18-B18)*(F18-C18)-(H18-C18)*(E18-B18)) -> -988.2806 | R18: =IF($D18=0,"",IFERROR(MOD(DEGREES(ATAN2(P18,-$F$3*Q18)),360),"")) -> 86.001103 | S18: =IF($D18=0,"",180-R18) -> 93.998897 | T18: =IF($D18=0,"",IF(R18>180,"入隅(凹)","出隅(凸)")) -> 出隅(凸) | V18: -57.76 | W18: 19.72 | X18: -19.76 | Y18: 30.62 | Z18: 8.02 | AA18: 4.72
A19: 15 | D19: =IF(ROW()-4<=$F$2,1,0) -> 0 | E19: =IF($D19=0,0,INDEX($B$5:$B$20,IF(ROW()-4=$F$2,1,ROW()-4+1))) -> 0 | F19: =IF($D19=0,0,INDEX($C$5:$C$20,IF(ROW()-4=$F$2,1,ROW()-4+1))) -> 0 | G19: =IF($D19=0,0,INDEX($B$5:$B$20,IF(ROW()-4=1,$F$2,ROW()-4-1))) -> 0 | H19: =IF($D19=0,0,INDEX($C$5:$C$20,IF(ROW()-4=1,$F$2,ROW()-4-1))) -> 0 | I19: =IF($D19=0,0,B19*F19-E19*C19) -> 0 | J19: =IF($D19=0,0,SQRT((E19-B19)^2+(F19-C19)^2)) -> 0 | K19: =IF($D19=0,0,(C19^2+C19*F19+F19^2)*I19) -> 0 | L19: =IF($D19=0,0,(B19^2+B19*E19+E19^2)*I19) -> 0 | M19: =IF($D19=0,0,(B19*F19+2*B19*C19+2*E19*F19+E19*C19)*I19) -> 0 | N19: =IF($D19=0,0,(B19+E19)*I19) -> 0 | O19: =IF($D19=0,0,(C19+F19)*I19) -> 0 | P19: =IF($D19=0,0,(G19-B19)*(E19-B19)+(H19-C19)*(F19-C19)) -> 0 | Q19: =IF($D19=0,0,(G19-B19)*(F19-C19)-(H19-C19)*(E19-B19)) -> 0 | R19: =IF($D19=0,"",IFERROR(MOD(DEGREES(ATAN2(P19,-$F$3*Q19)),360),"")) | S19: =IF($D19=0,"",180-R19) | T19: =IF($D19=0,"",IF(R19>180,"入隅(凹)","出隅(凸)")) | X19: -39.14 | Y19: 26.5 | Z19: -8.02 | AA19: 4.72
A20: 16 | D20: =IF(ROW()-4<=$F$2,1,0) -> 0 | E20: =IF($D20=0,0,INDEX($B$5:$B$20,IF(ROW()-4=$F$2,1,ROW()-4+1))) -> 0 | F20: =IF($D20=0,0,INDEX($C$5:$C$20,IF(ROW()-4=$F$2,1,ROW()-4+1))) -> 0 | G20: =IF($D20=0,0,INDEX($B$5:$B$20,IF(ROW()-4=1,$F$2,ROW()-4-1))) -> 0 | H20: =IF($D20=0,0,INDEX($C$5:$C$20,IF(ROW()-4=1,$F$2,ROW()-4-1))) -> 0 | I20: =IF($D20=0,0,B20*F20-E20*C20) -> 0 | J20: =IF($D20=0,0,SQRT((E20-B20)^2+(F20-C20)^2)) -> 0 | K20: =IF($D20=0,0,(C20^2+C20*F20+F20^2)*I20) -> 0 | L20: =IF($D20=0,0,(B20^2+B20*E20+E20^2)*I20) -> 0 | M20: =IF($D20=0,0,(B20*F20+2*B20*C20+2*E20*F20+E20*C20)*I20) -> 0 | N20: =IF($D20=0,0,(B20+E20)*I20) -> 0 | O20: =IF($D20=0,0,(C20+F20)*I20) -> 0 | P20: =IF($D20=0,0,(G20-B20)*(E20-B20)+(H20-C20)*(F20-C20)) -> 0 | Q20: =IF($D20=0,0,(G20-B20)*(F20-C20)-(H20-C20)*(E20-B20)) -> 0 | R20: =IF($D20=0,"",IFERROR(MOD(DEGREES(ATAN2(P20,-$F$3*Q20)),360),"")) | S20: =IF($D20=0,"",180-R20) | T20: =IF($D20=0,"",IF(R20>180,"入隅(凹)","出隅(凸)")) | X20: -57.76 | Y20: 19.72 | Z20: -9.91 | AA20: 31.65
Z21: -29.52 | AA21: 28.9
A22: ■ 形状の計算結果 | Z22: -57.76 | AA22: 19.72
A23: 符号付き面積 [mm²] | B23: =0.5*SUM(I5:I20) -> 4885.1596 | C23: 多角形の向き判定に使う（＋なら反時計回り）
A24: 面積 A [mm²] | B24: =ABS(B23) -> 4885.1596 | C24: シューレース公式 A=½|Σ(xᵢyᵢ₊₁−xᵢ₊₁yᵢ)| 🟢
A25: 周長 [mm] | B25: =SUM(J5:J20) -> 295.87238 | C25: 各辺の長さの合計
A26: 重心 Cx [mm] | B26: =IF(B23=0,0,SUM(N5:N20)/(6*B23)) -> 0 | C26: 図心のX座標 🟢
A27: 重心 Cy [mm] | B27: =IF(B23=0,0,SUM(O5:O20)/(6*B23)) -> 5.1506868 | C27: 図心のY座標 🟢
A28: Ixx (重心まわり) [mm⁴] | B28: =$F$3*SUM(K5:K20)/12-$B$24*$B$27^2 -> 988366.04 | C28: X軸まわり断面二次モーメント 🟢
A29: Iyy (重心まわり) [mm⁴] | B29: =$F$3*SUM(L5:L20)/12-$B$24*$B$26^2 -> 3936219.6 | C29: Y軸まわり 🟢
A30: Ixy (重心まわり) [mm⁴] | B30: =$F$3*SUM(M5:M20)/24-$B$24*$B$26*$B$27 -> 0 | C30: 相乗モーメント 🟢
A31: Imin [mm⁴] | B31: =($B$28+$B$29)/2-SQRT((($B$28-$B$29)/2)^2+$B$30^2) -> 988366.04 | C31: 主（しゅ）断面二次モーメント 最小
A32: Imax [mm⁴] | B32: =($B$28+$B$29)/2+SQRT((($B$28-$B$29)/2)^2+$B$30^2) -> 3936219.6 | C32: 主断面二次モーメント 最大
A33: 主軸角 θp [°] | B33: =DEGREES(0.5*ATAN2($B$28-$B$29,-2*$B$30)) -> -90 | C33: tan2θ=−2Ixy/(Ixx−Iyy) 🟢
A34: θpでのI [mm⁴] | B34: =($B$28+$B$29)/2+($B$28-$B$29)/2*COS(2*RADIANS($B$33))-$B$30*SIN(2*RADIANS($B$33)) -> 3936219.6 | C34: 判定用の中間値
A35: 長手方向の角度 [°] | B35: =IF(ABS($B$34-$B$31)<ABS($B$34-$B$32),$B$33,$B$33+90) -> 0 | C35: 0°に近いほど X軸＝長手。大きくずれたら座標を回して入れ直す
A36: Xmin [mm] | B36: =MIN($B$5:$B$20) -> -57.76
A37: Xmax [mm] | B37: =MAX($B$5:$B$20) -> 57.76
A38: Ymin [mm] | B38: =MIN($C$5:$C$20) -> -25.95
A39: Ymax [mm] | B39: =MAX($C$5:$C$20) -> 32
A40: X方向の長さ [mm] | B40: =$B$37-$B$36 -> 115.52
...

Sheet 断面
A1: ② 断面（積層）— シム＋裏板＋接着＋摩擦材 を1本の「はり」に合成
A2: 変換断面法（transformed section）で 曲げ剛性EI・単位長さ質量ρA・中立軸を求める 🟢
A3: 幅 b [m]（＝形状シートの採用w） | D3: =形状!$B$46/1000 -> 0.042288431
A4: 長さ L [m]（＝形状シートの採用L） | D4: =形状!$B$45/1000 -> 0.11552
A5: 投影面積 [m²] | D5: =形状!$B$24/1000000 -> 0.0048851596
A7: 層（下から順） | B7: 使用1/0 | C7: 材料名（材料DBと同じ文字） | D7: 厚さ t [mm] | E7: E [GPa] | F7: ρ [kg/m³] | G7: ν | H7: η | I7: t [m] | J7: 下端y [m] | K7: 中心y [m] | L7: E·A [N] | M7: E·A·y | N7: ρ·A [kg/m] | O7: EI項(面外) | P7: EI項(面内) | Q7: E·A(軸) | R7: η·EI項
A8: 1: シム | B8: 0 | C8: シム鋼板 SPCC | D8: 0.8 | E8: =IFERROR(INDEX(材料DB!$B$5:$B$45,MATCH($C8,材料DB!$A$5:$A$45,0)),0) -> 205 | F8: =IFERROR(INDEX(材料DB!$C$5:$C$45,MATCH($C8,材料DB!$A$5:$A$45,0)),0) -> 7850 | G8: =IFERROR(INDEX(材料DB!$D$5:$D$45,MATCH($C8,材料DB!$A$5:$A$45,0)),0) -> 0.3 | H8: =IFERROR(INDEX(材料DB!$E$5:$E$45,MATCH($C8,材料DB!$A$5:$A$45,0)),0) -> 0.0002 | I8: =IF($B8=1,$D8/1000,0) -> 0 | J8: =0 -> 0 | K8: =J8+I8/2 -> 0 | L8: =E8*1000000000*$D$3*I8 -> 0 | M8: =L8*K8 -> 0 | N8: =F8*$D$3*I8 -> 0 | O8: =E8*1000000000*$D$3*(I8^3/12+I8*(K8-$D$15)^2) -> 0 | P8: =E8*1000000000*(I8*$D$3^3/12) -> 0 | Q8: =L8 -> 0 | R8: =H8*O8 -> 0
A9: 2: 裏板 | B9: 1 | C9: 鋼 SPCC(裏板) | D9: 5 | E9: =IFERROR(INDEX(材料DB!$B$5:$B$45,MATCH($C9,材料DB!$A$5:$A$45,0)),0) -> 205 | F9: =IFERROR(INDEX(材料DB!$C$5:$C$45,MATCH($C9,材料DB!$A$5:$A$45,0)),0) -> 7850 | G9: =IFERROR(INDEX(材料DB!$D$5:$D$45,MATCH($C9,材料DB!$A$5:$A$45,0)),0) -> 0.3 | H9: =IFERROR(INDEX(材料DB!$E$5:$E$45,MATCH($C9,材料DB!$A$5:$A$45,0)),0) -> 0.0002 | I9: =IF($B9=1,$D9/1000,0) -> 0.005 | J9: =J8+I8 -> 0 | K9: =J9+I9/2 -> 0.0025 | L9: =E9*1000000000*$D$3*I9 -> 43345642 | M9: =L9*K9 -> 108364.11 | N9: =F9*$D$3*I9 -> 1.6598209 | O9: =E9*1000000000*$D$3*(I9^3/12+I9*(K9-$D$15)^2) -> 94.156529 | P9: =E9*1000000000*(I9*$D$3^3/12) -> 6459.6256 | Q9: =L9 -> 43345642 | R9: =H9*O9 -> 0.018831306
A10: 3: 接着層 | B10: 1 | C10: 接着層 フェノール | D10: 0.2 | E10: =IFERROR(INDEX(材料DB!$B$5:$B$45,MATCH($C10,材料DB!$A$5:$A$45,0)),0) -> 3 | F10: =IFERROR(INDEX(材料DB!$C$5:$C$45,MATCH($C10,材料DB!$A$5:$A$45,0)),0) -> 1300 | G10: =IFERROR(INDEX(材料DB!$D$5:$D$45,MATCH($C10,材料DB!$A$5:$A$45,0)),0) -> 0.35 | H10: =IFERROR(INDEX(材料DB!$E$5:$E$45,MATCH($C10,材料DB!$A$5:$A$45,0)),0) -> 0.08 | I10: =IF($B10=1,$D10/1000,0) -> 0.0002 | J10: =J9+I9 -> 0.005 | K10: =J10+I10/2 -> 0.0051 | L10: =E10*1000000000*$D$3*I10 -> 25373.059 | M10: =L10*K10 -> 129.4026 | N10: =F10*$D$3*I10 -> 0.010994992 | O10: =E10*1000000000*$D$3*(I10^3/12+I10*(K10-$D$15)^2) -> 0.13452423 | P10: =E10*1000000000*(I10*$D$3^3/12) -> 3.7812443 | Q10: =L10 -> 25373.059 | R10: =H10*O10 -> 0.010761938
A11: 4: 摩擦材 | B11: 1 | C11: 摩擦材 一般(圧縮) | D11: 11 | E11: =IFERROR(INDEX(材料DB!$B$5:$B$45,MATCH($C11,材料DB!$A$5:$A$45,0)),0) -> 3.5 | F11: =IFERROR(INDEX(材料DB!$C$5:$C$45,MATCH($C11,材料DB!$A$5:$A$45,0)),0) -> 2600 | G11: =IFERROR(INDEX(材料DB!$D$5:$D$45,MATCH($C11,材料DB!$A$5:$A$45,0)),0) -> 0.25 | H11: =IFERROR(INDEX(材料DB!$E$5:$E$45,MATCH($C11,材料DB!$A$5:$A$45,0)),0) -> 0.04 | I11: =IF($B11=1,$D11/1000,0) -> 0.011 | J11: =J10+I10 -> 0.0052 | K11: =J11+I11/2 -> 0.0107 | L11: =E11*1000000000*$D$3*I11 -> 1628104.6 | M11: =L11*K11 -> 17420.719 | N11: =F11*$D$3*I11 -> 1.2094491 | O11: =E11*1000000000*$D$3*(I11^3/12+I11*(K11-$D$15)^2) -> 118.07436 | P11: =E11*1000000000*(I11*$D$3^3/12) -> 242.62984 | Q11: =L11 -> 1628104.6 | R11: =H11*O11 -> 4.7229744
A13: ■ 合成結果
A14: ΣE·A [N] | D14: =SUM(L8:L11) -> 44999120 | E14: 各層の 弾性率×断面積 の合計
A15: 中立軸 ȳ [m] | D15: =IF($D$14=0,0,SUM(M8:M11)/$D$14) -> 0.0027981487 | E15: 曲げても伸び縮みしない高さ。下端からの距離 🟢
A16: EI 面外曲げ [N·m²] | D16: =SUM(O8:O11) -> 212.36541 | E16: 厚み方向にたわむ剛性。パッドの主モードはこれ 🟢
A17: EI 面内曲げ [N·m²] | D17: =SUM(P8:P11) -> 6706.0367 | E17: 面内（半径方向）にたわむ剛性。高周波側 🟢
A18: EA 軸 [N] | D18: =SUM(Q8:Q11) -> 44999120 | E18: 伸び縮みの剛性 🟢
A19: ρA 単位長さ質量 [kg/m] | D19: =SUM(N8:N11) -> 2.8802651 | E19: 1mあたりの重さ 🟢
A20: 総厚 h [m] | D20: =SUM(I8:I11) -> 0.0162 | E20: 使用する層の厚さ合計
A21: 等価ヤング率 E_eq(面外) [GPa] | D21: =IF($D$20=0,0,$D$16/($D$3*$D$20^3/12)/1000000000) -> 14.174195 | E21: 1枚板とみなしたときの見かけのE
A22: 等価密度 ρ_eq [kg/m³] | D22: =IF($D$20=0,0,$D$19/($D$3*$D$20)) -> 4204.321 | E22: 1枚板とみなしたときの見かけのρ
A23: 等価ポアソン比 ν_eq | D23: =IF($D$14=0,0.3,SUMPRODUCT(G8:G11,L8:L11)/$D$14) -> 0.29821915 | E23: E·Aで重み付け平均
A24: 等価せん断弾性率 G_eq [Pa] | D24: =$D$21*1000000000/(2*(1+$D$23)) -> 5.4590919e+09 | E24: G=E/(2(1+ν)) 🟢
A25: ねじり係数 β | D25: =IF($D$3<=0,0,(1/3)*(1-0.63*($D$20/$D$3)+0.052*($D$20/$D$3)^5)) -> 0.2530288 | E25: 長方形断面のねじり定数 J=β·b·h³ 🟢 Roark近似
A26: GJ ねじり剛性 [N·m²] | D26: =$D$24*$D$25*$D$3*$D$20^3 -> 248.3459 | E26: ねじりにくさ 🟡(積層は近似)
A27: ρIp 単位長さ極慣性 [kg·m] | D27: =$D$19*($D$3^2+$D$20^2)/12 -> 0.00049222564 | E27: ねじりの回りにくさ 🟡
A28: 合成損失係数 η_eq | D28: =IF($D$16=0,0,SUM(R8:R11)/$D$16) -> 0.022379198 | E28: EI重み付け平均（RKU法の簡易版）🟡
A29: パッド質量 [g] | D29: =SUMPRODUCT(F8:F11,I8:I11)*$D$5*1000 -> 332.72822 | E29: 実測して合っていれば密度入力は正しい
A32: ■ 中立軸の意味（ここが一番の勘どころ）
A33: 曲げると、上側は縮み・下側は伸びる。その境目で「伸びも縮みもしない面」が中立軸（ちゅうりつじく）です。
A34: 鋼の裏板（E=205GPa）と摩擦材（E=3.5GPa）では硬さが約60倍違うので、中立軸はほぼ裏板の中に寄ります。
A35: つまり ⇒ 摩擦材の厚さを変えても剛性はあまり増えず、重さだけ増える ⇒ 固有振動数は下がる。
A36: 逆に裏板を 5.0mm → 6.0mm にすると EI は約 (6/5)³＝1.73倍になり、周波数は約√1.73＝1.32倍に上がります。

Sheet 固有振動数
A1: ③ 固有振動数の予測（自由−自由：ピアノ線で吊った状態）
A2: 4系統：①面外曲げ ②ねじり ③面内曲げ ④面内伸縮。せん断変形（Timoshenko）補正つき。単位は Hz
A3: 損失係数 η（空欄→断面シートの合成値） | E3: =IF($D$3="",断面!$D$28,$D$3) -> 0.022379198 | F3: せん断補正 使う=1 / 使わない=0 | I3: 1 | J3: κ(長方形=5/6) | K3: =5/6 -> 0.83333333
A4: 回転半径 r_out [m] = h/√12 | D4: =断面!$D$20/SQRT(12) -> 0.0046765372 | E4: r_in = w/√12 | F4: =断面!$D$3/SQRT(12) -> 0.012207619 | G4: 1+E/(κG) | H4: =1+2*(1+断面!$D$23)/$K$3 -> 4.115726
A5: # | B5: モード種別 | C5: n | D5: 係数 (βL) or n | E5: (βL)² | F5: f Euler [Hz] | G5: せん断補正係数 | H5: f 補正後 [Hz] | I5: ★採用 f [Hz] | J5: 波長 λ [mm] | K5: λ/断面寸法 | L5: 妥当性 | M5: 備考 | O5: f [Hz] | P5: η | Q5: 振幅 A | R5: モード名
A6: 1 | B6: 面外曲げ | C6: 1 | D6: 4.730041 | E6: =D6^2 -> 22.373288 | F6: =IFERROR(E6/(2*PI()*断面!$D$4^2)*SQRT(断面!$D$16/断面!$D$19),0) -> 2291.1907 | G6: =IFERROR(1/SQRT(1+E6*($D$4/断面!$D$4)^2*$H$4),1) -> 0.93213711 | H6: =F6*G6 -> 2135.7039 | I6: =IF($I$3=1,H6,F6) -> 2135.7039 | J6: =IFERROR(2*PI()*断面!$D$4/D6*1000,0) -> 153.45186 | K6: =IFERROR(J6/(断面!$D$20*1000),0) -> 9.4723367 | L6: =IF(K6>=6,"🟢 良",IF(K6>=3,"🟡 誤差±10%程度","🔴 参考値のみ")) -> 🟢 良 | M6: 板が反（そ）るように曲がる。鳴きの主役 🟢 | O6: =IF(I6<=0,1000000000,I6) -> 2135.7039 | P6: =$E$3 -> 0.022379198 | Q6: 1 | R6: =B6&" "&C6&"次" -> 面外曲げ 1次
A7: 2 | B7: 面外曲げ | C7: 2 | D7: 7.853205 | E7: =D7^2 -> 61.672829 | F7: =IFERROR(E7/(2*PI()*断面!$D$4^2)*SQRT(断面!$D$16/断面!$D$19),0) -> 6315.7554 | G7: =IFERROR(1/SQRT(1+E7*($D$4/断面!$D$4)^2*$H$4),1) -> 0.84037109 | H7: =F7*G7 -> 5307.5783 | I7: =IF($I$3=1,H7,F7) -> 5307.5783 | J7: =IFERROR(2*PI()*断面!$D$4/D7*1000,0) -> 92.425139 | K7: =IFERROR(J7/(断面!$D$20*1000),0) -> 5.7052555 | L7: =IF(K7>=6,"🟢 良",IF(K7>=3,"🟡 誤差±10%程度","🔴 参考値のみ")) -> 🟡 誤差±10%程度 | M7: 板が反（そ）るように曲がる。鳴きの主役 🟢 | O7: =IF(I7<=0,1000000000,I7) -> 5307.5783 | P7: =$E$3 -> 0.022379198 | Q7: 1 | R7: =B7&" "&C7&"次" -> 面外曲げ 2次
A8: 3 | B8: 面外曲げ | C8: 3 | D8: 10.995608 | E8: =D8^2 -> 120.9034 | F8: =IFERROR(E8/(2*PI()*断面!$D$4^2)*SQRT(断面!$D$16/断面!$D$19),0) -> 12381.405 | G8: =IFERROR(1/SQRT(1+E8*($D$4/断面!$D$4)^2*$H$4),1) -> 0.74216916 | H8: =F8*G8 -> 9189.0971 | I8: =IF($I$3=1,H8,F8) -> 9189.0971 | J8: =IFERROR(2*PI()*断面!$D$4/D8*1000,0) -> 66.011226 | K8: =IFERROR(J8/(断面!$D$20*1000),0) -> 4.074767 | L8: =IF(K8>=6,"🟢 良",IF(K8>=3,"🟡 誤差±10%程度","🔴 参考値のみ")) -> 🟡 誤差±10%程度 | M8: 板が反（そ）るように曲がる。鳴きの主役 🟢 | O8: =IF(I8<=0,1000000000,I8) -> 9189.0971 | P8: =$E$3 -> 0.022379198 | Q8: 1 | R8: =B8&" "&C8&"次" -> 面外曲げ 3次
A9: 4 | B9: 面外曲げ | C9: 4 | D9: 14.137165 | E9: =D9^2 -> 199.85943 | F9: =IFERROR(E9/(2*PI()*断面!$D$4^2)*SQRT(断面!$D$16/断面!$D$19),0) -> 20467.09 | G9: =IFERROR(1/SQRT(1+E9*($D$4/断面!$D$4)^2*$H$4),1) -> 0.65259909 | H9: =F9*G9 -> 13356.804 | I9: =IF($I$3=1,H9,F9) -> 13356.804 | J9: =IFERROR(2*PI()*断面!$D$4/D9*1000,0) -> 51.342229 | K9: =IFERROR(J9/(断面!$D$20*1000),0) -> 3.1692734 | L9: =IF(K9>=6,"🟢 良",IF(K9>=3,"🟡 誤差±10%程度","🔴 参考値のみ")) -> 🟡 誤差±10%程度 | M9: 板が反（そ）るように曲がる。鳴きの主役 🟢 | O9: =IF(I9<=0,1000000000,I9) -> 13356.804 | P9: =$E$3 -> 0.022379198 | Q9: 1 | R9: =B9&" "&C9&"次" -> 面外曲げ 4次
A10: 5 | B10: 面外曲げ | C10: 5 | D10: 17.27876 | E10: =D10^2 -> 298.55555 | F10: =IFERROR(E10/(2*PI()*断面!$D$4^2)*SQRT(断面!$D$16/断面!$D$19),0) -> 30574.304 | G10: =IFERROR(1/SQRT(1+E10*($D$4/断面!$D$4)^2*$H$4),1) -> 0.5760315 | H10: =F10*G10 -> 17611.762 | I10: =IF($I$3=1,H10,F10) -> 17611.762 | J10: =IFERROR(2*PI()*断面!$D$4/D10*1000,0) -> 42.007272 | K10: =IFERROR(J10/(断面!$D$20*1000),0) -> 2.5930415 | L10: =IF(K10>=6,"🟢 良",IF(K10>=3,"🟡 誤差±10%程度","🔴 参考値のみ")) -> 🔴 参考値のみ | M10: 板が反（そ）るように曲がる。鳴きの主役 🟢 | O10: =IF(I10<=0,1000000000,I10) -> 17611.762 | P10: =$E$3 -> 0.022379198 | Q10: 1 | R10: =B10&" "&C10&"次" -> 面外曲げ 5次
A11: 6 | B11: 面外曲げ | C11: 6 | D11: 20.420352 | E11: =D11^2 -> 416.99078 | F11: =IFERROR(E11/(2*PI()*断面!$D$4^2)*SQRT(断面!$D$16/断面!$D$19),0) -> 42702.951 | G11: =IFERROR(1/SQRT(1+E11*($D$4/断面!$D$4)^2*$H$4),1) -> 0.51214109 | H11: =F11*G11 -> 21869.936 | I11: =IF($I$3=1,H11,F11) -> 21869.936 | J11: =IFERROR(2*PI()*断面!$D$4/D11*1000,0) -> 35.544616 | K11: =IFERROR(J11/(断面!$D$20*1000),0) -> 2.1941121 | L11: =IF(K11>=6,"🟢 良",IF(K11>=3,"🟡 誤差±10%程度","🔴 参考値のみ")) -> 🔴 参考値のみ | M11: 板が反（そ）るように曲がる。鳴きの主役 🟢 | O11: =IF(I11<=0,1000000000,I11) -> 21869.936 | P11: =$E$3 -> 0.022379198 | Q11: 1 | R11: =B11&" "&C11&"次" -> 面外曲げ 6次
A12: 7 | B12: ねじり | C12: 1 | D12: 1 | E12: =D12^2 -> 1 | F12: =IFERROR(D12/(2*断面!$D$4)*SQRT(断面!$D$26/断面!$D$27),0) -> 3074.3917 | G12: =1 -> 1 | H12: =F12*G12 -> 3074.3917 | I12: =IF($I$3=1,H12,F12) -> 3074.3917 | J12: =IFERROR(2*断面!$D$4/D12*1000,0) -> 231.04 | K12: =IFERROR(J12/(MAX(断面!$D$3,断面!$D$20)*1000),0) -> 5.4634327 | L12: =IF(K12>=6,"🟢 良",IF(K12>=3,"🟡 誤差±10%程度","🔴 参考値のみ")) -> 🟡 誤差±10%程度 | M12: 板がねじれる。1次ねじりは1次曲げの近くに出やすい 🟡 | O12: =IF(I12<=0,1000000000,I12) -> 3074.3917 | P12: =$E$3 -> 0.022379198 | Q12: 1 | R12: =B12&" "&C12&"次" -> ねじり 1次
A13: 8 | B13: ねじり | C13: 2 | D13: 2 | E13: =D13^2 -> 4 | F13: =IFERROR(D13/(2*断面!$D$4)*SQRT(断面!$D$26/断面!$D$27),0) -> 6148.7834 | G13: =1 -> 1 | H13: =F13*G13 -> 6148.7834 | I13: =IF($I$3=1,H13,F13) -> 6148.7834 | J13: =IFERROR(2*断面!$D$4/D13*1000,0) -> 115.52 | K13: =IFERROR(J13/(MAX(断面!$D$3,断面!$D$20)*1000),0) -> 2.7317164 | L13: =IF(K13>=6,"🟢 良",IF(K13>=3,"🟡 誤差±10%程度","🔴 参考値のみ")) -> 🔴 参考値のみ | M13: 板がねじれる。1次ねじりは1次曲げの近くに出やすい 🟡 | O13: =IF(I13<=0,1000000000,I13) -> 6148.7834 | P13: =$E$3 -> 0.022379198 | Q13: 1 | R13: =B13&" "&C13&"次" -> ねじり 2次
A14: 9 | B14: ねじり | C14: 3 | D14: 3 | E14: =D14^2 -> 9 | F14: =IFERROR(D14/(2*断面!$D$4)*SQRT(断面!$D$26/断面!$D$27),0) -> 9223.1751 | G14: =1 -> 1 | H14: =F14*G14 -> 9223.1751 | I14: =IF($I$3=1,H14,F14) -> 9223.1751 | J14: =IFERROR(2*断面!$D$4/D14*1000,0) -> 77.013333 | K14: =IFERROR(J14/(MAX(断面!$D$3,断面!$D$20)*1000),0) -> 1.8211442 | L14: =IF(K14>=6,"🟢 良",IF(K14>=3,"🟡 誤差±10%程度","🔴 参考値のみ")) -> 🔴 参考値のみ | M14: 板がねじれる。1次ねじりは1次曲げの近くに出やすい 🟡 | O14: =IF(I14<=0,1000000000,I14) -> 9223.1751 | P14: =$E$3 -> 0.022379198 | Q14: 1 | R14: =B14&" "&C14&"次" -> ねじり 3次
A15: 10 | B15: ねじり | C15: 4 | D15: 4 | E15: =D15^2 -> 16 | F15: =IFERROR(D15/(2*断面!$D$4)*SQRT(断面!$D$26/断面!$D$27),0) -> 12297.567 | G15: =1 -> 1 | H15: =F15*G15 -> 12297.567 | I15: =IF($I$3=1,H15,F15) -> 12297.567 | J15: =IFERROR(2*断面!$D$4/D15*1000,0) -> 57.76 | K15: =IFERROR(J15/(MAX(断面!$D$3,断面!$D$20)*1000),0) -> 1.3658582 | L15: =IF(K15>=6,"🟢 良",IF(K15>=3,"🟡 誤差±10%程度","🔴 参考値のみ")) -> 🔴 参考値のみ | M15: 板がねじれる。1次ねじりは1次曲げの近くに出やすい 🟡 | O15: =IF(I15<=0,1000000000,I15) -> 12297.567 | P15: =$E$3 -> 0.022379198 | Q15: 1 | R15: =B15&" "&C15&"次" -> ねじり 4次
A16: 11 | B16: 面内曲げ | C16: 1 | D16: 4.730041 | E16: =D16^2 -> 22.373288 | F16: =IFERROR(E16/(2*PI()*断面!$D$4^2)*SQRT(断面!$D$17/断面!$D$19),0) -> 12875.151 | G16: =IFERROR(1/SQRT(1+E16*($F$4/断面!$D$4)^2*$H$4),1) -> 0.70215485 | H16: =F16*G16 -> 9040.3494 | I16: =IF($I$3=1,H16,F16) -> 9040.3494 | J16: =IFERROR(2*PI()*断面!$D$4/D16*1000,0) -> 153.45186 | K16: =IFERROR(J16/(断面!$D$3*1000),0) -> 3.6286958 | L16: =IF(K16>=6,"🟢 良",IF(K16>=3,"🟡 誤差±10%程度","🔴 参考値のみ")) -> 🟡 誤差±10%程度 | M16: 面の中で（半径方向に）波打つ。5kHz以上で効く 🟢 | O16: =IF(I16<=0,1000000000,I16) -> 9040.3494 | P16: =$E$3 -> 0.022379198 | Q16: 1 | R16: =B16&" "&C16&"次" -> 面内曲げ 1次
A17: 12 | B17: 面内曲げ | C17: 2 | D17: 7.853205 | E17: =D17^2 -> 61.672829 | F17: =IFERROR(E17/(2*PI()*断面!$D$4^2)*SQRT(断面!$D$17/断面!$D$19),0) -> 35490.848 | G17: =IFERROR(1/SQRT(1+E17*($F$4/断面!$D$4)^2*$H$4),1) -> 0.51067126 | H17: =F17*G17 -> 18124.156 | I17: =IF($I$3=1,H17,F17) -> 18124.156 | J17: =IFERROR(2*PI()*断面!$D$4/D17*1000,0) -> 92.425139 | K17: =IFERROR(J17/(断面!$D$3*1000),0) -> 2.1855892 | L17: =IF(K17>=6,"🟢 良",IF(K17>=3,"🟡 誤差±10%程度","🔴 参考値のみ")) -> 🔴 参考値のみ | M17: 面の中で（半径方向に）波打つ。5kHz以上で効く 🟢 | O17: =IF(I17<=0,1000000000,I17) -> 18124.156 | P17: =$E$3 -> 0.022379198 | Q17: 1 | R17: =B17&" "&C17&"次" -> 面内曲げ 2次
A18: 13 | B18: 面内曲げ | C18: 3 | D18: 10.995608 | E18: =D18^2 -> 120.9034 | F18: =IFERROR(E18/(2*PI()*断面!$D$4^2)*SQRT(断面!$D$17/断面!$D$19),0) -> 69576.248 | G18: =IFERROR(1/SQRT(1+E18*($F$4/断面!$D$4)^2*$H$4),1) -> 0.39052672 | H18: =F18*G18 -> 27171.384 | I18: =IF($I$3=1,H18,F18) -> 27171.384 | J18: =IFERROR(2*PI()*断面!$D$4/D18*1000,0) -> 66.011226 | K18: =IFERROR(J18/(断面!$D$3*1000),0) -> 1.560976 | L18: =IF(K18>=6,"🟢 良",IF(K18>=3,"🟡 誤差±10%程度","🔴 参考値のみ")) -> 🔴 参考値のみ | M18: 面の中で（半径方向に）波打つ。5kHz以上で効く 🟢 | O18: =IF(I18<=0,1000000000,I18) -> 27171.384 | P18: =$E$3 -> 0.022379198 | Q18: 1 | R18: =B18&" "&C18&"次" -> 面内曲げ 3次
A19: 14 | B19: 面内曲げ | C19: 4 | D19: 14.137165 | E19: =D19^2 -> 199.85943 | F19: =IFERROR(E19/(2*PI()*断面!$D$4^2)*SQRT(断面!$D$17/断面!$D$19),0) -> 115013.06 | G19: =IFERROR(1/SQRT(1+E19*($F$4/断面!$D$4)^2*$H$4),1) -> 0.31332978 | H19: =F19*G19 -> 36037.017 | I19: =IF($I$3=1,H19,F19) -> 36037.017 | J19: =IFERROR(2*PI()*断面!$D$4/D19*1000,0) -> 51.342229 | K19: =IFERROR(J19/(断面!$D$3*1000),0) -> 1.2140963 | L19: =IF(K19>=6,"🟢 良",IF(K19>=3,"🟡 誤差±10%程度","🔴 参考値のみ")) -> 🔴 参考値のみ | M19: 面の中で（半径方向に）波打つ。5kHz以上で効く 🟢 | O19: =IF(I19<=0,1000000000,I19) -> 36037.017 | P19: =$E$3 -> 0.022379198 | Q19: 1 | R19: =B19&" "&C19&"次" -> 面内曲げ 4次
A20: 15 | B20: 面内伸縮 | C20: 1 | D20: 1 | E20: =D20^2 -> 1 | F20: =IFERROR(D20/(2*断面!$D$4)*SQRT(断面!$D$18/断面!$D$19),0) -> 17107.975 | G20: =1 -> 1 | H20: =F20*G20 -> 17107.975 | I20: =IF($I$3=1,H20,F20) -> 17107.975 | J20: =IFERROR(2*断面!$D$4/D20*1000,0) -> 231.04 | K20: =IFERROR(J20/(MAX(断面!$D$3,断面!$D$20)*1000),0) -> 5.4634327 | L20: =IF(K20>=6,"🟢 良",IF(K20>=3,"🟡 誤差±10%程度","🔴 参考値のみ")) -> 🟡 誤差±10%程度 | M20: 円周方向に伸び縮み。10kHz超の高音鳴きに関与 🟢 | O20: =IF(I20<=0,1000000000,I20) -> 17107.975 | P20: =$E$3 -> 0.022379198 | Q20: 1 | R20: =B20&" "&C20&"次" -> 面内伸縮 1次
A21: 16 | B21: 面内伸縮 | C21: 2 | D21: 2 | E21: =D21^2 -> 4 | F21: =IFERROR(D21/(2*断面!$D$4)*SQRT(断面!$D$18/断面!$D$19),0) -> 34215.95 | G21: =1 -> 1 | H21: =F21*G21 -> 34215.95 | I21: =IF($I$3=1,H21,F21) -> 34215.95 | J21: =IFERROR(2*断面!$D$4/D21*1000,0) -> 115.52 | K21: =IFERROR(J21/(MAX(断面!$D$3,断面!$D$20)*1000),0) -> 2.7317164 | L21: =IF(K21>=6,"🟢 良",IF(K21>=3,"🟡 誤差±10%程度","🔴 参考値のみ")) -> 🔴 参考値のみ | M21: 円周方向に伸び縮み。10kHz超の高音鳴きに関与 🟢 | O21: =IF(I21<=0,1000000000,I21) -> 34215.95 | P21: =$E$3 -> 0.022379198 | Q21: 1 | R21: =B21&" "&C21&"次" -> 面内伸縮 2次
A22: 17 | B22: 面内伸縮 | C22: 3 | D22: 3 | E22: =D22^2 -> 9 | F22: =IFERROR(D22/(2*断面!$D$4)*SQRT(断面!$D$18/断面!$D$19),0) -> 51323.925 | G22: =1 -> 1 | H22: =F22*G22 -> 51323.925 | I22: =IF($I$3=1,H22,F22) -> 51323.925 | J22: =IFERROR(2*断面!$D$4/D22*1000,0) -> 77.013333 | K22: =IFERROR(J22/(MAX(断面!$D$3,断面!$D$20)*1000),0) -> 1.8211442 | L22: =IF(K22>=6,"🟢 良",IF(K22>=3,"🟡 誤差±10%程度","🔴 参考値のみ")) -> 🔴 参考値のみ | M22: 円周方向に伸び縮み。10kHz超の高音鳴きに関与 🟢 | O22: =IF(I22<=0,1000000000,I22) -> 51323.925 | P22: =$E$3 -> 0.022379198 | Q22: 1 | R22: =B22&" "&C22&"次" -> 面内伸縮 3次
A24: ■ 使っている式（🟢＝教科書どおり／🟡＝妥当な近似）
A25: 面外曲げ・面内曲げ | C25: f = (βL)² /(2π L²) × √(EI / ρA) | G25: 自由−自由はり（Euler-Bernoulli）。βL = 4.7300, 7.8532, 10.9956, 14.1372, 17.2788, 20.4204（cos(βL)cosh(βL)=1 の解） 🟢
A26: 周波数の比 | C26: f₁ : f₂ : f₃ : f₄ = 1 : 2.757 : 5.404 : 8.933 | G26: 実測がこの比から外れたら「曲げモードではない」or「せん断が効いている」 🟢
A27: せん断補正 | C27: f補正 = f / √(1 + (βL)²·(r/L)²·(1 + E/(κG))) | G27: Timoshenkoの一次近似。r=断面回転半径, κ=5/6。高次ほど大きく下がる。厚くて短いパッドでは必須 🟡
A28: ねじり | C28: f = n /(2L) × √(GJ / ρIp) | G28: 自由−自由ねじり棒。J=β·b·h³、β=(1/3)(1−0.630(h/b)+0.052(h/b)⁵) 🟢/🟡（積層のGJは近似）
A29: 面内伸縮 | C29: f = n /(2L) × √(EA / ρA) | G29: 自由−自由の縦振動。棒の中の音速 c=√(E/ρ) の半波長ずつ 🟢
A30: 波長 | C30: λ = 2πL/(βL)（曲げ）、λ = 2L/n（ねじり・伸縮） | G30: λ/断面寸法 が小さいほど1次元はり近似が苦しい。6以上あれば安心 🟢
A31: 最重要の性質 | C31: f ∝ h / L²（均質1枚板のとき） | G31: 厚さ2倍→周波数2倍。長さ2倍→周波数1/4。設計で一番効くのは L（長さ） 🟢
A33: ■ 感度（どこをいじると何Hz動くか）
A34: 長さ L を x 倍 → 面外曲げは 1/x² 倍。L が 5% 伸びるだけで周波数は約 9% 下がる（最も効く）
A35: 裏板の厚さ t1 を x 倍 → EI は x³、質量は x なので周波数はおよそ x 倍（摩擦材が乗っている分やや鈍る）
A36: 摩擦材のヤング率 E2 を x 倍 → 中立軸が裏板に寄っているため周波数はほとんど動かない
A37: 摩擦材の厚さ t2 を増やす → 重さだけ増えて剛性はあまり増えない ⇒ 周波数は下がる（摩耗すると鳴き周波数が上がる理由）
A38: ⚠ せん断補正を OFF にすると高次モードを 20〜50% 高く出します。実測と合わないときはまずここを疑う

Sheet スペクトル
A1: ④ スペクトル（FFT画面と同じ形のグラフ用データ）
A2: 各モードを1自由度系として複素数で足し合わせ、応答の大きさ |H(f)| を作る 🟢
A3: 開始周波数 [Hz] | C3: 0 | D3: 刻み Δf [Hz] | F3: 10 | G3: 点数 | H3: 2001 | I3: dB基準値 | K3: 1 | L3: ※ ピークを拡大したいときは 開始=4900, Δf=0.5 のように変える
A5: 周波数 f [Hz] | B5: 実部 Re | C5: 虚部 Im | D5: 応答 |H| | E5: レベル [dB]
A6: =$C$3 -> 0 | B6: =SUMPRODUCT(固有振動数!$Q$6:$Q$22*(1-($A6/固有振動数!$O$6:$O$22)^2)/((1-($A6/固有振動数!$O$6:$O$22)^2)^2+固有振動数!$P$6:$P$22^2)) -> 16.99149 | C6: =-SUMPRODUCT(固有振動数!$Q$6:$Q$22*固有振動数!$P$6:$P$22/((1-($A6/固有振動数!$O$6:$O$22)^2)^2+固有振動数!$P$6:$P$22^2)) -> -0.38025592 | D6: =SQRT(B6^2+C6^2) -> 16.995745 | E6: =20*LOG10(MAX(D6,0.000000000001)/$K$3) -> 24.606804
A7: =A6+$F$3 -> 10 | B7: =SUMPRODUCT(固有振動数!$Q$6:$Q$22*(1-($A7/固有振動数!$O$6:$O$22)^2)/((1-($A7/固有振動数!$O$6:$O$22)^2)^2+固有振動数!$P$6:$P$22^2)) -> 16.991535 | C7: =-SUMPRODUCT(固有振動数!$Q$6:$Q$22*固有振動数!$P$6:$P$22/((1-($A7/固有振動数!$O$6:$O$22)^2)^2+固有振動数!$P$6:$P$22^2)) -> -0.38025794 | D7: =SQRT(B7^2+C7^2) -> 16.99579 | E7: =20*LOG10(MAX(D7,0.000000000001)/$K$3) -> 24.606827
A8: =A7+$F$3 -> 20 | B8: =SUMPRODUCT(固有振動数!$Q$6:$Q$22*(1-($A8/固有振動数!$O$6:$O$22)^2)/((1-($A8/固有振動数!$O$6:$O$22)^2)^2+固有振動数!$P$6:$P$22^2)) -> 16.99167 | C8: =-SUMPRODUCT(固有振動数!$Q$6:$Q$22*固有振動数!$P$6:$P$22/((1-($A8/固有振動数!$O$6:$O$22)^2)^2+固有振動数!$P$6:$P$22^2)) -> -0.38026397 | D8: =SQRT(B8^2+C8^2) -> 16.995924 | E8: =20*LOG10(MAX(D8,0.000000000001)/$K$3) -> 24.606896
A9: =A8+$F$3 -> 30 | B9: =SUMPRODUCT(固有振動数!$Q$6:$Q$22*(1-($A9/固有振動数!$O$6:$O$22)^2)/((1-($A9/固有振動数!$O$6:$O$22)^2)^2+固有振動数!$P$6:$P$22^2)) -> 16.991895 | C9: =-SUMPRODUCT(固有振動数!$Q$6:$Q$22*固有振動数!$P$6:$P$22/((1-($A9/固有振動数!$O$6:$O$22)^2)^2+固有振動数!$P$6:$P$22^2)) -> -0.38027404 | D9: =SQRT(B9^2+C9^2) -> 16.996149 | E9: =20*LOG10(MAX(D9,0.000000000001)/$K$3) -> 24.607011
A10: =A9+$F$3 -> 40 | B10: =SUMPRODUCT(固有振動数!$Q$6:$Q$22*(1-($A10/固有振動数!$O$6:$O$22)^2)/((1-($A10/固有振動数!$O$6:$O$22)^2)^2+固有振動数!$P$6:$P$22^2)) -> 16.99221 | C10: =-SUMPRODUCT(固有振動数!$Q$6:$Q$22*固有振動数!$P$6:$P$22/((1-($A10/固有振動数!$O$6:$O$22)^2)^2+固有振動数!$P$6:$P$22^2)) -> -0.38028814 | D10: =SQRT(B10^2+C10^2) -> 16.996464 | E10: =20*LOG10(MAX(D10,0.000000000001)/$K$3) -> 24.607172
A11: =A10+$F$3 -> 50 | B11: =SUMPRODUCT(固有振動数!$Q$6:$Q$22*(1-($A11/固有振動数!$O$6:$O$22)^2)/((1-($A11/固有振動数!$O$6:$O$22)^2)^2+固有振動数!$P$6:$P$22^2)) -> 16.992614 | C11: =-SUMPRODUCT(固有振動数!$Q$6:$Q$22*固有振動数!$P$6:$P$22/((1-($A11/固有振動数!$O$6:$O$22)^2)^2+固有振動数!$P$6:$P$22^2)) -> -0.38030627 | D11: =SQRT(B11^2+C11^2) -> 16.99687 | E11: =20*LOG10(MAX(D11,0.000000000001)/$K$3) -> 24.607379
A12: =A11+$F$3 -> 60 | B12: =SUMPRODUCT(固有振動数!$Q$6:$Q$22*(1-($A12/固有振動数!$O$6:$O$22)^2)/((1-($A12/固有振動数!$O$6:$O$22)^2)^2+固有振動数!$P$6:$P$22^2)) -> 16.993109 | C12: =-SUMPRODUCT(固有振動数!$Q$6:$Q$22*固有振動数!$P$6:$P$22/((1-($A12/固有振動数!$O$6:$O$22)^2)^2+固有振動数!$P$6:$P$22^2)) -> -0.38032844 | D12: =SQRT(B12^2+C12^2) -> 16.997365 | E12: =20*LOG10(MAX(D12,0.000000000001)/$K$3) -> 24.607632
A13: =A12+$F$3 -> 70 | B13: =SUMPRODUCT(固有振動数!$Q$6:$Q$22*(1-($A13/固有振動数!$O$6:$O$22)^2)/((1-($A13/固有振動数!$O$6:$O$22)^2)^2+固有振動数!$P$6:$P$22^2)) -> 16.993694 | C13: =-SUMPRODUCT(固有振動数!$Q$6:$Q$22*固有振動数!$P$6:$P$22/((1-($A13/固有振動数!$O$6:$O$22)^2)^2+固有振動数!$P$6:$P$22^2)) -> -0.38035465 | D13: =SQRT(B13^2+C13^2) -> 16.99795 | E13: =20*LOG10(MAX(D13,0.000000000001)/$K$3) -> 24.607931
A14: =A13+$F$3 -> 80 | B14: =SUMPRODUCT(固有振動数!$Q$6:$Q$22*(1-($A14/固有振動数!$O$6:$O$22)^2)/((1-($A14/固有振動数!$O$6:$O$22)^2)^2+固有振動数!$P$6:$P$22^2)) -> 16.994369 | C14: =-SUMPRODUCT(固有振動数!$Q$6:$Q$22*固有振動数!$P$6:$P$22/((1-($A14/固有振動数!$O$6:$O$22)^2)^2+固有振動数!$P$6:$P$22^2)) -> -0.38038492 | D14: =SQRT(B14^2+C14^2) -> 16.998626 | E14: =20*LOG10(MAX(D14,0.000000000001)/$K$3) -> 24.608276
A15: =A14+$F$3 -> 90 | B15: =SUMPRODUCT(固有振動数!$Q$6:$Q$22*(1-($A15/固有振動数!$O$6:$O$22)^2)/((1-($A15/固有振動数!$O$6:$O$22)^2)^2+固有振動数!$P$6:$P$22^2)) -> 16.995135 | C15: =-SUMPRODUCT(固有振動数!$Q$6:$Q$22*固有振動数!$P$6:$P$22/((1-($A15/固有振動数!$O$6:$O$22)^2)^2+固有振動数!$P$6:$P$22^2)) -> -0.38041924 | D15: =SQRT(B15^2+C15^2) -> 16.999392 | E15: =20*LOG10(MAX(D15,0.000000000001)/$K$3) -> 24.608668
A16: =A15+$F$3 -> 100 | B16: =SUMPRODUCT(固有振動数!$Q$6:$Q$22*(1-($A16/固有振動数!$O$6:$O$22)^2)/((1-($A16/固有振動数!$O$6:$O$22)^2)^2+固有振動数!$P$6:$P$22^2)) -> 16.995991 | C16: =-SUMPRODUCT(固有振動数!$Q$6:$Q$22*固有振動数!$P$6:$P$22/((1-($A16/固有振動数!$O$6:$O$22)^2)^2+固有振動数!$P$6:$P$22^2)) -> -0.38045763 | D16: =SQRT(B16^2+C16^2) -> 17.000249 | E16: =20*LOG10(MAX(D16,0.000000000001)/$K$3) -> 24.609106
A17: =A16+$F$3 -> 110 | B17: =SUMPRODUCT(固有振動数!$Q$6:$Q$22*(1-($A17/固有振動数!$O$6:$O$22)^2)/((1-($A17/固有振動数!$O$6:$O$22)^2)^2+固有振動数!$P$6:$P$22^2)) -> 16.996938 | C17: =-SUMPRODUCT(固有振動数!$Q$6:$Q$22*固有振動数!$P$6:$P$22/((1-($A17/固有振動数!$O$6:$O$22)^2)^2+固有振動数!$P$6:$P$22^2)) -> -0.38050009 | D17: =SQRT(B17^2+C17^2) -> 17.001197 | E17: =20*LOG10(MAX(D17,0.000000000001)/$K$3) -> 24.60959
A18: =A17+$F$3 -> 120 | B18: =SUMPRODUCT(固有振動数!$Q$6:$Q$22*(1-($A18/固有振動数!$O$6:$O$22)^2)/((1-($A18/固有振動数!$O$6:$O$22)^2)^2+固有振動数!$P$6:$P$22^2)) -> 16.997976 | C18: =-SUMPRODUCT(固有振動数!$Q$6:$Q$22*固有振動数!$P$6:$P$22/((1-($A18/固有振動数!$O$6:$O$22)^2)^2+固有振動数!$P$6:$P$22^2)) -> -0.38054664 | D18: =SQRT(B18^2+C18^2) -> 17.002235 | E18: =20*LOG10(MAX(D18,0.000000000001)/$K$3) -> 24.61012
... A29: =A28+$F$3 -> 230 | B29: =SUMPRODUCT(固有振動数!$Q$6:$Q$22*(1-($A29/固有振動数!$O$6:$O$22)^2)/((1-($A29/固有振動数!$O$6:$O$22)^2)^2+固有振動数!$P$6:$P$22^2)) -> 17.015443 | C29: =-SUMPRODUCT(固有振動数!$Q$6:$Q$22*固有振動数!$P$6:$P$22/((1-($A29/固有振動数!$O$6:$O$22)^2)^2+固有振動数!$P$6:$P$22^2)) -> -0.38133248 | D29: =SQRT(B29^2+C29^2) -> 17.019715 | E29: =20*LOG10(MAX(D29,0.000000000001)/$K$3) -> 24.619046
A30: =A29+$F$3 -> 240 | B30: =SUMPRODUCT(固有振動数!$Q$6:$Q$22*(1-($A30/固有振動数!$O$6:$O$22)^2)/((1-($A30/固有振動数!$O$6:$O$22)^2)^2+固有振動数!$P$6:$P$22^2)) -> 17.017588 | C30: =-SUMPRODUCT(固有振動数!$Q$6:$Q$22*固有振動数!$P$6:$P$22/((1-($A30/固有振動数!$O$6:$O$22)^2)^2+固有振動数!$P$6:$P$22^2)) -> -0.38142928 | D30: =SQRT(B30^2+C30^2) -> 17.021862 | E30: =20*LOG10(MAX(D30,0.000000000001)/$K$3) -> 24.620141 | G30: ■ 使い方
A31: =A30+$F$3 -> 250 | B31: =SUMPRODUCT(固有振動数!$Q$6:$Q$22*(1-($A31/固有振動数!$O$6:$O$22)^2)/((1-($A31/固有振動数!$O$6:$O$22)^2)^2+固有振動数!$P$6:$P$22^2)) -> 17.019827 | C31: =-SUMPRODUCT(固有振動数!$Q$6:$Q$22*固有振動数!$P$6:$P$22/((1-($A31/固有振動数!$O$6:$O$22)^2)^2+固有振動数!$P$6:$P$22^2)) -> -0.3815304 | D31: =SQRT(B31^2+C31^2) -> 17.024103 | E31: =20*LOG10(MAX(D31,0.000000000001)/$K$3) -> 24.621285 | G31: A〜E列をそのままコピーすれば、gnuplot / Python / Origin / Excel の別グラフに貼れます。
A32: =A31+$F$3 -> 260 | B32: =SUMPRODUCT(固有振動数!$Q$6:$Q$22*(1-($A32/固有振動数!$O$6:$O$22)^2)/((1-($A32/固有振動数!$O$6:$O$22)^2)^2+固有振動数!$P$6:$P$22^2)) -> 17.022161 | C32: =-SUMPRODUCT(固有振動数!$Q$6:$Q$22*固有振動数!$P$6:$P$22/((1-($A32/固有振動数!$O$6:$O$22)^2)^2+固有振動数!$P$6:$P$22^2)) -> -0.38163588 | D32: =SQRT(B32^2+C32^2) -> 17.026439 | E32: =20*LOG10(MAX(D32,0.000000000001)/$K$3) -> 24.622476 | G32: CSVで欲しいときは A5:E2006 を選択 → 別シートに値貼り付け → 「CSVで保存」。
A33: =A32+$F$3 -> 270 | B33: =SUMPRODUCT(固有振動数!$Q$6:$Q$22*(1-($A33/固有振動数!$O$6:$O$22)^2)/((1-($A33/固有振動数!$O$6:$O$22)^2)^2+固有振動数!$P$6:$P$22^2)) -> 17.02459 | C33: =-SUMPRODUCT(固有振動数!$Q$6:$Q$22*固有振動数!$P$6:$P$22/((1-($A33/固有振動数!$O$6:$O$22)^2)^2+固有振動数!$P$6:$P$22^2)) -> -0.38174573 | D33: =SQRT(B33^2+C33^2) -> 17.02887 | E33: =20*LOG10(MAX(D33,0.000000000001)/$K$3) -> 24.623716 | G33: 縦軸dBは相対値です。絶対値が必要なら実測FRFの1点で K3（基準値）を合わせてください。
A34: =A33+$F$3 -> 280 | B34: =SUMPRODUCT(固有振動数!$Q$6:$Q$22*(1-($A34/固有振動数!$O$6:$O$22)^2)/((1-($A34/固有振動数!$O$6:$O$22)^2)^2+固有振動数!$P$6:$P$22^2)) -> 17.027115 | C34: =-SUMPRODUCT(固有振動数!$Q$6:$Q$22*固有振動数!$P$6:$P$22/((1-($A34/固有振動数!$O$6:$O$22)^2)^2+固有振動数!$P$6:$P$22^2)) -> -0.38185998 | D34: =SQRT(B34^2+C34^2) -> 17.031396 | E34: =20*LOG10(MAX(D34,0.000000000001)/$K$3) -> 24.625005 | G34: 山（ピーク）の高さは 1/η に比例します。η=0.01 なら山の高さは約100倍＝40dB。
A35: =A34+$F$3 -> 290 | B35: =SUMPRODUCT(固有振動数!$Q$6:$Q$22*(1-($A35/固有振動数!$O$6:$O$22)^2)/((1-($A35/固有振動数!$O$6:$O$22)^2)^2+固有振動数!$P$6:$P$22^2)) -> 17.029735 | C35: =-SUMPRODUCT(固有振動数!$Q$6:$Q$22*固有振動数!$P$6:$P$22/((1-($A35/固有振動数!$O$6:$O$22)^2)^2+固有振動数!$P$6:$P$22^2)) -> -0.38197867 | D35: =SQRT(B35^2+C35^2) -> 17.034019 | E35: =20*LOG10(MAX(D35,0.000000000001)/$K$3) -> 24.626342 | G35: 山の幅（半値幅）は Δf ≒ η × f です。η=0.01, f=5000Hz なら幅50Hz。
A36: =A35+$F$3 -> 300 | B36: =SUMPRODUCT(固有振動数!$Q$6:$Q$22*(1-($A36/固有振動数!$O$6:$O$22)^2)/((1-($A36/固有振動数!$O$6:$O$22)^2)^2+固有振動数!$P$6:$P$22^2)) -> 17.032452 | C36: =-SUMPRODUCT(固有振動数!$Q$6:$Q$22*固有振動数!$P$6:$P$22/((1-($A36/固有振動数!$O$6:$O$22)^2)^2+固有振動数!$P$6:$P$22^2)) -> -0.38210183 | D36: =SQRT(B36^2+C36^2) -> 17.036738 | E36: =20*LOG10(MAX(D36,0.000000000001)/$K$3) -> 24.627729 | G36: ⚠ Δf（刻み）が半値幅より粗いと、山が低く・細く描かれます。ηが小さいときは刻みを細かく。
A37: =A36+$F$3 -> 310 | B37: =SUMPRODUCT(固有振動数!$Q$6:$Q$22*(1-($A37/固有振動数!$O$6:$O$22)^2)/((1-($A37/固有振動数!$O$6:$O$22)^2)^2+固有振動数!$P$6:$P$22^2)) -> 17.035266 | C37: =-SUMPRODUCT(固有振動数!$Q$6:$Q$22*固有振動数!$P$6:$P$22/((1-($A37/固有振動数!$O$6:$O$22)^2)^2+固有振動数!$P$6:$P$22^2)) -> -0.38222949 | D37: =SQRT(B37^2+C37^2) -> 17.039554 | E37: =20*LOG10(MAX(D37,0.000000000001)/$K$3) -> 24.629164
A38: =A37+$F$3 -> 320 | B38: =SUMPRODUCT(固有振動数!$Q$6:$Q$22*(1-($A38/固有振動数!$O$6:$O$22)^2)/((1-($A38/固有振動数!$O$6:$O$22)^2)^2+固有振動数!$P$6:$P$22^2)) -> 17.038177 | C38: =-SUMPRODUCT(固有振動数!$Q$6:$Q$22*固有振動数!$P$6:$P$22/((1-($A38/固有振動数!$O$6:$O$22)^2)^2+固有振動数!$P$6:$P$22^2)) -> -0.38236168 | D38: =SQRT(B38^2+C38^2) -> 17.042467 | E38: =20*LOG10(MAX(D38,0.000000000001)/$K$3) -> 24.630649
A39: =A38+$F$3 -> 330 | B39: =SUMPRODUCT(固有振動数!$Q$6:$Q$22*(1-($A39/固有振動数!$O$6:$O$22)^2)/((1-($A39/固有振動数!$O$6:$O$22)^2)^2+固有振動数!$P$6:$P$22^2)) -> 17.041186 | C39: =-SUMPRODUCT(固有振動数!$Q$6:$Q$22*固有振動数!$P$6:$P$22/((1-($A39/固有振動数!$O$6:$O$22)^2)^2+固有振動数!$P$6:$P$22^2)) -> -0.38249844 | D39: =SQRT(B39^2+C39^2) -> 17.045478 | E39: =20*LOG10(MAX(D39,0.000000000001)/$K$3) -> 24.632184
A40: =A39+$F$3 -> 340 | B40: =SUMPRODUCT(固有振動数!$Q$6:$Q$22*(1-($A40/固有振動数!$O$6:$O$22)^2)/((1-($A40/固有振動数!$O$6:$O$22)^2)^2+固有振動数!$P$6:$P$22^2)) -> 17.044293 | C40: =-SUMPRODUCT(固有振動数!$Q$6:$Q$22*固有振動数!$P$6:$P$22/((1-($A40/固有振動数!$O$6:$O$22)^2)^2+固有振動数!$P$6:$P$22^2)) -> -0.38263981 | D40: =SQRT(B40^2+C40^2) -> 17.048588 | E40: =20*LOG10(MAX(D40,0.000000000001)/$K$3) -> 24.633768
A41: =A40+$F$3 -> 350 | B41: =SUMPRODUCT(固有振動数!$Q$6:$Q$22*(1-($A41/固有振動数!$O$6:$O$22)^2)/((1-($A41/固有振動数!$O$6:$O$22)^2)^2+固有振動数!$P$6:$P$22^2)) -> 17.0475 | C41: =-SUMPRODUCT(固有振動数!$Q$6:$Q$22*固有振動数!$P$6:$P$22/((1-($A41/固有振動数!$O$6:$O$22)^2)^2+固有振動数!$P$6:$P$22^2)) -> -0.38278582 | D41: =SQRT(B41^2+C41^2) -> 17.051797 | E41: =20*LOG10(MAX(D41,0.000000000001)/$K$3) -> 24.635403
A42: =A41+$F$3 -> 360 | B42: =SUMPRODUCT(固有振動数!$Q$6:$Q$22*(1-($A42/固有振動数!$O$6:$O$22)^2)/((1-($A42/固有振動数!$O$6:$O$22)^2)^2+固有振動数!$P$6:$P$22^2)) -> 17.050805 | C42: =-SUMPRODUCT(固有振動数!$Q$6:$Q$22*固有振動数!$P$6:$P$22/((1-($A42/固有振動数!$O$6:$O$22)^2)^2+固有振動数!$P$6:$P$22^2)) -> -0.38293652 | D42: =SQRT(B42^2+C42^2) -> 17.055105 | E42: =20*LOG10(MAX(D42,0.000000000001)/$K$3) -> 24.637088
A43: =A42+$F$3 -> 370 | B43: =SUMPRODUCT(固有振動数!$Q$6:$Q$22*(1-($A43/固有振動数!$O$6:$O$22)^2)/((1-($A43/固有振動数!$O$6:$O$22)^2)^2+固有振動数!$P$6:$P$22^2)) -> 17.054211 | C43: =-SUMPRODUCT(固有振動数!$Q$6:$Q$22*固有振動数!$P$6:$P$22/((1-($A43/固有振動数!$O$6:$O$22)^2)^2+固有振動数!$P$6:$P$22^2)) -> -0.38309194 | D43: =SQRT(B43^2+C43^2) -> 17.058513 | E43: =20*LOG10(MAX(D43,0.000000000001)/$K$3) -> 24.638824
A44: =A43+$F$3 -> 380 | B44: =SUMPRODUCT(固有振動数!$Q$6:$Q$22*(1-($A44/固有振動数!$O$6:$O$22)^2)/((1-($A44/固有振動数!$O$6:$O$22)^2)^2+固有振動数!$P$6:$P$22^2)) -> 17.057718 | C44: =-SUMPRODUCT(固有振動数!$Q$6:$Q$22*固有振動数!$P$6:$P$22/((1-($A44/固有振動数!$O$6:$O$22)^2)^2+固有振動数!$P$6:$P$22^2)) -> -0.38325213 | D44: =SQRT(B44^2+C44^2) -> 17.062023 | E44: =20*LOG10(MAX(D44,0.000000000001)/$K$3) -> 24.64061
A45: =A44+$F$3 -> 390 | B45: =SUMPRODUCT(固有振動数!$Q$6:$Q$22*(1-($A45/固有振動数!$O$6:$O$22)^2)/((1-($A45/固有振動数!$O$6:$O$22)^2)^2+固有振動数!$P$6:$P$22^2)) -> 17.061326 | C45: =-SUMPRODUCT(固有振動数!$Q$6:$Q$22*固有振動数!$P$6:$P$22/((1-($A45/固有振動数!$O$6:$O$22)^2)^2+固有振動数!$P$6:$P$22^2)) -> -0.38341714 | D45: =SQRT(B45^2+C45^2) -> 17.065633 | E45: =20*LOG10(MAX(D45,0.000000000001)/$K$3) -> 24.642448
A46: =A45+$F$3 -> 400 | B46: =SUMPRODUCT(固有振動数!$Q$6:$Q$22*(1-($A46/固有振動数!$O$6:$O$22)^2)/((1-($A46/固有振動数!$O$6:$O$22)^2)^2+固有振動数!$P$6:$P$22^2)) -> 17.065036 | C46: =-SUMPRODUCT(固有振動数!$Q$6:$Q$22*固有振動数!$P$6:$P$22/((1-($A46/固有振動数!$O$6:$O$22)^2)^2+固有振動数!$P$6:$P$22^2)) -> -0.383587 | D46: =SQRT(B46^2+C46^2) -> 17.069346 | E46: =20*LOG10(MAX(D46,0.000000000001)/$K$3) -> 24.644338
A47: =A46+$F$3 -> 410 | B47: =SUMPRODUCT(固有振動数!$Q$6:$Q$22*(1-($A47/固有振動数!$O$6:$O$22)^2)/((1-($A47/固有振動数!$O$6:$O$22)^2)^2+固有振動数!$P$6:$P$22^2)) -> 17.068848 | C47: =-SUMPRODUCT(固有振動数!$Q$6:$Q$22*固有振動数!$P$6:$P$22/((1-($A47/固有振動数!$O$6:$O$22)^2)^2+固有振動数!$P$6:$P$22^2)) -> -0.38376178 | D47: =SQRT(B47^2+C47^2) -> 17.073162 | E47: =20*LOG10(MAX(D47,0.000000000001)/$K$3) -> 24.646279
A48: =A47+$F$3 -> 420 | B48: =SUMPRODUCT(固有振動数!$Q$6:$Q$22*(1-($A48/固有振動数!$O$6:$O$22)^2)/((1-($A48/固有振動数!$O$6:$O$22)^2)^2+固有振動数!$P$6:$P$22^2)) -> 17.072764 | C48: =-SUMPRODUCT(固有振動数!$Q$6:$Q$22*固有振動数!$P$6:$P$22/((1-($A48/固有振動数!$O$6:$O$22)^2)^2+固有振動数!$P$6:$P$22^2)) -> -0.38394151 | D48: =SQRT(B48^2+C48^2) -> 17.077081 | E48: =20*LOG10(MAX(D48,0.000000000001)/$K$3) -> 24.648273
... A2006: =A2005+$F$3 -> 20000 | B2006: =SUMPRODUCT(固有振動数!$Q$6:$Q$22*(1-($A2006/固有振動数!$O$6:$O$22)^2)/((1-($A2006/固有振動数!$O$6:$O$22)^2)^2+固有振動数!$P$6:$P$22^2)) -> -0.80473207 | C2006: =-SUMPRODUCT(固有振動数!$Q$6:$Q$22*固有振動数!$P$6:$P$22/((1-($A2006/固有振動数!$O$6:$O$22)^2)^2+固有振動数!$P$6:$P$22^2)) -> -1.9817201 | D2006: =SQRT(B2006^2+C2006^2) -> 2.1388802 | E2006: =20*LOG10(MAX(D2006,0.000000000001)/$K$3) -> 6.6037291

Sheet 鳴きリスク
A1: ⑤ 鳴（な）きリスク スクリーニング
A2: SAE J2521 の対象帯域 1.25〜16 kHz を基準に、モード密集とディスクとの一致度を点数化 🟡（CEAの代わりにはなりません）
A3: 帯域 下限 [Hz] | C3: 1250 | D3: 帯域 上限 [Hz] | F3: 16000 | G3: 接近とみなす差 [%] | I3: 3
A5: ■ ディスク（ローター）の固有振動数 [Hz]（分かる範囲で入力／空欄可）
A6: D1 | B6: 1800 | C6: ← ここは「例」です。必ず自分のローターの実測値／FEM値に差し替えてください（🔴 要確認）
A7: D2 | B7: 3200
A8: D3 | B8: 5000
A9: D4 | B9: 7100
A10: D5 | B10: 9400
A11: D6
A12: D7
A13: D8
A14: D9
A15: D10
A17: # | B17: モード名 | C17: f [Hz] | D17: 帯域内? | E17: 最近接パッドモード差 [%] | F17: 最近接ディスクモード差 [%] | G17: 個別判定
A18: 1 | B18: =固有振動数!$R$6 -> 面外曲げ 1次 | C18: =固有振動数!$I$6 -> 2135.7039 | D18: =IF(AND(C18>=$C$3,C18<=$F$3),"○ 帯域内","− 帯域外") -> ○ 帯域内 | E18: =MIN(L18:AB18) -> 43.95215 | F18: =MIN(AD18:AM18) -> 15.718655 | G18: =IF(D18="− 帯域外","− 対象外",IF(OR(E18<$I$3,F18<$I$3),"🔴 高リスク",IF(OR(E18<$I$3*2,F18<$I$3*2),"🟡 中リスク","🟢 低リスク"))) -> 🟢 低リスク | L18: =IF(OR(0=0,$C18<=0,$C$18<=0),1000000,ABS($C18-$C$18)/$C18*100) -> 1000000 | M18: =IF(OR(1=0,$C18<=0,$C$19<=0),1000000,ABS($C18-$C$19)/$C18*100) -> 148.51658 | N18: =IF(OR(2=0,$C18<=0,$C$20<=0),1000000,ABS($C18-$C$20)/$C18*100) -> 330.26081 | O18: =IF(OR(3=0,$C18<=0,$C$21<=0),1000000,ABS($C18-$C$21)/$C18*100) -> 525.40523 | P18: =IF(OR(4=0,$C18<=0,$C$22<=0),1000000,ABS($C18-$C$22)/$C18*100) -> 724.63501 | Q18: =IF(OR(5=0,$C18<=0,$C$23<=0),1000000,ABS($C18-$C$23)/$C18*100) -> 924.01533 | R18: =IF(OR(6=0,$C18<=0,$C$24<=0),1000000,ABS($C18-$C$24)/$C18*100) -> 43.95215 | S18: =IF(OR(7=0,$C18<=0,$C$25<=0),1000000,ABS($C18-$C$25)/$C18*100) -> 187.9043 | T18: =IF(OR(8=0,$C18<=0,$C$26<=0),1000000,ABS($C18-$C$26)/$C18*100) -> 331.85645 | U18: =IF(OR(9=0,$C18<=0,$C$27<=0),1000000,ABS($C18-$C$27)/$C18*100) -> 475.8086 | V18: =IF(OR(10=0,$C18<=0,$C$28<=0),1000000,ABS($C18-$C$28)/$C18*100) -> 323.296 | W18: =IF(OR(11=0,$C18<=0,$C$29<=0),1000000,ABS($C18-$C$29)/$C18*100) -> 748.6268 | X18: =IF(OR(12=0,$C18<=0,$C$30<=0),1000000,ABS($C18-$C$30)/$C18*100) -> 1172.2449 | Y18: =IF(OR(13=0,$C18<=0,$C$31<=0),1000000,ABS($C18-$C$31)/$C18*100) -> 1587.3602 | Z18: =IF(OR(14=0,$C18<=0,$C$32<=0),1000000,ABS($C18-$C$32)/$C18*100) -> 701.04619 | AA18: =IF(OR(15=0,$C18<=0,$C$33<=0),1000000,ABS($C18-$C$33)/$C18*100) -> 1502.0924 | AB18: =IF(OR(16=0,$C18<=0,$C$34<=0),1000000,ABS($C18-$C$34)/$C18*100) -> 2303.1386 | AD18: =IF(OR($B$6="",$B$6<=0,$C18<=0),1000000,ABS($C18-$B$6)/$C18*100) -> 15.718655 | AE18: =IF(OR($B$7="",$B$7<=0,$C18<=0),1000000,ABS($C18-$B$7)/$C18*100) -> 49.833503 | AF18: =IF(OR($B$8="",$B$8<=0,$C18<=0),1000000,ABS($C18-$B$8)/$C18*100) -> 134.11485 | AG18: =IF(OR($B$9="",$B$9<=0,$C18<=0),1000000,ABS($C18-$B$9)/$C18*100) -> 232.44308 | AH18: =IF(OR($B$10="",$B$10<=0,$C18<=0),1000000,ABS($C18-$B$10)/$C18*100) -> 340.13591 | AI18: =IF(OR($B$11="",$B$11<=0,$C18<=0),1000000,ABS($C18-$B$11)/$C18*100) -> 1000000 | AJ18: =IF(OR($B$12="",$B$12<=0,$C18<=0),1000000,ABS($C18-$B$12)/$C18*100) -> 1000000 | AK18: =IF(OR($B$13="",$B$13<=0,$C18<=0),1000000,ABS($C18-$B$13)/$C18*100) -> 1000000 | AL18: =IF(OR($B$14="",$B$14<=0,$C18<=0),1000000,ABS($C18-$B$14)/$C18*100) -> 1000000 | AM18: =IF(OR($B$15="",$B$15<=0,$C18<=0),1000000,ABS($C18-$B$15)/$C18*100) -> 1000000
A19: 2 | B19: =固有振動数!$R$7 -> 面外曲げ 2次 | C19: =固有振動数!$I$7 -> 5307.5783 | D19: =IF(AND(C19>=$C$3,C19<=$F$3),"○ 帯域内","− 帯域外") -> ○ 帯域内 | E19: =MIN(L19:AB19) -> 15.849133 | F19: =MIN(AD19:AM19) -> 5.7950777 | G19: =IF(D19="− 帯域外","− 対象外",IF(OR(E19<$I$3,F19<$I$3),"🔴 高リスク",IF(OR(E19<$I$3*2,F19<$I$3*2),"🟡 中リスク","🟢 低リスク"))) -> 🟡 中リスク | L19: =IF(OR(0=1,$C19<=0,$C$18<=0),1000000,ABS($C19-$C$18)/$C19*100) -> 59.761236 | M19: =IF(OR(1=1,$C19<=0,$C$19<=0),1000000,ABS($C19-$C$19)/$C19*100) -> 1000000 | N19: =IF(OR(2=1,$C19<=0,$C$20<=0),1000000,ABS($C19-$C$20)/$C19*100) -> 73.131635 | O19: =IF(OR(3=1,$C19<=0,$C$21<=0),1000000,ABS($C19-$C$21)/$C19*100) -> 151.65534 | P19: =IF(OR(4=1,$C19<=0,$C$22<=0),1000000,ABS($C19-$C$22)/$C19*100) -> 231.82294 | Q19: =IF(OR(5=1,$C19<=0,$C$23<=0),1000000,ABS($C19-$C$23)/$C19*100) -> 312.05112 | R19: =IF(OR(6=1,$C19<=0,$C$24<=0),1000000,ABS($C19-$C$24)/$C19*100) -> 42.075434 | S19: =IF(OR(7=1,$C19<=0,$C$25<=0),1000000,ABS($C19-$C$25)/$C19*100) -> 15.849133 | T19: =IF(OR(8=1,$C19<=0,$C$26<=0),1000000,ABS($C19-$C$26)/$C19*100) -> 73.773699 | U19: =IF(OR(9=1,$C19<=0,$C$27<=0),1000000,ABS($C19-$C$27)/$C19*100) -> 131.69827 | V19: =IF(OR(10=1,$C19<=0,$C$28<=0),1000000,ABS($C19-$C$28)/$C19*100) -> 70.329082 | W19: =IF(OR(11=1,$C19<=0,$C$29<=0),1000000,ABS($C19-$C$29)/$C19*100) -> 241.47694 | X19: =IF(OR(12=1,$C19<=0,$C$30<=0),1000000,ABS($C19-$C$30)/$C19*100) -> 411.93562 | Y19: =IF(OR(13=1,$C19<=0,$C$31<=0),1000000,ABS($C19-$C$31)/$C19*100) -> 578.97288 | Z19: =IF(OR(14=1,$C19<=0,$C$32<=0),1000000,ABS($C19-$C$32)/$C19*100) -> 222.33109 | AA19: =IF(OR(15=1,$C19<=0,$C$33<=0),1000000,ABS($C19-$C$33)/$C19*100) -> 544.66218 | AB19: =IF(OR(16=1,$C19<=0,$C$34<=0),1000000,ABS($C19-$C$34)/$C19*100) -> 866.99327 | AD19: =IF(OR($B$6="",$B$6<=0,$C19<=0),1000000,ABS($C19-$B$6)/$C19*100) -> 66.086228 | AE19: =IF(OR($B$7="",$B$7<=0,$C19<=0),1000000,ABS($C19-$B$7)/$C19*100) -> 39.70885 | AF19: =IF(OR($B$8="",$B$8<=0,$C19<=0),1000000,ABS($C19-$B$8)/$C19*100) -> 5.7950777 | AG19: =IF(OR($B$9="",$B$9<=0,$C19<=0),1000000,ABS($C19-$B$9)/$C19*100) -> 33.77099 | AH19: =IF(OR($B$10="",$B$10<=0,$C19<=0),1000000,ABS($C19-$B$10)/$C19*100) -> 77.105254 | AI19: =IF(OR($B$11="",$B$11<=0,$C19<=0),1000000,ABS($C19-$B$11)/$C19*100) -> 1000000 | AJ19: =IF(OR($B$12="",$B$12<=0,$C19<=0),1000000,ABS($C19-$B$12)/$C19*100) -> 1000000 | AK19: =IF(OR($B$13="",$B$13<=0,$C19<=0),1000000,ABS($C19-$B$13)/$C19*100) -> 1000000 | AL19: =IF(OR($B$14="",$B$14<=0,$C19<=0),1000000,ABS($C19-$B$14)/$C19*100) -> 1000000 | AM19: =IF(OR($B$15="",$B$15<=0,$C19<=0),1000000,ABS($C19-$B$15)/$C19*100) -> 1000000
