Workbook

Sheet 使い方
B1: 鉄板ハンマリング → 自動ピーク検出 → カーブフィット法 損失係数ηの自動算出
B2: ■ このファイルは何をするもの？
B3: RION SA-01A4（FFT／指数・指数窓／平均=無し／解析点数32768）で測ったスペクトルを貼り付けると、
B4: たくさん並んだ山（ピーク）を自動で見つけ、山ごとに『1自由度カーブフィット』を行って
B5: 固有振動数 fn と 損失係数 η（そんしつけいすう）を出します。指数窓で余分に付いた減衰も自動で引き算します。
B7: ■ 使う順番（この4ステップだけ）
B8: STEP1 「設定」シートの黄色いセルに、測定した条件を入れる（レンジ・点数・指数窓の減衰値・単位）。
B9: STEP2 「データ」シートの A列＝周波数[Hz]、B列＝振幅 に、SA-01のCSVを貼り付ける（2行目から）。
B10: ※ 今は動作確認用のサンプル（鉄板を模した模擬データ）が入っています。上書きしてOKです。
B11: STEP3 再計算する（LibreOffice Calc は Ctrl+Shift+F9 で完全再計算）。
B12: STEP4 「ピーク一覧」シートを見る。Y列＝固有振動数 fn、AB列＝損失係数 η（補正後）が答えです。
B14: ■ 色のルール
... B30: ④ 平均=無しの1発打ちなので、コヒーレンスは使えません。波形がクリップしていないかだけは必ず目視確認を。

Sheet 設定
A3: 【1】測定条件（RION SA-01A4）
A4: 解析周波数レンジ [Hz] | B4: 2000 | C4: SA-01の「解析周波数」。1Hz〜40kHz。狭くするほどΔfが細かくなる
A5: レンジ区分 | B5: 20kHz以下 | C5: 「20kHz以下」か「40kHz」。サンプリング係数が変わる
A6: サンプリング係数 | B6: =IF($B$5="40kHz",2.4,2.56) -> 2.56 | C6: 出典:SA-01ハードウェアマニュアル(分析部)
A7: サンプリング周波数 fs [Hz] | B7: =$B$4*$B$6 -> 5120 | C7: fs = レンジ × 係数
A8: 解析サンプリング点数 N | B8: 32768 | C8: 2^N(N=6〜15)＝64〜32768点。今回は最大の32768
A9: 表示ライン数 | B9: =ROUNDDOWN($B$8/$B$6,0)+1 -> 12801 | C9: 20kHz以下で32768点→12801ライン
A10: 記録時間 T [s] | B10: =$B$8/$B$7 -> 6.4 | C10: T = N / fs。指数窓の1フレーム長
A11: 周波数分解能 Δf [Hz] | B11: =$B$7/$B$8 -> 0.15625 | C11: Δf = fs / N。データ1点あたりの周波数の刻み
A13: 【2】指数窓（指数・指数）の設定
A14: 減衰値の指定方式 | B14: % | C14: SA-01「指数ウィンド設定＝フレーム終端での減衰値」の単位。「%」か「dB」
A15: フレーム終端の減衰値 | B15: 5 | C15: 例:5 → 記録の終わりで振幅が5%(=1/20)まで減る設定
A16: 減衰比 r（終端/先頭） | B16: =IF($B$14="dB",10^($B$15/20),$B$15/100) -> 0.05 | C16: r=0.05 なら終端で5%
A17: 窓の時定数 τ [s] | B17: =-$B$10/LN($B$16) -> 2.1363725 | C17: w(t)=exp(-t/τ)。τ= -T/ln(r)
A18: 付加される損失係数 @1kHz | B18: =1/(PI()*1000*$B$17) -> 0.0001489955 | C18: Δη=1/(π・fn・τ)。これを実測ηから引く
A20: 【3】貼り付けたデータの単位
A21: B列（振幅）の単位 | B21: dB | C21: 「dB」なら 10^(dB/20) でリニアに変換。リニアで貼るなら「リニア」
A23: 【4】ピーク自動検出のパラメータ
A24: 探索の片側点数 m | B24: 8 | C24: 左右 m 点より高ければ『山の頂上』とみなす
A25: しきい値 [dB]（最大から下） | B25: -45 | C25: 最大ピークより何dB下までを山として拾うか。ノイズが多いなら -30 など
A26: 突出量ウィンドウ 片側点数 M | B26: 40 | C26: 山のふもとを見る幅。半値幅の2〜4倍の点数が目安
A27: 必要な突出量 [dB] | B27: 6 | C27: ふもと（谷）より何dB高ければ本物の山とみなすか。ノイズの小波を除く要
A28: 解析 開始周波数 [Hz] | B28: 50 | C28: これより低い周波数は無視（低域のうねり・剛体モード除去）
A29: 解析 終了周波数 [Hz] | B29: 2000 | C29: これより高い周波数は無視
A30: ウィンドウ最大値 | B30: =MAX($B$24,$B$26) -> 40 | C30: 自動
A31: 最大振幅 |H|max | B31: =MAX(データ!$C$2:$C$13701) -> 306.96227 | C31: 自動
A32: しきい値（リニア） | B32: =$B$31*10^($B$25/20) -> 1.7261757 | C32: 自動
A33: 検出されたピーク数 | B33: =MAX(データ!$G$2:$G$13701) -> 6 | C33: 多すぎ/少なすぎなら m・M・しきい値・突出量 を調整
A35: 【5】カーブフィットの帯域
A36: 1回目 帯域 片側点数 | B36: 25 | C36: 最初は固定幅でざっくりフィットしてηを推定
A37: 2回目 帯域係数（×η×fn） | B37: 1.5 | C37: 2回目は山の幅に合わせて自動で帯域を決める。1.0〜2.0推奨
A38: データ最終行インデックス | B38: 13700 | C38: 変更不可（データシートの行数）
A40: 【6】分解能チェック（一番大事）
A41: 代表周波数 fn [Hz] | B41: 1000 | C41: チェックしたい周波数を入れる
A42: 想定する損失係数 η | B42: 0.003 | C42: 鉄の板の目安 0.0005〜0.005
A43: 半値幅 Δf3dB [Hz] | B43: =$B$41*$B$42 -> 3 | C43: Δf3dB ≒ η × fn
A44: 半値幅内のデータ点数 | B44: =$B$43/$B$11 -> 19.2 | C44: 10点以上が目標
A45: 判定 | B45: =IF($B$44>=10,"OK：十分",IF($B$44>=5,"注意：やや粗い","不足：レンジを下げて測り直す")) -> OK：十分 | C45: 「不足」ならηは信用できない

Sheet データ
A1: 周波数 f [Hz] | B1: 振幅（貼付：dB） | C1: |H| リニア | D1: u = f^2 | E1: y = 1/|H|^2 | F1: ピーク判定 | G1: 通番 | H1: ピークID
A2: 0 | B2: 12.4532 | C2: =IF($A2="","",IF(設定!$B$21="dB",10^($B2/20),ABS($B2))) -> 4.1943049 | D2: =IF($A2="","",$A2^2) -> 0 | E2: =IF($A2="","",IF($C2<=0,"",1/$C2^2)) -> 0.056843394 | F2: =IF(OR(ROW()-設定!$B$30<2,ROW()+設定!$B$30>13701,N($A2)<=0,N(INDEX($A$2:$A$13701,MIN(13700,MAX(1,ROW()-1+設定!$B$30))))<=0,$A2<設定!$B$28,$A2>設定!$B$29),0,IF(AND($C2>=MAX(INDEX($C$1:$C$13701,MAX(1,ROW()-設定!$B$24)):INDEX($C$1:$C$13701,MAX(1,ROW()-1))),$C2>MAX(INDEX($C$1:$C$13701,MIN(13701,ROW()+1)):INDEX($C$1:$C$13701,MIN(13701,ROW()+設定!$B$24))),$C2>=設定!$B$32,$C2>=MAX(MIN(INDEX($C$1:$C$13701,MAX(1,ROW()-設定!$B$26)):INDEX($C$1:$C$13701,MAX(1,ROW()-1))),MIN(INDEX($C$1:$C$13701,MIN(13701,ROW()+1)):INDEX($C$1:$C$13701,MIN(13701,ROW()+設定!$B$26))))*10^(設定!$B$27/20)),1,0)) -> 0 | G2: =IF($F2=1,1,0) -> 0 | H2: =IF($F2=1,$G2,"")
A3: 0.15625 | B3: 12.4839 | C3: =IF($A3="","",IF(設定!$B$21="dB",10^($B3/20),ABS($B3))) -> 4.2091558 | D3: =IF($A3="","",$A3^2) -> 0.024414062 | E3: =IF($A3="","",IF($C3<=0,"",1/$C3^2)) -> 0.056442988 | F3: =IF(OR(ROW()-設定!$B$30<2,ROW()+設定!$B$30>13701,N($A3)<=0,N(INDEX($A$2:$A$13701,MIN(13700,MAX(1,ROW()-1+設定!$B$30))))<=0,$A3<設定!$B$28,$A3>設定!$B$29),0,IF(AND($C3>=MAX(INDEX($C$1:$C$13701,MAX(1,ROW()-設定!$B$24)):INDEX($C$1:$C$13701,MAX(1,ROW()-1))),$C3>MAX(INDEX($C$1:$C$13701,MIN(13701,ROW()+1)):INDEX($C$1:$C$13701,MIN(13701,ROW()+設定!$B$24))),$C3>=設定!$B$32,$C3>=MAX(MIN(INDEX($C$1:$C$13701,MAX(1,ROW()-設定!$B$26)):INDEX($C$1:$C$13701,MAX(1,ROW()-1))),MIN(INDEX($C$1:$C$13701,MIN(13701,ROW()+1)):INDEX($C$1:$C$13701,MIN(13701,ROW()+設定!$B$26))))*10^(設定!$B$27/20)),1,0)) -> 0 | G3: =$G2+IF($F3=1,1,0) -> 0 | H3: =IF($F3=1,$G3,"")
A4: 0.3125 | B4: 12.4241 | C4: =IF($A4="","",IF(設定!$B$21="dB",10^($B4/20),ABS($B4))) -> 4.1802764 | D4: =IF($A4="","",$A4^2) -> 0.09765625 | E4: =IF($A4="","",IF($C4<=0,"",1/$C4^2)) -> 0.057225553 | F4: =IF(OR(ROW()-設定!$B$30<2,ROW()+設定!$B$30>13701,N($A4)<=0,N(INDEX($A$2:$A$13701,MIN(13700,MAX(1,ROW()-1+設定!$B$30))))<=0,$A4<設定!$B$28,$A4>設定!$B$29),0,IF(AND($C4>=MAX(INDEX($C$1:$C$13701,MAX(1,ROW()-設定!$B$24)):INDEX($C$1:$C$13701,MAX(1,ROW()-1))),$C4>MAX(INDEX($C$1:$C$13701,MIN(13701,ROW()+1)):INDEX($C$1:$C$13701,MIN(13701,ROW()+設定!$B$24))),$C4>=設定!$B$32,$C4>=MAX(MIN(INDEX($C$1:$C$13701,MAX(1,ROW()-設定!$B$26)):INDEX($C$1:$C$13701,MAX(1,ROW()-1))),MIN(INDEX($C$1:$C$13701,MIN(13701,ROW()+1)):INDEX($C$1:$C$13701,MIN(13701,ROW()+設定!$B$26))))*10^(設定!$B$27/20)),1,0)) -> 0 | G4: =$G3+IF($F4=1,1,0) -> 0 | H4: =IF($F4=1,$G4,"")
A5: 0.46875 | B5: 12.3594 | C5: =IF($A5="","",IF(設定!$B$21="dB",10^($B5/20),ABS($B5))) -> 4.1492538 | D5: =IF($A5="","",$A5^2) -> 0.21972656 | E5: =IF($A5="","",IF($C5<=0,"",1/$C5^2)) -> 0.058084466 | F5: =IF(OR(ROW()-設定!$B$30<2,ROW()+設定!$B$30>13701,N($A5)<=0,N(INDEX($A$2:$A$13701,MIN(13700,MAX(1,ROW()-1+設定!$B$30))))<=0,$A5<設定!$B$28,$A5>設定!$B$29),0,IF(AND($C5>=MAX(INDEX($C$1:$C$13701,MAX(1,ROW()-設定!$B$24)):INDEX($C$1:$C$13701,MAX(1,ROW()-1))),$C5>MAX(INDEX($C$1:$C$13701,MIN(13701,ROW()+1)):INDEX($C$1:$C$13701,MIN(13701,ROW()+設定!$B$24))),$C5>=設定!$B$32,$C5>=MAX(MIN(INDEX($C$1:$C$13701,MAX(1,ROW()-設定!$B$26)):INDEX($C$1:$C$13701,MAX(1,ROW()-1))),MIN(INDEX($C$1:$C$13701,MIN(13701,ROW()+1)):INDEX($C$1:$C$13701,MIN(13701,ROW()+設定!$B$26))))*10^(設定!$B$27/20)),1,0)) -> 0 | G5: =$G4+IF($F5=1,1,0) -> 0 | H5: =IF($F5=1,$G5,"")
A6: 0.625 | B6: 12.4057 | C6: =IF($A6="","",IF(設定!$B$21="dB",10^($B6/20),ABS($B6))) -> 4.1714304 | D6: =IF($A6="","",$A6^2) -> 0.390625 | E6: =IF($A6="","",IF($C6<=0,"",1/$C6^2)) -> 0.057468518 | F6: =IF(OR(ROW()-設定!$B$30<2,ROW()+設定!$B$30>13701,N($A6)<=0,N(INDEX($A$2:$A$13701,MIN(13700,MAX(1,ROW()-1+設定!$B$30))))<=0,$A6<設定!$B$28,$A6>設定!$B$29),0,IF(AND($C6>=MAX(INDEX($C$1:$C$13701,MAX(1,ROW()-設定!$B$24)):INDEX($C$1:$C$13701,MAX(1,ROW()-1))),$C6>MAX(INDEX($C$1:$C$13701,MIN(13701,ROW()+1)):INDEX($C$1:$C$13701,MIN(13701,ROW()+設定!$B$24))),$C6>=設定!$B$32,$C6>=MAX(MIN(INDEX($C$1:$C$13701,MAX(1,ROW()-設定!$B$26)):INDEX($C$1:$C$13701,MAX(1,ROW()-1))),MIN(INDEX($C$1:$C$13701,MIN(13701,ROW()+1)):INDEX($C$1:$C$13701,MIN(13701,ROW()+設定!$B$26))))*10^(設定!$B$27/20)),1,0)) -> 0 | G6: =$G5+IF($F6=1,1,0) -> 0 | H6: =IF($F6=1,$G6,"")
A7: 0.78125 | B7: 12.3491 | C7: =IF($A7="","",IF(設定!$B$21="dB",10^($B7/20),ABS($B7))) -> 4.1443364 | D7: =IF($A7="","",$A7^2) -> 0.61035156 | E7: =IF($A7="","",IF($C7<=0,"",1/$C7^2)) -> 0.058222386 | F7: =IF(OR(ROW()-設定!$B$30<2,ROW()+設定!$B$30>13701,N($A7)<=0,N(INDEX($A$2:$A$13701,MIN(13700,MAX(1,ROW()-1+設定!$B$30))))<=0,$A7<設定!$B$28,$A7>設定!$B$29),0,IF(AND($C7>=MAX(INDEX($C$1:$C$13701,MAX(1,ROW()-設定!$B$24)):INDEX($C$1:$C$13701,MAX(1,ROW()-1))),$C7>MAX(INDEX($C$1:$C$13701,MIN(13701,ROW()+1)):INDEX($C$1:$C$13701,MIN(13701,ROW()+設定!$B$24))),$C7>=設定!$B$32,$C7>=MAX(MIN(INDEX($C$1:$C$13701,MAX(1,ROW()-設定!$B$26)):INDEX($C$1:$C$13701,MAX(1,ROW()-1))),MIN(INDEX($C$1:$C$13701,MIN(13701,ROW()+1)):INDEX($C$1:$C$13701,MIN(13701,ROW()+設定!$B$26))))*10^(設定!$B$27/20)),1,0)) -> 0 | G7: =$G6+IF($F7=1,1,0) -> 0 | H7: =IF($F7=1,$G7,"")
A8: 0.9375 | B8: 12.4589 | C8: =IF($A8="","",IF(設定!$B$21="dB",10^($B8/20),ABS($B8))) -> 4.1970583 | D8: =IF($A8="","",$A8^2) -> 0.87890625 | E8: =IF($A8="","",IF($C8<=0,"",1/$C8^2)) -> 0.056768837 | F8: =IF(OR(ROW()-設定!$B$30<2,ROW()+設定!$B$30>13701,N($A8)<=0,N(INDEX($A$2:$A$13701,MIN(13700,MAX(1,ROW()-1+設定!$B$30))))<=0,$A8<設定!$B$28,$A8>設定!$B$29),0,IF(AND($C8>=MAX(INDEX($C$1:$C$13701,MAX(1,ROW()-設定!$B$24)):INDEX($C$1:$C$13701,MAX(1,ROW()-1))),$C8>MAX(INDEX($C$1:$C$13701,MIN(13701,ROW()+1)):INDEX($C$1:$C$13701,MIN(13701,ROW()+設定!$B$24))),$C8>=設定!$B$32,$C8>=MAX(MIN(INDEX($C$1:$C$13701,MAX(1,ROW()-設定!$B$26)):INDEX($C$1:$C$13701,MAX(1,ROW()-1))),MIN(INDEX($C$1:$C$13701,MIN(13701,ROW()+1)):INDEX($C$1:$C$13701,MIN(13701,ROW()+設定!$B$26))))*10^(設定!$B$27/20)),1,0)) -> 0 | G8: =$G7+IF($F8=1,1,0) -> 0 | H8: =IF($F8=1,$G8,"")
A9: 1.09375 | B9: 12.5912 | C9: =IF($A9="","",IF(設定!$B$21="dB",10^($B9/20),ABS($B9))) -> 4.2614755 | D9: =IF($A9="","",$A9^2) -> 1.1962891 | E9: =IF($A9="","",IF($C9<=0,"",1/$C9^2)) -> 0.055065552 | F9: =IF(OR(ROW()-設定!$B$30<2,ROW()+設定!$B$30>13701,N($A9)<=0,N(INDEX($A$2:$A$13701,MIN(13700,MAX(1,ROW()-1+設定!$B$30))))<=0,$A9<設定!$B$28,$A9>設定!$B$29),0,IF(AND($C9>=MAX(INDEX($C$1:$C$13701,MAX(1,ROW()-設定!$B$24)):INDEX($C$1:$C$13701,MAX(1,ROW()-1))),$C9>MAX(INDEX($C$1:$C$13701,MIN(13701,ROW()+1)):INDEX($C$1:$C$13701,MIN(13701,ROW()+設定!$B$24))),$C9>=設定!$B$32,$C9>=MAX(MIN(INDEX($C$1:$C$13701,MAX(1,ROW()-設定!$B$26)):INDEX($C$1:$C$13701,MAX(1,ROW()-1))),MIN(INDEX($C$1:$C$13701,MIN(13701,ROW()+1)):INDEX($C$1:$C$13701,MIN(13701,ROW()+設定!$B$26))))*10^(設定!$B$27/20)),1,0)) -> 0 | G9: =$G8+IF($F9=1,1,0) -> 0 | H9: =IF($F9=1,$G9,"")
A10: 1.25 | B10: 12.4013 | C10: =IF($A10="","",IF(設定!$B$21="dB",10^($B10/20),ABS($B10))) -> 4.1693178 | D10: =IF($A10="","",$A10^2) -> 1.5625 | E10: =IF($A10="","",IF($C10<=0,"",1/$C10^2)) -> 0.057526771 | F10: =IF(OR(ROW()-設定!$B$30<2,ROW()+設定!$B$30>13701,N($A10)<=0,N(INDEX($A$2:$A$13701,MIN(13700,MAX(1,ROW()-1+設定!$B$30))))<=0,$A10<設定!$B$28,$A10>設定!$B$29),0,IF(AND($C10>=MAX(INDEX($C$1:$C$13701,MAX(1,ROW()-設定!$B$24)):INDEX($C$1:$C$13701,MAX(1,ROW()-1))),$C10>MAX(INDEX($C$1:$C$13701,MIN(13701,ROW()+1)):INDEX($C$1:$C$13701,MIN(13701,ROW()+設定!$B$24))),$C10>=設定!$B$32,$C10>=MAX(MIN(INDEX($C$1:$C$13701,MAX(1,ROW()-設定!$B$26)):INDEX($C$1:$C$13701,MAX(1,ROW()-1))),MIN(INDEX($C$1:$C$13701,MIN(13701,ROW()+1)):INDEX($C$1:$C$13701,MIN(13701,ROW()+設定!$B$26))))*10^(設定!$B$27/20)),1,0)) -> 0 | G10: =$G9+IF($F10=1,1,0) -> 0 | H10: =IF($F10=1,$G10,"")
A11: 1.40625 | B11: 12.3878 | C11: =IF($A11="","",IF(設定!$B$21="dB",10^($B11/20),ABS($B11))) -> 4.1628427 | D11: =IF($A11="","",$A11^2) -> 1.9775391 | E11: =IF($A11="","",IF($C11<=0,"",1/$C11^2)) -> 0.057705871 | F11: =IF(OR(ROW()-設定!$B$30<2,ROW()+設定!$B$30>13701,N($A11)<=0,N(INDEX($A$2:$A$13701,MIN(13700,MAX(1,ROW()-1+設定!$B$30))))<=0,$A11<設定!$B$28,$A11>設定!$B$29),0,IF(AND($C11>=MAX(INDEX($C$1:$C$13701,MAX(1,ROW()-設定!$B$24)):INDEX($C$1:$C$13701,MAX(1,ROW()-1))),$C11>MAX(INDEX($C$1:$C$13701,MIN(13701,ROW()+1)):INDEX($C$1:$C$13701,MIN(13701,ROW()+設定!$B$24))),$C11>=設定!$B$32,$C11>=MAX(MIN(INDEX($C$1:$C$13701,MAX(1,ROW()-設定!$B$26)):INDEX($C$1:$C$13701,MAX(1,ROW()-1))),MIN(INDEX($C$1:$C$13701,MIN(13701,ROW()+1)):INDEX($C$1:$C$13701,MIN(13701,ROW()+設定!$B$26))))*10^(設定!$B$27/20)),1,0)) -> 0 | G11: =$G10+IF($F11=1,1,0) -> 0 | H11: =IF($F11=1,$G11,"")
A12: 1.5625 | B12: 12.5036 | C12: =IF($A12="","",IF(設定!$B$21="dB",10^($B12/20),ABS($B12))) -> 4.2187132 | D12: =IF($A12="","",$A12^2) -> 2.4414062 | E12: =IF($A12="","",IF($C12<=0,"",1/$C12^2)) -> 0.056187538 | F12: =IF(OR(ROW()-設定!$B$30<2,ROW()+設定!$B$30>13701,N($A12)<=0,N(INDEX($A$2:$A$13701,MIN(13700,MAX(1,ROW()-1+設定!$B$30))))<=0,$A12<設定!$B$28,$A12>設定!$B$29),0,IF(AND($C12>=MAX(INDEX($C$1:$C$13701,MAX(1,ROW()-設定!$B$24)):INDEX($C$1:$C$13701,MAX(1,ROW()-1))),$C12>MAX(INDEX($C$1:$C$13701,MIN(13701,ROW()+1)):INDEX($C$1:$C$13701,MIN(13701,ROW()+設定!$B$24))),$C12>=設定!$B$32,$C12>=MAX(MIN(INDEX($C$1:$C$13701,MAX(1,ROW()-設定!$B$26)):INDEX($C$1:$C$13701,MAX(1,ROW()-1))),MIN(INDEX($C$1:$C$13701,MIN(13701,ROW()+1)):INDEX($C$1:$C$13701,MIN(13701,ROW()+設定!$B$26))))*10^(設定!$B$27/20)),1,0)) -> 0 | G12: =$G11+IF($F12=1,1,0) -> 0 | H12: =IF($F12=1,$G12,"")
A13: 1.71875 | B13: 12.4899 | C13: =IF($A13="","",IF(設定!$B$21="dB",10^($B13/20),ABS($B13))) -> 4.2120644 | D13: =IF($A13="","",$A13^2) -> 2.9541016 | E13: =IF($A13="","",IF($C13<=0,"",1/$C13^2)) -> 0.056365063 | F13: =IF(OR(ROW()-設定!$B$30<2,ROW()+設定!$B$30>13701,N($A13)<=0,N(INDEX($A$2:$A$13701,MIN(13700,MAX(1,ROW()-1+設定!$B$30))))<=0,$A13<設定!$B$28,$A13>設定!$B$29),0,IF(AND($C13>=MAX(INDEX($C$1:$C$13701,MAX(1,ROW()-設定!$B$24)):INDEX($C$1:$C$13701,MAX(1,ROW()-1))),$C13>MAX(INDEX($C$1:$C$13701,MIN(13701,ROW()+1)):INDEX($C$1:$C$13701,MIN(13701,ROW()+設定!$B$24))),$C13>=設定!$B$32,$C13>=MAX(MIN(INDEX($C$1:$C$13701,MAX(1,ROW()-設定!$B$26)):INDEX($C$1:$C$13701,MAX(1,ROW()-1))),MIN(INDEX($C$1:$C$13701,MIN(13701,ROW()+1)):INDEX($C$1:$C$13701,MIN(13701,ROW()+設定!$B$26))))*10^(設定!$B$27/20)),1,0)) -> 0 | G13: =$G12+IF($F13=1,1,0) -> 0 | H13: =IF($F13=1,$G13,"")
A14: 1.875 | B14: 12.4636 | C14: =IF($A14="","",IF(設定!$B$21="dB",10^($B14/20),ABS($B14))) -> 4.19933 | D14: =IF($A14="","",$A14^2) -> 3.515625 | E14: =IF($A14="","",IF($C14<=0,"",1/$C14^2)) -> 0.056707435 | F14: =IF(OR(ROW()-設定!$B$30<2,ROW()+設定!$B$30>13701,N($A14)<=0,N(INDEX($A$2:$A$13701,MIN(13700,MAX(1,ROW()-1+設定!$B$30))))<=0,$A14<設定!$B$28,$A14>設定!$B$29),0,IF(AND($C14>=MAX(INDEX($C$1:$C$13701,MAX(1,ROW()-設定!$B$24)):INDEX($C$1:$C$13701,MAX(1,ROW()-1))),$C14>MAX(INDEX($C$1:$C$13701,MIN(13701,ROW()+1)):INDEX($C$1:$C$13701,MIN(13701,ROW()+設定!$B$24))),$C14>=設定!$B$32,$C14>=MAX(MIN(INDEX($C$1:$C$13701,MAX(1,ROW()-設定!$B$26)):INDEX($C$1:$C$13701,MAX(1,ROW()-1))),MIN(INDEX($C$1:$C$13701,MIN(13701,ROW()+1)):INDEX($C$1:$C$13701,MIN(13701,ROW()+設定!$B$26))))*10^(設定!$B$27/20)),1,0)) -> 0 | G14: =$G13+IF($F14=1,1,0) -> 0 | H14: =IF($F14=1,$G14,"")
... A12802: 2000 | B12802: 9.6631 | C12802: =IF($A12802="","",IF(設定!$B$21="dB",10^($B12802/20),ABS($B12802))) -> 3.0419705 | D12802: =IF($A12802="","",$A12802^2) -> 4000000 | E12802: =IF($A12802="","",IF($C12802<=0,"",1/$C12802^2)) -> 0.10806623 | F12802: =IF(OR(ROW()-設定!$B$30<2,ROW()+設定!$B$30>13701,N($A12802)<=0,N(INDEX($A$2:$A$13701,MIN(13700,MAX(1,ROW()-1+設定!$B$30))))<=0,$A12802<設定!$B$28,$A12802>設定!$B$29),0,IF(AND($C12802>=MAX(INDEX($C$1:$C$13701,MAX(1,ROW()-設定!$B$24)):INDEX($C$1:$C$13701,MAX(1,ROW()-1))),$C12802>MAX(INDEX($C$1:$C$13701,MIN(13701,ROW()+1)):INDEX($C$1:$C$13701,MIN(13701,ROW()+設定!$B$24))),$C12802>=設定!$B$32,$C12802>=MAX(MIN(INDEX($C$1:$C$13701,MAX(1,ROW()-設定!$B$26)):INDEX($C$1:$C$13701,MAX(1,ROW()-1))),MIN(INDEX($C$1:$C$13701,MIN(13701,ROW()+1)):INDEX($C$1:$C$13701,MIN(13701,ROW()+設定!$B$26))))*10^(設定!$B$27/20)),1,0)) -> 0 | G12802: =$G12801+IF($F12802=1,1,0) -> 6 | H12802: =IF($F12802=1,$G12802,"")
C12803: =IF($A12803="","",IF(設定!$B$21="dB",10^($B12803/20),ABS($B12803))) | D12803: =IF($A12803="","",$A12803^2) | E12803: =IF($A12803="","",IF($C12803<=0,"",1/$C12803^2)) | F12803: =IF(OR(ROW()-設定!$B$30<2,ROW()+設定!$B$30>13701,N($A12803)<=0,N(INDEX($A$2:$A$13701,MIN(13700,MAX(1,ROW()-1+設定!$B$30))))<=0,$A12803<設定!$B$28,$A12803>設定!$B$29),0,IF(AND($C12803>=MAX(INDEX($C$1:$C$13701,MAX(1,ROW()-設定!$B$24)):INDEX($C$1:$C$13701,MAX(1,ROW()-1))),$C12803>MAX(INDEX($C$1:$C$13701,MIN(13701,ROW()+1)):INDEX($C$1:$C$13701,MIN(13701,ROW()+設定!$B$24))),$C12803>=設定!$B$32,$C12803>=MAX(MIN(INDEX($C$1:$C$13701,MAX(1,ROW()-設定!$B$26)):INDEX($C$1:$C$13701,MAX(1,ROW()-1))),MIN(INDEX($C$1:$C$13701,MIN(13701,ROW()+1)):INDEX($C$1:$C$13701,MIN(13701,ROW()+設定!$B$26))))*10^(設定!$B$27/20)),1,0)) -> 0 | G12803: =$G12802+IF($F12803=1,1,0) -> 6 | H12803: =IF($F12803=1,$G12803,"")
C12804: =IF($A12804="","",IF(設定!$B$21="dB",10^($B12804/20),ABS($B12804))) | D12804: =IF($A12804="","",$A12804^2) | E12804: =IF($A12804="","",IF($C12804<=0,"",1/$C12804^2)) | F12804: =IF(OR(ROW()-設定!$B$30<2,ROW()+設定!$B$30>13701,N($A12804)<=0,N(INDEX($A$2:$A$13701,MIN(13700,MAX(1,ROW()-1+設定!$B$30))))<=0,$A12804<設定!$B$28,$A12804>設定!$B$29),0,IF(AND($C12804>=MAX(INDEX($C$1:$C$13701,MAX(1,ROW()-設定!$B$24)):INDEX($C$1:$C$13701,MAX(1,ROW()-1))),$C12804>MAX(INDEX($C$1:$C$13701,MIN(13701,ROW()+1)):INDEX($C$1:$C$13701,MIN(13701,ROW()+設定!$B$24))),$C12804>=設定!$B$32,$C12804>=MAX(MIN(INDEX($C$1:$C$13701,MAX(1,ROW()-設定!$B$26)):INDEX($C$1:$C$13701,MAX(1,ROW()-1))),MIN(INDEX($C$1:$C$13701,MIN(13701,ROW()+1)):INDEX($C$1:$C$13701,MIN(13701,ROW()+設定!$B$26))))*10^(設定!$B$27/20)),1,0)) -> 0 | G12804: =$G12803+IF($F12804=1,1,0) -> 6 | H12804: =IF($F12804=1,$G12804,"")
C12805: =IF($A12805="","",IF(設定!$B$21="dB",10^($B12805/20),ABS($B12805))) | D12805: =IF($A12805="","",$A12805^2) | E12805: =IF($A12805="","",IF($C12805<=0,"",1/$C12805^2)) | F12805: =IF(OR(ROW()-設定!$B$30<2,ROW()+設定!$B$30>13701,N($A12805)<=0,N(INDEX($A$2:$A$13701,MIN(13700,MAX(1,ROW()-1+設定!$B$30))))<=0,$A12805<設定!$B$28,$A12805>設定!$B$29),0,IF(AND($C12805>=MAX(INDEX($C$1:$C$13701,MAX(1,ROW()-設定!$B$24)):INDEX($C$1:$C$13701,MAX(1,ROW()-1))),$C12805>MAX(INDEX($C$1:$C$13701,MIN(13701,ROW()+1)):INDEX($C$1:$C$13701,MIN(13701,ROW()+設定!$B$24))),$C12805>=設定!$B$32,$C12805>=MAX(MIN(INDEX($C$1:$C$13701,MAX(1,ROW()-設定!$B$26)):INDEX($C$1:$C$13701,MAX(1,ROW()-1))),MIN(INDEX($C$1:$C$13701,MIN(13701,ROW()+1)):INDEX($C$1:$C$13701,MIN(13701,ROW()+設定!$B$26))))*10^(設定!$B$27/20)),1,0)) -> 0 | G12805: =$G12804+IF($F12805=1,1,0) -> 6 | H12805: =IF($F12805=1,$G12805,"")
C12806: =IF($A12806="","",IF(設定!$B$21="dB",10^($B12806/20),ABS($B12806))) | D12806: =IF($A12806="","",$A12806^2) | E12806: =IF($A12806="","",IF($C12806<=0,"",1/$C12806^2)) | F12806: =IF(OR(ROW()-設定!$B$30<2,ROW()+設定!$B$30>13701,N($A12806)<=0,N(INDEX($A$2:$A$13701,MIN(13700,MAX(1,ROW()-1+設定!$B$30))))<=0,$A12806<設定!$B$28,$A12806>設定!$B$29),0,IF(AND($C12806>=MAX(INDEX($C$1:$C$13701,MAX(1,ROW()-設定!$B$24)):INDEX($C$1:$C$13701,MAX(1,ROW()-1))),$C12806>MAX(INDEX($C$1:$C$13701,MIN(13701,ROW()+1)):INDEX($C$1:$C$13701,MIN(13701,ROW()+設定!$B$24))),$C12806>=設定!$B$32,$C12806>=MAX(MIN(INDEX($C$1:$C$13701,MAX(1,ROW()-設定!$B$26)):INDEX($C$1:$C$13701,MAX(1,ROW()-1))),MIN(INDEX($C$1:$C$13701,MIN(13701,ROW()+1)):INDEX($C$1:$C$13701,MIN(13701,ROW()+設定!$B$26))))*10^(設定!$B$27/20)),1,0)) -> 0 | G12806: =$G12805+IF($F12806=1,1,0) -> 6 | H12806: =IF($F12806=1,$G12806,"")
C12807: =IF($A12807="","",IF(設定!$B$21="dB",10^($B12807/20),ABS($B12807))) | D12807: =IF($A12807="","",$A12807^2) | E12807: =IF($A12807="","",IF($C12807<=0,"",1/$C12807^2)) | F12807: =IF(OR(ROW()-設定!$B$30<2,ROW()+設定!$B$30>13701,N($A12807)<=0,N(INDEX($A$2:$A$13701,MIN(13700,MAX(1,ROW()-1+設定!$B$30))))<=0,$A12807<設定!$B$28,$A12807>設定!$B$29),0,IF(AND($C12807>=MAX(INDEX($C$1:$C$13701,MAX(1,ROW()-設定!$B$24)):INDEX($C$1:$C$13701,MAX(1,ROW()-1))),$C12807>MAX(INDEX($C$1:$C$13701,MIN(13701,ROW()+1)):INDEX($C$1:$C$13701,MIN(13701,ROW()+設定!$B$24))),$C12807>=設定!$B$32,$C12807>=MAX(MIN(INDEX($C$1:$C$13701,MAX(1,ROW()-設定!$B$26)):INDEX($C$1:$C$13701,MAX(1,ROW()-1))),MIN(INDEX($C$1:$C$13701,MIN(13701,ROW()+1)):INDEX($C$1:$C$13701,MIN(13701,ROW()+設定!$B$26))))*10^(設定!$B$27/20)),1,0)) -> 0 | G12807: =$G12806+IF($F12807=1,1,0) -> 6 | H12807: =IF($F12807=1,$G12807,"")
C12808: =IF($A12808="","",IF(設定!$B$21="dB",10^($B12808/20),ABS($B12808))) | D12808: =IF($A12808="","",$A12808^2) | E12808: =IF($A12808="","",IF($C12808<=0,"",1/$C12808^2)) | F12808: =IF(OR(ROW()-設定!$B$30<2,ROW()+設定!$B$30>13701,N($A12808)<=0,N(INDEX($A$2:$A$13701,MIN(13700,MAX(1,ROW()-1+設定!$B$30))))<=0,$A12808<設定!$B$28,$A12808>設定!$B$29),0,IF(AND($C12808>=MAX(INDEX($C$1:$C$13701,MAX(1,ROW()-設定!$B$24)):INDEX($C$1:$C$13701,MAX(1,ROW()-1))),$C12808>MAX(INDEX($C$1:$C$13701,MIN(13701,ROW()+1)):INDEX($C$1:$C$13701,MIN(13701,ROW()+設定!$B$24))),$C12808>=設定!$B$32,$C12808>=MAX(MIN(INDEX($C$1:$C$13701,MAX(1,ROW()-設定!$B$26)):INDEX($C$1:$C$13701,MAX(1,ROW()-1))),MIN(INDEX($C$1:$C$13701,MIN(13701,ROW()+1)):INDEX($C$1:$C$13701,MIN(13701,ROW()+設定!$B$26))))*10^(設定!$B$27/20)),1,0)) -> 0 | G12808: =$G12807+IF($F12808=1,1,0) -> 6 | H12808: =IF($F12808=1,$G12808,"")
C12809: =IF($A12809="","",IF(設定!$B$21="dB",10^($B12809/20),ABS($B12809))) | D12809: =IF($A12809="","",$A12809^2) | E12809: =IF($A12809="","",IF($C12809<=0,"",1/$C12809^2)) | F12809: =IF(OR(ROW()-設定!$B$30<2,ROW()+設定!$B$30>13701,N($A12809)<=0,N(INDEX($A$2:$A$13701,MIN(13700,MAX(1,ROW()-1+設定!$B$30))))<=0,$A12809<設定!$B$28,$A12809>設定!$B$29),0,IF(AND($C12809>=MAX(INDEX($C$1:$C$13701,MAX(1,ROW()-設定!$B$24)):INDEX($C$1:$C$13701,MAX(1,ROW()-1))),$C12809>MAX(INDEX($C$1:$C$13701,MIN(13701,ROW()+1)):INDEX($C$1:$C$13701,MIN(13701,ROW()+設定!$B$24))),$C12809>=設定!$B$32,$C12809>=MAX(MIN(INDEX($C$1:$C$13701,MAX(1,ROW()-設定!$B$26)):INDEX($C$1:$C$13701,MAX(1,ROW()-1))),MIN(INDEX($C$1:$C$13701,MIN(13701,ROW()+1)):INDEX($C$1:$C$13701,MIN(13701,ROW()+設定!$B$26))))*10^(設定!$B$27/20)),1,0)) -> 0 | G12809: =$G12808+IF($F12809=1,1,0) -> 6 | H12809: =IF($F12809=1,$G12809,"")
C12810: =IF($A12810="","",IF(設定!$B$21="dB",10^($B12810/20),ABS($B12810))) | D12810: =IF($A12810="","",$A12810^2) | E12810: =IF($A12810="","",IF($C12810<=0,"",1/$C12810^2)) | F12810: =IF(OR(ROW()-設定!$B$30<2,ROW()+設定!$B$30>13701,N($A12810)<=0,N(INDEX($A$2:$A$13701,MIN(13700,MAX(1,ROW()-1+設定!$B$30))))<=0,$A12810<設定!$B$28,$A12810>設定!$B$29),0,IF(AND($C12810>=MAX(INDEX($C$1:$C$13701,MAX(1,ROW()-設定!$B$24)):INDEX($C$1:$C$13701,MAX(1,ROW()-1))),$C12810>MAX(INDEX($C$1:$C$13701,MIN(13701,ROW()+1)):INDEX($C$1:$C$13701,MIN(13701,ROW()+設定!$B$24))),$C12810>=設定!$B$32,$C12810>=MAX(MIN(INDEX($C$1:$C$13701,MAX(1,ROW()-設定!$B$26)):INDEX($C$1:$C$13701,MAX(1,ROW()-1))),MIN(INDEX($C$1:$C$13701,MIN(13701,ROW()+1)):INDEX($C$1:$C$13701,MIN(13701,ROW()+設定!$B$26))))*10^(設定!$B$27/20)),1,0)) -> 0 | G12810: =$G12809+IF($F12810=1,1,0) -> 6 | H12810: =IF($F12810=1,$G12810,"")
C12811: =IF($A12811="","",IF(設定!$B$21="dB",10^($B12811/20),ABS($B12811))) | D12811: =IF($A12811="","",$A12811^2) | E12811: =IF($A12811="","",IF($C12811<=0,"",1/$C12811^2)) | F12811: =IF(OR(ROW()-設定!$B$30<2,ROW()+設定!$B$30>13701,N($A12811)<=0,N(INDEX($A$2:$A$13701,MIN(13700,MAX(1,ROW()-1+設定!$B$30))))<=0,$A12811<設定!$B$28,$A12811>設定!$B$29),0,IF(AND($C12811>=MAX(INDEX($C$1:$C$13701,MAX(1,ROW()-設定!$B$24)):INDEX($C$1:$C$13701,MAX(1,ROW()-1))),$C12811>MAX(INDEX($C$1:$C$13701,MIN(13701,ROW()+1)):INDEX($C$1:$C$13701,MIN(13701,ROW()+設定!$B$24))),$C12811>=設定!$B$32,$C12811>=MAX(MIN(INDEX($C$1:$C$13701,MAX(1,ROW()-設定!$B$26)):INDEX($C$1:$C$13701,MAX(1,ROW()-1))),MIN(INDEX($C$1:$C$13701,MIN(13701,ROW()+1)):INDEX($C$1:$C$13701,MIN(13701,ROW()+設定!$B$26))))*10^(設定!$B$27/20)),1,0)) -> 0 | G12811: =$G12810+IF($F12811=1,1,0) -> 6 | H12811: =IF($F12811=1,$G12811,"")
C12812: =IF($A12812="","",IF(設定!$B$21="dB",10^($B12812/20),ABS($B12812))) | D12812: =IF($A12812="","",$A12812^2) | E12812: =IF($A12812="","",IF($C12812<=0,"",1/$C12812^2)) | F12812: =IF(OR(ROW()-設定!$B$30<2,ROW()+設定!$B$30>13701,N($A12812)<=0,N(INDEX($A$2:$A$13701,MIN(13700,MAX(1,ROW()-1+設定!$B$30))))<=0,$A12812<設定!$B$28,$A12812>設定!$B$29),0,IF(AND($C12812>=MAX(INDEX($C$1:$C$13701,MAX(1,ROW()-設定!$B$24)):INDEX($C$1:$C$13701,MAX(1,ROW()-1))),$C12812>MAX(INDEX($C$1:$C$13701,MIN(13701,ROW()+1)):INDEX($C$1:$C$13701,MIN(13701,ROW()+設定!$B$24))),$C12812>=設定!$B$32,$C12812>=MAX(MIN(INDEX($C$1:$C$13701,MAX(1,ROW()-設定!$B$26)):INDEX($C$1:$C$13701,MAX(1,ROW()-1))),MIN(INDEX($C$1:$C$13701,MIN(13701,ROW()+1)):INDEX($C$1:$C$13701,MIN(13701,ROW()+設定!$B$26))))*10^(設定!$B$27/20)),1,0)) -> 0 | G12812: =$G12811+IF($F12812=1,1,0) -> 6 | H12812: =IF($F12812=1,$G12812,"")
C12813: =IF($A12813="","",IF(設定!$B$21="dB",10^($B12813/20),ABS($B12813))) | D12813: =IF($A12813="","",$A12813^2) | E12813: =IF($A12813="","",IF($C12813<=0,"",1/$C12813^2)) | F12813: =IF(OR(ROW()-設定!$B$30<2,ROW()+設定!$B$30>13701,N($A12813)<=0,N(INDEX($A$2:$A$13701,MIN(13700,MAX(1,ROW()-1+設定!$B$30))))<=0,$A12813<設定!$B$28,$A12813>設定!$B$29),0,IF(AND($C12813>=MAX(INDEX($C$1:$C$13701,MAX(1,ROW()-設定!$B$24)):INDEX($C$1:$C$13701,MAX(1,ROW()-1))),$C12813>MAX(INDEX($C$1:$C$13701,MIN(13701,ROW()+1)):INDEX($C$1:$C$13701,MIN(13701,ROW()+設定!$B$24))),$C12813>=設定!$B$32,$C12813>=MAX(MIN(INDEX($C$1:$C$13701,MAX(1,ROW()-設定!$B$26)):INDEX($C$1:$C$13701,MAX(1,ROW()-1))),MIN(INDEX($C$1:$C$13701,MIN(13701,ROW()+1)):INDEX($C$1:$C$13701,MIN(13701,ROW()+設定!$B$26))))*10^(設定!$B$27/20)),1,0)) -> 0 | G12813: =$G12812+IF($F12813=1,1,0) -> 6 | H12813: =IF($F12813=1,$G12813,"")
C12814: =IF($A12814="","",IF(設定!$B$21="dB",10^($B12814/20),ABS($B12814))) | D12814: =IF($A12814="","",$A12814^2) | E12814: =IF($A12814="","",IF($C12814<=0,"",1/$C12814^2)) | F12814: =IF(OR(ROW()-設定!$B$30<2,ROW()+設定!$B$30>13701,N($A12814)<=0,N(INDEX($A$2:$A$13701,MIN(13700,MAX(1,ROW()-1+設定!$B$30))))<=0,$A12814<設定!$B$28,$A12814>設定!$B$29),0,IF(AND($C12814>=MAX(INDEX($C$1:$C$13701,MAX(1,ROW()-設定!$B$24)):INDEX($C$1:$C$13701,MAX(1,ROW()-1))),$C12814>MAX(INDEX($C$1:$C$13701,MIN(13701,ROW()+1)):INDEX($C$1:$C$13701,MIN(13701,ROW()+設定!$B$24))),$C12814>=設定!$B$32,$C12814>=MAX(MIN(INDEX($C$1:$C$13701,MAX(1,ROW()-設定!$B$26)):INDEX($C$1:$C$13701,MAX(1,ROW()-1))),MIN(INDEX($C$1:$C$13701,MIN(13701,ROW()+1)):INDEX($C$1:$C$13701,MIN(13701,ROW()+設定!$B$26))))*10^(設定!$B$27/20)),1,0)) -> 0 | G12814: =$G12813+IF($F12814=1,1,0) -> 6 | H12814: =IF($F12814=1,$G12814,"")
... C13701: =IF($A13701="","",IF(設定!$B$21="dB",10^($B13701/20),ABS($B13701))) | D13701: =IF($A13701="","",$A13701^2) | E13701: =IF($A13701="","",IF($C13701<=0,"",1/$C13701^2)) | F13701: =IF(OR(ROW()-設定!$B$30<2,ROW()+設定!$B$30>13701,N($A13701)<=0,N(INDEX($A$2:$A$13701,MIN(13700,MAX(1,ROW()-1+設定!$B$30))))<=0,$A13701<設定!$B$28,$A13701>設定!$B$29),0,IF(AND($C13701>=MAX(INDEX($C$1:$C$13701,MAX(1,ROW()-設定!$B$24)):INDEX($C$1:$C$13701,MAX(1,ROW()-1))),$C13701>MAX(INDEX($C$1:$C$13701,MIN(13701,ROW()+1)):INDEX($C$1:$C$13701,MIN(13701,ROW()+設定!$B$24))),$C13701>=設定!$B$32,$C13701>=MAX(MIN(INDEX($C$1:$C$13701,MAX(1,ROW()-設定!$B$26)):INDEX($C$1:$C$13701,MAX(1,ROW()-1))),MIN(INDEX($C$1:$C$13701,MIN(13701,ROW()+1)):INDEX($C$1:$C$13701,MIN(13701,ROW()+設定!$B$26))))*10^(設定!$B$27/20)),1,0)) -> 0 | G13701: =$G13700+IF($F13701=1,1,0) -> 6 | H13701: =IF($F13701=1,$G13701,"")

Sheet ピーク一覧
A1: カーブフィット法（1自由度・逆FRF2次多項式フィット）による固有振動数と損失係数
A2: ★答えは Y列（固有振動数 fn）と AB列（損失係数 η・指数窓補正後）です。AF列が「要確認」の行は目視チェック。
A4: 番号 | B4: 行位置 | C4: ピーク周波数 f_p [Hz] | D4: ピーク振幅（貼付単位） | E4: |H|peak | F4: ①開始 | G4: ①終了 | H4: ①点数 | I4: ①a2 | J4: ①a1 | K4: ①a0 | L4: ①R^2 | M4: ①vn | N4: ①fn [Hz] | O4: ①η(窓込) | P4: ②片側点数 | Q4: ②開始 | R4: ②終了 | S4: ②点数 | T4: ②a2 | U4: ②a1 | V4: ②a0 | W4: ②R^2 | X4: ②vn | Y4: ★fn [Hz] | Z4: η実測(窓込) | AA4: Δη 窓補正量 | AB4: ★η 補正後 | AC4: Q値 | AD4: 減衰比 ζ | AE4: 半値幅法η(参考) | AF4: 判定
A5: 1 | B5: =IFERROR(MATCH($A5,データ!$H$2:$H$13701,0),"") -> 2641 | C5: =IF($B5="","",INDEX(データ!$A$2:$A$13701,$B5)) -> 412.5 | D5: =IF($B5="","",INDEX(データ!$B$2:$B$13701,$B5)) -> 47.2841 | E5: =IF($B5="","",INDEX(データ!$C$2:$C$13701,$B5)) -> 231.31564 | F5: =IF($B5="","",MAX(1,$B5-設定!$B$36)) -> 2616 | G5: =IF($B5="","",MIN(設定!$B$38,$B5+設定!$B$36)) -> 2666 | H5: =IF($B5="","",$G5-$F5+1) -> 51 | I5: =IFERROR(INDEX(LINEST(INDEX(データ!$E$2:$E$13701,$F5):INDEX(データ!$E$2:$E$13701,$G5),(INDEX(データ!$D$2:$D$13701,$F5):INDEX(データ!$D$2:$D$13701,$G5)/$C5^2)^{1,2},TRUE(),TRUE()),1,1),"") -> 1.0196969 | J5: =IFERROR(INDEX(LINEST(INDEX(データ!$E$2:$E$13701,$F5):INDEX(データ!$E$2:$E$13701,$G5),(INDEX(データ!$D$2:$D$13701,$F5):INDEX(データ!$D$2:$D$13701,$G5)/$C5^2)^{1,2},TRUE(),TRUE()),1,2),"") -> -2.0375326 | K5: =IFERROR(INDEX(LINEST(INDEX(データ!$E$2:$E$13701,$F5):INDEX(データ!$E$2:$E$13701,$G5),(INDEX(データ!$D$2:$D$13701,$F5):INDEX(データ!$D$2:$D$13701,$G5)/$C5^2)^{1,2},TRUE(),TRUE()),1,3),"") -> 1.0178535 | L5: =IFERROR(INDEX(LINEST(INDEX(データ!$E$2:$E$13701,$F5):INDEX(データ!$E$2:$E$13701,$G5),(INDEX(データ!$D$2:$D$13701,$F5):INDEX(データ!$D$2:$D$13701,$G5)/$C5^2)^{1,2},TRUE(),TRUE()),3,1),"") -> 0.99381149 | M5: =IF($I5="","",-$J5/(2*$I5)) -> 0.99908744 | N5: =IF($M5="","",IF($M5<=0,"",$C5*SQRT($M5))) -> 412.31174 | O5: =IF($M5="","",IFERROR(SQRT(MAX(0,$K5/($I5*$M5^2)-1)),"")) -> 0.0040764609 | P5: =IF(OR($O5="",$N5=""),"",MAX(6,MIN(400,ROUND(設定!$B$37*$O5*$N5/設定!$B$11,0)))) -> 16 | Q5: =IF($P5="","",MAX(1,$B5-$P5)) -> 2625 | R5: =IF($P5="","",MIN(設定!$B$38,$B5+$P5)) -> 2657 | S5: =IF($P5="","",$R5-$Q5+1) -> 33 | T5: =IFERROR(INDEX(LINEST(INDEX(データ!$E$2:$E$13701,$Q5):INDEX(データ!$E$2:$E$13701,$R5),(INDEX(データ!$D$2:$D$13701,$Q5):INDEX(データ!$D$2:$D$13701,$R5)/$C5^2)^{1,2},TRUE(),TRUE()),1,1),"") -> 1.000788 | U5: =IFERROR(INDEX(LINEST(INDEX(データ!$E$2:$E$13701,$Q5):INDEX(データ!$E$2:$E$13701,$R5),(INDEX(データ!$D$2:$D$13701,$Q5):INDEX(データ!$D$2:$D$13701,$R5)/$C5^2)^{1,2},TRUE(),TRUE()),1,2),"") -> -2.0007086 | V5: =IFERROR(INDEX(LINEST(INDEX(データ!$E$2:$E$13701,$Q5):INDEX(データ!$E$2:$E$13701,$R5),(INDEX(データ!$D$2:$D$13701,$Q5):INDEX(データ!$D$2:$D$13701,$R5)/$C5^2)^{1,2},TRUE(),TRUE()),1,3),"") -> 0.99993931 | W5: =IFERROR(INDEX(LINEST(INDEX(データ!$E$2:$E$13701,$Q5):INDEX(データ!$E$2:$E$13701,$R5),(INDEX(データ!$D$2:$D$13701,$Q5):INDEX(データ!$D$2:$D$13701,$R5)/$C5^2)^{1,2},TRUE(),TRUE()),3,1),"") -> 0.99663655 | X5: =IF($T5="","",-$U5/(2*$T5)) -> 0.99956662 | Y5: =IF($X5="","",IF($X5<=0,"",$C5*SQRT($X5))) -> 412.41061 | Z5: =IF($X5="","",IFERROR(SQRT(MAX(0,$V5/($T5*$X5^2)-1)),"")) -> 0.0043096541 | AA5: =IF($Y5="","",1/(PI()*$Y5*設定!$B$17)) -> 0.00036127951 | AB5: =IF(OR($Z5="",$AA5=""),"",$Z5-$AA5) -> 0.0039483746 | AC5: =IF($AB5="","",IF($AB5<=0,"",1/$AB5)) -> 253.26878 | AD5: =IF($AB5="","",$AB5/2) -> 0.0019741873 | AE5: =IF($S5="","",IFERROR(SUMPRODUCT(ISNUMBER(INDEX(データ!$C$2:$C$13701,$Q5):INDEX(データ!$C$2:$C$13701,$R5))*(INDEX(データ!$C$2:$C$13701,$Q5):INDEX(データ!$C$2:$C$13701,$R5)>=$E5/SQRT(2)))*設定!$B$11/$Y5-$AA5,"")) -> 0.0038062903 | AF5: =IF($AB5="","",IF(AND($W5>=0.9,$AB5>0,$S5>=10,$Z5>$AA5*1.05),"OK","要確認")) -> OK
A6: 2 | B6: =IFERROR(MATCH($A6,データ!$H$2:$H$13701,0),"") -> 4020 | C6: =IF($B6="","",INDEX(データ!$A$2:$A$13701,$B6)) -> 627.96875 | D6: =IF($B6="","",INDEX(データ!$B$2:$B$13701,$B6)) -> 45.6776 | E6: =IF($B6="","",INDEX(データ!$C$2:$C$13701,$B6)) -> 192.25604 | F6: =IF($B6="","",MAX(1,$B6-設定!$B$36)) -> 3995 | G6: =IF($B6="","",MIN(設定!$B$38,$B6+設定!$B$36)) -> 4045 | H6: =IF($B6="","",$G6-$F6+1) -> 51 | I6: =IFERROR(INDEX(LINEST(INDEX(データ!$E$2:$E$13701,$F6):INDEX(データ!$E$2:$E$13701,$G6),(INDEX(データ!$D$2:$D$13701,$F6):INDEX(データ!$D$2:$D$13701,$G6)/$C6^2)^{1,2},TRUE(),TRUE()),1,1),"") -> 1.9214051 | J6: =IFERROR(INDEX(LINEST(INDEX(データ!$E$2:$E$13701,$F6):INDEX(データ!$E$2:$E$13701,$G6),(INDEX(データ!$D$2:$D$13701,$F6):INDEX(データ!$D$2:$D$13701,$G6)/$C6^2)^{1,2},TRUE(),TRUE()),1,2),"") -> -3.8427477 | K6: =IFERROR(INDEX(LINEST(INDEX(データ!$E$2:$E$13701,$F6):INDEX(データ!$E$2:$E$13701,$G6),(INDEX(データ!$D$2:$D$13701,$F6):INDEX(データ!$D$2:$D$13701,$G6)/$C6^2)^{1,2},TRUE(),TRUE()),1,3),"") -> 1.9213698 | L6: =IFERROR(INDEX(LINEST(INDEX(データ!$E$2:$E$13701,$F6):INDEX(データ!$E$2:$E$13701,$G6),(INDEX(データ!$D$2:$D$13701,$F6):INDEX(データ!$D$2:$D$13701,$G6)/$C6^2)^{1,2},TRUE(),TRUE()),3,1),"") -> 0.99647378 | M6: =IF($I6="","",-$J6/(2*$I6)) -> 0.99998373 | N6: =IF($M6="","",IF($M6<=0,"",$C6*SQRT($M6))) -> 627.96364 | O6: =IF($M6="","",IFERROR(SQRT(MAX(0,$K6/($I6*$M6^2)-1)),"")) -> 0.0037625802 | P6: =IF(OR($O6="",$N6=""),"",MAX(6,MIN(400,ROUND(設定!$B$37*$O6*$N6/設定!$B$11,0)))) -> 23 | Q6: =IF($P6="","",MAX(1,$B6-$P6)) -> 3997 | R6: =IF($P6="","",MIN(設定!$B$38,$B6+$P6)) -> 4043 | S6: =IF($P6="","",$R6-$Q6+1) -> 47 | T6: =IFERROR(INDEX(LINEST(INDEX(データ!$E$2:$E$13701,$Q6):INDEX(データ!$E$2:$E$13701,$R6),(INDEX(データ!$D$2:$D$13701,$Q6):INDEX(データ!$D$2:$D$13701,$R6)/$C6^2)^{1,2},TRUE(),TRUE()),1,1),"") -> 1.9283753 | U6: =IFERROR(INDEX(LINEST(INDEX(データ!$E$2:$E$13701,$Q6):INDEX(データ!$E$2:$E$13701,$R6),(INDEX(データ!$D$2:$D$13701,$Q6):INDEX(データ!$D$2:$D$13701,$R6)/$C6^2)^{1,2},TRUE(),TRUE()),1,2),"") -> -3.8569422 | V6: =IFERROR(INDEX(LINEST(INDEX(データ!$E$2:$E$13701,$Q6):INDEX(データ!$E$2:$E$13701,$R6),(INDEX(データ!$D$2:$D$13701,$Q6):INDEX(データ!$D$2:$D$13701,$R6)/$C6^2)^{1,2},TRUE(),TRUE()),1,3),"") -> 1.9285939 | W6: =IFERROR(INDEX(LINEST(INDEX(データ!$E$2:$E$13701,$Q6):INDEX(データ!$E$2:$E$13701,$R6),(INDEX(データ!$D$2:$D$13701,$Q6):INDEX(データ!$D$2:$D$13701,$R6)/$C6^2)^{1,2},TRUE(),TRUE()),3,1),"") -> 0.99709212 | X6: =IF($T6="","",-$U6/(2*$T6)) -> 1.0000497 | Y6: =IF($X6="","",IF($X6<=0,"",$C6*SQRT($X6))) -> 627.98435 | Z6: =IF($X6="","",IFERROR(SQRT(MAX(0,$V6/($T6*$X6^2)-1)),"")) -> 0.003742467 | AA6: =IF($Y6="","",1/(PI()*$Y6*設定!$B$17)) -> 0.00023725989 | AB6: =IF(OR($Z6="",$AA6=""),"",$Z6-$AA6) -> 0.0035052071 | AC6: =IF($AB6="","",IF($AB6<=0,"",1/$AB6)) -> 285.28985 | AD6: =IF($AB6="","",$AB6/2) -> 0.0017526036 | AE6: =IF($S6="","",IFERROR(SUMPRODUCT(ISNUMBER(INDEX(データ!$C$2:$C$13701,$Q6):INDEX(データ!$C$2:$C$13701,$R6))*(INDEX(データ!$C$2:$C$13701,$Q6):INDEX(データ!$C$2:$C$13701,$R6)>=$E6/SQRT(2)))*設定!$B$11/$Y6-$AA6,"")) -> 0.0034949191 | AF6: =IF($AB6="","",IF(AND($W6>=0.9,$AB6>0,$S6>=10,$Z6>$AA6*1.05),"OK","要確認")) -> OK
A7: 3 | B7: =IFERROR(MATCH($A7,データ!$H$2:$H$13701,0),"") -> 5792 | C7: =IF($B7="","",INDEX(データ!$A$2:$A$13701,$B7)) -> 904.84375 | D7: =IF($B7="","",INDEX(データ!$B$2:$B$13701,$B7)) -> 44.7847 | E7: =IF($B7="","",INDEX(データ!$C$2:$C$13701,$B7)) -> 173.47424 | F7: =IF($B7="","",MAX(1,$B7-設定!$B$36)) -> 5767 | G7: =IF($B7="","",MIN(設定!$B$38,$B7+設定!$B$36)) -> 5817 | H7: =IF($B7="","",$G7-$F7+1) -> 51 | I7: =IFERROR(INDEX(LINEST(INDEX(データ!$E$2:$E$13701,$F7):INDEX(データ!$E$2:$E$13701,$G7),(INDEX(データ!$D$2:$D$13701,$F7):INDEX(データ!$D$2:$D$13701,$G7)/$C7^2)^{1,2},TRUE(),TRUE()),1,1),"") -> 3.3107154 | J7: =IFERROR(INDEX(LINEST(INDEX(データ!$E$2:$E$13701,$F7):INDEX(データ!$E$2:$E$13701,$G7),(INDEX(データ!$D$2:$D$13701,$F7):INDEX(データ!$D$2:$D$13701,$G7)/$C7^2)^{1,2},TRUE(),TRUE()),1,2),"") -> -6.6217023 | K7: =IFERROR(INDEX(LINEST(INDEX(データ!$E$2:$E$13701,$F7):INDEX(データ!$E$2:$E$13701,$G7),(INDEX(データ!$D$2:$D$13701,$F7):INDEX(データ!$D$2:$D$13701,$G7)/$C7^2)^{1,2},TRUE(),TRUE()),1,3),"") -> 3.3110197 | L7: =IFERROR(INDEX(LINEST(INDEX(データ!$E$2:$E$13701,$F7):INDEX(データ!$E$2:$E$13701,$G7),(INDEX(データ!$D$2:$D$13701,$F7):INDEX(データ!$D$2:$D$13701,$G7)/$C7^2)^{1,2},TRUE(),TRUE()),3,1),"") -> 0.99557098 | M7: =IF($I7="","",-$J7/(2*$I7)) -> 1.000041 | N7: =IF($M7="","",IF($M7<=0,"",$C7*SQRT($M7))) -> 904.86231 | O7: =IF($M7="","",IFERROR(SQRT(MAX(0,$K7/($I7*$M7^2)-1)),"")) -> 0.0031466045 | P7: =IF(OR($O7="",$N7=""),"",MAX(6,MIN(400,ROUND(設定!$B$37*$O7*$N7/設定!$B$11,0)))) -> 27 | Q7: =IF($P7="","",MAX(1,$B7-$P7)) -> 5765 | R7: =IF($P7="","",MIN(設定!$B$38,$B7+$P7)) -> 5819 | S7: =IF($P7="","",$R7-$Q7+1) -> 55 | T7: =IFERROR(INDEX(LINEST(INDEX(データ!$E$2:$E$13701,$Q7):INDEX(データ!$E$2:$E$13701,$R7),(INDEX(データ!$D$2:$D$13701,$Q7):INDEX(データ!$D$2:$D$13701,$R7)/$C7^2)^{1,2},TRUE(),TRUE()),1,1),"") -> 3.3108558 | U7: =IFERROR(INDEX(LINEST(INDEX(データ!$E$2:$E$13701,$Q7):INDEX(データ!$E$2:$E$13701,$R7),(INDEX(データ!$D$2:$D$13701,$Q7):INDEX(データ!$D$2:$D$13701,$R7)/$C7^2)^{1,2},TRUE(),TRUE()),1,2),"") -> -6.6216306 | V7: =IFERROR(INDEX(LINEST(INDEX(データ!$E$2:$E$13701,$Q7):INDEX(データ!$E$2:$E$13701,$R7),(INDEX(データ!$D$2:$D$13701,$Q7):INDEX(データ!$D$2:$D$13701,$R7)/$C7^2)^{1,2},TRUE(),TRUE()),1,3),"") -> 3.3108076 | W7: =IFERROR(INDEX(LINEST(INDEX(データ!$E$2:$E$13701,$Q7):INDEX(データ!$E$2:$E$13701,$R7),(INDEX(データ!$D$2:$D$13701,$Q7):INDEX(データ!$D$2:$D$13701,$R7)/$C7^2)^{1,2},TRUE(),TRUE()),3,1),"") -> 0.99511757 | X7: =IF($T7="","",-$U7/(2*$T7)) -> 0.99998776 | Y7: =IF($X7="","",IF($X7<=0,"",$C7*SQRT($X7))) -> 904.83821 | Z7: =IF($X7="","",IFERROR(SQRT(MAX(0,$V7/($T7*$X7^2)-1)),"")) -> 0.0031466061 | AA7: =IF($Y7="","",1/(PI()*$Y7*設定!$B$17)) -> 0.00016466535 | AB7: =IF(OR($Z7="",$AA7=""),"",$Z7-$AA7) -> 0.0029819407 | AC7: =IF($AB7="","",IF($AB7<=0,"",1/$AB7)) -> 335.35207 | AD7: =IF($AB7="","",$AB7/2) -> 0.0014909704 | AE7: =IF($S7="","",IFERROR(SUMPRODUCT(ISNUMBER(INDEX(データ!$C$2:$C$13701,$Q7):INDEX(データ!$C$2:$C$13701,$R7))*(INDEX(データ!$C$2:$C$13701,$Q7):INDEX(データ!$C$2:$C$13701,$R7)>=$E7/SQRT(2)))*設定!$B$11/$Y7-$AA7,"")) -> 0.0029436251 | AF7: =IF($AB7="","",IF(AND($W7>=0.9,$AB7>0,$S7>=10,$Z7>$AA7*1.05),"OK","要確認")) -> OK
A8: 4 | B8: =IFERROR(MATCH($A8,データ!$H$2:$H$13701,0),"") -> 7174 | C8: =IF($B8="","",INDEX(データ!$A$2:$A$13701,$B8)) -> 1120.7812 | D8: =IF($B8="","",INDEX(データ!$B$2:$B$13701,$B8)) -> 49.7417 | E8: =IF($B8="","",INDEX(データ!$C$2:$C$13701,$B8)) -> 306.96227 | F8: =IF($B8="","",MAX(1,$B8-設定!$B$36)) -> 7149 | G8: =IF($B8="","",MIN(設定!$B$38,$B8+設定!$B$36)) -> 7199 | H8: =IF($B8="","",$G8-$F8+1) -> 51 | I8: =IFERROR(INDEX(LINEST(INDEX(データ!$E$2:$E$13701,$F8):INDEX(データ!$E$2:$E$13701,$G8),(INDEX(データ!$D$2:$D$13701,$F8):INDEX(データ!$D$2:$D$13701,$G8)/$C8^2)^{1,2},TRUE(),TRUE()),1,1),"") -> 1.2508827 | J8: =IFERROR(INDEX(LINEST(INDEX(データ!$E$2:$E$13701,$F8):INDEX(データ!$E$2:$E$13701,$G8),(INDEX(データ!$D$2:$D$13701,$F8):INDEX(データ!$D$2:$D$13701,$G8)/$C8^2)^{1,2},TRUE(),TRUE()),1,2),"") -> -2.5004418 | K8: =IFERROR(INDEX(LINEST(INDEX(データ!$E$2:$E$13701,$F8):INDEX(データ!$E$2:$E$13701,$G8),(INDEX(データ!$D$2:$D$13701,$F8):INDEX(データ!$D$2:$D$13701,$G8)/$C8^2)^{1,2},TRUE(),TRUE()),1,3),"") -> 1.24957 | L8: =IFERROR(INDEX(LINEST(INDEX(データ!$E$2:$E$13701,$F8):INDEX(データ!$E$2:$E$13701,$G8),(INDEX(データ!$D$2:$D$13701,$F8):INDEX(データ!$D$2:$D$13701,$G8)/$C8^2)^{1,2},TRUE(),TRUE()),3,1),"") -> 0.99844458 | M8: =IF($I8="","",-$J8/(2*$I8)) -> 0.99947091 | N8: =IF($M8="","",IF($M8<=0,"",$C8*SQRT($M8))) -> 1120.4847 | O8: =IF($M8="","",IFERROR(SQRT(MAX(0,$K8/($I8*$M8^2)-1)),"")) -> 0.0029105153 | P8: =IF(OR($O8="",$N8=""),"",MAX(6,MIN(400,ROUND(設定!$B$37*$O8*$N8/設定!$B$11,0)))) -> 31 | Q8: =IF($P8="","",MAX(1,$B8-$P8)) -> 7143 | R8: =IF($P8="","",MIN(設定!$B$38,$B8+$P8)) -> 7205 | S8: =IF($P8="","",$R8-$Q8+1) -> 63 | T8: =IFERROR(INDEX(LINEST(INDEX(データ!$E$2:$E$13701,$Q8):INDEX(データ!$E$2:$E$13701,$R8),(INDEX(データ!$D$2:$D$13701,$Q8):INDEX(データ!$D$2:$D$13701,$R8)/$C8^2)^{1,2},TRUE(),TRUE()),1,1),"") -> 1.2547411 | U8: =IFERROR(INDEX(LINEST(INDEX(データ!$E$2:$E$13701,$Q8):INDEX(データ!$E$2:$E$13701,$R8),(INDEX(データ!$D$2:$D$13701,$Q8):INDEX(データ!$D$2:$D$13701,$R8)/$C8^2)^{1,2},TRUE(),TRUE()),1,2),"") -> -2.5080819 | V8: =IFERROR(INDEX(LINEST(INDEX(データ!$E$2:$E$13701,$Q8):INDEX(データ!$E$2:$E$13701,$R8),(INDEX(データ!$D$2:$D$13701,$Q8):INDEX(データ!$D$2:$D$13701,$R8)/$C8^2)^{1,2},TRUE(),TRUE()),1,3),"") -> 1.2533518 | W8: =IFERROR(INDEX(LINEST(INDEX(データ!$E$2:$E$13701,$Q8):INDEX(データ!$E$2:$E$13701,$R8),(INDEX(データ!$D$2:$D$13701,$Q8):INDEX(データ!$D$2:$D$13701,$R8)/$C8^2)^{1,2},TRUE(),TRUE()),3,1),"") -> 0.99865163 | X8: =IF($T8="","",-$U8/(2*$T8)) -> 0.99944205 | Y8: =IF($X8="","",IF($X8<=0,"",$C8*SQRT($X8))) -> 1120.4685 | Z8: =IF($X8="","",IFERROR(SQRT(MAX(0,$V8/($T8*$X8^2)-1)),"")) -> 0.0028974088 | AA8: =IF($Y8="","",1/(PI()*$Y8*設定!$B$17)) -> 0.00013297607 | AB8: =IF(OR($Z8="",$AA8=""),"",$Z8-$AA8) -> 0.0027644327 | AC8: =IF($AB8="","",IF($AB8<=0,"",1/$AB8)) -> 361.73787 | AD8: =IF($AB8="","",$AB8/2) -> 0.0013822163 | AE8: =IF($S8="","",IFERROR(SUMPRODUCT(ISNUMBER(INDEX(データ!$C$2:$C$13701,$Q8):INDEX(データ!$C$2:$C$13701,$R8))*(INDEX(データ!$C$2:$C$13701,$Q8):INDEX(データ!$C$2:$C$13701,$R8)>=$E8/SQRT(2)))*設定!$B$11/$Y8-$AA8,"")) -> 0.0027954864 | AF8: =IF($AB8="","",IF(AND($W8>=0.9,$AB8>0,$S8>=10,$Z8>$AA8*1.05),"OK","要確認")) -> OK
A9: 5 | B9: =IFERROR(MATCH($A9,データ!$H$2:$H$13701,0),"") -> 9203 | C9: =IF($B9="","",INDEX(データ!$A$2:$A$13701,$B9)) -> 1437.8125 | D9: =IF($B9="","",INDEX(データ!$B$2:$B$13701,$B9)) -> 43.8251 | E9: =IF($B9="","",INDEX(データ!$C$2:$C$13701,$B9)) -> 155.32988 | F9: =IF($B9="","",MAX(1,$B9-設定!$B$36)) -> 9178 | G9: =IF($B9="","",MIN(設定!$B$38,$B9+設定!$B$36)) -> 9228 | H9: =IF($B9="","",$G9-$F9+1) -> 51 | I9: =IFERROR(INDEX(LINEST(INDEX(データ!$E$2:$E$13701,$F9):INDEX(データ!$E$2:$E$13701,$G9),(INDEX(データ!$D$2:$D$13701,$F9):INDEX(データ!$D$2:$D$13701,$G9)/$C9^2)^{1,2},TRUE(),TRUE()),1,1),"") -> 6.2965603 | J9: =IFERROR(INDEX(LINEST(INDEX(データ!$E$2:$E$13701,$F9):INDEX(データ!$E$2:$E$13701,$G9),(INDEX(データ!$D$2:$D$13701,$F9):INDEX(データ!$D$2:$D$13701,$G9)/$C9^2)^{1,2},TRUE(),TRUE()),1,2),"") -> -12.596509 | K9: =IFERROR(INDEX(LINEST(INDEX(データ!$E$2:$E$13701,$F9):INDEX(データ!$E$2:$E$13701,$G9),(INDEX(データ!$D$2:$D$13701,$F9):INDEX(データ!$D$2:$D$13701,$G9)/$C9^2)^{1,2},TRUE(),TRUE()),1,3),"") -> 6.2999909 | L9: =IFERROR(INDEX(LINEST(INDEX(データ!$E$2:$E$13701,$F9):INDEX(データ!$E$2:$E$13701,$G9),(INDEX(データ!$D$2:$D$13701,$F9):INDEX(データ!$D$2:$D$13701,$G9)/$C9^2)^{1,2},TRUE(),TRUE()),3,1),"") -> 0.99841116 | M9: =IF($I9="","",-$J9/(2*$I9)) -> 1.0002691 | N9: =IF($M9="","",IF($M9<=0,"",$C9*SQRT($M9))) -> 1438.0059 | O9: =IF($M9="","",IFERROR(SQRT(MAX(0,$K9/($I9*$M9^2)-1)),"")) -> 0.0025720638 | P9: =IF(OR($O9="",$N9=""),"",MAX(6,MIN(400,ROUND(設定!$B$37*$O9*$N9/設定!$B$11,0)))) -> 36 | Q9: =IF($P9="","",MAX(1,$B9-$P9)) -> 9167 | R9: =IF($P9="","",MIN(設定!$B$38,$B9+$P9)) -> 9239 | S9: =IF($P9="","",$R9-$Q9+1) -> 73 | T9: =IFERROR(INDEX(LINEST(INDEX(データ!$E$2:$E$13701,$Q9):INDEX(データ!$E$2:$E$13701,$R9),(INDEX(データ!$D$2:$D$13701,$Q9):INDEX(データ!$D$2:$D$13701,$R9)/$C9^2)^{1,2},TRUE(),TRUE()),1,1),"") -> 6.2389746 | U9: =IFERROR(INDEX(LINEST(INDEX(データ!$E$2:$E$13701,$Q9):INDEX(データ!$E$2:$E$13701,$R9),(INDEX(データ!$D$2:$D$13701,$Q9):INDEX(データ!$D$2:$D$13701,$R9)/$C9^2)^{1,2},TRUE(),TRUE()),1,2),"") -> -12.481327 | V9: =IFERROR(INDEX(LINEST(INDEX(データ!$E$2:$E$13701,$Q9):INDEX(データ!$E$2:$E$13701,$R9),(INDEX(データ!$D$2:$D$13701,$Q9):INDEX(データ!$D$2:$D$13701,$R9)/$C9^2)^{1,2},TRUE(),TRUE()),1,3),"") -> 6.2423952 | W9: =IFERROR(INDEX(LINEST(INDEX(データ!$E$2:$E$13701,$Q9):INDEX(データ!$E$2:$E$13701,$R9),(INDEX(データ!$D$2:$D$13701,$Q9):INDEX(データ!$D$2:$D$13701,$R9)/$C9^2)^{1,2},TRUE(),TRUE()),3,1),"") -> 0.99904214 | X9: =IF($T9="","",-$U9/(2*$T9)) -> 1.0002707 | Y9: =IF($X9="","",IF($X9<=0,"",$C9*SQRT($X9))) -> 1438.0071 | Z9: =IF($X9="","",IFERROR(SQRT(MAX(0,$V9/($T9*$X9^2)-1)),"")) -> 0.0026027739 | AA9: =IF($Y9="","",1/(PI()*$Y9*設定!$B$17)) -> 0.00010361249 | AB9: =IF(OR($Z9="",$AA9=""),"",$Z9-$AA9) -> 0.0024991614 | AC9: =IF($AB9="","",IF($AB9<=0,"",1/$AB9)) -> 400.13422 | AD9: =IF($AB9="","",$AB9/2) -> 0.0012495807 | AE9: =IF($S9="","",IFERROR(SUMPRODUCT(ISNUMBER(INDEX(データ!$C$2:$C$13701,$Q9):INDEX(データ!$C$2:$C$13701,$R9))*(INDEX(データ!$C$2:$C$13701,$Q9):INDEX(データ!$C$2:$C$13701,$R9)>=$E9/SQRT(2)))*設定!$B$11/$Y9-$AA9,"")) -> 0.0023955059 | AF9: =IF($AB9="","",IF(AND($W9>=0.9,$AB9>0,$S9>=10,$Z9>$AA9*1.05),"OK","要確認")) -> OK
A10: 6 | B10: =IFERROR(MATCH($A10,データ!$H$2:$H$13701,0),"") -> 11153 | C10: =IF($B10="","",INDEX(データ!$A$2:$A$13701,$B10)) -> 1742.5 | D10: =IF($B10="","",INDEX(データ!$B$2:$B$13701,$B10)) -> 48.6984 | E10: =IF($B10="","",INDEX(データ!$C$2:$C$13701,$B10)) -> 272.21998 | F10: =IF($B10="","",MAX(1,$B10-設定!$B$36)) -> 11128 | G10: =IF($B10="","",MIN(設定!$B$38,$B10+設定!$B$36)) -> 11178 | H10: =IF($B10="","",$G10-$F10+1) -> 51 | I10: =IFERROR(INDEX(LINEST(INDEX(データ!$E$2:$E$13701,$F10):INDEX(データ!$E$2:$E$13701,$G10),(INDEX(データ!$D$2:$D$13701,$F10):INDEX(データ!$D$2:$D$13701,$G10)/$C10^2)^{1,2},TRUE(),TRUE()),1,1),"") -> 2.5838219 | J10: =IFERROR(INDEX(LINEST(INDEX(データ!$E$2:$E$13701,$F10):INDEX(データ!$E$2:$E$13701,$G10),(INDEX(データ!$D$2:$D$13701,$F10):INDEX(データ!$D$2:$D$13701,$G10)/$C10^2)^{1,2},TRUE(),TRUE()),1,2),"") -> -5.167956 | K10: =IFERROR(INDEX(LINEST(INDEX(データ!$E$2:$E$13701,$F10):INDEX(データ!$E$2:$E$13701,$G10),(INDEX(データ!$D$2:$D$13701,$F10):INDEX(データ!$D$2:$D$13701,$G10)/$C10^2)^{1,2},TRUE(),TRUE()),1,3),"") -> 2.5841478 | L10: =IFERROR(INDEX(LINEST(INDEX(データ!$E$2:$E$13701,$F10):INDEX(データ!$E$2:$E$13701,$G10),(INDEX(データ!$D$2:$D$13701,$F10):INDEX(データ!$D$2:$D$13701,$G10)/$C10^2)^{1,2},TRUE(),TRUE()),3,1),"") -> 0.99705197 | M10: =IF($I10="","",-$J10/(2*$I10)) -> 1.0000604 | N10: =IF($M10="","",IF($M10<=0,"",$C10*SQRT($M10))) -> 1742.5526 | O10: =IF($M10="","",IFERROR(SQRT(MAX(0,$K10/($I10*$M10^2)-1)),"")) -> 0.0023053437 | P10: =IF(OR($O10="",$N10=""),"",MAX(6,MIN(400,ROUND(設定!$B$37*$O10*$N10/設定!$B$11,0)))) -> 39 | Q10: =IF($P10="","",MAX(1,$B10-$P10)) -> 11114 | R10: =IF($P10="","",MIN(設定!$B$38,$B10+$P10)) -> 11192 | S10: =IF($P10="","",$R10-$Q10+1) -> 79 | T10: =IFERROR(INDEX(LINEST(INDEX(データ!$E$2:$E$13701,$Q10):INDEX(データ!$E$2:$E$13701,$R10),(INDEX(データ!$D$2:$D$13701,$Q10):INDEX(データ!$D$2:$D$13701,$R10)/$C10^2)^{1,2},TRUE(),TRUE()),1,1),"") -> 2.6058331 | U10: =IFERROR(INDEX(LINEST(INDEX(データ!$E$2:$E$13701,$Q10):INDEX(データ!$E$2:$E$13701,$R10),(INDEX(データ!$D$2:$D$13701,$Q10):INDEX(データ!$D$2:$D$13701,$R10)/$C10^2)^{1,2},TRUE(),TRUE()),1,2),"") -> -5.2123079 | V10: =IFERROR(INDEX(LINEST(INDEX(データ!$E$2:$E$13701,$Q10):INDEX(データ!$E$2:$E$13701,$R10),(INDEX(データ!$D$2:$D$13701,$Q10):INDEX(データ!$D$2:$D$13701,$R10)/$C10^2)^{1,2},TRUE(),TRUE()),1,3),"") -> 2.6064884 | W10: =IFERROR(INDEX(LINEST(INDEX(データ!$E$2:$E$13701,$Q10):INDEX(データ!$E$2:$E$13701,$R10),(INDEX(データ!$D$2:$D$13701,$Q10):INDEX(データ!$D$2:$D$13701,$R10)/$C10^2)^{1,2},TRUE(),TRUE()),3,1),"") -> 0.99706878 | X10: =IF($T10="","",-$U10/(2*$T10)) -> 1.0001231 | Y10: =IF($X10="","",IF($X10<=0,"",$C10*SQRT($X10))) -> 1742.6073 | Z10: =IF($X10="","",IFERROR(SQRT(MAX(0,$V10/($T10*$X10^2)-1)),"")) -> 0.0022826938 | AA10: =IF($Y10="","",1/(PI()*$Y10*設定!$B$17)) -> 8.550148e-05 | AB10: =IF(OR($Z10="",$AA10=""),"",$Z10-$AA10) -> 0.0021971924 | AC10: =IF($AB10="","",IF($AB10<=0,"",1/$AB10)) -> 455.12629 | AD10: =IF($AB10="","",$AB10/2) -> 0.0010985962 | AE10: =IF($S10="","",IFERROR(SUMPRODUCT(ISNUMBER(INDEX(データ!$C$2:$C$13701,$Q10):INDEX(データ!$C$2:$C$13701,$R10))*(INDEX(データ!$C$2:$C$13701,$Q10):INDEX(データ!$C$2:$C$13701,$R10)>=$E10/SQRT(2)))*設定!$B$11/$Y10-$AA10,"")) -> 0.0021561109 | AF10: =IF($AB10="","",IF(AND($W10>=0.9,$AB10>0,$S10>=10,$Z10>$AA10*1.05),"OK","要確認")) -> OK
A11: 7 | B11: =IFERROR(MATCH($A11,データ!$H$2:$H$13701,0),"") | C11: =IF($B11="","",INDEX(データ!$A$2:$A$13701,$B11)) | D11: =IF($B11="","",INDEX(データ!$B$2:$B$13701,$B11)) | E11: =IF($B11="","",INDEX(データ!$C$2:$C$13701,$B11)) | F11: =IF($B11="","",MAX(1,$B11-設定!$B$36)) | G11: =IF($B11="","",MIN(設定!$B$38,$B11+設定!$B$36)) | H11: =IF($B11="","",$G11-$F11+1) | I11: =IFERROR(INDEX(LINEST(INDEX(データ!$E$2:$E$13701,$F11):INDEX(データ!$E$2:$E$13701,$G11),(INDEX(データ!$D$2:$D$13701,$F11):INDEX(データ!$D$2:$D$13701,$G11)/$C11^2)^{1,2},TRUE(),TRUE()),1,1),"") | J11: =IFERROR(INDEX(LINEST(INDEX(データ!$E$2:$E$13701,$F11):INDEX(データ!$E$2:$E$13701,$G11),(INDEX(データ!$D$2:$D$13701,$F11):INDEX(データ!$D$2:$D$13701,$G11)/$C11^2)^{1,2},TRUE(),TRUE()),1,2),"") | K11: =IFERROR(INDEX(LINEST(INDEX(データ!$E$2:$E$13701,$F11):INDEX(データ!$E$2:$E$13701,$G11),(INDEX(データ!$D$2:$D$13701,$F11):INDEX(データ!$D$2:$D$13701,$G11)/$C11^2)^{1,2},TRUE(),TRUE()),1,3),"") | L11: =IFERROR(INDEX(LINEST(INDEX(データ!$E$2:$E$13701,$F11):INDEX(データ!$E$2:$E$13701,$G11),(INDEX(データ!$D$2:$D$13701,$F11):INDEX(データ!$D$2:$D$13701,$G11)/$C11^2)^{1,2},TRUE(),TRUE()),3,1),"") | M11: =IF($I11="","",-$J11/(2*$I11)) | N11: =IF($M11="","",IF($M11<=0,"",$C11*SQRT($M11))) | O11: =IF($M11="","",IFERROR(SQRT(MAX(0,$K11/($I11*$M11^2)-1)),"")) | P11: =IF(OR($O11="",$N11=""),"",MAX(6,MIN(400,ROUND(設定!$B$37*$O11*$N11/設定!$B$11,0)))) | Q11: =IF($P11="","",MAX(1,$B11-$P11)) | R11: =IF($P11="","",MIN(設定!$B$38,$B11+$P11)) | S11: =IF($P11="","",$R11-$Q11+1) | T11: =IFERROR(INDEX(LINEST(INDEX(データ!$E$2:$E$13701,$Q11):INDEX(データ!$E$2:$E$13701,$R11),(INDEX(データ!$D$2:$D$13701,$Q11):INDEX(データ!$D$2:$D$13701,$R11)/$C11^2)^{1,2},TRUE(),TRUE()),1,1),"") | U11: =IFERROR(INDEX(LINEST(INDEX(データ!$E$2:$E$13701,$Q11):INDEX(データ!$E$2:$E$13701,$R11),(INDEX(データ!$D$2:$D$13701,$Q11):INDEX(データ!$D$2:$D$13701,$R11)/$C11^2)^{1,2},TRUE(),TRUE()),1,2),"") | V11: =IFERROR(INDEX(LINEST(INDEX(データ!$E$2:$E$13701,$Q11):INDEX(データ!$E$2:$E$13701,$R11),(INDEX(データ!$D$2:$D$13701,$Q11):INDEX(データ!$D$2:$D$13701,$R11)/$C11^2)^{1,2},TRUE(),TRUE()),1,3),"") | W11: =IFERROR(INDEX(LINEST(INDEX(データ!$E$2:$E$13701,$Q11):INDEX(データ!$E$2:$E$13701,$R11),(INDEX(データ!$D$2:$D$13701,$Q11):INDEX(データ!$D$2:$D$13701,$R11)/$C11^2)^{1,2},TRUE(),TRUE()),3,1),"") | X11: =IF($T11="","",-$U11/(2*$T11)) | Y11: =IF($X11="","",IF($X11<=0,"",$C11*SQRT($X11))) | Z11: =IF($X11="","",IFERROR(SQRT(MAX(0,$V11/($T11*$X11^2)-1)),"")) | AA11: =IF($Y11="","",1/(PI()*$Y11*設定!$B$17)) | AB11: =IF(OR($Z11="",$AA11=""),"",$Z11-$AA11) | AC11: =IF($AB11="","",IF($AB11<=0,"",1/$AB11)) | AD11: =IF($AB11="","",$AB11/2) | AE11: =IF($S11="","",IFERROR(SUMPRODUCT(ISNUMBER(INDEX(データ!$C$2:$C$13701,$Q11):INDEX(データ!$C$2:$C$13701,$R11))*(INDEX(データ!$C$2:$C$13701,$Q11):INDEX(データ!$C$2:$C$13701,$R11)>=$E11/SQRT(2)))*設定!$B$11/$Y11-$AA11,"")) | AF11: =IF($AB11="","",IF(AND($W11>=0.9,$AB11>0,$S11>=10,$Z11>$AA11*1.05),"OK","要確認"))
A12: 8 | B12: =IFERROR(MATCH($A12,データ!$H$2:$H$13701,0),"") | C12: =IF($B12="","",INDEX(データ!$A$2:$A$13701,$B12)) | D12: =IF($B12="","",INDEX(データ!$B$2:$B$13701,$B12)) | E12: =IF($B12="","",INDEX(データ!$C$2:$C$13701,$B12)) | F12: =IF($B12="","",MAX(1,$B12-設定!$B$36)) | G12: =IF($B12="","",MIN(設定!$B$38,$B12+設定!$B$36)) | H12: =IF($B12="","",$G12-$F12+1) | I12: =IFERROR(INDEX(LINEST(INDEX(データ!$E$2:$E$13701,$F12):INDEX(データ!$E$2:$E$13701,$G12),(INDEX(データ!$D$2:$D$13701,$F12):INDEX(データ!$D$2:$D$13701,$G12)/$C12^2)^{1,2},TRUE(),TRUE()),1,1),"") | J12: =IFERROR(INDEX(LINEST(INDEX(データ!$E$2:$E$13701,$F12):INDEX(データ!$E$2:$E$13701,$G12),(INDEX(データ!$D$2:$D$13701,$F12):INDEX(データ!$D$2:$D$13701,$G12)/$C12^2)^{1,2},TRUE(),TRUE()),1,2),"") | K12: =IFERROR(INDEX(LINEST(INDEX(データ!$E$2:$E$13701,$F12):INDEX(データ!$E$2:$E$13701,$G12),(INDEX(データ!$D$2:$D$13701,$F12):INDEX(データ!$D$2:$D$13701,$G12)/$C12^2)^{1,2},TRUE(),TRUE()),1,3),"") | L12: =IFERROR(INDEX(LINEST(INDEX(データ!$E$2:$E$13701,$F12):INDEX(データ!$E$2:$E$13701,$G12),(INDEX(データ!$D$2:$D$13701,$F12):INDEX(データ!$D$2:$D$13701,$G12)/$C12^2)^{1,2},TRUE(),TRUE()),3,1),"") | M12: =IF($I12="","",-$J12/(2*$I12)) | N12: =IF($M12="","",IF($M12<=0,"",$C12*SQRT($M12))) | O12: =IF($M12="","",IFERROR(SQRT(MAX(0,$K12/($I12*$M12^2)-1)),"")) | P12: =IF(OR($O12="",$N12=""),"",MAX(6,MIN(400,ROUND(設定!$B$37*$O12*$N12/設定!$B$11,0)))) | Q12: =IF($P12="","",MAX(1,$B12-$P12)) | R12: =IF($P12="","",MIN(設定!$B$38,$B12+$P12)) | S12: =IF($P12="","",$R12-$Q12+1) | T12: =IFERROR(INDEX(LINEST(INDEX(データ!$E$2:$E$13701,$Q12):INDEX(データ!$E$2:$E$13701,$R12),(INDEX(データ!$D$2:$D$13701,$Q12):INDEX(データ!$D$2:$D$13701,$R12)/$C12^2)^{1,2},TRUE(),TRUE()),1,1),"") | U12: =IFERROR(INDEX(LINEST(INDEX(データ!$E$2:$E$13701,$Q12):INDEX(データ!$E$2:$E$13701,$R12),(INDEX(データ!$D$2:$D$13701,$Q12):INDEX(データ!$D$2:$D$13701,$R12)/$C12^2)^{1,2},TRUE(),TRUE()),1,2),"") | V12: =IFERROR(INDEX(LINEST(INDEX(データ!$E$2:$E$13701,$Q12):INDEX(データ!$E$2:$E$13701,$R12),(INDEX(データ!$D$2:$D$13701,$Q12):INDEX(データ!$D$2:$D$13701,$R12)/$C12^2)^{1,2},TRUE(),TRUE()),1,3),"") | W12: =IFERROR(INDEX(LINEST(INDEX(データ!$E$2:$E$13701,$Q12):INDEX(データ!$E$2:$E$13701,$R12),(INDEX(データ!$D$2:$D$13701,$Q12):INDEX(データ!$D$2:$D$13701,$R12)/$C12^2)^{1,2},TRUE(),TRUE()),3,1),"") | X12: =IF($T12="","",-$U12/(2*$T12)) | Y12: =IF($X12="","",IF($X12<=0,"",$C12*SQRT($X12))) | Z12: =IF($X12="","",IFERROR(SQRT(MAX(0,$V12/($T12*$X12^2)-1)),"")) | AA12: =IF($Y12="","",1/(PI()*$Y12*設定!$B$17)) | AB12: =IF(OR($Z12="",$AA12=""),"",$Z12-$AA12) | AC12: =IF($AB12="","",IF($AB12<=0,"",1/$AB12)) | AD12: =IF($AB12="","",$AB12/2) | AE12: =IF($S12="","",IFERROR(SUMPRODUCT(ISNUMBER(INDEX(データ!$C$2:$C$13701,$Q12):INDEX(データ!$C$2:$C$13701,$R12))*(INDEX(データ!$C$2:$C$13701,$Q12):INDEX(データ!$C$2:$C$13701,$R12)>=$E12/SQRT(2)))*設定!$B$11/$Y12-$AA12,"")) | AF12: =IF($AB12="","",IF(AND($W12>=0.9,$AB12>0,$S12>=10,$Z12>$AA12*1.05),"OK","要確認"))
A13: 9 | B13: =IFERROR(MATCH($A13,データ!$H$2:$H$13701,0),"") | C13: =IF($B13="","",INDEX(データ!$A$2:$A$13701,$B13)) | D13: =IF($B13="","",INDEX(データ!$B$2:$B$13701,$B13)) | E13: =IF($B13="","",INDEX(データ!$C$2:$C$13701,$B13)) | F13: =IF($B13="","",MAX(1,$B13-設定!$B$36)) | G13: =IF($B13="","",MIN(設定!$B$38,$B13+設定!$B$36)) | H13: =IF($B13="","",$G13-$F13+1) | I13: =IFERROR(INDEX(LINEST(INDEX(データ!$E$2:$E$13701,$F13):INDEX(データ!$E$2:$E$13701,$G13),(INDEX(データ!$D$2:$D$13701,$F13):INDEX(データ!$D$2:$D$13701,$G13)/$C13^2)^{1,2},TRUE(),TRUE()),1,1),"") | J13: =IFERROR(INDEX(LINEST(INDEX(データ!$E$2:$E$13701,$F13):INDEX(データ!$E$2:$E$13701,$G13),(INDEX(データ!$D$2:$D$13701,$F13):INDEX(データ!$D$2:$D$13701,$G13)/$C13^2)^{1,2},TRUE(),TRUE()),1,2),"") | K13: =IFERROR(INDEX(LINEST(INDEX(データ!$E$2:$E$13701,$F13):INDEX(データ!$E$2:$E$13701,$G13),(INDEX(データ!$D$2:$D$13701,$F13):INDEX(データ!$D$2:$D$13701,$G13)/$C13^2)^{1,2},TRUE(),TRUE()),1,3),"") | L13: =IFERROR(INDEX(LINEST(INDEX(データ!$E$2:$E$13701,$F13):INDEX(データ!$E$2:$E$13701,$G13),(INDEX(データ!$D$2:$D$13701,$F13):INDEX(データ!$D$2:$D$13701,$G13)/$C13^2)^{1,2},TRUE(),TRUE()),3,1),"") | M13: =IF($I13="","",-$J13/(2*$I13)) | N13: =IF($M13="","",IF($M13<=0,"",$C13*SQRT($M13))) | O13: =IF($M13="","",IFERROR(SQRT(MAX(0,$K13/($I13*$M13^2)-1)),"")) | P13: =IF(OR($O13="",$N13=""),"",MAX(6,MIN(400,ROUND(設定!$B$37*$O13*$N13/設定!$B$11,0)))) | Q13: =IF($P13="","",MAX(1,$B13-$P13)) | R13: =IF($P13="","",MIN(設定!$B$38,$B13+$P13)) | S13: =IF($P13="","",$R13-$Q13+1) | T13: =IFERROR(INDEX(LINEST(INDEX(データ!$E$2:$E$13701,$Q13):INDEX(データ!$E$2:$E$13701,$R13),(INDEX(データ!$D$2:$D$13701,$Q13):INDEX(データ!$D$2:$D$13701,$R13)/$C13^2)^{1,2},TRUE(),TRUE()),1,1),"") | U13: =IFERROR(INDEX(LINEST(INDEX(データ!$E$2:$E$13701,$Q13):INDEX(データ!$E$2:$E$13701,$R13),(INDEX(データ!$D$2:$D$13701,$Q13):INDEX(データ!$D$2:$D$13701,$R13)/$C13^2)^{1,2},TRUE(),TRUE()),1,2),"") | V13: =IFERROR(INDEX(LINEST(INDEX(データ!$E$2:$E$13701,$Q13):INDEX(データ!$E$2:$E$13701,$R13),(INDEX(データ!$D$2:$D$13701,$Q13):INDEX(データ!$D$2:$D$13701,$R13)/$C13^2)^{1,2},TRUE(),TRUE()),1,3),"") | W13: =IFERROR(INDEX(LINEST(INDEX(データ!$E$2:$E$13701,$Q13):INDEX(データ!$E$2:$E$13701,$R13),(INDEX(データ!$D$2:$D$13701,$Q13):INDEX(データ!$D$2:$D$13701,$R13)/$C13^2)^{1,2},TRUE(),TRUE()),3,1),"") | X13: =IF($T13="","",-$U13/(2*$T13)) | Y13: =IF($X13="","",IF($X13<=0,"",$C13*SQRT($X13))) | Z13: =IF($X13="","",IFERROR(SQRT(MAX(0,$V13/($T13*$X13^2)-1)),"")) | AA13: =IF($Y13="","",1/(PI()*$Y13*設定!$B$17)) | AB13: =IF(OR($Z13="",$AA13=""),"",$Z13-$AA13) | AC13: =IF($AB13="","",IF($AB13<=0,"",1/$AB13)) | AD13: =IF($AB13="","",$AB13/2) | AE13: =IF($S13="","",IFERROR(SUMPRODUCT(ISNUMBER(INDEX(データ!$C$2:$C$13701,$Q13):INDEX(データ!$C$2:$C$13701,$R13))*(INDEX(データ!$C$2:$C$13701,$Q13):INDEX(データ!$C$2:$C$13701,$R13)>=$E13/SQRT(2)))*設定!$B$11/$Y13-$AA13,"")) | AF13: =IF($AB13="","",IF(AND($W13>=0.9,$AB13>0,$S13>=10,$Z13>$AA13*1.05),"OK","要確認"))
A14: 10 | B14: =IFERROR(MATCH($A14,データ!$H$2:$H$13701,0),"") | C14: =IF($B14="","",INDEX(データ!$A$2:$A$13701,$B14)) | D14: =IF($B14="","",INDEX(データ!$B$2:$B$13701,$B14)) | E14: =IF($B14="","",INDEX(データ!$C$2:$C$13701,$B14)) | F14: =IF($B14="","",MAX(1,$B14-設定!$B$36)) | G14: =IF($B14="","",MIN(設定!$B$38,$B14+設定!$B$36)) | H14: =IF($B14="","",$G14-$F14+1) | I14: =IFERROR(INDEX(LINEST(INDEX(データ!$E$2:$E$13701,$F14):INDEX(データ!$E$2:$E$13701,$G14),(INDEX(データ!$D$2:$D$13701,$F14):INDEX(データ!$D$2:$D$13701,$G14)/$C14^2)^{1,2},TRUE(),TRUE()),1,1),"") | J14: =IFERROR(INDEX(LINEST(INDEX(データ!$E$2:$E$13701,$F14):INDEX(データ!$E$2:$E$13701,$G14),(INDEX(データ!$D$2:$D$13701,$F14):INDEX(データ!$D$2:$D$13701,$G14)/$C14^2)^{1,2},TRUE(),TRUE()),1,2),"") | K14: =IFERROR(INDEX(LINEST(INDEX(データ!$E$2:$E$13701,$F14):INDEX(データ!$E$2:$E$13701,$G14),(INDEX(データ!$D$2:$D$13701,$F14):INDEX(データ!$D$2:$D$13701,$G14)/$C14^2)^{1,2},TRUE(),TRUE()),1,3),"") | L14: =IFERROR(INDEX(LINEST(INDEX(データ!$E$2:$E$13701,$F14):INDEX(データ!$E$2:$E$13701,$G14),(INDEX(データ!$D$2:$D$13701,$F14):INDEX(データ!$D$2:$D$13701,$G14)/$C14^2)^{1,2},TRUE(),TRUE()),3,1),"") | M14: =IF($I14="","",-$J14/(2*$I14)) | N14: =IF($M14="","",IF($M14<=0,"",$C14*SQRT($M14))) | O14: =IF($M14="","",IFERROR(SQRT(MAX(0,$K14/($I14*$M14^2)-1)),"")) | P14: =IF(OR($O14="",$N14=""),"",MAX(6,MIN(400,ROUND(設定!$B$37*$O14*$N14/設定!$B$11,0)))) | Q14: =IF($P14="","",MAX(1,$B14-$P14)) | R14: =IF($P14="","",MIN(設定!$B$38,$B14+$P14)) | S14: =IF($P14="","",$R14-$Q14+1) | T14: =IFERROR(INDEX(LINEST(INDEX(データ!$E$2:$E$13701,$Q14):INDEX(データ!$E$2:$E$13701,$R14),(INDEX(データ!$D$2:$D$13701,$Q14):INDEX(データ!$D$2:$D$13701,$R14)/$C14^2)^{1,2},TRUE(),TRUE()),1,1),"") | U14: =IFERROR(INDEX(LINEST(INDEX(データ!$E$2:$E$13701,$Q14):INDEX(データ!$E$2:$E$13701,$R14),(INDEX(データ!$D$2:$D$13701,$Q14):INDEX(データ!$D$2:$D$13701,$R14)/$C14^2)^{1,2},TRUE(),TRUE()),1,2),"") | V14: =IFERROR(INDEX(LINEST(INDEX(データ!$E$2:$E$13701,$Q14):INDEX(データ!$E$2:$E$13701,$R14),(INDEX(データ!$D$2:$D$13701,$Q14):INDEX(データ!$D$2:$D$13701,$R14)/$C14^2)^{1,2},TRUE(),TRUE()),1,3),"") | W14: =IFERROR(INDEX(LINEST(INDEX(データ!$E$2:$E$13701,$Q14):INDEX(データ!$E$2:$E$13701,$R14),(INDEX(データ!$D$2:$D$13701,$Q14):INDEX(データ!$D$2:$D$13701,$R14)/$C14^2)^{1,2},TRUE(),TRUE()),3,1),"") | X14: =IF($T14="","",-$U14/(2*$T14)) | Y14: =IF($X14="","",IF($X14<=0,"",$C14*SQRT($X14))) | Z14: =IF($X14="","",IFERROR(SQRT(MAX(0,$V14/($T14*$X14^2)-1)),"")) | AA14: =IF($Y14="","",1/(PI()*$Y14*設定!$B$17)) | AB14: =IF(OR($Z14="",$AA14=""),"",$Z14-$AA14) | AC14: =IF($AB14="","",IF($AB14<=0,"",1/$AB14)) | AD14: =IF($AB14="","",$AB14/2) | AE14: =IF($S14="","",IFERROR(SUMPRODUCT(ISNUMBER(INDEX(データ!$C$2:$C$13701,$Q14):INDEX(データ!$C$2:$C$13701,$R14))*(INDEX(データ!$C$2:$C$13701,$Q14):INDEX(データ!$C$2:$C$13701,$R14)>=$E14/SQRT(2)))*設定!$B$11/$Y14-$AA14,"")) | AF14: =IF($AB14="","",IF(AND($W14>=0.9,$AB14>0,$S14>=10,$Z14>$AA14*1.05),"OK","要確認"))
A15: 11 | B15: =IFERROR(MATCH($A15,データ!$H$2:$H$13701,0),"") | C15: =IF($B15="","",INDEX(データ!$A$2:$A$13701,$B15)) | D15: =IF($B15="","",INDEX(データ!$B$2:$B$13701,$B15)) | E15: =IF($B15="","",INDEX(データ!$C$2:$C$13701,$B15)) | F15: =IF($B15="","",MAX(1,$B15-設定!$B$36)) | G15: =IF($B15="","",MIN(設定!$B$38,$B15+設定!$B$36)) | H15: =IF($B15="","",$G15-$F15+1) | I15: =IFERROR(INDEX(LINEST(INDEX(データ!$E$2:$E$13701,$F15):INDEX(データ!$E$2:$E$13701,$G15),(INDEX(データ!$D$2:$D$13701,$F15):INDEX(データ!$D$2:$D$13701,$G15)/$C15^2)^{1,2},TRUE(),TRUE()),1,1),"") | J15: =IFERROR(INDEX(LINEST(INDEX(データ!$E$2:$E$13701,$F15):INDEX(データ!$E$2:$E$13701,$G15),(INDEX(データ!$D$2:$D$13701,$F15):INDEX(データ!$D$2:$D$13701,$G15)/$C15^2)^{1,2},TRUE(),TRUE()),1,2),"") | K15: =IFERROR(INDEX(LINEST(INDEX(データ!$E$2:$E$13701,$F15):INDEX(データ!$E$2:$E$13701,$G15),(INDEX(データ!$D$2:$D$13701,$F15):INDEX(データ!$D$2:$D$13701,$G15)/$C15^2)^{1,2},TRUE(),TRUE()),1,3),"") | L15: =IFERROR(INDEX(LINEST(INDEX(データ!$E$2:$E$13701,$F15):INDEX(データ!$E$2:$E$13701,$G15),(INDEX(データ!$D$2:$D$13701,$F15):INDEX(データ!$D$2:$D$13701,$G15)/$C15^2)^{1,2},TRUE(),TRUE()),3,1),"") | M15: =IF($I15="","",-$J15/(2*$I15)) | N15: =IF($M15="","",IF($M15<=0,"",$C15*SQRT($M15))) | O15: =IF($M15="","",IFERROR(SQRT(MAX(0,$K15/($I15*$M15^2)-1)),"")) | P15: =IF(OR($O15="",$N15=""),"",MAX(6,MIN(400,ROUND(設定!$B$37*$O15*$N15/設定!$B$11,0)))) | Q15: =IF($P15="","",MAX(1,$B15-$P15)) | R15: =IF($P15="","",MIN(設定!$B$38,$B15+$P15)) | S15: =IF($P15="","",$R15-$Q15+1) | T15: =IFERROR(INDEX(LINEST(INDEX(データ!$E$2:$E$13701,$Q15):INDEX(データ!$E$2:$E$13701,$R15),(INDEX(データ!$D$2:$D$13701,$Q15):INDEX(データ!$D$2:$D$13701,$R15)/$C15^2)^{1,2},TRUE(),TRUE()),1,1),"") | U15: =IFERROR(INDEX(LINEST(INDEX(データ!$E$2:$E$13701,$Q15):INDEX(データ!$E$2:$E$13701,$R15),(INDEX(データ!$D$2:$D$13701,$Q15):INDEX(データ!$D$2:$D$13701,$R15)/$C15^2)^{1,2},TRUE(),TRUE()),1,2),"") | V15: =IFERROR(INDEX(LINEST(INDEX(データ!$E$2:$E$13701,$Q15):INDEX(データ!$E$2:$E$13701,$R15),(INDEX(データ!$D$2:$D$13701,$Q15):INDEX(データ!$D$2:$D$13701,$R15)/$C15^2)^{1,2},TRUE(),TRUE()),1,3),"") | W15: =IFERROR(INDEX(LINEST(INDEX(データ!$E$2:$E$13701,$Q15):INDEX(データ!$E$2:$E$13701,$R15),(INDEX(データ!$D$2:$D$13701,$Q15):INDEX(データ!$D$2:$D$13701,$R15)/$C15^2)^{1,2},TRUE(),TRUE()),3,1),"") | X15: =IF($T15="","",-$U15/(2*$T15)) | Y15: =IF($X15="","",IF($X15<=0,"",$C15*SQRT($X15))) | Z15: =IF($X15="","",IFERROR(SQRT(MAX(0,$V15/($T15*$X15^2)-1)),"")) | AA15: =IF($Y15="","",1/(PI()*$Y15*設定!$B$17)) | AB15: =IF(OR($Z15="",$AA15=""),"",$Z15-$AA15) | AC15: =IF($AB15="","",IF($AB15<=0,"",1/$AB15)) | AD15: =IF($AB15="","",$AB15/2) | AE15: =IF($S15="","",IFERROR(SUMPRODUCT(ISNUMBER(INDEX(データ!$C$2:$C$13701,$Q15):INDEX(データ!$C$2:$C$13701,$R15))*(INDEX(データ!$C$2:$C$13701,$Q15):INDEX(データ!$C$2:$C$13701,$R15)>=$E15/SQRT(2)))*設定!$B$11/$Y15-$AA15,"")) | AF15: =IF($AB15="","",IF(AND($W15>=0.9,$AB15>0,$S15>=10,$Z15>$AA15*1.05),"OK","要確認"))
